Workbook
Name G: NA()
Name Hi: NA()
Name hii: NA()
Name Ho: NA()
Name maruza: [1]Jenipapo!$E$73
Name N: NA()
Name Resumo_da_Avaliação_do_Desempenho_do_Elo_Ibura: [1]Ibura!$A$11:$D$13
Name T: NA()
Name Vazão: NA()
Name Vi: NA()
Name Viii: NA()
Name W: NA()
Name _FilterDatabase_0: #REF!

Sheet ESCALA
A1: DATA | B1: ESCALA | C1: ESCALA
B2: 07:00h às 19:00h | C2: 19:00h às 07:00h
A3: 43922 | E3: DIGITAR PRIMEIRO DIA DO MÊS
A4: =ESCALA!A3+1 -> 43923
A5: =ESCALA!A4+1 -> 43924
A6: =ESCALA!A5+1 -> 43925
A7: =ESCALA!A6+1 -> 43926
A8: =ESCALA!A7+1 -> 43927
A9: =ESCALA!A8+1 -> 43928
A10: =ESCALA!A9+1 -> 43929
A11: =ESCALA!A10+1 -> 43930
A12: =ESCALA!A11+1 -> 43931
A13: =ESCALA!A12+1 -> 43932
A14: =ESCALA!A13+1 -> 43933
A15: =ESCALA!A14+1 -> 43934
... A33: =ESCALA!A32+1 -> 43952

Sheet 1
D2: CONTROLE DE ANÁLISE FÍSICO - QUÍMICAS \ ETA CASTELO BRANCO | AB2: CONTROLE DE PRODUTOS QUÍMICOS APLICADOS \ ETA CASTELO BRANCO
A4: HORA | B4: COR (Uc) | F4: TURBIDEZ (Ut) | K4: Ph | O4: CLORO RESIDUAL (mg/L) | R4: DOSAGEM DO COAGULANTE | T4: VAZÃO DA ETA | U4: TIPO DE COAGU LANTE | V4: TÉCNICO | X4: Hora | Y4: Vazão ETA (l/s) | Z4: Vazão Coagulante (l/h) | AA4: Código | AB4: Dosagem (mg/l) | AC4: Vazão Polímero (l/h) | AD4: Dosagem (mg/l) | AE4: Pré 1 (Lib/dia) | AF4: Pré 1 (Kg/h) | AG4: Pré 2 (Lib/dia) | AH4: Pré 2 (Kg/h) | AI4: Pós (Lib/dia) | AJ4: Pós (Kg/h) | AK4: Pré 1 (Lib/dia) cilindros | AL4: Pré 1 (Kg/h) cilindros | AM4: Pré 2 (Lib/dia) cilindros | AN4: Pré 2 (Kg/h) cilindros | AO4: Pós (Lib/dia) cilindros | AP4: Pós (Kg/h) cilindros | AQ4: COAGULANTE | AU4: Tempo de Utilização (h)
AQ5: Codigo | AR5: Nome | AS5: d (g/ml) | AT5: C (%)
B6: Bruta | C6: DEC_1 | D6: DEC_2 | E6: TRAT | F6: Bruta | G6: DEC_1 | H6: DEC_2 | I6: TRAT | J6: FILT | K6: Bruta | L6: DEC_1 | M6: DEC_2 | N6: TRAT | O6: TRAT | P6: DEC_1 | Q6: DEC_2 | R6: L/h | S6: mg/l | T6: L/s | X6: 0.041666667 | Y6: 3337 | Z6: 1198 | AA6: 1 | AB6: =IF('1'!AA6=1,(('1'!Z6*'1'!$AS$6*'1'!$AT$6)/('1'!Y6*0.0036)),IF('1'!AA6=2,(('1'!Z6*'1'!$AS$7*'1'!$AT$7)/('1'!Y6*0.0036)))) -> 66.316219 | AD6: =(('1'!AC6*'1'!$Q$10*1000000))/('1'!Z10*3600) -> 0 | AF6: =('1'!AE6/24)*0.454 -> 0 | AH6: =('1'!AG6/24)*0.454 -> 0 | AI6: 5400 | AJ6: =('1'!AI6/24)*0.454 -> 102.15 | AL6: =('1'!AK6/24)*0.454 -> 0 | AN6: =('1'!AM6/24)*0.454 -> 0 | AP6: =('1'!AO6/24)*0.454 -> 0 | AQ6: 1 | AR6: S.A.L | AS6: 1.33 | AT6: 0.5 | AU6: 0
A7: 0 | B7: 115 | C7: 13 | D7: 14 | E7: 6 | F7: 7.5 | G7: 1 | H7: 1 | I7: 0.5 | J7: 0.5 | K7: 6.9 | L7: 6.6 | M7: 6.6 | N7: 6.3 | O7: 3.6 | U7: =IF('1'!AA6=1,'1'!AR6,'1'!AR7) -> S.A.L | X7: 0.083333333 | Y7: 3353 | Z7: 1198 | AA7: 1 | AB7: =IF('1'!AA7=1,(('1'!Z7*'1'!$AS$6*'1'!$AT$6)/('1'!Y7*0.0036)),IF('1'!AA7=2,(('1'!Z7*'1'!$AS$7*'1'!$AT$7)/('1'!Y7*0.0036)))) -> 65.999768 | AD7: =(('1'!AC7*'1'!$Q$10*1000000))/('1'!Z11*3600) -> 0 | AF7: =('1'!AE7/24)*0.454 -> 0 | AH7: =('1'!AG7/24)*0.454 -> 0 | AI7: 5400 | AJ7: =('1'!AI7/24)*0.454 -> 102.15 | AL7: =('1'!AK7/24)*0.454 -> 0 | AN7: =('1'!AM7/24)*0.454 -> 0 | AP7: =('1'!AO7/24)*0.454 -> 0 | AQ7: 2 | AR7: PAC 18 | AS7: 1.377 | AT7: 1 | AU7: 24
A8: 0.083333333 | B8: 114 | C8: 12 | D8: 13 | E8: 6 | F8: 7.3 | G8: 0.9 | H8: 0.9 | I8: 0.5 | J8: 0.4 | K8: 6.9 | L8: 6.6 | M8: 6.6 | N8: 6.3 | O8: 3.6 | R8: ='1'!Z7 -> 1198 | S8: ='1'!AB7 -> 65.999768 | T8: ='1'!Y7 -> 3353 | U8: =IF('1'!AA7=1,'1'!AR6,'1'!AR7) -> S.A.L | X8: 0.125 | Y8: 3362 | Z8: 1198 | AA8: 1 | AB8: =IF('1'!AA8=1,(('1'!Z8*'1'!$AS$6*'1'!$AT$6)/('1'!Y8*0.0036)),IF('1'!AA8=2,(('1'!Z8*'1'!$AS$7*'1'!$AT$7)/('1'!Y8*0.0036)))) -> 65.823088 | AD8: =(('1'!AC8*'1'!$Q$10*1000000))/('1'!Z12*3600) -> 0 | AF8: =('1'!AE8/24)*0.454 -> 0 | AH8: =('1'!AG8/24)*0.454 -> 0 | AI8: 5400 | AJ8: =('1'!AI8/24)*0.454 -> 102.15 | AL8: =('1'!AK8/24)*0.454 -> 0 | AN8: =('1'!AM8/24)*0.454 -> 0 | AP8: =('1'!AO8/24)*0.454 -> 0 | AQ8: Polímero Catiônico
A9: 0.16666667 | B9: 112 | C9: 12 | D9: 12 | E9: 5 | F9: 7.2 | G9: 0.8 | H9: 0.9 | I9: 0.5 | J9: 0.4 | K9: 6.9 | L9: 6.6 | M9: 6 | N9: 6.3 | O9: 3.8 | R9: ='1'!Z9 -> 1198 | S9: ='1'!AB9 -> 65.881876 | T9: ='1'!Y9 -> 3359 | U9: =IF('1'!AA9=1,'1'!AR6,'1'!AR7) -> S.A.L | X9: 0.16666667 | Y9: 3359 | Z9: 1198 | AA9: 1 | AB9: =IF('1'!AA9=1,(('1'!Z9*'1'!$AS$6*'1'!$AT$6)/('1'!Y9*0.0036)),IF('1'!AA9=2,(('1'!Z9*'1'!$AS$7*'1'!$AT$7)/('1'!Y9*0.0036)))) -> 65.881876 | AD9: =(('1'!AC9*'1'!$Q$10*1000000))/('1'!Z13*3600) -> 0 | AF9: =('1'!AE9/24)*0.454 -> 0 | AH9: =('1'!AG9/24)*0.454 -> 0 | AI9: 5400 | AJ9: =('1'!AI9/24)*0.454 -> 102.15 | AL9: =('1'!AK9/24)*0.454 -> 0 | AN9: =('1'!AM9/24)*0.454 -> 0 | AP9: =('1'!AO9/24)*0.454 -> 0 | AQ9: Nome | AT9: C (%)
A10: 0.25 | B10: 111 | C10: 12 | D10: 12 | E10: 5 | F10: 6.9 | G10: 0.8 | H10: 0.9 | I10: 0.5 | J10: 0.4 | K10: 6.9 | L10: 6.6 | M10: 6.6 | N10: 6.3 | O10: 3.8 | R10: ='1'!Z11 -> 1198 | S10: ='1'!AB11 -> 65.725341 | T10: ='1'!Y11 -> 3367 | U10: =IF('1'!AA11=1,'1'!AR6,'1'!AR7) -> S.A.L | X10: 0.20833333 | Y10: 3371 | Z10: 1198 | AA10: 1 | AB10: =IF('1'!AA10=1,(('1'!Z10*'1'!$AS$6*'1'!$AT$6)/('1'!Y10*0.0036)),IF('1'!AA10=2,(('1'!Z10*'1'!$AS$7*'1'!$AT$7)/('1'!Y10*0.0036)))) -> 65.647352 | AD10: =(('1'!AC10*'1'!$Q$10*1000000))/('1'!Z14*3600) -> 0 | AF10: =('1'!AE10/24)*0.454 -> 0 | AH10: =('1'!AG10/24)*0.454 -> 0 | AI10: 5400 | AJ10: =('1'!AI10/24)*0.454 -> 102.15 | AL10: =('1'!AK10/24)*0.454 -> 0 | AN10: =('1'!AM10/24)*0.454 -> 0 | AP10: =('1'!AO10/24)*0.454 -> 0 | AQ10: Aguapol 200 | AT10: 0.002
A11: 0.33333333 | B11: 108 | C11: 12 | D11: 11 | E11: 6 | F11: 7 | G11: 0.9 | H11: 0.9 | I11: 0.5 | J11: 0.4 | K11: 6.9 | L11: 6.6 | M11: 6.6 | N11: 6.3 | O11: 3.8 | R11: ='1'!Z13 -> 1198 | S11: ='1'!AB13 -> 66.058872 | T11: ='1'!Y13 -> 3350 | U11: =IF('1'!AA13=1,'1'!AR6,'1'!AR7) -> S.A.L | X11: 0.25 | Y11: 3367 | Z11: 1198 | AA11: 1 | AB11: =IF('1'!AA11=1,(('1'!Z11*'1'!$AS$6*'1'!$AT$6)/('1'!Y11*0.0036)),IF('1'!AA11=2,(('1'!Z11*'1'!$AS$7*'1'!$AT$7)/('1'!Y11*0.0036)))) -> 65.725341 | AD11: =(('1'!AC11*'1'!$Q$10*1000000))/('1'!Z15*3600) -> 0 | AF11: =('1'!AE11/24)*0.454 -> 0 | AH11: =('1'!AG11/24)*0.454 -> 0 | AI11: 5400 | AJ11: =('1'!AI11/24)*0.454 -> 102.15 | AL11: =('1'!AK11/24)*0.454 -> 0 | AN11: =('1'!AM11/24)*0.454 -> 0 | AP11: =('1'!AO11/24)*0.454 -> 0
A12: 0.41666667 | B12: 109 | C12: 12 | D12: 11 | E12: 6 | F12: 7.1 | G12: 0.9 | H12: 0.9 | I12: 0.5 | J12: 0.4 | K12: 6.9 | L12: 6.6 | M12: 6.6 | N12: 6.3 | O12: 3.6 | R12: ='1'!Z15 -> 1198 | S12: ='1'!AB15 -> 66.058872 | T12: ='1'!Y15 -> 3350 | U12: =IF('1'!AA15=1,'1'!AR6,'1'!AR7) -> S.A.L | V12: =ESCALA!$B$3 | X12: 0.29166667 | Y12: 3350 | Z12: 1198 | AA12: 1 | AB12: =IF('1'!AA12=1,(('1'!Z12*'1'!$AS$6*'1'!$AT$6)/('1'!Y12*0.0036)),IF('1'!AA12=2,(('1'!Z12*'1'!$AS$7*'1'!$AT$7)/('1'!Y12*0.0036)))) -> 66.058872 | AD12: =(('1'!AC12*'1'!$Q$10*1000000))/('1'!Z16*3600) -> 0 | AF12: =('1'!AE12/24)*0.454 -> 0 | AH12: =('1'!AG12/24)*0.454 -> 0 | AI12: 5200 | AJ12: =('1'!AI12/24)*0.454 -> 98.366667 | AL12: =('1'!AK12/24)*0.454 -> 0 | AN12: =('1'!AM12/24)*0.454 -> 0 | AP12: =('1'!AO12/24)*0.454 -> 0
A13: 0.5 | B13: 110 | C13: 12 | D13: 11 | E13: 6 | F13: 7.3 | G13: 1 | H13: 1 | I13: 0.5 | J13: 0.4 | K13: 6.9 | L13: 6.6 | M13: 6.6 | N13: 6.3 | O13: 3.6 | R13: ='1'!Z17 -> 1198 | S13: ='1'!AB17 -> 66.058872 | T13: ='1'!Y17 -> 3350 | U13: =IF('1'!AA17=1,'1'!AR6,'1'!AR7) -> S.A.L | X13: 0.33333333 | Y13: 3350 | Z13: 1198 | AA13: 1 | AB13: =IF('1'!AA13=1,(('1'!Z13*'1'!$AS$6*'1'!$AT$6)/('1'!Y13*0.0036)),IF('1'!AA13=2,(('1'!Z13*'1'!$AS$7*'1'!$AT$7)/('1'!Y13*0.0036)))) -> 66.058872 | AD13: =(('1'!AC13*'1'!$Q$10*1000000))/('1'!Z17*3600) -> 0 | AF13: =('1'!AE13/24)*0.454 -> 0 | AH13: =('1'!AG13/24)*0.454 -> 0 | AI13: 5200 | AJ13: =('1'!AI13/24)*0.454 -> 98.366667 | AL13: =('1'!AK13/24)*0.454 -> 0 | AN13: =('1'!AM13/24)*0.454 -> 0 | AP13: =('1'!AO13/24)*0.454 -> 0
A14: 0.58333333 | B14: 110 | C14: 12 | D14: 12 | E14: 6 | F14: 7.5 | G14: 1 | H14: 1.1 | I14: 0.5 | J14: 0.4 | K14: 6.9 | L14: 6.6 | M14: 6.6 | N14: 6.3 | O14: 3.5 | R14: ='1'!Z19 -> 1198 | S14: ='1'!AB19 -> 66.058872 | T14: ='1'!Y19 -> 3350 | U14: =IF('1'!AA19=1,'1'!AR6,'1'!AR7) -> S.A.L | X14: 0.375 | Y14: 3350 | Z14: 1198 | AA14: 1 | AB14: =IF('1'!AA14=1,(('1'!Z14*'1'!$AS$6*'1'!$AT$6)/('1'!Y14*0.0036)),IF('1'!AA14=2,(('1'!Z14*'1'!$AS$7*'1'!$AT$7)/('1'!Y14*0.0036)))) -> 66.058872 | AD14: =(('1'!AC14*'1'!$Q$10*1000000))/('1'!Z18*3600) -> 0 | AF14: =('1'!AE14/24)*0.454 -> 0 | AH14: =('1'!AG14/24)*0.454 -> 0 | AI14: 5200 | AJ14: =('1'!AI14/24)*0.454 -> 98.366667 | AL14: =('1'!AK14/24)*0.454 -> 0 | AN14: =('1'!AM14/24)*0.454 -> 0 | AP14: =('1'!AO14/24)*0.454 -> 0
A15: 0.66666667 | B15: 108 | C15: 12 | D15: 12 | E15: 6 | F15: 7.6 | G15: 1 | H15: 1.1 | I15: 0.5 | J15: 0.4 | K15: 6.9 | L15: 6.6 | M15: 6.6 | N15: 6.3 | O15: 3.5 | R15: ='1'!Z21 -> 1198 | S15: ='1'!AB21 -> 66.058872 | T15: ='1'!Y21 -> 3350 | U15: =IF('1'!AA21=1,'1'!AR6,'1'!AR7) -> S.A.L | X15: 0.41666667 | Y15: 3350 | Z15: 1198 | AA15: 1 | AB15: =IF('1'!AA15=1,(('1'!Z15*'1'!$AS$6*'1'!$AT$6)/('1'!Y15*0.0036)),IF('1'!AA15=2,(('1'!Z15*'1'!$AS$7*'1'!$AT$7)/('1'!Y15*0.0036)))) -> 66.058872 | AD15: =(('1'!AC15*'1'!$Q$10*1000000))/('1'!Z19*3600) -> 0 | AF15: =('1'!AE15/24)*0.454 -> 0 | AH15: =('1'!AG15/24)*0.454 -> 0 | AI15: 5200 | AJ15: =('1'!AI15/24)*0.454 -> 98.366667 | AL15: =('1'!AK15/24)*0.454 -> 0 | AN15: =('1'!AM15/24)*0.454 -> 0 | AP15: =('1'!AO15/24)*0.454 -> 0
A16: 0.75 | B16: 109 | C16: 12 | D16: 12 | E16: 6 | F16: 7.4 | G16: 1 | H16: 1 | I16: 0.5 | J16: 0.4 | K16: 6.9 | L16: 6.6 | M16: 6.6 | N16: 6.3 | O16: 3.5 | R16: ='1'!Z23 -> 1198 | S16: ='1'!AB23 -> 66.058872 | T16: ='1'!Y23 -> 3350 | U16: =IF('1'!AA23=1,'1'!AR6,'1'!AR7) -> S.A.L | X16: 0.45833333 | Y16: 3350 | Z16: 1198 | AA16: 1 | AB16: =IF('1'!AA16=1,(('1'!Z16*'1'!$AS$6*'1'!$AT$6)/('1'!Y16*0.0036)),IF('1'!AA16=2,(('1'!Z16*'1'!$AS$7*'1'!$AT$7)/('1'!Y16*0.0036)))) -> 66.058872 | AD16: =(('1'!AC16*'1'!$Q$10*1000000))/('1'!Z20*3600) -> 0 | AF16: =('1'!AE16/24)*0.454 -> 0 | AH16: =('1'!AG16/24)*0.454 -> 0 | AI16: 5200 | AJ16: =('1'!AI16/24)*0.454 -> 98.366667 | AL16: =('1'!AK16/24)*0.454 -> 0 | AN16: =('1'!AM16/24)*0.454 -> 0 | AP16: =('1'!AO16/24)*0.454 -> 0
A17: 0.83333333 | B17: 107 | C17: 12 | D17: 12 | E17: 6 | F17: 7.3 | G17: 0.9 | H17: 0.9 | I17: 0.5 | J17: 0.4 | K17: 7 | L17: 6.6 | M17: 6.6 | N17: 6.3 | O17: 3.6 | R17: ='1'!Z25 -> 1198 | S17: ='1'!AB25 -> 66.058872 | T17: ='1'!Y25 -> 3350 | U17: =IF('1'!AA25=1,'1'!AR6,'1'!AR7) -> S.A.L | V17: =ESCALA!$C$3 | X17: 0.5 | Y17: 3350 | Z17: 1198 | AA17: 1 | AB17: =IF('1'!AA17=1,(('1'!Z17*'1'!$AS$6*'1'!$AT$6)/('1'!Y17*0.0036)),IF('1'!AA17=2,(('1'!Z17*'1'!$AS$7*'1'!$AT$7)/('1'!Y17*0.0036)))) -> 66.058872 | AD17: =(('1'!AC17*'1'!$Q$10*1000000))/('1'!Z21*3600) -> 0 | AF17: =('1'!AE17/24)*0.454 -> 0 | AH17: =('1'!AG17/24)*0.454 -> 0 | AI17: 5200 | AJ17: =('1'!AI17/24)*0.454 -> 98.366667 | AL17: =('1'!AK17/24)*0.454 -> 0 | AN17: =('1'!AM17/24)*0.454 -> 0 | AP17: =('1'!AO17/24)*0.454 -> 0
A18: 0.91666667 | B18: 109 | C18: 12 | D18: 12 | E18: 6 | F18: 7.2 | G18: 1 | H18: 0.9 | I18: 0.5 | J18: 0.4 | K18: 7 | L18: 6.6 | M18: 6.6 | N18: 6.3 | O18: 3.6 | R18: ='1'!Z27 -> 1030 | S18: ='1'!AB27 -> 77.029915 | T18: ='1'!Y27 -> 2470 | U18: =IF('1'!AA27=1,'1'!AR6,'1'!AR7) -> S.A.L | X18: 0.54166667 | Y18: 3350 | Z18: 1198 | AA18: 1 | AB18: =IF('1'!AA18=1,(('1'!Z18*'1'!$AS$6*'1'!$AT$6)/('1'!Y18*0.0036)),IF('1'!AA18=2,(('1'!Z18*'1'!$AS$7*'1'!$AT$7)/('1'!Y18*0.0036)))) -> 66.058872 | AD18: =(('1'!AC18*'1'!$Q$10*1000000))/('1'!Z22*3600) -> 0 | AF18: =('1'!AE18/24)*0.454 -> 0 | AH18: =('1'!AG18/24)*0.454 -> 0 | AI18: 5200 | AJ18: =('1'!AI18/24)*0.454 -> 98.366667 | AL18: =('1'!AK18/24)*0.454 -> 0 | AN18: =('1'!AM18/24)*0.454 -> 0 | AP18: =('1'!AO18/24)*0.454 -> 0
A19: Média | B19: {=IF('1'!B7:B18>0.01,AVERAGE('1'!B7:B18),"")} -> 110.16667 | C19: {=IF('1'!C7:C18>0.01,AVERAGE('1'!C7:C18),"")} -> 12.083333 | D19: {=IF('1'!D7:D18>0.01,AVERAGE('1'!D7:D18),"")} -> 12 | E19: {=IF('1'!E7:E18>0.01,AVERAGE('1'!E7:E18),"")} -> 5.8333333 | F19: {=IF('1'!F7:F18>0.01,AVERAGE('1'!F7:F18),"")} -> 7.275 | G19: {=IF('1'!G7:G18>0.01,AVERAGE('1'!G7:G18),"")} -> 0.93333333 | H19: {=IF('1'!H7:H18>0.01,AVERAGE('1'!H7:H18),"")} -> 0.95833333 | I19: {=IF('1'!I7:I18>0.01,AVERAGE('1'!I7:I18),"")} -> 0.5 | ... S19: {=IF('1'!S7:S18>0.01,AVERAGE('1'!S7:S18),"")} | X19: 0.58333333 | Y19: 3350 | Z19: 1198 | AA19: 1 | AB19: =IF('1'!AA19=1,(('1'!Z19*'1'!$AS$6*'1'!$AT$6)/('1'!Y19*0.0036)),IF('1'!AA19=2,(('1'!Z19*'1'!$AS$7*'1'!$AT$7)/('1'!Y19*0.0036)))) -> 66.058872 | AD19: =(('1'!AC19*'1'!$Q$10*1000000))/('1'!Z23*3600) -> 0 | AF19: =('1'!AE19/24)*0.454 -> 0 | AH19: =('1'!AG19/24)*0.454 -> 0 | AI19: 5200 | AJ19: =('1'!AI19/24)*0.454 -> 98.366667 | AL19: =('1'!AK19/24)*0.454 -> 0 | AN19: =('1'!AM19/24)*0.454 -> 0 | AP19: =('1'!AO19/24)*0.454 -> 0
A20: Máximo | B20: =MAX('1'!B7:B18) -> 115 | C20: =MAX('1'!C7:C18) -> 13 | D20: =MAX('1'!D7:D18) -> 14 | E20: =MAX('1'!E7:E18) -> 6 | F20: =MAX('1'!F7:F18) -> 7.6 | G20: =MAX('1'!G7:G18) -> 1 | H20: =MAX('1'!H7:H18) -> 1.1 | I20: =MAX('1'!I7:I18) -> 0.5 | ... S20: =MAX('1'!S7:S18) -> 77.029915 | X20: 0.625 | Y20: 3350 | Z20: 1198 | AA20: 1 | AB20: =IF('1'!AA20=1,(('1'!Z20*'1'!$AS$6*'1'!$AT$6)/('1'!Y20*0.0036)),IF('1'!AA20=2,(('1'!Z20*'1'!$AS$7*'1'!$AT$7)/('1'!Y20*0.0036)))) -> 66.058872 | AD20: =(('1'!AC20*'1'!$Q$10*1000000))/('1'!Z24*3600) -> 0 | AF20: =('1'!AE20/24)*0.454 -> 0 | AH20: =('1'!AG20/24)*0.454 -> 0 | AI20: 5200 | AJ20: =('1'!AI20/24)*0.454 -> 98.366667 | AL20: =('1'!AK20/24)*0.454 -> 0 | AN20: =('1'!AM20/24)*0.454 -> 0 | AP20: =('1'!AO20/24)*0.454 -> 0
A21: Mínimo | B21: =MIN('1'!B7:B18) -> 107 | C21: =MIN('1'!C7:C18) -> 12 | D21: =MIN('1'!D7:D18) -> 11 | E21: =MIN('1'!E7:E18) -> 5 | F21: =MIN('1'!F7:F18) -> 6.9 | G21: =MIN('1'!G7:G18) -> 0.8 | H21: =MIN('1'!H7:H18) -> 0.9 | I21: =MIN('1'!I7:I18) -> 0.5 | ... S21: =MIN('1'!S7:S18) -> 65.725341 | X21: 0.66666667 | Y21: 3350 | Z21: 1198 | AA21: 1 | AB21: =IF('1'!AA21=1,(('1'!Z21*'1'!$AS$6*'1'!$AT$6)/('1'!Y21*0.0036)),IF('1'!AA21=2,(('1'!Z21*'1'!$AS$7*'1'!$AT$7)/('1'!Y21*0.0036)))) -> 66.058872 | AD21: =(('1'!AC21*'1'!$Q$10*1000000))/('1'!Y21*3600) -> 0 | AF21: =('1'!AE21/24)*0.454 -> 0 | AH21: =('1'!AG21/24)*0.454 -> 0 | AI21: 5200 | AJ21: =('1'!AI21/24)*0.454 -> 98.366667 | AL21: =('1'!AK21/24)*0.454 -> 0 | AN21: =('1'!AM21/24)*0.454 -> 0 | AP21: =('1'!AO21/24)*0.454 -> 0
R22: Total | X22: 0.70833333 | Y22: 3350 | Z22: 1198 | AA22: 1 | AB22: =IF('1'!AA22=1,(('1'!Z22*'1'!$AS$6*'1'!$AT$6)/('1'!Y22*0.0036)),IF('1'!AA22=2,(('1'!Z22*'1'!$AS$7*'1'!$AT$7)/('1'!Y22*0.0036)))) -> 66.058872 | AD22: =(('1'!AC22*'1'!$Q$10*1000000))/('1'!Y22*3600) -> 0 | AF22: =('1'!AE22/24)*0.454 -> 0 | AH22: =('1'!AG22/24)*0.454 -> 0 | AI22: 5200 | AJ22: =('1'!AI22/24)*0.454 -> 98.366667 | AL22: =('1'!AK22/24)*0.454 -> 0 | AN22: =('1'!AM22/24)*0.454 -> 0 | AP22: =('1'!AO22/24)*0.454 -> 0
A23: TURBIDEZ DOS FILTROS DA 1ª E 2ª ETAPAS | R23: 440 | S23: Litros | X23: 0.75 | Y23: 3350 | Z23: 1198 | AA23: 1 | AB23: =IF('1'!AA23=1,(('1'!Z23*'1'!$AS$6*'1'!$AT$6)/('1'!Y23*0.0036)),IF('1'!AA23=2,(('1'!Z23*'1'!$AS$7*'1'!$AT$7)/('1'!Y23*0.0036)))) -> 66.058872 | AD23: =(('1'!AC23*'1'!$Q$10*1000000))/('1'!Y23*3600) -> 0 | AF23: =('1'!AE23/24)*0.454 -> 0 | AH23: =('1'!AG23/24)*0.454 -> 0 | AI23: 5200 | AJ23: =('1'!AI23/24)*0.454 -> 98.366667 | AL23: =('1'!AK23/24)*0.454 -> 0 | AN23: =('1'!AM23/24)*0.454 -> 0 | AP23: =('1'!AO23/24)*0.454 -> 0
A24: HORA | B24: 1 | C24: 2 | D24: 3 | E24: 4 | F24: 5 | G24: 6 | H24: 7 | I24: 8 | J24: 9 | K24: 10 | L24: 11 | M24: 12 | N24: 13 | O24: 14 | P24: 15 | Q24: 16 | R24: 0 | S24: Kilos | X24: 0.79166667 | Y24: 3350 | Z24: 1198 | AA24: 1 | AB24: =IF('1'!AA24=1,(('1'!Z24*'1'!$AS$6*'1'!$AT$6)/('1'!Y24*0.0036)),IF('1'!AA24=2,(('1'!Z24*'1'!$AS$7*'1'!$AT$7)/('1'!Y24*0.0036)))) -> 66.058872 | AD24: =(('1'!AC24*'1'!$Q$10*1000000))/('1'!Y24*3600) -> 0 | AF24: =('1'!AE24/24)*0.454 -> 0 | AH24: =('1'!AG24/24)*0.454 -> 0 | AI24: 5200 | AJ24: =('1'!AI24/24)*0.454 -> 98.366667 | AL24: =('1'!AK24/24)*0.454 -> 0 | AN24: =('1'!AM24/24)*0.454 -> 0 | AP24: =('1'!AO24/24)*0.454 -> 0
A25: 0.41666667 | R25: =#DIV/0! -> #DIV/0! | T25: DATA | U25: =ESCALA!$A$3 -> 43922 | X25: 0.83333333 | Y25: 3350 | Z25: 1198 | AA25: 1 | AB25: =IF('1'!AA25=1,(('1'!Z25*'1'!$AS$6*'1'!$AT$6)/('1'!Y25*0.0036)),IF('1'!AA25=2,(('1'!Z25*'1'!$AS$7*'1'!$AT$7)/('1'!Y25*0.0036)))) -> 66.058872 | AD25: =(('1'!AC25*'1'!$Q$10*1000000))/('1'!Y25*3600) -> 0 | AF25: =('1'!AE25/24)*0.454 -> 0 | AH25: =('1'!AG25/24)*0.454 -> 0 | AI25: 5200 | AJ25: =('1'!AI25/24)*0.454 -> 98.366667 | AL25: =('1'!AK25/24)*0.454 -> 0 | AN25: =('1'!AM25/24)*0.454 -> 0 | AP25: =('1'!AO25/24)*0.454 -> 0
A26: 0.66666667 | X26: 0.875 | Y26: 3350 | Z26: 1198 | AA26: 1 | AB26: =IF('1'!AA26=1,(('1'!Z26*'1'!$AS$6*'1'!$AT$6)/('1'!Y26*0.0036)),IF('1'!AA26=2,(('1'!Z26*'1'!$AS$7*'1'!$AT$7)/('1'!Y26*0.0036)))) -> 66.058872 | AD26: =(('1'!AC26*'1'!$Q$10*1000000))/('1'!Y26*3600) -> 0 | AF26: =('1'!AE26/24)*0.454 -> 0 | AH26: =('1'!AG26/24)*0.454 -> 0 | AI26: 5200 | AJ26: =('1'!AI26/24)*0.454 -> 98.366667 | AL26: =('1'!AK26/24)*0.454 -> 0 | AN26: =('1'!AM26/24)*0.454 -> 0 | AP26: =('1'!AO26/24)*0.454 -> 0
A27: Média | B27: =#DIV/0! -> #DIV/0! | C27: =#DIV/0! -> #DIV/0! | D27: =#DIV/0! -> #DIV/0! | E27: =#DIV/0! -> #DIV/0! | F27: =#DIV/0! -> #DIV/0! | G27: =#DIV/0! -> #DIV/0! | H27: =#DIV/0! -> #DIV/0! | I27: =#DIV/0! -> #DIV/0! | ... Q27: =#DIV/0! -> #DIV/0! | X27: 0.91666667 | Y27: 2470 | Z27: 1030 | AA27: 1 | AB27: =IF('1'!AA27=1,(('1'!Z27*'1'!$AS$6*'1'!$AT$6)/('1'!Y27*0.0036)),IF('1'!AA27=2,(('1'!Z27*'1'!$AS$7*'1'!$AT$7)/('1'!Y27*0.0036)))) -> 77.029915 | AD27: =(('1'!AC27*'1'!$Q$10*1000000))/('1'!Y27*3600) -> 0 | AF27: =('1'!AE27/24)*0.454 -> 0 | AH27: =('1'!AG27/24)*0.454 -> 0 | AI27: 5200 | AJ27: =('1'!AI27/24)*0.454 -> 98.366667 | AL27: =('1'!AK27/24)*0.454 -> 0 | AN27: =('1'!AM27/24)*0.454 -> 0 | AP27: =('1'!AO27/24)*0.454 -> 0
A28: OBSERVAÇÕES | X28: 0.95833333 | Y28: 3350 | Z28: 1198 | AA28: 1 | AB28: =IF('1'!AA28=1,(('1'!Z28*'1'!$AS$6*'1'!$AT$6)/('1'!Y28*0.0036)),IF('1'!AA28=2,(('1'!Z28*'1'!$AS$7*'1'!$AT$7)/('1'!Y28*0.0036)))) -> 66.058872 | AD28: =(('1'!AC28*'1'!$Q$10*1000000))/('1'!Y28*3600) -> 0 | AF28: =('1'!AE28/24)*0.454 -> 0 | AH28: =('1'!AG28/24)*0.454 -> 0 | AI28: 5200 | AJ28: =('1'!AI28/24)*0.454 -> 98.366667 | AL28: =('1'!AK28/24)*0.454 -> 0 | AN28: =('1'!AM28/24)*0.454 -> 0 | AP28: =('1'!AO28/24)*0.454 -> 0
X29: 1 | Y29: 3350 | Z29: 1198 | AA29: 1 | AB29: =IF('1'!AA29=1,(('1'!Z29*'1'!$AS$6*'1'!$AT$6)/('1'!Y29*0.0036)),IF('1'!AA29=2,(('1'!Z29*'1'!$AS$7*'1'!$AT$7)/('1'!Y29*0.0036)))) -> 66.058872 | AD29: =(('1'!AC29*'1'!$Q$10*1000000))/('1'!Y29*3600) -> 0 | AF29: =('1'!AE29/24)*0.454 -> 0 | AH29: =('1'!AG29/24)*0.454 -> 0 | AI29: 5200 | AJ29: =('1'!AI29/24)*0.454 -> 98.366667 | AL29: =('1'!AK29/24)*0.454 -> 0 | AN29: =('1'!AM29/24)*0.454 -> 0 | AP29: =('1'!AO29/24)*0.454 -> 0
X30: Total | Y30: =SUM('1'!Y6:Y29)*3.6 -> 286448.4 | Z30: =SUM('1'!Z6:Z29) -> 28584 | AF30: =SUM('1'!AF6:AF29) -> 0 | AH30: =SUM('1'!AH6:AH29) -> 0 | AJ30: =SUM('1'!AJ6:AJ29) -> 2383.5 | AL30: =SUM('1'!AL6:AL29) -> 0 | AN30: =SUM('1'!AN6:AN29) -> 0 | AP30: =SUM('1'!AP6:AP29) -> 0
X32: S.A.L (l) - (kg) | Z32: =SUMIF('1'!AA6:AA29,"=1",'1'!Z6:Z29) -> 28584 | AA32: ='1'!Z32*'1'!AS6 -> 38016.72 | AB32: =SUMIF('1'!$AA$6:$AA$29,"=1",'1'!$AB$6:$AB$29)/COUNTIF('1'!$AA$6:$AA$29,"=1") -> 66.476016 | AC32: =SUMIF('1'!AA6:AA29,"=1",'1'!AC6:AC29) -> 0
X33: PAC 18 (l) - (kg) | Z33: =SUMIF('1'!AA6:AA29,"=2",'1'!Z6:Z29) -> 0 | AA33: ='1'!Z33*'1'!AS7 -> 0 | AB33: =SUMIF('1'!$AA$6:$AA$29,"=2",'1'!$AB$6:$AB$29)/COUNTIF('1'!$AA$6:$AA$29,"=2") -> #DIV/0! | AC33: =SUMIF('1'!AA6:AA29,"=2",'1'!AC6:AC29) -> 0
X34: Média | Y34: =AVERAGE('1'!Y6:Y29) -> 3315.375 | Z34: =AVERAGE('1'!Z6:Z29) -> 1191 | AC34: =SUM('1'!AC6:AC29)/COUNTIF('1'!AC6:AC29,"<>0") -> #DIV/0! | AD34: =SUM('1'!AD6:AD29)/COUNTIF('1'!AD6:AD29,"<>0") -> #DIV/0! | AF34: =AVERAGE('1'!AF6:AF29) -> 0 | AH34: =AVERAGE('1'!AH6:AH29) -> 0 | AJ34: ='1'!AJ30/24 -> 99.3125 | AL34: =AVERAGE('1'!AL6:AL29) -> 0 | AN34: =AVERAGE('1'!AN6:AN29) -> 0 | AP34: =AVERAGE('1'!AP6:AP29) -> 0
C35: Alcalinidade (mg/L) | F35: Ferro (mg/L) | I35: Manganês (mg/L) | L35: Alumínio (mg/L) | U35: TÉCNICO | X35: Decantadores | AA35: Filtros | AJ35: CLORAÇÃO INTERMEDIÁRIA | AO35: PÓS CLORAÇÃO
B36: HORA | C36: Bruta | D36: Dec. | E36: Trat (R-3) | F36: Bruta | G36: Filt. | H36: Trat (R-3) | I36: Bruta | J36: Filt. | K36: Trat (R-3) | L36: Trat (R-3) | X36: Lavados | AA36: Lavados
B37: 0.33333333 | C37: 60.2 | D37: 33.1 | E37: 29.1 | F37: 1 | G37: 0.2 | H37: 0.1 | I37: 0.15 | J37: 0.03 | K37: 0.03 | L37: 0.15 | U37: ='1'!V12 | X37: HORAS OPERANDO | Z37: =COUNTA('1'!Z6:Z29) -> 24 | AJ37: CARRETA | AL37: CILINDROS | AO37: CARRETA | AQ37: CILINDROS
B38: 0.66666667 | AJ38: CONSUMO | AK38: =SUM('1'!AF30+'1'!AH30) -> 0 | AL38: CONSUMO | AM38: =SUM('1'!AL30+'1'!AN30) -> 0 | AO38: CONSUMO | AP38: ='1'!AJ30 -> 2383.5 | AQ38: CONSUMO | AR38: ='1'!AP30 -> 0
A39: Nº amostras de água TRATADA | C39: Nº amostras de água FILTRADA | E39: Nº amostras de água tratada/filtrada FORA DO PADRÃO | J39: Nº amostras de água tratada/filtrada no PADRÃO | O39: Nº de amostras com turbidez menor ou igual a 0,5 NTU | R39: ÁGUA FILTRADA | S39: Nº de amostras com turbidez menor ou igual a 1,0 NTU | AJ39: DOSAGEM | AK39: =('1'!AK38/'1'!Y30)*1000 -> 0 | AL39: DOSAGEM | AM39: =('1'!AM38/'1'!Y30)*1000 -> 0 | AO39: DOSAGEM | AP39: =('1'!AP38/'1'!Y30)*1000 -> 8.3208704 | AQ39: DOSAGEM | AR39: =('1'!AR38/'1'!Y30)*1000 -> 0
A40: COR | B40: TURBIDEZ | C40: TURBIDEZ | E40: COR | G40: TURBIDEZ | J40: COR | L40: TURBIDEZ | X40: ESTOQUE DE COAGULANTE | AJ40: Consumo Total | AL40: =SUM('1'!AK38,'1'!AM38) -> 0 | AO40: Consumo Total | AQ40: =SUM('1'!AP38,'1'!AR38) -> 2383.5
A41: =COUNTA('1'!E7:E18) -> 12 | B41: =COUNTA('1'!I7:I18) -> 12 | C41: =COUNTA('1'!J7:J18) -> 12 | E41: =COUNTIF('1'!E7:E18,">15") -> 0 | G41: =COUNTIF('1'!J7:J18,">1") -> 0 | J41: ='1'!A41-'1'!E41 -> 12 | L41: ='1'!C41-'1'!G41 -> 12 | O41: =COUNTIF('1'!J7:J18,"<=0,5") -> 12 | S41: =COUNTIF('1'!J7:J18,"<=1,0") -> 12 | AJ41: Dosagem Final | AL41: =SUM(('1'!AK38+'1'!AM38)/'1'!Y30)*1000 -> 0 | AO41: Dosagem Final | AQ41: =SUM(('1'!AP38+'1'!AR38)/'1'!Y30)*1000 -> 8.3208704
O42: ÁGUA FILTRATADA | X42: SULFATO DE ALUMÍNIO
H43: Nº de amostras água tratada com turbidez <= 5,0 NTU | L43: Nº de amostras água tratada para aluminio | Q43: Nº de amostras com turbidez entre 0,5 e 1,0 NTU | X43: TINA 01 | Z43: TINA 02 | AB43: TINA 03 | AD43: TANQUE
...

Sheet 2
D2: CONTROLE DE ANÁLISE FÍSICO - QUÍMICAS \ ETA CASTELO BRANCO | AB2: CONTROLE DE PRODUTOS QUÍMICOS APLICADOS \ ETA CASTELO BRANCO
A4: HORA | B4: COR (Uc) | F4: TURBIDEZ (Ut) | K4: Ph | O4: CLORO RESIDUAL (mg/L) | R4: DOSAGEM DO COAGULANTE | T4: VAZÃO DA ETA | U4: TIPO DE COAGULANTE | V4: TÉCNICO | X4: Hora | Y4: Vazão ETA (l/s) | Z4: Vazão Coagulante (l/h) | AA4: Código | AB4: Dosagem (mg/l) | AC4: Vazão Polímero (l/h) | AD4: Dosagem (mg/l) | AE4: Pré 1 (Lib/dia) | AF4: Pré 1 (Kg/h) | AG4: Pré 2 (Lib/dia) | AH4: Pré 2 (Kg/h) | AI4: Pós (Lib/dia) | AJ4: Pós (Kg/h) | AK4: Pré 1 (Lib/dia) cilindros | AL4: Pré 1 (Kg/h) cilindros | AM4: Pré 2 (Lib/dia) cilindros | AN4: Pré 2 (Kg/h) cilindros | AO4: Pós (Lib/dia) cilindros | AP4: Pós (Kg/h) cilindros | AQ4: COAGULANTE | AU4: Tempo de Utilização (h)
AQ5: Codigo | AR5: Nome | AS5: d (g/ml) | AT5: C (%)
B6: Bruta | C6: DEC_1 | D6: DEC_2 | E6: TRAT | F6: Bruta | G6: DEC_1 | H6: DEC_2 | I6: TRAT | J6: FILT | K6: Bruta | L6: DEC_1 | M6: DEC_2 | N6: TRAT | O6: TRAT | P6: DEC_1 | Q6: DEC_2 | R6: L/h | S6: mg/l | T6: L/s | X6: 0.041666667 | Y6: 3350 | Z6: 1196 | AA6: 6069 | AB6: =IF('2'!AA6=1,(('2'!Z6*'2'!$AS$6*'2'!$AT$6)/('2'!Y6*0.0036)),IF('2'!AA6=2,(('2'!Z6*'2'!$AS$7*'2'!$AT$7)/('2'!Y6*0.0036)))) -> FALSE | AD6: =(('2'!AC6*'2'!$Q$10*1000000))/('2'!Y6*3600) -> 0 | AF6: =('2'!AE6/24)*0.454 -> 0 | AH6: =('2'!AG6/24)*0.454 -> 0 | AI6: 5200 | AJ6: =('2'!AI6/24)*0.454 -> 98.366667 | AL6: =('2'!AK6/24)*0.454 -> 0 | AN6: =('2'!AM6/24)*0.454 -> 0 | AP6: =('2'!AO6/24)*0.454 -> 0 | AQ6: 1 | AR6: S.A.L | AS6: 1.33 | AT6: 0.5 | AU6: 0
A7: 0 | B7: 125 | C7: 12 | D7: 12 | E7: 5 | F7: 11 | G7: 1.1 | H7: 1 | I7: 0.4 | J7: 0.4 | K7: 7 | L7: 6.6 | M7: 6.6 | N7: 6.3 | O7: 3.6 | R7: ='1'!$Z$29 -> 1198 | S7: ='1'!$AB$29 -> 66.058872 | T7: ='1'!$Y$29 -> 3350 | U7: =IF('2'!AA6=1,'2'!AR6,'2'!AR7) -> PAC 18 | V7: =ESCALA!$B$3 | X7: 2653.0833 | Y7: 3350 | Z7: 1196 | AA7: 210 | AB7: =IF('2'!AA7=1,(('2'!Z7*'2'!$AS$6*'2'!$AT$6)/('2'!Y7*0.0036)),IF('2'!AA7=2,(('2'!Z7*'2'!$AS$7*'2'!$AT$7)/('2'!Y7*0.0036)))) -> FALSE | AD7: =(('2'!AC7*'2'!$Q$10*1000000))/('2'!Y7*3600) -> 0 | AF7: =('2'!AE7/24)*0.454 -> 0 | AH7: =('2'!AG7/24)*0.454 -> 0 | AI7: 5200 | AJ7: =('2'!AI7/24)*0.454 -> 98.366667 | AL7: =('2'!AK7/24)*0.454 -> 0 | AN7: =('2'!AM7/24)*0.454 -> 0 | AP7: =('2'!AO7/24)*0.454 -> 0 | AQ7: 2 | AR7: PAC 18 | AS7: 1.377 | AT7: 1 | AU7: 24
A8: 0.083333333 | B8: 142 | C8: 12 | D8: 12 | E8: 5 | F8: 28 | G8: 1.1 | H8: 1 | I8: 0.4 | J8: 0.4 | K8: 7 | L8: 6.6 | M8: 6.6 | N8: 6.3 | O8: 3.6 | R8: ='2'!Z7 -> 1196 | S8: ='2'!AB7 -> FALSE | T8: ='2'!Y7 -> 3350 | U8: =IF('2'!AA7=1,'2'!AR6,'2'!AR7) -> PAC 18 | X8: 2645.125 | Y8: 3350 | Z8: 1196 | AA8: 1 | AB8: =IF('2'!AA8=1,(('2'!Z8*'2'!$AS$6*'2'!$AT$6)/('2'!Y8*0.0036)),IF('2'!AA8=2,(('2'!Z8*'2'!$AS$7*'2'!$AT$7)/('2'!Y8*0.0036)))) -> 65.94859 | AD8: =(('2'!AC8*'2'!$Q$10*1000000))/('2'!Y8*3600) -> 0 | AF8: =('2'!AE8/24)*0.454 -> 0 | AH8: =('2'!AG8/24)*0.454 -> 0 | AI8: 5200 | AJ8: =('2'!AI8/24)*0.454 -> 98.366667 | AL8: =('2'!AK8/24)*0.454 -> 0 | AN8: =('2'!AM8/24)*0.454 -> 0 | AP8: =('2'!AO8/24)*0.454 -> 0 | AQ8: Polímero Catiônico
A9: 0.16666667 | B9: 194 | C9: 12 | D9: 12 | E9: 5 | F9: 62 | G9: 1.2 | H9: 1 | I9: 0.4 | J9: 0.4 | K9: 7 | L9: 6.6 | M9: 6.6 | N9: 6.3 | O9: 3.6 | R9: ='2'!Z9 -> 1196 | S9: ='2'!AB9 -> 65.94859 | T9: ='2'!Y9 -> 3350 | U9: =IF('2'!AA9=1,'2'!AR6,'2'!AR7) -> S.A.L | X9: 0.16666667 | Y9: 3350 | Z9: 1196 | AA9: 1 | AB9: =IF('2'!AA9=1,(('2'!Z9*'2'!$AS$6*'2'!$AT$6)/('2'!Y9*0.0036)),IF('2'!AA9=2,(('2'!Z9*'2'!$AS$7*'2'!$AT$7)/('2'!Y9*0.0036)))) -> 65.94859 | AD9: =(('2'!AC9*'2'!$Q$10*1000000))/('2'!Y9*3600) -> 0 | AF9: =('2'!AE9/24)*0.454 -> 0 | AH9: =('2'!AG9/24)*0.454 -> 0 | AI9: 5200 | AJ9: =('2'!AI9/24)*0.454 -> 98.366667 | AL9: =('2'!AK9/24)*0.454 -> 0 | AN9: =('2'!AM9/24)*0.454 -> 0 | AP9: =('2'!AO9/24)*0.454 -> 0 | AQ9: Nome | AT9: C (%)
A10: 0.25 | B10: 210 | C10: 12 | D10: 12 | E10: 5 | F10: 75 | G10: 1.2 | H10: 1 | I10: 0.4 | J10: 0.4 | K10: 7 | L10: 6.6 | M10: 6.6 | N10: 6.3 | O10: 3.6 | R10: ='2'!Z11 -> 1196 | S10: ='2'!AB11 -> 65.94859 | T10: ='2'!Y11 -> 3350 | U10: =IF('2'!AA11=1,'2'!AR6,'2'!AR7) -> S.A.L | X10: 0.20833333 | Y10: 3350 | Z10: 1196 | AA10: 1 | AB10: =IF('2'!AA10=1,(('2'!Z10*'2'!$AS$6*'2'!$AT$6)/('2'!Y10*0.0036)),IF('2'!AA10=2,(('2'!Z10*'2'!$AS$7*'2'!$AT$7)/('2'!Y10*0.0036)))) -> 65.94859 | AD10: =(('2'!AC10*'2'!$Q$10*1000000))/('2'!Y10*3600) -> 0 | AF10: =('2'!AE10/24)*0.454 -> 0 | AH10: =('2'!AG10/24)*0.454 -> 0 | AI10: 5200 | AJ10: =('2'!AI10/24)*0.454 -> 98.366667 | AL10: =('2'!AK10/24)*0.454 -> 0 | AN10: =('2'!AM10/24)*0.454 -> 0 | AP10: =('2'!AO10/24)*0.454 -> 0 | AQ10: Aguapol 200 | AT10: 0.002
A11: 0.33333333 | B11: 209 | C11: 12.1 | D11: 11.3 | E11: 3.2 | F11: 76 | G11: 1.8 | H11: 1.2 | I11: 0.4 | J11: 0.4 | K11: 7 | L11: 6.5 | M11: 6.5 | N11: 6.4 | O11: 3.5 | R11: ='2'!Z13 -> 1200 | S11: ='2'!AB13 -> 65.196078 | T11: ='2'!Y13 -> 3400 | U11: =IF('2'!AA13=1,'2'!AR6,'2'!AR7) -> S.A.L | X11: 0.25 | Y11: 3350 | Z11: 1196 | AA11: 1 | AB11: =IF('2'!AA11=1,(('2'!Z11*'2'!$AS$6*'2'!$AT$6)/('2'!Y11*0.0036)),IF('2'!AA11=2,(('2'!Z11*'2'!$AS$7*'2'!$AT$7)/('2'!Y11*0.0036)))) -> 65.94859 | AD11: =(('2'!AC11*'2'!$Q$10*1000000))/('2'!Y11*3600) -> 0 | AF11: =('2'!AE11/24)*0.454 -> 0 | AH11: =('2'!AG11/24)*0.454 -> 0 | AI11: 5200 | AJ11: =('2'!AI11/24)*0.454 -> 98.366667 | AL11: =('2'!AK11/24)*0.454 -> 0 | AN11: =('2'!AM11/24)*0.454 -> 0 | AP11: =('2'!AO11/24)*0.454 -> 0
A12: 0.41666667 | B12: 198 | C12: 12.3 | D12: 10.9 | E12: 2.3 | F12: 78 | G12: 2.4 | H12: 1.4 | I12: 0.5 | J12: 0.5 | K12: 7 | L12: 6.5 | M12: 6.5 | N12: 6.4 | O12: 3.5 | R12: ='2'!Z15 -> 1200 | S12: ='2'!AB15 -> 65.196078 | T12: ='2'!Y15 -> 3400 | U12: =IF('2'!AA15=1,'2'!AR6,'2'!AR7) -> S.A.L | V12: =ESCALA!$B$4 | X12: 0.29166667 | Y12: 3350 | Z12: 1196 | AA12: 1 | AB12: =IF('2'!AA12=1,(('2'!Z12*'2'!$AS$6*'2'!$AT$6)/('2'!Y12*0.0036)),IF('2'!AA12=2,(('2'!Z12*'2'!$AS$7*'2'!$AT$7)/('2'!Y12*0.0036)))) -> 65.94859 | AD12: =(('2'!AC12*'2'!$Q$10*1000000))/('2'!Y12*3600) -> 0 | AF12: =('2'!AE12/24)*0.454 -> 0 | AH12: =('2'!AG12/24)*0.454 -> 0 | AI12: 5200 | AJ12: =('2'!AI12/24)*0.454 -> 98.366667 | AL12: =('2'!AK12/24)*0.454 -> 0 | AN12: =('2'!AM12/24)*0.454 -> 0 | AP12: =('2'!AO12/24)*0.454 -> 0
A13: 0.5 | B13: 203 | C13: 12.1 | D13: 11.3 | E13: 3.6 | F13: 79 | G13: 2.6 | H13: 2.2 | I13: 0.6 | J13: 0.6 | K13: 7 | L13: 6.5 | M13: 6.5 | N13: 6.2 | O13: 3.5 | R13: ='2'!Z17 -> 1200 | S13: ='2'!AB17 -> 65.196078 | T13: ='2'!Y17 -> 3400 | U13: =IF('2'!AA17=1,'2'!AR6,'2'!AR7) -> S.A.L | X13: 0.33333333 | Y13: 3400 | Z13: 1200 | AA13: 1 | AB13: =IF('2'!AA13=1,(('2'!Z13*'2'!$AS$6*'2'!$AT$6)/('2'!Y13*0.0036)),IF('2'!AA13=2,(('2'!Z13*'2'!$AS$7*'2'!$AT$7)/('2'!Y13*0.0036)))) -> 65.196078 | AD13: =(('2'!AC13*'2'!$Q$10*1000000))/('2'!Y13*3600) -> 0 | AF13: =('2'!AE13/24)*0.454 -> 0 | AH13: =('2'!AG13/24)*0.454 -> 0 | AI13: 5200 | AJ13: =('2'!AI13/24)*0.454 -> 98.366667 | AL13: =('2'!AK13/24)*0.454 -> 0 | AN13: =('2'!AM13/24)*0.454 -> 0 | AP13: =('2'!AO13/24)*0.454 -> 0
A14: 0.58333333 | B14: 220 | C14: 15.3 | D14: 14.6 | E14: 5.1 | F14: 86 | G14: 4.8 | H14: 4.4 | I14: 0.6 | J14: 0.8 | K14: 7.2 | L14: 6.5 | M14: 6.4 | N14: 6.1 | O14: 3.5 | R14: ='2'!Z19 -> 1200 | S14: ='2'!AB19 -> 65.196078 | T14: ='2'!Y19 -> 3400 | U14: =IF('2'!AA19=1,'2'!AR6,'2'!AR7) -> S.A.L | X14: 0.375 | Y14: 3400 | Z14: 1200 | AA14: 1 | AB14: =IF('2'!AA14=1,(('2'!Z14*'2'!$AS$6*'2'!$AT$6)/('2'!Y14*0.0036)),IF('2'!AA14=2,(('2'!Z14*'2'!$AS$7*'2'!$AT$7)/('2'!Y14*0.0036)))) -> 65.196078 | AD14: =(('2'!AC14*'2'!$Q$10*1000000))/('2'!Y14*3600) -> 0 | AF14: =('2'!AE14/24)*0.454 -> 0 | AH14: =('2'!AG14/24)*0.454 -> 0 | AI14: 5200 | AJ14: =('2'!AI14/24)*0.454 -> 98.366667 | AL14: =('2'!AK14/24)*0.454 -> 0 | AN14: =('2'!AM14/24)*0.454 -> 0 | AP14: =('2'!AO14/24)*0.454 -> 0
A15: 0.66666667 | B15: 230 | C15: 16.3 | D15: 15.8 | E15: 6.3 | F15: 143 | G15: 5.2 | H15: 4.3 | I15: 0.7 | J15: 1 | K15: 6.9 | L15: 6.4 | M15: 6.3 | N15: 6.4 | O15: 3.6 | R15: ='2'!Z21 -> 1380 | S15: ='2'!AB21 -> 74.97549 | T15: ='2'!Y21 -> 3400 | U15: =IF('2'!AA21=1,'2'!AR6,'2'!AR7) -> S.A.L | X15: 0.41666667 | Y15: 3400 | Z15: 1200 | AA15: 1 | AB15: =IF('2'!AA15=1,(('2'!Z15*'2'!$AS$6*'2'!$AT$6)/('2'!Y15*0.0036)),IF('2'!AA15=2,(('2'!Z15*'2'!$AS$7*'2'!$AT$7)/('2'!Y15*0.0036)))) -> 65.196078 | AD15: =(('2'!AC15*'2'!$Q$10*1000000))/('2'!Y15*3600) -> 0 | AF15: =('2'!AE15/24)*0.454 -> 0 | AH15: =('2'!AG15/24)*0.454 -> 0 | AI15: 5200 | AJ15: =('2'!AI15/24)*0.454 -> 98.366667 | AL15: =('2'!AK15/24)*0.454 -> 0 | AN15: =('2'!AM15/24)*0.454 -> 0 | AP15: =('2'!AO15/24)*0.454 -> 0
A16: 0.75 | B16: 249 | C16: 18 | D16: 17.6 | E16: 7.2 | F16: 196 | G16: 5.6 | H16: 4.4 | I16: 0.8 | J16: 1.4 | K16: 6.9 | L16: 6.4 | M16: 6.3 | N16: 6.4 | O16: 3.6 | R16: ='2'!Z23 -> 1380 | S16: ='2'!AB23 -> 74.103682 | T16: ='2'!Y23 -> 3440 | U16: =IF('2'!AA23=1,'2'!AR6,'2'!AR7) -> S.A.L | X16: 0.45833333 | Y16: 3400 | Z16: 1200 | AA16: 1 | AB16: =IF('2'!AA16=1,(('2'!Z16*'2'!$AS$6*'2'!$AT$6)/('2'!Y16*0.0036)),IF('2'!AA16=2,(('2'!Z16*'2'!$AS$7*'2'!$AT$7)/('2'!Y16*0.0036)))) -> 65.196078 | AD16: =(('2'!AC16*'2'!$Q$10*1000000))/('2'!Y16*3600) -> 0 | AF16: =('2'!AE16/24)*0.454 -> 0 | AH16: =('2'!AG16/24)*0.454 -> 0 | AI16: 5200 | AJ16: =('2'!AI16/24)*0.454 -> 98.366667 | AL16: =('2'!AK16/24)*0.454 -> 0 | AN16: =('2'!AM16/24)*0.454 -> 0 | AP16: =('2'!AO16/24)*0.454 -> 0
A17: 0.83333333 | B17: 275 | C17: 18.3 | D17: 17.8 | E17: 8.6 | F17: 264 | G17: 5.7 | H17: 4.6 | I17: 0.9 | J17: 1.3 | K17: 6.7 | L17: 6.4 | M17: 6.3 | N17: 6.2 | O17: 3.6 | R17: ='2'!Z25 -> 1380 | S17: ='2'!AB25 -> 74.103682 | T17: ='2'!Y25 -> 3440 | U17: =IF('2'!AA25=1,'2'!AR6,'2'!AR7) -> S.A.L | V17: =ESCALA!$C$4 | X17: 0.5 | Y17: 3400 | Z17: 1200 | AA17: 1 | AB17: =IF('2'!AA17=1,(('2'!Z17*'2'!$AS$6*'2'!$AT$6)/('2'!Y17*0.0036)),IF('2'!AA17=2,(('2'!Z17*'2'!$AS$7*'2'!$AT$7)/('2'!Y17*0.0036)))) -> 65.196078 | AD17: =(('2'!AC17*'2'!$Q$10*1000000))/('2'!Y17*3600) -> 0 | AF17: =('2'!AE17/24)*0.454 -> 0 | AH17: =('2'!AG17/24)*0.454 -> 0 | AI17: 5200 | AJ17: =('2'!AI17/24)*0.454 -> 98.366667 | AL17: =('2'!AK17/24)*0.454 -> 0 | AN17: =('2'!AM17/24)*0.454 -> 0 | AP17: =('2'!AO17/24)*0.454 -> 0
A18: 0.91666667 | B18: 263 | C18: 17.7 | D18: 10.6 | E18: 7.6 | F18: 242 | G18: 5.7 | H18: 2.2 | I18: 0.9 | J18: 1.2 | K18: 6.7 | L18: 6.4 | M18: 6.3 | N18: 6.2 | O18: 3.6 | R18: ='2'!Z27 -> 1850 | S18: ='2'!AB27 -> 100.51062 | T18: ='2'!Y27 -> 3400 | U18: =IF('2'!AA27=1,'2'!AR6,'2'!AR7) -> S.A.L | X18: 0.54166667 | Y18: 3400 | Z18: 1200 | AA18: 1 | AB18: =IF('2'!AA18=1,(('2'!Z18*'2'!$AS$6*'2'!$AT$6)/('2'!Y18*0.0036)),IF('2'!AA18=2,(('2'!Z18*'2'!$AS$7*'2'!$AT$7)/('2'!Y18*0.0036)))) -> 65.196078 | AD18: =(('2'!AC18*'2'!$Q$10*1000000))/('2'!Y18*3600) -> 0 | AF18: =('2'!AE18/24)*0.454 -> 0 | AH18: =('2'!AG18/24)*0.454 -> 0 | AI18: 5200 | AJ18: =('2'!AI18/24)*0.454 -> 98.366667 | AL18: =('2'!AK18/24)*0.454 -> 0 | AN18: =('2'!AM18/24)*0.454 -> 0 | AP18: =('2'!AO18/24)*0.454 -> 0
A19: Média | B19: {=IF('2'!B7:B18>0.01,AVERAGE('2'!B7:B18),"")} -> 209.83333 | C19: {=IF('2'!C7:C18>0.01,AVERAGE('2'!C7:C18),"")} -> 14.175 | D19: {=IF('2'!D7:D18>0.01,AVERAGE('2'!D7:D18),"")} -> 13.158333 | E19: {=IF('2'!E7:E18>0.01,AVERAGE('2'!E7:E18),"")} -> 5.325 | F19: {=IF('2'!F7:F18>0.01,AVERAGE('2'!F7:F18),"")} -> 111.66667 | G19: {=IF('2'!G7:G18>0.01,AVERAGE('2'!G7:G18),"")} -> 3.2 | H19: {=IF('2'!H7:H18>0.01,AVERAGE('2'!H7:H18),"")} -> 2.3916667 | I19: {=IF('2'!I7:I18>0.01,AVERAGE('2'!I7:I18),"")} -> 0.58333333 | ... S19: {=IF('2'!S7:S18>0.01,AVERAGE('2'!S7:S18),"")} -> 71.130349 | X19: 0.58333333 | Y19: 3400 | Z19: 1200 | AA19: 1 | AB19: =IF('2'!AA19=1,(('2'!Z19*'2'!$AS$6*'2'!$AT$6)/('2'!Y19*0.0036)),IF('2'!AA19=2,(('2'!Z19*'2'!$AS$7*'2'!$AT$7)/('2'!Y19*0.0036)))) -> 65.196078 | AD19: =(('2'!AC19*'2'!$Q$10*1000000))/('2'!Y19*3600) -> 0 | AF19: =('2'!AE19/24)*0.454 -> 0 | AH19: =('2'!AG19/24)*0.454 -> 0 | AI19: 5200 | AJ19: =('2'!AI19/24)*0.454 -> 98.366667 | AL19: =('2'!AK19/24)*0.454 -> 0 | AN19: =('2'!AM19/24)*0.454 -> 0 | AP19: =('2'!AO19/24)*0.454 -> 0
A20: Máximo | B20: =MAX('2'!B7:B18) -> 275 | C20: =MAX('2'!C7:C18) -> 18.3 | D20: =MAX('2'!D7:D18) -> 17.8 | E20: =MAX('2'!E7:E18) -> 8.6 | F20: =MAX('2'!F7:F18) -> 264 | G20: =MAX('2'!G7:G18) -> 5.7 | H20: =MAX('2'!H7:H18) -> 4.6 | I20: =MAX('2'!I7:I18) -> 0.9 | ... S20: =MAX('2'!S7:S18) -> 100.51062 | X20: 0.625 | Y20: 3400 | Z20: 1350 | AA20: 1 | AB20: =IF('2'!AA20=1,(('2'!Z20*'2'!$AS$6*'2'!$AT$6)/('2'!Y20*0.0036)),IF('2'!AA20=2,(('2'!Z20*'2'!$AS$7*'2'!$AT$7)/('2'!Y20*0.0036)))) -> 73.345588 | AD20: =(('2'!AC20*'2'!$Q$10*1000000))/('2'!Y20*3600) -> 0 | AF20: =('2'!AE20/24)*0.454 -> 0 | AH20: =('2'!AG20/24)*0.454 -> 0 | AI20: 5200 | AJ20: =('2'!AI20/24)*0.454 -> 98.366667 | AL20: =('2'!AK20/24)*0.454 -> 0 | AN20: =('2'!AM20/24)*0.454 -> 0 | AP20: =('2'!AO20/24)*0.454 -> 0
A21: Mínimo | B21: =MIN('2'!B7:B18) -> 125 | C21: =MIN('2'!C7:C18) -> 12 | D21: =MIN('2'!D7:D18) -> 10.6 | E21: =MIN('2'!E7:E18) -> 2.3 | F21: =MIN('2'!F7:F18) -> 11 | G21: =MIN('2'!G7:G18) -> 1.1 | H21: =MIN('2'!H7:H18) -> 1 | I21: =MIN('2'!I7:I18) -> 0.4 | ... S21: =MIN('2'!S7:S18) -> 65.196078 | X21: 0.66666667 | Y21: 3400 | Z21: 1380 | AA21: 1 | AB21: =IF('2'!AA21=1,(('2'!Z21*'2'!$AS$6*'2'!$AT$6)/('2'!Y21*0.0036)),IF('2'!AA21=2,(('2'!Z21*'2'!$AS$7*'2'!$AT$7)/('2'!Y21*0.0036)))) -> 74.97549 | AD21: =(('2'!AC21*'2'!$Q$10*1000000))/('2'!Y21*3600) -> 0 | AF21: =('2'!AE21/24)*0.454 -> 0 | AH21: =('2'!AG21/24)*0.454 -> 0 | AI21: 5200 | AJ21: =('2'!AI21/24)*0.454 -> 98.366667 | AL21: =('2'!AK21/24)*0.454 -> 0 | AN21: =('2'!AM21/24)*0.454 -> 0 | AP21: =('2'!AO21/24)*0.454 -> 0
R22: Total | X22: 0.70833333 | Y22: 3440 | Z22: 1380 | AA22: 1 | AB22: =IF('2'!AA22=1,(('2'!Z22*'2'!$AS$6*'2'!$AT$6)/('2'!Y22*0.0036)),IF('2'!AA22=2,(('2'!Z22*'2'!$AS$7*'2'!$AT$7)/('2'!Y22*0.0036)))) -> 74.103682 | AD22: =(('2'!AC22*'2'!$Q$10*1000000))/('2'!Y22*3600) -> 0 | AF22: =('2'!AE22/24)*0.454 -> 0 | AH22: =('2'!AG22/24)*0.454 -> 0 | AI22: 5200 | AJ22: =('2'!AI22/24)*0.454 -> 98.366667 | AL22: =('2'!AK22/24)*0.454 -> 0 | AN22: =('2'!AM22/24)*0.454 -> 0 | AP22: =('2'!AO22/24)*0.454 -> 0
A23: TURBIDEZ DOS FILTROS DA 1ª E 2ª ETAPAS | R23: 440 | S23: Litros | X23: 0.75 | Y23: 3440 | Z23: 1380 | AA23: 1 | AB23: =IF('2'!AA23=1,(('2'!Z23*'2'!$AS$6*'2'!$AT$6)/('2'!Y23*0.0036)),IF('2'!AA23=2,(('2'!Z23*'2'!$AS$7*'2'!$AT$7)/('2'!Y23*0.0036)))) -> 74.103682 | AD23: =(('2'!AC23*'2'!$Q$10*1000000))/('2'!Y23*3600) -> 0 | AF23: =('2'!AE23/24)*0.454 -> 0 | AH23: =('2'!AG23/24)*0.454 -> 0 | AI23: 5200 | AJ23: =('2'!AI23/24)*0.454 -> 98.366667 | AL23: =('2'!AK23/24)*0.454 -> 0 | AN23: =('2'!AM23/24)*0.454 -> 0 | AP23: =('2'!AO23/24)*0.454 -> 0
A24: HORA | B24: 1 | C24: 2 | D24: 3 | E24: 4 | F24: 5 | G24: 6 | H24: 7 | I24: 8 | J24: 9 | K24: 10 | L24: 11 | M24: 12 | N24: 13 | O24: 14 | P24: 15 | Q24: 16 | R24: 0 | S24: Kilos | X24: 0.79166667 | Y24: 3440 | Z24: 1380 | AA24: 1 | AB24: =IF('2'!AA24=1,(('2'!Z24*'2'!$AS$6*'2'!$AT$6)/('2'!Y24*0.0036)),IF('2'!AA24=2,(('2'!Z24*'2'!$AS$7*'2'!$AT$7)/('2'!Y24*0.0036)))) -> 74.103682 | AD24: =(('2'!AC24*'2'!$Q$10*1000000))/('2'!Y24*3600) -> 0 | AF24: =('2'!AE24/24)*0.454 -> 0 | AH24: =('2'!AG24/24)*0.454 -> 0 | AI24: 5200 | AJ24: =('2'!AI24/24)*0.454 -> 98.366667 | AL24: =('2'!AK24/24)*0.454 -> 0 | AN24: =('2'!AM24/24)*0.454 -> 0 | AP24: =('2'!AO24/24)*0.454 -> 0
A25: 0.41666667 | B25: 0.51 | C25: 0.3 | D25: 0.4 | E25: 0.56 | F25: 0.48 | G25: xxx | H25: 0.53 | I25: 0.43 | J25: xxx | K25: 0.56 | L25: 0.35 | M25: 0.42 | N25: 0.39 | O25: 0.47 | P25: 0.52 | Q25: xxx | R25: =#DIV/0! -> #DIV/0! | T25: DATA | U25: =ESCALA!$A$4 -> 43923 | X25: 0.83333333 | Y25: 3440 | Z25: 1380 | AA25: 1 | AB25: =IF('2'!AA25=1,(('2'!Z25*'2'!$AS$6*'2'!$AT$6)/('2'!Y25*0.0036)),IF('2'!AA25=2,(('2'!Z25*'2'!$AS$7*'2'!$AT$7)/('2'!Y25*0.0036)))) -> 74.103682 | AD25: =(('2'!AC25*'2'!$Q$10*1000000))/('2'!Y25*3600) -> 0 | AF25: =('2'!AE25/24)*0.454 -> 0 | AH25: =('2'!AG25/24)*0.454 -> 0 | AI25: 5200 | AJ25: =('2'!AI25/24)*0.454 -> 98.366667 | AL25: =('2'!AK25/24)*0.454 -> 0 | AN25: =('2'!AM25/24)*0.454 -> 0 | AP25: =('2'!AO25/24)*0.454 -> 0
A26: 0.66666667 | R26: =#DIV/0! -> #DIV/0! | X26: 0.875 | Y26: 3400 | Z26: 1850 | AA26: 1 | AB26: =IF('2'!AA26=1,(('2'!Z26*'2'!$AS$6*'2'!$AT$6)/('2'!Y26*0.0036)),IF('2'!AA26=2,(('2'!Z26*'2'!$AS$7*'2'!$AT$7)/('2'!Y26*0.0036)))) -> 100.51062 | AD26: =(('2'!AC26*'2'!$Q$10*1000000))/('2'!Y26*3600) -> 0 | AF26: =('2'!AE26/24)*0.454 -> 0 | AH26: =('2'!AG26/24)*0.454 -> 0 | AJ26: =('2'!AI26/24)*0.454 -> 0 | AL26: =('2'!AK26/24)*0.454 -> 0 | AN26: =('2'!AM26/24)*0.454 -> 0 | AP26: =('2'!AO26/24)*0.454 -> 0
A27: Média | B27: =#DIV/0! -> #DIV/0! | C27: =#DIV/0! -> #DIV/0! | D27: =#DIV/0! -> #DIV/0! | E27: =#DIV/0! -> #DIV/0! | F27: =#DIV/0! -> #DIV/0! | G27: =#DIV/0! -> #DIV/0! | H27: =#DIV/0! -> #DIV/0! | I27: =#DIV/0! -> #DIV/0! | ... Q27: =#DIV/0! -> #DIV/0! | X27: 0.91666667 | Y27: 3400 | Z27: 1850 | AA27: 1 | AB27: =IF('2'!AA27=1,(('2'!Z27*'2'!$AS$6*'2'!$AT$6)/('2'!Y27*0.0036)),IF('2'!AA27=2,(('2'!Z27*'2'!$AS$7*'2'!$AT$7)/('2'!Y27*0.0036)))) -> 100.51062 | AD27: =(('2'!AC27*'2'!$Q$10*1000000))/('2'!Y27*3600) -> 0 | AF27: =('2'!AE27/24)*0.454 -> 0 | AH27: =('2'!AG27/24)*0.454 -> 0 | AJ27: =('2'!AI27/24)*0.454 -> 0 | AL27: =('2'!AK27/24)*0.454 -> 0 | AN27: =('2'!AM27/24)*0.454 -> 0 | AP27: =('2'!AO27/24)*0.454 -> 0
A28: OBSERVAÇÕES | X28: 0.95833333 | Y28: 3400 | Z28: 1850 | AA28: 1 | AB28: =IF('2'!AA28=1,(('2'!Z28*'2'!$AS$6*'2'!$AT$6)/('2'!Y28*0.0036)),IF('2'!AA28=2,(('2'!Z28*'2'!$AS$7*'2'!$AT$7)/('2'!Y28*0.0036)))) -> 100.51062 | AD28: =(('2'!AC28*'2'!$Q$10*1000000))/('2'!Y28*3600) -> 0 | AF28: =('2'!AE28/24)*0.454 -> 0 | AH28: =('2'!AG28/24)*0.454 -> 0 | AJ28: =('2'!AI28/24)*0.454 -> 0 | AL28: =('2'!AK28/24)*0.454 -> 0 | AN28: =('2'!AM28/24)*0.454 -> 0 | AP28: =('2'!AO28/24)*0.454 -> 0
X29: 1 | Y29: 3400 | Z29: 1850 | AA29: 1 | AB29: =IF('2'!AA29=1,(('2'!Z29*'2'!$AS$6*'2'!$AT$6)/('2'!Y29*0.0036)),IF('2'!AA29=2,(('2'!Z29*'2'!$AS$7*'2'!$AT$7)/('2'!Y29*0.0036)))) -> 100.51062 | AD29: =(('2'!AC29*'2'!$Q$10*1000000))/('2'!Y29*3600) -> 0 | AF29: =('2'!AE29/24)*0.454 -> 0 | AH29: =('2'!AG29/24)*0.454 -> 0 | AJ29: =('2'!AI29/24)*0.454 -> 0 | AL29: =('2'!AK29/24)*0.454 -> 0 | AN29: =('2'!AM29/24)*0.454 -> 0 | AP29: =('2'!AO29/24)*0.454 -> 0
X30: Total | Y30: =SUM('2'!Y6:Y29)*3.6 -> 293076 | Z30: =SUM('2'!Z6:Z29) -> 32422 | AF30: =SUM('2'!AF6:AF29) -> 0 | AH30: =SUM('2'!AH6:AH29) -> 0 | AJ30: =SUM('2'!AJ6:AJ29) -> 1967.3333 | AL30: =SUM('2'!AL6:AL29) -> 0 | AN30: =SUM('2'!AN6:AN29) -> 0 | AP30: =SUM('2'!AP6:AP29) -> 0
X32: S.A.L (l) - (kg) | Z32: =SUMIF('2'!AA6:AA29,"=1",'2'!Z6:Z29) -> 30030 | AA32: ='2'!Z32*'2'!AS6 -> 39939.9 | AB32: =SUMIF('2'!$AA$6:$AA$29,"=1",'2'!$AB$6:$AB$29)/COUNTIF('2'!$AA$6:$AA$29,"=1") -> 74.222445 | AC32: =SUMIF('2'!AA6:AA29,"=1",'2'!AC6:AC29) -> 0
X33: PAC 18 (l) - (kg) | Z33: =SUMIF('2'!AA6:AA29,"=2",'2'!Z6:Z29) -> 0 | AA33: ='2'!Z33*'2'!AS7 -> 0 | AB33: =SUMIF('2'!$AA$6:$AA$29,"=2",'2'!$AB$6:$AB$29)/COUNTIF('2'!$AA$6:$AA$29,"=2") -> #DIV/0! | AC33: =SUMIF('2'!AA6:AA29,"=2",'2'!AC6:AC29) -> 0
X34: Média | Y34: =AVERAGE('2'!Y6:Y29) -> 3392.0833 | Z34: =AVERAGE('2'!Z6:Z29) -> 1350.9167 | AC34: =SUM('2'!AC6:AC29)/COUNTIF('2'!AC6:AC29,"<>0") -> #DIV/0! | AD34: =SUM('2'!AD6:AD29)/COUNTIF('2'!AD6:AD29,"<>0") -> #DIV/0! | AF34: =AVERAGE('2'!AF6:AF29) -> 0 | AH34: =AVERAGE('2'!AH6:AH29) -> 0 | AJ34: ='2'!AJ30/24 -> 81.972222 | AL34: =AVERAGE('2'!AL6:AL29) -> 0 | AN34: =AVERAGE('2'!AN6:AN29) -> 0 | AP34: =AVERAGE('2'!AP6:AP29) -> 0
C35: Alcalinidade (mg/L) | F35: Ferro (mg/L) | I35: Manganês (mg/L) | L35: Alumínio (mg/L) | U35: TÉCNICO | X35: Decantadores | AA35: Filtros | AJ35: CLORAÇÃO INTERMEDIÁRIA | AO35: PÓS CLORAÇÃO
B36: HORA | C36: Bruta | D36: Dec. | E36: Trat (R-3) | F36: Bruta | G36: Filt. | H36: Trat (R-3) | I36: Bruta | J36: Filt. | K36: Trat (R-3) | L36: Trat (R-3) | X36: Lavados | Y36: 1 | AA36: Lavados | AB36: 4
B37: 0.33333333 | C37: 72.3 | D37: 54.2 | E37: 36.1 | F37: 1.2 | G37: 0.2 | H37: 0.2 | I37: 0.15 | J37: 0 | K37: 0 | L37: 0.1 | U37: ='2'!V12 | X37: HORAS OPERANDO | Z37: =COUNTA('2'!Z6:Z29) -> 24 | AJ37: CARRETA | AL37: CILINDROS | AO37: CARRETA | AQ37: CILINDROS
B38: 0.66666667 | F38: 0.6 | H38: 0 | I38: 0.03 | K38: 0.03 | AJ38: CONSUMO | AK38: =SUM('2'!AF30+'2'!AH30) -> 0 | AL38: CONSUMO | AM38: =SUM('2'!AL30+'2'!AN30) -> 0 | AO38: CONSUMO | AP38: ='2'!AJ30 -> 1967.3333 | AQ38: CONSUMO | AR38: ='2'!AP30 -> 0
A39: Nº amostras de água TRATADA | C39: Nº amostras de água FILTRADA | E39: Nº amostras de água tratada/filtrada FORA DO PADRÃO | J39: Nº amostras de água tratada/filtrada no PADRÃO | O39: Nº de amostras com turbidez menor ou igual a 0,5 NTU | R39: ÁGUA FILTRADA | S39: Nº de amostras com turbidez menor ou igual a 1,0 NTU | AJ39: DOSAGEM | AK39: =('2'!AK38/'2'!Y30)*1000 -> 0 | AL39: DOSAGEM | AM39: =('2'!AM38/'2'!Y30)*1000 -> 0 | AO39: DOSAGEM | AP39: =('2'!AP38/'2'!Y30)*1000 -> 6.7127071 | AQ39: DOSAGEM | AR39: =('2'!AR38/'2'!Y30)*1000 -> 0
A40: COR | B40: TURBIDEZ | C40: TURBIDEZ | E40: COR | G40: TURBIDEZ | J40: COR | L40: TURBIDEZ | X40: ESTOQUE DE COAGULANTE | AJ40: Consumo Total | AL40: =SUM('2'!AK38,'2'!AM38) -> 0 | AO40: Consumo Total | AQ40: =SUM('2'!AP38,'2'!AR38) -> 1967.3333
A41: =COUNTA('2'!E7:E18) -> 12 | B41: =COUNTA('2'!I7:I18) -> 12 | C41: =COUNTA('2'!J7:J18) -> 12 | E41: =COUNTIF('2'!E7:E18,">15") -> 0 | G41: =COUNTIF('2'!J7:J18,">1") -> 3 | J41: ='2'!A41-'2'!E41 -> 12 | L41: ='2'!C41-'2'!G41 -> 9 | O41: =COUNTIF('2'!J7:J18,"<=0,5") -> 6 | S41: =COUNTIF('2'!J7:J18,"<=1,0") -> 9 | AJ41: Dosagem Final | AL41: =SUM(('2'!AK38+'2'!AM38)/'2'!Y30)*1000 -> 0 | AO41: Dosagem Final | AQ41: =SUM(('2'!AP38+'2'!AR38)/'2'!Y30)*1000 -> 6.7127071
O42: ÁGUA FILTRATADA | X42: SULFATO DE ALUMÍNIO
H43: Nº de amostras água tratada com turbidez <= 5,0 NTU | L43: Nº de amostras água tratada para aluminio | Q43: Nº de amostras com turbidez entre 0,5 e 1,0 NTU | X43: TINA 01 | Z43: TINA 02 | AB43: TINA 03 | AD43: TANQUE
...

Sheet 3
D2: CONTROLE DE ANÁLISE FÍSICO - QUÍMICAS \ ETA CASTELO BRANCO | AB2: CONTROLE DE PRODUTOS QUÍMICOS APLICADOS \ ETA CASTELO BRANCO
A4: HORA | B4: COR (Uc) | F4: TURBIDEZ (Ut) | K4: Ph | O4: CLORO RESIDUAL (mg/L) | R4: DOSAGEM DO COAGULANTE | T4: VAZÃO DA ETA | U4: TIPO DE COAGULANTE | V4: TÉCNICO | X4: Hora | Y4: Vazão ETA (l/s) | Z4: Vazão Coagulante (l/h) | AA4: Código | AB4: Dosagem (mg/l) | AC4: Vazão Polímero (l/h) | AD4: Dosagem (mg/l) | AE4: Pré 1 (Lib/dia) | AF4: Pré 1 (Kg/h) | AG4: Pré 2 (Lib/dia) | AH4: Pré 2 (Kg/h) | AI4: Pós (Lib/dia) | AJ4: Pós (Kg/h) | AK4: Pré 1 (Lib/dia) cilindros | AL4: Pré 1 (Kg/h) cilindros | AM4: Pré 2 (Lib/dia) cilindros | AN4: Pré 2 (Kg/h) cilindros | AO4: Pós (Lib/dia) cilindros | AP4: Pós (Kg/h) cilindros | AQ4: COAGULANTE | AU4: Tempo de Utilização (h)
AQ5: Codigo | AR5: Nome | AS5: d (g/ml) | AT5: C (%)
B6: Bruta | C6: DEC_1 | D6: DEC_2 | E6: TRAT | F6: Bruta | G6: DEC_1 | H6: DEC_2 | I6: TRAT | J6: FILT | K6: Bruta | L6: DEC_1 | M6: DEC_2 | N6: TRAT | O6: TRAT | P6: DEC_1 | Q6: DEC_2 | R6: L/h | S6: mg/l | T6: L/s | X6: 0.041666667 | Y6: 3400 | Z6: 1850 | AA6: 1 | AB6: =IF('3'!AA6=1,(('3'!Z6*'3'!$AS$6*'3'!$AT$6)/('3'!Y6*0.0036)),IF('3'!AA6=2,(('3'!Z6*'3'!$AS$7*'3'!$AT$7)/('3'!Y6*0.0036)))) -> 100.51062 | AD6: =(('3'!AC6*'3'!$O$9*1000000))/('3'!Y6*3600) -> 0 | AF6: =('3'!AE6/24)*0.454 -> 0 | AH6: =('3'!AG6/24)*0.454 -> 0 | AI6: 5200 | AJ6: =('3'!AI6/24)*0.454 -> 98.366667 | AL6: =('3'!AK6/24)*0.454 -> 0 | AN6: =('3'!AM6/24)*0.454 -> 0 | AP6: =('3'!AO6/24)*0.454 -> 0 | AQ6: 1 | AR6: S.A.L | AS6: 1.33 | AT6: 0.5 | AU6: 0
A7: 0 | B7: 246 | C7: 16.3 | D7: 10.2 | E7: 7.3 | F7: 226 | G7: 4.9 | H7: 2.1 | I7: 0.9 | J7: 1.2 | K7: 6.7 | L7: 6.4 | M7: 6.3 | N7: 6.2 | O7: 3.6 | R7: ='2'!$Z$29 -> 1850 | S7: ='2'!$AB$29 -> 100.51062 | T7: ='2'!$Y$29 -> 3400 | U7: =IF('3'!AA6=1,'3'!AR6,'3'!AR7) -> S.A.L | V7: =ESCALA!$C$4 | X7: 0.083333333 | Y7: 3400 | Z7: 1850 | AA7: 1 | AB7: =IF('3'!AA7=1,(('3'!Z7*'3'!$AS$6*'3'!$AT$6)/('3'!Y7*0.0036)),IF('3'!AA7=2,(('3'!Z7*'3'!$AS$7*'3'!$AT$7)/('3'!Y7*0.0036)))) -> 100.51062 | AD7: =(('3'!AC7*'3'!$O$9*1000000))/('3'!Y7*3600) -> 0 | AF7: =('3'!AE7/24)*0.454 -> 0 | AH7: =('3'!AG7/24)*0.454 -> 0 | AI7: 5200 | AJ7: =('3'!AI7/24)*0.454 -> 98.366667 | AL7: =('3'!AK7/24)*0.454 -> 0 | AN7: =('3'!AM7/24)*0.454 -> 0 | AP7: =('3'!AO7/24)*0.454 -> 0 | AQ7: 2 | AR7: PAC 18 | AS7: 1.377 | AT7: 1 | AU7: 24
A8: 0.083333333 | B8: 259 | C8: 12.1 | D8: 9.3 | E8: 5.9 | F8: 209 | G8: 3.6 | H8: 2 | I8: 0.8 | J8: 0.8 | K8: 6.7 | L8: 6.4 | M8: 6.2 | N8: 6.1 | O8: 3.6 | R8: ='3'!Z7 -> 1850 | S8: ='3'!AB7 -> 100.51062 | T8: ='3'!Y7 -> 3400 | U8: =IF('3'!AA7=1,'3'!AR6,'3'!AR7) -> S.A.L | X8: 0.125 | Y8: 3400 | Z8: 1850 | AA8: 1 | AB8: =IF('3'!AA8=1,(('3'!Z8*'3'!$AS$6*'3'!$AT$6)/('3'!Y8*0.0036)),IF('3'!AA8=2,(('3'!Z8*'3'!$AS$7*'3'!$AT$7)/('3'!Y8*0.0036)))) -> 100.51062 | AD8: =(('3'!AC8*'3'!$O$9*1000000))/('3'!Y8*3600) -> 0 | AF8: =('3'!AE8/24)*0.454 -> 0 | AH8: =('3'!AG8/24)*0.454 -> 0 | AI8: 5200 | AJ8: =('3'!AI8/24)*0.454 -> 98.366667 | AL8: =('3'!AK8/24)*0.454 -> 0 | AN8: =('3'!AM8/24)*0.454 -> 0 | AP8: =('3'!AO8/24)*0.454 -> 0 | AQ8: Polímero Catiônico
A9: 0.16666667 | B9: 273 | C9: 10.6 | D9: 8.6 | E9: 4.6 | F9: 195 | G9: 3.2 | H9: 1.9 | I9: 0.8 | J9: 0.6 | K9: 6.6 | L9: 6.2 | M9: 6.2 | N9: 6.1 | O9: 3.6 | R9: ='3'!Z9 -> 1850 | S9: ='3'!AB9 -> 100.51062 | T9: ='3'!Y9 -> 3400 | U9: =IF('3'!AA9=1,'3'!AR6,'3'!AR7) -> S.A.L | X9: 0.16666667 | Y9: 3400 | Z9: 1850 | AA9: 1 | AB9: =IF('3'!AA9=1,(('3'!Z9*'3'!$AS$6*'3'!$AT$6)/('3'!Y9*0.0036)),IF('3'!AA9=2,(('3'!Z9*'3'!$AS$7*'3'!$AT$7)/('3'!Y9*0.0036)))) -> 100.51062 | AD9: =(('3'!AC9*'3'!$O$9*1000000))/('3'!Y9*3600) -> 0 | AF9: =('3'!AE9/24)*0.454 -> 0 | AH9: =('3'!AG9/24)*0.454 -> 0 | AI9: 5200 | AJ9: =('3'!AI9/24)*0.454 -> 98.366667 | AL9: =('3'!AK9/24)*0.454 -> 0 | AN9: =('3'!AM9/24)*0.454 -> 0 | AP9: =('3'!AO9/24)*0.454 -> 0 | AQ9: Nome | AT9: C (%)
A10: 0.25 | B10: 301 | C10: 9.9 | D10: 7.2 | E10: 3 | F10: 186 | G10: 2.7 | H10: 1.5 | I10: 0.6 | J10: 0.6 | K10: 6.6 | L10: 6.2 | M10: 6.1 | N10: 6 | O10: 3.6 | R10: ='3'!Z11 -> 1850 | S10: ='3'!AB11 -> 100.51062 | T10: ='3'!Y11 -> 3400 | U10: =IF('3'!AA11=1,'3'!AR6,'3'!AR7) -> S.A.L | X10: 0.20833333 | Y10: 3400 | Z10: 1850 | AA10: 1 | AB10: =IF('3'!AA10=1,(('3'!Z10*'3'!$AS$6*'3'!$AT$6)/('3'!Y10*0.0036)),IF('3'!AA10=2,(('3'!Z10*'3'!$AS$7*'3'!$AT$7)/('3'!Y10*0.0036)))) -> 100.51062 | AD10: =(('3'!AC10*'3'!$O$9*1000000))/('3'!Y10*3600) -> 0 | AF10: =('3'!AE10/24)*0.454 -> 0 | AH10: =('3'!AG10/24)*0.454 -> 0 | AI10: 5200 | AJ10: =('3'!AI10/24)*0.454 -> 98.366667 | AL10: =('3'!AK10/24)*0.454 -> 0 | AN10: =('3'!AM10/24)*0.454 -> 0 | AP10: =('3'!AO10/24)*0.454 -> 0 | AQ10: Aguapol 200 | AT10: 0.002
A11: 0.33333333 | B11: 319 | C11: 14 | D11: 12 | E11: 4 | F11: 157 | G11: 3.8 | H11: 2.2 | I11: 0.7 | J11: 0.5 | K11: 6.6 | L11: 6.2 | M11: 6.2 | N11: 6 | O11: 3.6 | R11: ='3'!Z13 -> 1850 | S11: ='3'!AB13 -> 100.18649 | T11: ='3'!Y13 -> 3411 | U11: =IF('3'!AA13=1,'3'!AR6,'3'!AR7) -> S.A.L | X11: 0.25 | Y11: 3400 | Z11: 1850 | AA11: 1 | AB11: =IF('3'!AA11=1,(('3'!Z11*'3'!$AS$6*'3'!$AT$6)/('3'!Y11*0.0036)),IF('3'!AA11=2,(('3'!Z11*'3'!$AS$7*'3'!$AT$7)/('3'!Y11*0.0036)))) -> 100.51062 | AD11: =(('3'!AC11*'3'!$O$9*1000000))/('3'!Y11*3600) -> 0 | AF11: =('3'!AE11/24)*0.454 -> 0 | AH11: =('3'!AG11/24)*0.454 -> 0 | AI11: 5200 | AJ11: =('3'!AI11/24)*0.454 -> 98.366667 | AL11: =('3'!AK11/24)*0.454 -> 0 | AN11: =('3'!AM11/24)*0.454 -> 0 | AP11: =('3'!AO11/24)*0.454 -> 0
A12: 0.41666667 | B12: 308 | C12: 13 | D12: 13 | E12: 9 | F12: 163 | G12: 3.3 | H12: 2.1 | I12: 0.9 | J12: 0.5 | K12: 6.6 | L12: 6.2 | M12: 6.2 | N12: 6 | O12: 3.6 | R12: ='3'!Z15 -> 1850 | S12: ='3'!AB15 -> 100.77738 | T12: ='3'!Y15 -> 3391 | U12: =IF('3'!AA15=1,'3'!AR6,'3'!AR7) -> S.A.L | V12: =ESCALA!$B$5 | X12: 0.29166667 | Y12: 3380 | Z12: 1850 | AA12: 1 | AB12: =IF('3'!AA12=1,(('3'!Z12*'3'!$AS$6*'3'!$AT$6)/('3'!Y12*0.0036)),IF('3'!AA12=2,(('3'!Z12*'3'!$AS$7*'3'!$AT$7)/('3'!Y12*0.0036)))) -> 101.10536 | AD12: =(('3'!AC12*'3'!$O$9*1000000))/('3'!Y12*3600) -> 0 | AF12: =('3'!AE12/24)*0.454 -> 0 | AH12: =('3'!AG12/24)*0.454 -> 0 | AI12: 5200 | AJ12: =('3'!AI12/24)*0.454 -> 98.366667 | AL12: =('3'!AK12/24)*0.454 -> 0 | AN12: =('3'!AM12/24)*0.454 -> 0 | AP12: =('3'!AO12/24)*0.454 -> 0
A13: 0.5 | B13: 318 | C13: 16 | D13: 16 | E13: 11 | F13: 156 | G13: 3.8 | H13: 2.8 | I13: 1.3 | J13: 0.8 | K13: 6.6 | L13: 6.1 | M13: 6.1 | N13: 6 | O13: 3.6 | R13: ='3'!Z17 -> 1750 | S13: ='3'!AB17 -> 95.895547 | T13: ='3'!Y17 -> 3371 | U13: =IF('3'!AA17=1,'3'!AR6,'3'!AR7) -> S.A.L | X13: 0.33333333 | Y13: 3411 | Z13: 1850 | AA13: 1 | AB13: =IF('3'!AA13=1,(('3'!Z13*'3'!$AS$6*'3'!$AT$6)/('3'!Y13*0.0036)),IF('3'!AA13=2,(('3'!Z13*'3'!$AS$7*'3'!$AT$7)/('3'!Y13*0.0036)))) -> 100.18649 | AD13: =(('3'!AC13*'3'!$O$9*1000000))/('3'!Y13*3600) -> 0 | AF13: =('3'!AE13/24)*0.454 -> 0 | AH13: =('3'!AG13/24)*0.454 -> 0 | AI13: 5200 | AJ13: =('3'!AI13/24)*0.454 -> 98.366667 | AL13: =('3'!AK13/24)*0.454 -> 0 | AN13: =('3'!AM13/24)*0.454 -> 0 | AP13: =('3'!AO13/24)*0.454 -> 0
A14: 0.58333333 | B14: 317 | C14: 19 | D14: 19 | E14: 9 | F14: 149 | G14: 3.8 | H14: 2.3 | I14: 1.23 | J14: 1.2 | K14: 6.6 | L14: 6.2 | M14: 6.2 | N14: 6 | O14: 3.6 | R14: ='3'!Z19 -> 1750 | S14: ='3'!AB19 -> 96.095092 | T14: ='3'!Y19 -> 3364 | U14: =IF('3'!AA19=1,'3'!AR6,'3'!AR7) -> S.A.L | X14: 0.375 | Y14: 3392 | Z14: 1850 | AA14: 1 | AB14: =IF('3'!AA14=1,(('3'!Z14*'3'!$AS$6*'3'!$AT$6)/('3'!Y14*0.0036)),IF('3'!AA14=2,(('3'!Z14*'3'!$AS$7*'3'!$AT$7)/('3'!Y14*0.0036)))) -> 100.74767 | AD14: =(('3'!AC14*'3'!$O$9*1000000))/('3'!Y14*3600) -> 0 | AF14: =('3'!AE14/24)*0.454 -> 0 | AH14: =('3'!AG14/24)*0.454 -> 0 | AI14: 5200 | AJ14: =('3'!AI14/24)*0.454 -> 98.366667 | AL14: =('3'!AK14/24)*0.454 -> 0 | AN14: =('3'!AM14/24)*0.454 -> 0 | AP14: =('3'!AO14/24)*0.454 -> 0
A15: 0.66666667 | B15: 320 | C15: 20 | D15: 20 | E15: 9 | F15: 142 | G15: 3.9 | H15: 2.6 | I15: 1.2 | J15: 1.2 | K15: 6.6 | L15: 6.2 | M15: 6.2 | N15: 6 | O15: 3.6 | R15: ='3'!Z21 -> 1750 | S15: ='3'!AB21 -> 96.959775 | T15: ='3'!Y21 -> 3334 | U15: =IF('3'!AA21=1,'3'!AR6,'3'!AR7) -> S.A.L | X15: 0.41666667 | Y15: 3391 | Z15: 1850 | AA15: 1 | AB15: =IF('3'!AA15=1,(('3'!Z15*'3'!$AS$6*'3'!$AT$6)/('3'!Y15*0.0036)),IF('3'!AA15=2,(('3'!Z15*'3'!$AS$7*'3'!$AT$7)/('3'!Y15*0.0036)))) -> 100.77738 | AD15: =(('3'!AC15*'3'!$O$9*1000000))/('3'!Y15*3600) -> 0 | AF15: =('3'!AE15/24)*0.454 -> 0 | AH15: =('3'!AG15/24)*0.454 -> 0 | AI15: 5200 | AJ15: =('3'!AI15/24)*0.454 -> 98.366667 | AL15: =('3'!AK15/24)*0.454 -> 0 | AN15: =('3'!AM15/24)*0.454 -> 0 | AP15: =('3'!AO15/24)*0.454 -> 0
A16: 0.75 | B16: 317 | C16: 20 | D16: 20 | E16: 9 | F16: 137 | G16: 3.3 | H16: 2.5 | I16: 1.1 | J16: 1.1 | K16: 6.6 | L16: 6.2 | M16: 6.2 | N16: 6 | O16: 3.8 | R16: ='3'!Z23 -> 1550 | S16: ='3'!AB23 -> 84.709895 | T16: ='3'!Y23 -> 3380 | U16: =IF('3'!AA23=1,'3'!AR6,'3'!AR7) -> S.A.L | X16: 0.45833333 | Y16: 3380 | Z16: 1750 | AA16: 1 | AB16: =IF('3'!AA16=1,(('3'!Z16*'3'!$AS$6*'3'!$AT$6)/('3'!Y16*0.0036)),IF('3'!AA16=2,(('3'!Z16*'3'!$AS$7*'3'!$AT$7)/('3'!Y16*0.0036)))) -> 95.640204 | AD16: =(('3'!AC16*'3'!$O$9*1000000))/('3'!Y16*3600) -> 0 | AF16: =('3'!AE16/24)*0.454 -> 0 | AH16: =('3'!AG16/24)*0.454 -> 0 | AI16: 5200 | AJ16: =('3'!AI16/24)*0.454 -> 98.366667 | AL16: =('3'!AK16/24)*0.454 -> 0 | AN16: =('3'!AM16/24)*0.454 -> 0 | AP16: =('3'!AO16/24)*0.454 -> 0
A17: 0.83333333 | B17: 321 | C17: 18 | D17: 18 | E17: 8 | F17: 139 | G17: 3.3 | H17: 2.4 | I17: 1 | J17: 1 | K17: 6.6 | L17: 6.2 | M17: 6.2 | N17: 6 | O17: 3.8 | R17: ='3'!Z25 -> 1550 | S17: ='3'!AB25 -> 84.709895 | T17: ='3'!Y25 -> 3380 | U17: =IF('3'!AA25=1,'3'!AR6,'3'!AR7) -> S.A.L | V17: =ESCALA!$C$5 | X17: 0.5 | Y17: 3371 | Z17: 1750 | AA17: 1 | AB17: =IF('3'!AA17=1,(('3'!Z17*'3'!$AS$6*'3'!$AT$6)/('3'!Y17*0.0036)),IF('3'!AA17=2,(('3'!Z17*'3'!$AS$7*'3'!$AT$7)/('3'!Y17*0.0036)))) -> 95.895547 | AD17: =(('3'!AC17*'3'!$O$9*1000000))/('3'!Y17*3600) -> 0 | AF17: =('3'!AE17/24)*0.454 -> 0 | AH17: =('3'!AG17/24)*0.454 -> 0 | AI17: 5200 | AJ17: =('3'!AI17/24)*0.454 -> 98.366667 | AL17: =('3'!AK17/24)*0.454 -> 0 | AN17: =('3'!AM17/24)*0.454 -> 0 | AP17: =('3'!AO17/24)*0.454 -> 0
A18: 0.91666667 | B18: 324 | C18: 18 | D18: 18 | E18: 8 | F18: 137 | G18: 3.1 | H18: 2.3 | I18: 0.9 | J18: 0.9 | K18: 6.6 | L18: 6.2 | M18: 6.2 | N18: 6 | O18: 3.8 | R18: ='3'!Z27 -> 1550 | S18: ='3'!AB27 -> 84.835391 | T18: ='3'!Y27 -> 3375 | U18: =IF('3'!AA27=1,'3'!AR6,'3'!AR7) -> S.A.L | X18: 0.54166667 | Y18: 3372 | Z18: 1750 | AA18: 1 | AB18: =IF('3'!AA18=1,(('3'!Z18*'3'!$AS$6*'3'!$AT$6)/('3'!Y18*0.0036)),IF('3'!AA18=2,(('3'!Z18*'3'!$AS$7*'3'!$AT$7)/('3'!Y18*0.0036)))) -> 95.867108 | AD18: =(('3'!AC18*'3'!$O$9*1000000))/('3'!Y18*3600) -> 0 | AF18: =('3'!AE18/24)*0.454 -> 0 | AH18: =('3'!AG18/24)*0.454 -> 0 | AI18: 5200 | AJ18: =('3'!AI18/24)*0.454 -> 98.366667 | AL18: =('3'!AK18/24)*0.454 -> 0 | AN18: =('3'!AM18/24)*0.454 -> 0 | AP18: =('3'!AO18/24)*0.454 -> 0
A19: Média | B19: {=IF('3'!B7:B18>0.01,AVERAGE('3'!B7:B18),"")} -> 301.91667 | C19: {=IF('3'!C7:C18>0.01,AVERAGE('3'!C7:C18),"")} -> 15.575 | D19: {=IF('3'!D7:D18>0.01,AVERAGE('3'!D7:D18),"")} -> 14.275 | E19: {=IF('3'!E7:E18>0.01,AVERAGE('3'!E7:E18),"")} -> 7.3166667 | F19: {=IF('3'!F7:F18>0.01,AVERAGE('3'!F7:F18),"")} -> 166.33333 | G19: {=IF('3'!G7:G18>0.01,AVERAGE('3'!G7:G18),"")} -> 3.5583333 | H19: {=IF('3'!H7:H18>0.01,AVERAGE('3'!H7:H18),"")} -> 2.225 | I19: {=IF('3'!I7:I18>0.01,AVERAGE('3'!I7:I18),"")} -> 0.9525 | ... S19: {=IF('3'!S7:S18>0.01,AVERAGE('3'!S7:S18),"")} -> 95.517663 | X19: 0.58333333 | Y19: 3364 | Z19: 1750 | AA19: 1 | AB19: =IF('3'!AA19=1,(('3'!Z19*'3'!$AS$6*'3'!$AT$6)/('3'!Y19*0.0036)),IF('3'!AA19=2,(('3'!Z19*'3'!$AS$7*'3'!$AT$7)/('3'!Y19*0.0036)))) -> 96.095092 | AD19: =(('3'!AC19*'3'!$O$9*1000000))/('3'!Y19*3600) -> 0 | AF19: =('3'!AE19/24)*0.454 -> 0 | AH19: =('3'!AG19/24)*0.454 -> 0 | AI19: 5200 | AJ19: =('3'!AI19/24)*0.454 -> 98.366667 | AL19: =('3'!AK19/24)*0.454 -> 0 | AN19: =('3'!AM19/24)*0.454 -> 0 | AP19: =('3'!AO19/24)*0.454 -> 0
A20: Máximo | B20: =MAX('3'!B7:B18) -> 324 | C20: =MAX('3'!C7:C18) -> 20 | D20: =MAX('3'!D7:D18) -> 20 | E20: =MAX('3'!E7:E18) -> 11 | F20: =MAX('3'!F7:F18) -> 226 | G20: =MAX('3'!G7:G18) -> 4.9 | H20: =MAX('3'!H7:H18) -> 2.8 | I20: =MAX('3'!I7:I18) -> 1.3 | ... S20: =MAX('3'!S7:S18) -> 100.77738 | X20: 0.625 | Y20: 3369 | Z20: 1750 | AA20: 1 | AB20: =IF('3'!AA20=1,(('3'!Z20*'3'!$AS$6*'3'!$AT$6)/('3'!Y20*0.0036)),IF('3'!AA20=2,(('3'!Z20*'3'!$AS$7*'3'!$AT$7)/('3'!Y20*0.0036)))) -> 95.952475 | AD20: =(('3'!AC20*'3'!$O$9*1000000))/('3'!Y20*3600) -> 0 | AF20: =('3'!AE20/24)*0.454 -> 0 | AH20: =('3'!AG20/24)*0.454 -> 0 | AI20: 5200 | AJ20: =('3'!AI20/24)*0.454 -> 98.366667 | AL20: =('3'!AK20/24)*0.454 -> 0 | AN20: =('3'!AM20/24)*0.454 -> 0 | AP20: =('3'!AO20/24)*0.454 -> 0
A21: Mínimo | B21: =MIN('3'!B7:B18) -> 246 | C21: =MIN('3'!C7:C18) -> 9.9 | D21: =MIN('3'!D7:D18) -> 7.2 | E21: =MIN('3'!E7:E18) -> 3 | F21: =MIN('3'!F7:F18) -> 137 | G21: =MIN('3'!G7:G18) -> 2.7 | H21: =MIN('3'!H7:H18) -> 1.5 | I21: =MIN('3'!I7:I18) -> 0.6 | ... S21: =MIN('3'!S7:S18) -> 84.709895 | X21: 0.66666667 | Y21: 3334 | Z21: 1750 | AA21: 1 | AB21: =IF('3'!AA21=1,(('3'!Z21*'3'!$AS$6*'3'!$AT$6)/('3'!Y21*0.0036)),IF('3'!AA21=2,(('3'!Z21*'3'!$AS$7*'3'!$AT$7)/('3'!Y21*0.0036)))) -> 96.959775 | AD21: =(('3'!AC21*'3'!$O$9*1000000))/('3'!Y21*3600) -> 0 | AF21: =('3'!AE21/24)*0.454 -> 0 | AH21: =('3'!AG21/24)*0.454 -> 0 | AI21: 5200 | AJ21: =('3'!AI21/24)*0.454 -> 98.366667 | AL21: =('3'!AK21/24)*0.454 -> 0 | AN21: =('3'!AM21/24)*0.454 -> 0 | AP21: =('3'!AO21/24)*0.454 -> 0
R22: Total | X22: 0.70833333 | Y22: 3420 | Z22: 1550 | AA22: 1 | AB22: =IF('3'!AA22=1,(('3'!Z22*'3'!$AS$6*'3'!$AT$6)/('3'!Y22*0.0036)),IF('3'!AA22=2,(('3'!Z22*'3'!$AS$7*'3'!$AT$7)/('3'!Y22*0.0036)))) -> 83.719136 | AD22: =(('3'!AC22*'3'!$O$9*1000000))/('3'!Y22*3600) -> 0 | AF22: =('3'!AE22/24)*0.454 -> 0 | AH22: =('3'!AG22/24)*0.454 -> 0 | AI22: 5000 | AJ22: =('3'!AI22/24)*0.454 -> 94.583333 | AL22: =('3'!AK22/24)*0.454 -> 0 | AN22: =('3'!AM22/24)*0.454 -> 0 | AP22: =('3'!AO22/24)*0.454 -> 0
A23: TURBIDEZ DOS FILTROS DA 1ª E 2ª ETAPAS | R23: 440 | S23: Litros | X23: 0.75 | Y23: 3380 | Z23: 1550 | AA23: 1 | AB23: =IF('3'!AA23=1,(('3'!Z23*'3'!$AS$6*'3'!$AT$6)/('3'!Y23*0.0036)),IF('3'!AA23=2,(('3'!Z23*'3'!$AS$7*'3'!$AT$7)/('3'!Y23*0.0036)))) -> 84.709895 | AD23: =(('3'!AC23*'3'!$O$9*1000000))/('3'!Y23*3600) -> 0 | AF23: =('3'!AE23/24)*0.454 -> 0 | AH23: =('3'!AG23/24)*0.454 -> 0 | AI23: 5000 | AJ23: =('3'!AI23/24)*0.454 -> 94.583333 | AL23: =('3'!AK23/24)*0.454 -> 0 | AN23: =('3'!AM23/24)*0.454 -> 0 | AP23: =('3'!AO23/24)*0.454 -> 0
A24: HORA | B24: 1 | C24: 2 | D24: 3 | E24: 4 | F24: 5 | G24: 6 | H24: 7 | I24: 8 | J24: 9 | K24: 10 | L24: 11 | M24: 12 | N24: 13 | O24: 14 | P24: 15 | Q24: 16 | R24: 0 | S24: Kilos | X24: 0.79166667 | Y24: 3420 | Z24: 1550 | AA24: 1 | AB24: =IF('3'!AA24=1,(('3'!Z24*'3'!$AS$6*'3'!$AT$6)/('3'!Y24*0.0036)),IF('3'!AA24=2,(('3'!Z24*'3'!$AS$7*'3'!$AT$7)/('3'!Y24*0.0036)))) -> 83.719136 | AD24: =(('3'!AC24*'3'!$O$9*1000000))/('3'!Y24*3600) -> 0 | AF24: =('3'!AE24/24)*0.454 -> 0 | AH24: =('3'!AG24/24)*0.454 -> 0 | AI24: 5000 | AJ24: =('3'!AI24/24)*0.454 -> 94.583333 | AL24: =('3'!AK24/24)*0.454 -> 0 | AN24: =('3'!AM24/24)*0.454 -> 0 | AP24: =('3'!AO24/24)*0.454 -> 0
