Workbook

Sheet ESCALA
A1: DATA | B1: ESCALA | C1: ESCALA
B2: 07:00h às 19:00h | C2: 19:00h às 07:00h
A3: 43922 | E3: DIGITAR PRIMEIRO DIA DO MÊS
A4: =ESCALA!A3+1 -> 43923
A5: =ESCALA!A4+1 -> 43924
A6: =ESCALA!A5+1 -> 43925
A7: =ESCALA!A6+1 -> 43926
A8: =ESCALA!A7+1 -> 43927
A9: =ESCALA!A8+1 -> 43928
A10: =ESCALA!A9+1 -> 43929
A11: =ESCALA!A10+1 -> 43930
A12: =ESCALA!A11+1 -> 43931
A13: =ESCALA!A12+1 -> 43932
A14: =ESCALA!A13+1 -> 43933
A15: =ESCALA!A14+1 -> 43934
... A33: =ESCALA!A32+1 -> 43952

Sheet 1
D2: CONTROLE DE ANÁLISE FÍSICO - QUÍMICAS \ ETA CASTELO BRANCO | AB2: CONTROLE DE PRODUTOS QUÍMICOS APLICADOS \ ETA CASTELO BRANCO
A4: HORA | B4: COR (Uc) | F4: TURBIDEZ (Ut) | K4: Ph | O4: CLORO RESIDUAL (mg/L) | R4: DOSAGEM DO COAGULANTE | T4: VAZÃO DA ETA | U4: TIPO DE COAGU LANTE | V4: TÉCNICO | X4: Hora | Y4: Vazão ETA (l/s) | Z4: Vazão Coagulante (l/h) | AA4: Código | AB4: Dosagem (mg/l) | AC4: Vazão Polímero (l/h) | AD4: Dosagem (mg/l) | AE4: Pré 1 (Lib/dia) | AF4: Pré 1 (Kg/h) | AG4: Pré 2 (Lib/dia) | AH4: Pré 2 (Kg/h) | AI4: Pós (Lib/dia) | AJ4: Pós (Kg/h) | AK4: Pré 1 (Lib/dia) cilindros | AL4: Pré 1 (Kg/h) cilindros | AM4: Pré 2 (Lib/dia) cilindros | AN4: Pré 2 (Kg/h) cilindros | AO4: Pós (Lib/dia) cilindros | AP4: Pós (Kg/h) cilindros | AQ4: COAGULANTE | AU4: Tempo de Utilização (h)
AQ5: Codigo | AR5: Nome | AS5: d (g/ml) | AT5: C (%)
B6: Bruta | C6: DEC_1 | D6: DEC_2 | E6: TRAT | F6: Bruta | G6: DEC_1 | H6: DEC_2 | I6: TRAT | J6: FILT | K6: Bruta | L6: DEC_1 | M6: DEC_2 | N6: TRAT | O6: TRAT | P6: DEC_1 | Q6: DEC_2 | R6: L/h | S6: mg/l | T6: L/s | X6: 0.041666667 | Y6: 3187 | Z6: 1320 | AA6: 1 | AB6: =IF('1'!AA6=1,(('1'!Z6*'1'!$AS$6*'1'!$AT$6)/('1'!Y6*0.0036)),IF('1'!AA6=2,(('1'!Z6*'1'!$AS$7*'1'!$AT$7)/('1'!Y6*0.0036)))) -> 76.508733 | AD6: =(('1'!AC6*'1'!$Q$10*1000000))/('1'!Z10*3600) -> 0 | AE6: 2000 | AF6: =('1'!AE6/24)*0.454 -> 37.833333 | AG6: 500 | AH6: =('1'!AG6/24)*0.454 -> 9.4583333 | AI6: 2500 | AJ6: =('1'!AI6/24)*0.454 -> 47.291667 | AL6: =('1'!AK6/24)*0.454 -> 0 | AN6: =('1'!AM6/24)*0.454 -> 0 | AP6: =('1'!AO6/24)*0.454 -> 0 | AQ6: 1 | AR6: S.A.L | AS6: 1.33 | AT6: 0.5 | AU6: 0
A7: 0 | B7: 219 | C7: 10 | D7: 11 | E7: 9 | F7: 56 | G7: 1.3 | H7: 1.7 | I7: 0.8 | J7: 0.7 | K7: 6.7 | L7: 6.1 | M7: 6.2 | N7: 6 | O7: 3.5 | P7: 0.6 | Q7: 0.3 | U7: =IF('1'!AA6=1,'1'!AR6,'1'!AR7) -> S.A.L | X7: 0.083333333 | Y7: 3177 | Z7: 1320 | AA7: 1 | AB7: =IF('1'!AA7=1,(('1'!Z7*'1'!$AS$6*'1'!$AT$6)/('1'!Y7*0.0036)),IF('1'!AA7=2,(('1'!Z7*'1'!$AS$7*'1'!$AT$7)/('1'!Y7*0.0036)))) -> 76.749554 | AD7: =(('1'!AC7*'1'!$Q$10*1000000))/('1'!Z11*3600) -> 0 | AE7: 2000 | AF7: =('1'!AE7/24)*0.454 -> 37.833333 | AG7: 500 | AH7: =('1'!AG7/24)*0.454 -> 9.4583333 | AI7: 2500 | AJ7: =('1'!AI7/24)*0.454 -> 47.291667 | AL7: =('1'!AK7/24)*0.454 -> 0 | AN7: =('1'!AM7/24)*0.454 -> 0 | AP7: =('1'!AO7/24)*0.454 -> 0 | AQ7: 2 | AR7: PAC 18 | AS7: 1.377 | AT7: 1 | AU7: 24
A8: 0.083333333 | B8: 222 | C8: 10 | D8: 11 | E8: 8 | F8: 57 | G8: 1.3 | H8: 1.7 | I8: 0.8 | J8: 0.7 | K8: 6.7 | L8: 6.1 | M8: 6.2 | N8: 6 | O8: 3.5 | P8: 0.6 | Q8: 0.3 | R8: ='1'!Z7 -> 1320 | S8: ='1'!AB7 -> 76.749554 | T8: ='1'!Y7 -> 3177 | U8: =IF('1'!AA7=1,'1'!AR6,'1'!AR7) -> S.A.L | X8: 0.125 | Y8: 3158 | Z8: 1320 | AA8: 1 | AB8: =IF('1'!AA8=1,(('1'!Z8*'1'!$AS$6*'1'!$AT$6)/('1'!Y8*0.0036)),IF('1'!AA8=2,(('1'!Z8*'1'!$AS$7*'1'!$AT$7)/('1'!Y8*0.0036)))) -> 77.211315 | AD8: =(('1'!AC8*'1'!$Q$10*1000000))/('1'!Z12*3600) -> 0 | AE8: 2000 | AF8: =('1'!AE8/24)*0.454 -> 37.833333 | AG8: 500 | AH8: =('1'!AG8/24)*0.454 -> 9.4583333 | AI8: 2500 | AJ8: =('1'!AI8/24)*0.454 -> 47.291667 | AL8: =('1'!AK8/24)*0.454 -> 0 | AN8: =('1'!AM8/24)*0.454 -> 0 | AP8: =('1'!AO8/24)*0.454 -> 0 | AQ8: Polímero Catiônico
A9: 0.16666667 | B9: 226 | C9: 10 | D9: 11 | E9: 8 | F9: 57 | G9: 1.3 | H9: 1.8 | I9: 0.8 | J9: 0.7 | K9: 6.7 | L9: 6.1 | M9: 6.2 | N9: 6 | O9: 3.5 | P9: 0.6 | Q9: 0.3 | R9: ='1'!Z9 -> 1320 | S9: ='1'!AB9 -> 75.701128 | T9: ='1'!Y9 -> 3221 | U9: =IF('1'!AA9=1,'1'!AR6,'1'!AR7) -> S.A.L | X9: 0.16666667 | Y9: 3221 | Z9: 1320 | AA9: 1 | AB9: =IF('1'!AA9=1,(('1'!Z9*'1'!$AS$6*'1'!$AT$6)/('1'!Y9*0.0036)),IF('1'!AA9=2,(('1'!Z9*'1'!$AS$7*'1'!$AT$7)/('1'!Y9*0.0036)))) -> 75.701128 | AD9: =(('1'!AC9*'1'!$Q$10*1000000))/('1'!Z13*3600) -> 0 | AE9: 2000 | AF9: =('1'!AE9/24)*0.454 -> 37.833333 | AG9: 500 | AH9: =('1'!AG9/24)*0.454 -> 9.4583333 | AI9: 2500 | AJ9: =('1'!AI9/24)*0.454 -> 47.291667 | AL9: =('1'!AK9/24)*0.454 -> 0 | AN9: =('1'!AM9/24)*0.454 -> 0 | AP9: =('1'!AO9/24)*0.454 -> 0 | AQ9: Nome | AT9: C (%)
A10: 0.25 | B10: 230 | C10: 11 | D10: 11 | E10: 7 | F10: 60 | G10: 1.4 | H10: 1.8 | I10: 0.8 | J10: 0.7 | K10: 6.7 | L10: 6.1 | M10: 6.2 | N10: 6 | O10: 3.5 | P10: 0.6 | Q10: 0.3 | R10: ='1'!Z11 -> 1320 | S10: ='1'!AB11 -> 75.842405 | T10: ='1'!Y11 -> 3215 | U10: =IF('1'!AA11=1,'1'!AR6,'1'!AR7) -> S.A.L | X10: 0.20833333 | Y10: 3199 | Z10: 1320 | AA10: 1 | AB10: =IF('1'!AA10=1,(('1'!Z10*'1'!$AS$6*'1'!$AT$6)/('1'!Y10*0.0036)),IF('1'!AA10=2,(('1'!Z10*'1'!$AS$7*'1'!$AT$7)/('1'!Y10*0.0036)))) -> 76.221736 | AD10: =(('1'!AC10*'1'!$Q$10*1000000))/('1'!Z14*3600) -> 0 | AE10: 2000 | AF10: =('1'!AE10/24)*0.454 -> 37.833333 | AG10: 500 | AH10: =('1'!AG10/24)*0.454 -> 9.4583333 | AI10: 2500 | AJ10: =('1'!AI10/24)*0.454 -> 47.291667 | AL10: =('1'!AK10/24)*0.454 -> 0 | AN10: =('1'!AM10/24)*0.454 -> 0 | AP10: =('1'!AO10/24)*0.454 -> 0 | AQ10: Aguapol 200 | AT10: 0.002
A11: 0.33333333 | B11: 233 | C11: 11 | D11: 12 | E11: 7 | F11: 62 | G11: 1.5 | H11: 1.7 | I11: 0.7 | J11: 0.7 | K11: 6.9 | L11: 6.3 | M11: 6.3 | N11: 6 | O11: 3.6 | P11: 0.5 | Q11: 0.3 | R11: ='1'!Z13 -> 1320 | S11: ='1'!AB13 -> 76.60488 | T11: ='1'!Y13 -> 3183 | U11: =IF('1'!AA13=1,'1'!AR6,'1'!AR7) -> S.A.L | X11: 0.25 | Y11: 3215 | Z11: 1320 | AA11: 1 | AB11: =IF('1'!AA11=1,(('1'!Z11*'1'!$AS$6*'1'!$AT$6)/('1'!Y11*0.0036)),IF('1'!AA11=2,(('1'!Z11*'1'!$AS$7*'1'!$AT$7)/('1'!Y11*0.0036)))) -> 75.842405 | AD11: =(('1'!AC11*'1'!$Q$10*1000000))/('1'!Z15*3600) -> 0 | AE11: 2000 | AF11: =('1'!AE11/24)*0.454 -> 37.833333 | AG11: 500 | AH11: =('1'!AG11/24)*0.454 -> 9.4583333 | AI11: 2500 | AJ11: =('1'!AI11/24)*0.454 -> 47.291667 | AL11: =('1'!AK11/24)*0.454 -> 0 | AN11: =('1'!AM11/24)*0.454 -> 0 | AP11: =('1'!AO11/24)*0.454 -> 0
A12: 0.41666667 | B12: 226 | C12: 12 | D12: 13 | E12: 7 | F12: 59 | G12: 1.6 | H12: 1.9 | I12: 0.7 | J12: 0.6 | K12: 6.9 | L12: 6.3 | M12: 6.3 | N12: 6 | O12: 3.6 | P12: 0.4 | Q12: 0.1 | R12: ='1'!Z15 -> 1320 | S12: ='1'!AB15 -> 76.749554 | T12: ='1'!Y15 -> 3177 | U12: =IF('1'!AA15=1,'1'!AR6,'1'!AR7) -> S.A.L | V12: =ESCALA!$B$3 -> 0 | X12: 0.29166667 | Y12: 3189 | Z12: 1320 | AA12: 1 | AB12: =IF('1'!AA12=1,(('1'!Z12*'1'!$AS$6*'1'!$AT$6)/('1'!Y12*0.0036)),IF('1'!AA12=2,(('1'!Z12*'1'!$AS$7*'1'!$AT$7)/('1'!Y12*0.0036)))) -> 76.46075 | AD12: =(('1'!AC12*'1'!$Q$10*1000000))/('1'!Z16*3600) -> 0 | AE12: 2000 | AF12: =('1'!AE12/24)*0.454 -> 37.833333 | AG12: 500 | AH12: =('1'!AG12/24)*0.454 -> 9.4583333 | AI12: 2500 | AJ12: =('1'!AI12/24)*0.454 -> 47.291667 | AL12: =('1'!AK12/24)*0.454 -> 0 | AN12: =('1'!AM12/24)*0.454 -> 0 | AP12: =('1'!AO12/24)*0.454 -> 0
A13: 0.5 | B13: 223 | C13: 12 | D13: 13 | E13: 7 | F13: 57 | G13: 1.6 | H13: 1.8 | I13: 0.7 | J13: 0.6 | K13: 6.9 | L13: 6.3 | M13: 6.3 | N13: 6 | O13: 3.2 | R13: ='1'!Z17 -> 1320 | S13: ='1'!AB17 -> 76.484734 | T13: ='1'!Y17 -> 3188 | U13: =IF('1'!AA17=1,'1'!AR6,'1'!AR7) -> S.A.L | X13: 0.33333333 | Y13: 3183 | Z13: 1320 | AA13: 1 | AB13: =IF('1'!AA13=1,(('1'!Z13*'1'!$AS$6*'1'!$AT$6)/('1'!Y13*0.0036)),IF('1'!AA13=2,(('1'!Z13*'1'!$AS$7*'1'!$AT$7)/('1'!Y13*0.0036)))) -> 76.60488 | AD13: =(('1'!AC13*'1'!$Q$10*1000000))/('1'!Z17*3600) -> 0 | AE13: 2000 | AF13: =('1'!AE13/24)*0.454 -> 37.833333 | AG13: 500 | AH13: =('1'!AG13/24)*0.454 -> 9.4583333 | AI13: 2500 | AJ13: =('1'!AI13/24)*0.454 -> 47.291667 | AL13: =('1'!AK13/24)*0.454 -> 0 | AN13: =('1'!AM13/24)*0.454 -> 0 | AP13: =('1'!AO13/24)*0.454 -> 0
A14: 0.58333333 | B14: 220 | C14: 12 | D14: 13 | E14: 7 | F14: 56 | G14: 1.7 | H14: 1.8 | I14: 0.7 | J14: 0.7 | K14: 6.9 | L14: 6.3 | M14: 6.3 | N14: 6 | O14: 3 | R14: ='1'!Z19 -> 1350 | S14: ='1'!AB19 -> 78.002815 | T14: ='1'!Y19 -> 3197 | U14: =IF('1'!AA19=1,'1'!AR6,'1'!AR7) -> S.A.L | X14: 0.375 | Y14: 3187 | Z14: 1320 | AA14: 1 | AB14: =IF('1'!AA14=1,(('1'!Z14*'1'!$AS$6*'1'!$AT$6)/('1'!Y14*0.0036)),IF('1'!AA14=2,(('1'!Z14*'1'!$AS$7*'1'!$AT$7)/('1'!Y14*0.0036)))) -> 76.508733 | AD14: =(('1'!AC14*'1'!$Q$10*1000000))/('1'!Z18*3600) -> 0 | AE14: 2000 | AF14: =('1'!AE14/24)*0.454 -> 37.833333 | AG14: 500 | AH14: =('1'!AG14/24)*0.454 -> 9.4583333 | AI14: 2500 | AJ14: =('1'!AI14/24)*0.454 -> 47.291667 | AL14: =('1'!AK14/24)*0.454 -> 0 | AN14: =('1'!AM14/24)*0.454 -> 0 | AP14: =('1'!AO14/24)*0.454 -> 0
A15: 0.66666667 | B15: 224 | C15: 13 | D15: 13 | E15: 7 | F15: 58 | G15: 1.8 | H15: 1.8 | I15: 0.7 | J15: 0.7 | K15: 6.9 | L15: 6.3 | M15: 6.3 | N15: 6 | O15: 2.8 | R15: ='1'!Z21 -> 1350 | S15: ='1'!AB21 -> 77.421608 | T15: ='1'!Y21 -> 3221 | U15: =IF('1'!AA21=1,'1'!AR6,'1'!AR7) -> S.A.L | X15: 0.41666667 | Y15: 3177 | Z15: 1320 | AA15: 1 | AB15: =IF('1'!AA15=1,(('1'!Z15*'1'!$AS$6*'1'!$AT$6)/('1'!Y15*0.0036)),IF('1'!AA15=2,(('1'!Z15*'1'!$AS$7*'1'!$AT$7)/('1'!Y15*0.0036)))) -> 76.749554 | AD15: =(('1'!AC15*'1'!$Q$10*1000000))/('1'!Z19*3600) -> 0 | AF15: =('1'!AE15/24)*0.454 -> 0 | AH15: =('1'!AG15/24)*0.454 -> 0 | AI15: 2500 | AJ15: =('1'!AI15/24)*0.454 -> 47.291667 | AL15: =('1'!AK15/24)*0.454 -> 0 | AN15: =('1'!AM15/24)*0.454 -> 0 | AP15: =('1'!AO15/24)*0.454 -> 0
A16: 0.75 | B16: 228 | C16: 14 | D16: 14 | E16: 7 | F16: 60 | G16: 1.8 | H16: 1.9 | I16: 0.8 | J16: 0.7 | K16: 6.9 | L16: 6.3 | M16: 6.3 | N16: 6 | O16: 2.6 | R16: ='1'!Z23 -> 1350 | S16: ='1'!AB23 -> 77.566096 | T16: ='1'!Y23 -> 3215 | U16: =IF('1'!AA23=1,'1'!AR6,'1'!AR7) -> S.A.L | X16: 0.45833333 | Y16: 3158 | Z16: 1320 | AA16: 1 | AB16: =IF('1'!AA16=1,(('1'!Z16*'1'!$AS$6*'1'!$AT$6)/('1'!Y16*0.0036)),IF('1'!AA16=2,(('1'!Z16*'1'!$AS$7*'1'!$AT$7)/('1'!Y16*0.0036)))) -> 77.211315 | AD16: =(('1'!AC16*'1'!$Q$10*1000000))/('1'!Z20*3600) -> 0 | AF16: =('1'!AE16/24)*0.454 -> 0 | AH16: =('1'!AG16/24)*0.454 -> 0 | AI16: 2500 | AJ16: =('1'!AI16/24)*0.454 -> 47.291667 | AL16: =('1'!AK16/24)*0.454 -> 0 | AN16: =('1'!AM16/24)*0.454 -> 0 | AP16: =('1'!AO16/24)*0.454 -> 0
A17: 0.83333333 | B17: 244 | C17: 14 | D17: 15 | E17: 7 | F17: 64 | G17: 1.7 | H17: 2 | I17: 0.9 | J17: 0.7 | K17: 6.9 | L17: 6.3 | M17: 6.3 | N17: 6 | O17: 2.5 | R17: ='1'!Z25 -> 1350 | S17: ='1'!AB25 -> 77.638543 | T17: ='1'!Y25 -> 3212 | U17: =IF('1'!AA25=1,'1'!AR6,'1'!AR7) -> S.A.L | V17: =ESCALA!$C$3 -> 0 | X17: 0.5 | Y17: 3188 | Z17: 1320 | AA17: 1 | AB17: =IF('1'!AA17=1,(('1'!Z17*'1'!$AS$6*'1'!$AT$6)/('1'!Y17*0.0036)),IF('1'!AA17=2,(('1'!Z17*'1'!$AS$7*'1'!$AT$7)/('1'!Y17*0.0036)))) -> 76.484734 | AD17: =(('1'!AC17*'1'!$Q$10*1000000))/('1'!Z21*3600) -> 0 | AF17: =('1'!AE17/24)*0.454 -> 0 | AH17: =('1'!AG17/24)*0.454 -> 0 | AI17: 2500 | AJ17: =('1'!AI17/24)*0.454 -> 47.291667 | AL17: =('1'!AK17/24)*0.454 -> 0 | AN17: =('1'!AM17/24)*0.454 -> 0 | AP17: =('1'!AO17/24)*0.454 -> 0
A18: 0.91666667 | B18: 258 | C18: 15 | D18: 16 | E18: 7 | F18: 67 | G18: 1.7 | H18: 2 | I18: 0.9 | J18: 0.7 | K18: 6.9 | L18: 6.3 | M18: 6.3 | N18: 6 | O18: 2.5 | R18: ='1'!Z27 -> 1350 | S18: ='1'!AB27 -> 76.801663 | T18: ='1'!Y27 -> 3247 | U18: =IF('1'!AA27=1,'1'!AR6,'1'!AR7) -> S.A.L | X18: 0.54166667 | Y18: 3204 | Z18: 1320 | AA18: 1 | AB18: =IF('1'!AA18=1,(('1'!Z18*'1'!$AS$6*'1'!$AT$6)/('1'!Y18*0.0036)),IF('1'!AA18=2,(('1'!Z18*'1'!$AS$7*'1'!$AT$7)/('1'!Y18*0.0036)))) -> 76.102788 | AD18: =(('1'!AC18*'1'!$Q$10*1000000))/('1'!Z22*3600) -> 0 | AF18: =('1'!AE18/24)*0.454 -> 0 | AH18: =('1'!AG18/24)*0.454 -> 0 | AI18: 2500 | AJ18: =('1'!AI18/24)*0.454 -> 47.291667 | AL18: =('1'!AK18/24)*0.454 -> 0 | AN18: =('1'!AM18/24)*0.454 -> 0 | AP18: =('1'!AO18/24)*0.454 -> 0
A19: Média | B19: {=IF('1'!B7:B18>0.01,AVERAGE('1'!B7:B18),"")} -> 229.41667 | C19: {=IF('1'!C7:C18>0.01,AVERAGE('1'!C7:C18),"")} -> 12 | D19: {=IF('1'!D7:D18>0.01,AVERAGE('1'!D7:D18),"")} -> 12.75 | E19: {=IF('1'!E7:E18>0.01,AVERAGE('1'!E7:E18),"")} -> 7.3333333 | F19: {=IF('1'!F7:F18>0.01,AVERAGE('1'!F7:F18),"")} -> 59.416667 | G19: {=IF('1'!G7:G18>0.01,AVERAGE('1'!G7:G18),"")} -> 1.5583333 | H19: {=IF('1'!H7:H18>0.01,AVERAGE('1'!H7:H18),"")} -> 1.825 | I19: {=IF('1'!I7:I18>0.01,AVERAGE('1'!I7:I18),"")} -> 0.775 | ... S19: {=IF('1'!S7:S18>0.01,AVERAGE('1'!S7:S18),"")} | X19: 0.58333333 | Y19: 3197 | Z19: 1350 | AA19: 1 | AB19: =IF('1'!AA19=1,(('1'!Z19*'1'!$AS$6*'1'!$AT$6)/('1'!Y19*0.0036)),IF('1'!AA19=2,(('1'!Z19*'1'!$AS$7*'1'!$AT$7)/('1'!Y19*0.0036)))) -> 78.002815 | AD19: =(('1'!AC19*'1'!$Q$10*1000000))/('1'!Z23*3600) -> 0 | AF19: =('1'!AE19/24)*0.454 -> 0 | AH19: =('1'!AG19/24)*0.454 -> 0 | AI19: 2500 | AJ19: =('1'!AI19/24)*0.454 -> 47.291667 | AL19: =('1'!AK19/24)*0.454 -> 0 | AN19: =('1'!AM19/24)*0.454 -> 0 | AP19: =('1'!AO19/24)*0.454 -> 0
A20: Máximo | B20: =MAX('1'!B7:B18) -> 258 | C20: =MAX('1'!C7:C18) -> 15 | D20: =MAX('1'!D7:D18) -> 16 | E20: =MAX('1'!E7:E18) -> 9 | F20: =MAX('1'!F7:F18) -> 67 | G20: =MAX('1'!G7:G18) -> 1.8 | H20: =MAX('1'!H7:H18) -> 2 | I20: =MAX('1'!I7:I18) -> 0.9 | ... S20: =MAX('1'!S7:S18) -> 78.002815 | X20: 0.625 | Y20: 3193 | Z20: 1350 | AA20: 1 | AB20: =IF('1'!AA20=1,(('1'!Z20*'1'!$AS$6*'1'!$AT$6)/('1'!Y20*0.0036)),IF('1'!AA20=2,(('1'!Z20*'1'!$AS$7*'1'!$AT$7)/('1'!Y20*0.0036)))) -> 78.100532 | AD20: =(('1'!AC20*'1'!$Q$10*1000000))/('1'!Z24*3600) -> 0 | AF20: =('1'!AE20/24)*0.454 -> 0 | AH20: =('1'!AG20/24)*0.454 -> 0 | AI20: 2500 | AJ20: =('1'!AI20/24)*0.454 -> 47.291667 | AL20: =('1'!AK20/24)*0.454 -> 0 | AN20: =('1'!AM20/24)*0.454 -> 0 | AP20: =('1'!AO20/24)*0.454 -> 0
A21: Mínimo | B21: =MIN('1'!B7:B18) -> 219 | C21: =MIN('1'!C7:C18) -> 10 | D21: =MIN('1'!D7:D18) -> 11 | E21: =MIN('1'!E7:E18) -> 7 | F21: =MIN('1'!F7:F18) -> 56 | G21: =MIN('1'!G7:G18) -> 1.3 | H21: =MIN('1'!H7:H18) -> 1.7 | I21: =MIN('1'!I7:I18) -> 0.7 | ... S21: =MIN('1'!S7:S18) -> 75.701128 | X21: 0.66666667 | Y21: 3221 | Z21: 1350 | AA21: 1 | AB21: =IF('1'!AA21=1,(('1'!Z21*'1'!$AS$6*'1'!$AT$6)/('1'!Y21*0.0036)),IF('1'!AA21=2,(('1'!Z21*'1'!$AS$7*'1'!$AT$7)/('1'!Y21*0.0036)))) -> 77.421608 | AD21: =(('1'!AC21*'1'!$Q$10*1000000))/('1'!Y21*3600) -> 0 | AF21: =('1'!AE21/24)*0.454 -> 0 | AH21: =('1'!AG21/24)*0.454 -> 0 | AI21: 2500 | AJ21: =('1'!AI21/24)*0.454 -> 47.291667 | AL21: =('1'!AK21/24)*0.454 -> 0 | AN21: =('1'!AM21/24)*0.454 -> 0 | AP21: =('1'!AO21/24)*0.454 -> 0
R22: Total | X22: 0.70833333 | Y22: 3199 | Z22: 1350 | AA22: 1 | AB22: =IF('1'!AA22=1,(('1'!Z22*'1'!$AS$6*'1'!$AT$6)/('1'!Y22*0.0036)),IF('1'!AA22=2,(('1'!Z22*'1'!$AS$7*'1'!$AT$7)/('1'!Y22*0.0036)))) -> 77.954048 | AD22: =(('1'!AC22*'1'!$Q$10*1000000))/('1'!Y22*3600) -> 0 | AF22: =('1'!AE22/24)*0.454 -> 0 | AH22: =('1'!AG22/24)*0.454 -> 0 | AI22: 2500 | AJ22: =('1'!AI22/24)*0.454 -> 47.291667 | AL22: =('1'!AK22/24)*0.454 -> 0 | AN22: =('1'!AM22/24)*0.454 -> 0 | AP22: =('1'!AO22/24)*0.454 -> 0
A23: TURBIDEZ DOS FILTROS DA 1ª E 2ª ETAPAS | R23: 440 | S23: Litros | X23: 0.75 | Y23: 3215 | Z23: 1350 | AA23: 1 | AB23: =IF('1'!AA23=1,(('1'!Z23*'1'!$AS$6*'1'!$AT$6)/('1'!Y23*0.0036)),IF('1'!AA23=2,(('1'!Z23*'1'!$AS$7*'1'!$AT$7)/('1'!Y23*0.0036)))) -> 77.566096 | AD23: =(('1'!AC23*'1'!$Q$10*1000000))/('1'!Y23*3600) -> 0 | AF23: =('1'!AE23/24)*0.454 -> 0 | AH23: =('1'!AG23/24)*0.454 -> 0 | AI23: 2500 | AJ23: =('1'!AI23/24)*0.454 -> 47.291667 | AL23: =('1'!AK23/24)*0.454 -> 0 | AN23: =('1'!AM23/24)*0.454 -> 0 | AP23: =('1'!AO23/24)*0.454 -> 0
A24: HORA | B24: 1 | C24: 2 | D24: 3 | E24: 4 | F24: 5 | G24: 6 | H24: 7 | I24: 8 | J24: 9 | K24: 10 | L24: 11 | M24: 12 | N24: 13 | O24: 14 | P24: 15 | Q24: 16 | R24: 0 | S24: Kilos | X24: 0.79166667 | Y24: 3204 | Z24: 1350 | AA24: 1 | AB24: =IF('1'!AA24=1,(('1'!Z24*'1'!$AS$6*'1'!$AT$6)/('1'!Y24*0.0036)),IF('1'!AA24=2,(('1'!Z24*'1'!$AS$7*'1'!$AT$7)/('1'!Y24*0.0036)))) -> 77.832397 | AD24: =(('1'!AC24*'1'!$Q$10*1000000))/('1'!Y24*3600) -> 0 | AF24: =('1'!AE24/24)*0.454 -> 0 | AH24: =('1'!AG24/24)*0.454 -> 0 | AI24: 3000 | AJ24: =('1'!AI24/24)*0.454 -> 56.75 | AL24: =('1'!AK24/24)*0.454 -> 0 | AN24: =('1'!AM24/24)*0.454 -> 0 | AP24: =('1'!AO24/24)*0.454 -> 0
A25: 0.41666667 | R25: =#DIV/0! -> #DIV/0! | T25: DATA | U25: =ESCALA!$A$3 -> 43922 | X25: 0.83333333 | Y25: 3212 | Z25: 1350 | AA25: 1 | AB25: =IF('1'!AA25=1,(('1'!Z25*'1'!$AS$6*'1'!$AT$6)/('1'!Y25*0.0036)),IF('1'!AA25=2,(('1'!Z25*'1'!$AS$7*'1'!$AT$7)/('1'!Y25*0.0036)))) -> 77.638543 | AD25: =(('1'!AC25*'1'!$Q$10*1000000))/('1'!Y25*3600) -> 0 | AF25: =('1'!AE25/24)*0.454 -> 0 | AH25: =('1'!AG25/24)*0.454 -> 0 | AI25: 3000 | AJ25: =('1'!AI25/24)*0.454 -> 56.75 | AL25: =('1'!AK25/24)*0.454 -> 0 | AN25: =('1'!AM25/24)*0.454 -> 0 | AP25: =('1'!AO25/24)*0.454 -> 0
A26: 0.66666667 | X26: 0.875 | Y26: 3186 | Z26: 1350 | AA26: 1 | AB26: =IF('1'!AA26=1,(('1'!Z26*'1'!$AS$6*'1'!$AT$6)/('1'!Y26*0.0036)),IF('1'!AA26=2,(('1'!Z26*'1'!$AS$7*'1'!$AT$7)/('1'!Y26*0.0036)))) -> 78.272128 | AD26: =(('1'!AC26*'1'!$Q$10*1000000))/('1'!Y26*3600) -> 0 | AF26: =('1'!AE26/24)*0.454 -> 0 | AH26: =('1'!AG26/24)*0.454 -> 0 | AI26: 3000 | AJ26: =('1'!AI26/24)*0.454 -> 56.75 | AL26: =('1'!AK26/24)*0.454 -> 0 | AN26: =('1'!AM26/24)*0.454 -> 0 | AP26: =('1'!AO26/24)*0.454 -> 0
A27: Média | B27: =#DIV/0! -> #DIV/0! | C27: =#DIV/0! -> #DIV/0! | D27: =#DIV/0! -> #DIV/0! | E27: =#DIV/0! -> #DIV/0! | F27: =#DIV/0! -> #DIV/0! | G27: =#DIV/0! -> #DIV/0! | H27: =#DIV/0! -> #DIV/0! | I27: =#DIV/0! -> #DIV/0! | ... Q27: =#DIV/0! -> #DIV/0! | X27: 0.91666667 | Y27: 3247 | Z27: 1350 | AA27: 1 | AB27: =IF('1'!AA27=1,(('1'!Z27*'1'!$AS$6*'1'!$AT$6)/('1'!Y27*0.0036)),IF('1'!AA27=2,(('1'!Z27*'1'!$AS$7*'1'!$AT$7)/('1'!Y27*0.0036)))) -> 76.801663 | AD27: =(('1'!AC27*'1'!$Q$10*1000000))/('1'!Y27*3600) -> 0 | AF27: =('1'!AE27/24)*0.454 -> 0 | AH27: =('1'!AG27/24)*0.454 -> 0 | AI27: 3000 | AJ27: =('1'!AI27/24)*0.454 -> 56.75 | AL27: =('1'!AK27/24)*0.454 -> 0 | AN27: =('1'!AM27/24)*0.454 -> 0 | AP27: =('1'!AO27/24)*0.454 -> 0
A28: OBSERVAÇÕES | X28: 0.95833333 | Y28: 3201 | Z28: 1350 | AA28: 1 | AB28: =IF('1'!AA28=1,(('1'!Z28*'1'!$AS$6*'1'!$AT$6)/('1'!Y28*0.0036)),IF('1'!AA28=2,(('1'!Z28*'1'!$AS$7*'1'!$AT$7)/('1'!Y28*0.0036)))) -> 77.905342 | AD28: =(('1'!AC28*'1'!$Q$10*1000000))/('1'!Y28*3600) -> 0 | AF28: =('1'!AE28/24)*0.454 -> 0 | AH28: =('1'!AG28/24)*0.454 -> 0 | AI28: 3000 | AJ28: =('1'!AI28/24)*0.454 -> 56.75 | AL28: =('1'!AK28/24)*0.454 -> 0 | AN28: =('1'!AM28/24)*0.454 -> 0 | AP28: =('1'!AO28/24)*0.454 -> 0
X29: 1 | Y29: 3243 | Z29: 1350 | AA29: 1 | AB29: =IF('1'!AA29=1,(('1'!Z29*'1'!$AS$6*'1'!$AT$6)/('1'!Y29*0.0036)),IF('1'!AA29=2,(('1'!Z29*'1'!$AS$7*'1'!$AT$7)/('1'!Y29*0.0036)))) -> 76.896392 | AD29: =(('1'!AC29*'1'!$Q$10*1000000))/('1'!Y29*3600) -> 0 | AF29: =('1'!AE29/24)*0.454 -> 0 | AH29: =('1'!AG29/24)*0.454 -> 0 | AI29: 3000 | AJ29: =('1'!AI29/24)*0.454 -> 56.75 | AL29: =('1'!AK29/24)*0.454 -> 0 | AN29: =('1'!AM29/24)*0.454 -> 0 | AP29: =('1'!AO29/24)*0.454 -> 0
X30: Total | Y30: =SUM('1'!Y6:Y29)*3.6 -> 276339.6 | Z30: =SUM('1'!Z6:Z29) -> 32010 | AF30: =SUM('1'!AF6:AF29) -> 340.5 | AH30: =SUM('1'!AH6:AH29) -> 85.125 | AJ30: =SUM('1'!AJ6:AJ29) -> 1191.75 | AL30: =SUM('1'!AL6:AL29) -> 0 | AN30: =SUM('1'!AN6:AN29) -> 0 | AP30: =SUM('1'!AP6:AP29) -> 0
X32: S.A.L (l) - (kg) | Z32: =SUMIF('1'!AA6:AA29,"=1",'1'!Z6:Z29) -> 32010 | AA32: ='1'!Z32*'1'!AS6 -> 42573.3 | AB32: =SUMIF('1'!$AA$6:$AA$29,"=1",'1'!$AB$6:$AB$29)/COUNTIF('1'!$AA$6:$AA$29,"=1") -> 77.031216 | AC32: =SUMIF('1'!AA6:AA29,"=1",'1'!AC6:AC29) -> 0
X33: PAC 18 (l) - (kg) | Z33: =SUMIF('1'!AA6:AA29,"=2",'1'!Z6:Z29) -> 0 | AA33: ='1'!Z33*'1'!AS7 -> 0 | AB33: =SUMIF('1'!$AA$6:$AA$29,"=2",'1'!$AB$6:$AB$29)/COUNTIF('1'!$AA$6:$AA$29,"=2") -> #DIV/0! | AC33: =SUMIF('1'!AA6:AA29,"=2",'1'!AC6:AC29) -> 0
X34: Média | Y34: =AVERAGE('1'!Y6:Y29) -> 3198.375 | Z34: =AVERAGE('1'!Z6:Z29) -> 1333.75 | AC34: =SUM('1'!AC6:AC29)/COUNTIF('1'!AC6:AC29,"<>0") -> 0 | AD34: =SUM('1'!AD6:AD29)/COUNTIF('1'!AD6:AD29,"<>0") -> #DIV/0! | AF34: =AVERAGE('1'!AF6:AF29) -> 14.1875 | AH34: =AVERAGE('1'!AH6:AH29) -> 3.546875 | AJ34: ='1'!AJ30/24 -> 49.65625 | AL34: =AVERAGE('1'!AL6:AL29) -> 0 | AN34: =AVERAGE('1'!AN6:AN29) -> 0 | AP34: =AVERAGE('1'!AP6:AP29) -> 0
C35: Alcalinidade (mg/L) | F35: Ferro (mg/L) | I35: Manganês (mg/L) | L35: Alumínio (mg/L) | U35: TÉCNICO | X35: Decantadores | AA35: Filtros | AC35: Decantadores 2ª etapa | AJ35: CLORAÇÃO INTERMEDIÁRIA | AO35: PÓS CLORAÇÃO
B36: HORA | C36: Bruta | D36: Dec. | E36: Trat (R-3) | F36: Bruta | G36: Filt. | H36: Trat (R-3) | I36: Bruta | J36: Filt. | K36: Trat (R-3) | L36: Trat (R-3) | X36: Lavados | AA36: Lavados | AB36: 5 | AC36: Descargas | AD36: 4
B37: 0.33333333 | C37: 53.1 | D37: 22.1 | E37: 18.1 | F37: 1.8 | G37: 0.2 | H37: 0.1 | I37: 0.15 | J37: 0.06 | K37: 0.03 | L37: 0.15 | U37: ='1'!V12 -> 0 | X37: HORAS OPERANDO | Z37: =COUNTA('1'!Z6:Z29) -> 24 | AC37: Tempo de duração | AD37: 60’ | AJ37: CARRETA | AL37: CILINDROS | AO37: CARRETA | AQ37: CILINDROS
B38: 0.66666667 | AJ38: CONSUMO | AK38: =SUM('1'!AF30+'1'!AH30) -> 425.625 | AL38: CONSUMO | AM38: =SUM('1'!AL30+'1'!AN30) -> 0 | AO38: CONSUMO | AP38: ='1'!AJ30 -> 1191.75 | AQ38: CONSUMO | AR38: ='1'!AP30 -> 0
A39: Nº amostras de água TRATADA | C39: Nº amostras de água FILTRADA | E39: Nº amostras de água tratada/filtrada FORA DO PADRÃO | J39: Nº amostras de água tratada/filtrada no PADRÃO | O39: Nº de amostras com turbidez menor ou igual a 0,5 NTU | R39: ÁGUA FILTRADA | S39: Nº de amostras com turbidez menor ou igual a 1,0 NTU | AJ39: DOSAGEM | AK39: =('1'!AK38/'1'!Y30)*1000 -> 1.5402244 | AL39: DOSAGEM | AM39: =('1'!AM38/'1'!Y30)*1000 -> 0 | AO39: DOSAGEM | AP39: =('1'!AP38/'1'!Y30)*1000 -> 4.3126284 | AQ39: DOSAGEM | AR39: =('1'!AR38/'1'!Y30)*1000 -> 0
A40: COR | B40: TURBIDEZ | C40: TURBIDEZ | E40: COR | G40: TURBIDEZ | J40: COR | L40: TURBIDEZ | X40: ESTOQUE DE COAGULANTE | AJ40: Consumo Total | AL40: =SUM('1'!AK38,'1'!AM38) -> 425.625 | AO40: Consumo Total | AQ40: =SUM('1'!AP38,'1'!AR38) -> 1191.75
A41: =COUNTA('1'!E7:E18) -> 12 | B41: =COUNTA('1'!I7:I18) -> 12 | C41: =COUNTA('1'!J7:J18) -> 12 | D41: =COUNTA('1'!K7:K18) -> 12 | E41: =COUNTIF('1'!E7:E18,">15") -> 0 | G41: =COUNTIF('1'!J7:J18,">1") -> 0 | J41: ='1'!A41-'1'!E41 -> 12 | L41: ='1'!C41-'1'!G41 -> 12 | O41: =COUNTIF('1'!J7:J18,"<=0,5") -> 0 | S41: =COUNTIF('1'!J7:J18,"<=1,0") -> 12 | AJ41: Dosagem Final | AL41: =SUM(('1'!AK38+'1'!AM38)/'1'!Y30)*1000 -> 1.5402244 | AO41: Dosagem Final | AQ41: =SUM(('1'!AP38+'1'!AR38)/'1'!Y30)*1000 -> 4.3126284
O42: ÁGUA FILTRATADA | X42: SULFATO DE ALUMÍNIO
H43: Nº de amostras água tratada com turbidez <= 5,0 NTU | L43: Nº de amostras água tratada para aluminio | Q43: Nº de amostras com turbidez entre 0,5 e 1,0 NTU | X43: TINA 01 | Z43: TINA 02 | AB43: TINA 03 | AD43: TANQUE
...

Sheet 2
D2: CONTROLE DE ANÁLISE FÍSICO - QUÍMICAS \ ETA CASTELO BRANCO | AB2: CONTROLE DE PRODUTOS QUÍMICOS APLICADOS \ ETA CASTELO BRANCO
A4: HORA | B4: COR (Uc) | F4: TURBIDEZ (Ut) | K4: Ph | O4: CLORO RESIDUAL (mg/L) | R4: DOSAGEM DO COAGULANTE | T4: VAZÃO DA ETA | U4: TIPO DE COAGULANTE | V4: TÉCNICO | X4: Hora | Y4: Vazão ETA (l/s) | Z4: Vazão Coagulante (l/h) | AA4: Código | AB4: Dosagem (mg/l) | AC4: Vazão Polímero (l/h) | AD4: Dosagem (mg/l) | AE4: Pré 1 (Lib/dia) | AF4: Pré 1 (Kg/h) | AG4: Pré 2 (Lib/dia) | AH4: Pré 2 (Kg/h) | AI4: Pós (Lib/dia) | AJ4: Pós (Kg/h) | AK4: Pré 1 (Lib/dia) cilindros | AL4: Pré 1 (Kg/h) cilindros | AM4: Pré 2 (Lib/dia) cilindros | AN4: Pré 2 (Kg/h) cilindros | AO4: Pós (Lib/dia) cilindros | AP4: Pós (Kg/h) cilindros | AQ4: COAGULANTE | AU4: Tempo de Utilização (h)
AQ5: Codigo | AR5: Nome | AS5: d (g/ml) | AT5: C (%)
B6: Bruta | C6: DEC_1 | D6: DEC_2 | E6: TRAT | F6: Bruta | G6: DEC_1 | H6: DEC_2 | I6: TRAT | J6: FILT | K6: Bruta | L6: DEC_1 | M6: DEC_2 | N6: TRAT | O6: TRAT | P6: DEC_1 | Q6: DEC_2 | R6: L/h | S6: mg/l | T6: L/s | X6: 0.041666667 | Y6: 3193 | Z6: 1350 | AA6: 1 | AB6: =IF('2'!AA6=1,(('2'!Z6*'2'!$AS$6*'2'!$AT$6)/('2'!Y6*0.0036)),IF('2'!AA6=2,(('2'!Z6*'2'!$AS$7*'2'!$AT$7)/('2'!Y6*0.0036)))) -> 78.100532 | AD6: =(('2'!AC6*'2'!$Q$10*1000000))/('2'!Y6*3600) -> 0 | AF6: =('2'!AE6/24)*0.454 -> 0 | AH6: =('2'!AG6/24)*0.454 -> 0 | AI6: 3300 | AJ6: =('2'!AI6/24)*0.454 -> 62.425 | AL6: =('2'!AK6/24)*0.454 -> 0 | AN6: =('2'!AM6/24)*0.454 -> 0 | AP6: =('2'!AO6/24)*0.454 -> 0 | AQ6: 1 | AR6: S.A.L | AS6: 1.33 | AT6: 0.5 | AU6: 0
A7: 0 | B7: 254 | C7: 15 | D7: 17 | E7: 7 | F7: 66 | G7: 1.7 | H7: 2 | I7: 0.8 | J7: 0.7 | K7: 6.9 | L7: 6.3 | M7: 6.3 | N7: 6 | O7: 2.5 | R7: ='1'!$Z$29 -> 1350 | S7: ='1'!$AB$29 -> 76.896392 | T7: ='1'!$Y$29 -> 3243 | U7: =IF('2'!AA6=1,'2'!AR6,'2'!AR7) -> S.A.L | V7: =ESCALA!$B$3 -> 0 | X7: 2653.0833 | Y7: 3221 | Z7: 1350 | AA7: 1 | AB7: =IF('2'!AA7=1,(('2'!Z7*'2'!$AS$6*'2'!$AT$6)/('2'!Y7*0.0036)),IF('2'!AA7=2,(('2'!Z7*'2'!$AS$7*'2'!$AT$7)/('2'!Y7*0.0036)))) -> 77.421608 | AD7: =(('2'!AC7*'2'!$Q$10*1000000))/('2'!Y7*3600) -> 0 | AF7: =('2'!AE7/24)*0.454 -> 0 | AH7: =('2'!AG7/24)*0.454 -> 0 | AI7: 3300 | AJ7: =('2'!AI7/24)*0.454 -> 62.425 | AL7: =('2'!AK7/24)*0.454 -> 0 | AN7: =('2'!AM7/24)*0.454 -> 0 | AP7: =('2'!AO7/24)*0.454 -> 0 | AQ7: 2 | AR7: PAC 18 | AS7: 1.377 | AT7: 1 | AU7: 24
A8: 0.083333333 | B8: 246 | C8: 15 | D8: 17 | E8: 7 | F8: 64 | G8: 1.7 | H8: 2.1 | I8: 0.7 | J8: 0.7 | K8: 6.9 | L8: 6.3 | M8: 6.3 | N8: 6 | O8: 2.5 | R8: ='2'!Z7 -> 1350 | S8: ='2'!AB7 -> 77.421608 | T8: ='2'!Y7 -> 3221 | U8: =IF('2'!AA7=1,'2'!AR6,'2'!AR7) -> S.A.L | X8: 2645.125 | Y8: 3199 | Z8: 1350 | AA8: 1 | AB8: =IF('2'!AA8=1,(('2'!Z8*'2'!$AS$6*'2'!$AT$6)/('2'!Y8*0.0036)),IF('2'!AA8=2,(('2'!Z8*'2'!$AS$7*'2'!$AT$7)/('2'!Y8*0.0036)))) -> 77.954048 | AD8: =(('2'!AC8*'2'!$Q$10*1000000))/('2'!Y8*3600) -> 0 | AF8: =('2'!AE8/24)*0.454 -> 0 | AH8: =('2'!AG8/24)*0.454 -> 0 | AI8: 3300 | AJ8: =('2'!AI8/24)*0.454 -> 62.425 | AL8: =('2'!AK8/24)*0.454 -> 0 | AN8: =('2'!AM8/24)*0.454 -> 0 | AP8: =('2'!AO8/24)*0.454 -> 0 | AQ8: Polímero Catiônico
A9: 0.16666667 | B9: 238 | C9: 16 | D9: 18 | E9: 8 | F9: 63 | G9: 1.7 | H9: 2.1 | I9: 0.7 | J9: 0.7 | K9: 6.9 | L9: 6.3 | M9: 6.3 | N9: 6 | O9: 2.6 | R9: ='2'!Z9 -> 1350 | S9: ='2'!AB9 -> 77.566096 | T9: ='2'!Y9 -> 3215 | U9: =IF('2'!AA9=1,'2'!AR6,'2'!AR7) -> S.A.L | X9: 0.16666667 | Y9: 3215 | Z9: 1350 | AA9: 1 | AB9: =IF('2'!AA9=1,(('2'!Z9*'2'!$AS$6*'2'!$AT$6)/('2'!Y9*0.0036)),IF('2'!AA9=2,(('2'!Z9*'2'!$AS$7*'2'!$AT$7)/('2'!Y9*0.0036)))) -> 77.566096 | AD9: =(('2'!AC9*'2'!$Q$10*1000000))/('2'!Y9*3600) -> 0 | AF9: =('2'!AE9/24)*0.454 -> 0 | AH9: =('2'!AG9/24)*0.454 -> 0 | AI9: 3300 | AJ9: =('2'!AI9/24)*0.454 -> 62.425 | AL9: =('2'!AK9/24)*0.454 -> 0 | AN9: =('2'!AM9/24)*0.454 -> 0 | AP9: =('2'!AO9/24)*0.454 -> 0 | AQ9: Nome | AT9: C (%)
A10: 0.25 | B10: 232 | C10: 16 | D10: 18 | E10: 8 | F10: 62 | G10: 1.7 | H10: 2.2 | I10: 0.8 | J10: 0.7 | K10: 6.9 | L10: 6.3 | M10: 6.3 | N10: 6 | O10: 2.6 | R10: ='2'!Z11 -> 1350 | S10: ='2'!AB11 -> 77.638543 | T10: ='2'!Y11 -> 3212 | U10: =IF('2'!AA11=1,'2'!AR6,'2'!AR7) -> S.A.L | X10: 0.20833333 | Y10: 3204 | Z10: 1350 | AA10: 1 | AB10: =IF('2'!AA10=1,(('2'!Z10*'2'!$AS$6*'2'!$AT$6)/('2'!Y10*0.0036)),IF('2'!AA10=2,(('2'!Z10*'2'!$AS$7*'2'!$AT$7)/('2'!Y10*0.0036)))) -> 77.832397 | AD10: =(('2'!AC10*'2'!$Q$10*1000000))/('2'!Y10*3600) -> 0 | AF10: =('2'!AE10/24)*0.454 -> 0 | AH10: =('2'!AG10/24)*0.454 -> 0 | AI10: 3300 | AJ10: =('2'!AI10/24)*0.454 -> 62.425 | AL10: =('2'!AK10/24)*0.454 -> 0 | AN10: =('2'!AM10/24)*0.454 -> 0 | AP10: =('2'!AO10/24)*0.454 -> 0 | AQ10: Aguapol 200 | AT10: 0.002
A11: 0.33333333 | B11: 238 | C11: 15 | D11: 18 | E11: 8 | F11: 60 | G11: 1.8 | H11: 2.3 | I11: 0.8 | J11: 0.7 | K11: 7 | L11: 6.2 | M11: 6.3 | N11: 6 | O11: 2 | R11: ='2'!Z13 -> 1320 | S11: ='2'!AB13 -> 76.079043 | T11: ='2'!Y13 -> 3205 | U11: =IF('2'!AA13=1,'2'!AR6,'2'!AR7) -> S.A.L | X11: 0.25 | Y11: 3212 | Z11: 1350 | AA11: 1 | AB11: =IF('2'!AA11=1,(('2'!Z11*'2'!$AS$6*'2'!$AT$6)/('2'!Y11*0.0036)),IF('2'!AA11=2,(('2'!Z11*'2'!$AS$7*'2'!$AT$7)/('2'!Y11*0.0036)))) -> 77.638543 | AD11: =(('2'!AC11*'2'!$Q$10*1000000))/('2'!Y11*3600) -> 0 | AF11: =('2'!AE11/24)*0.454 -> 0 | AH11: =('2'!AG11/24)*0.454 -> 0 | AI11: 3300 | AJ11: =('2'!AI11/24)*0.454 -> 62.425 | AL11: =('2'!AK11/24)*0.454 -> 0 | AN11: =('2'!AM11/24)*0.454 -> 0 | AP11: =('2'!AO11/24)*0.454 -> 0
A12: 0.41666667 | B12: 235 | C12: 15 | D12: 18 | E12: 8 | F12: 59 | G12: 1.8 | H12: 2.2 | I12: 0.8 | J12: 0.7 | K12: 7 | L12: 6.2 | M12: 6.3 | N12: 6 | O12: 2 | R12: ='2'!Z15 -> 1300 | S12: ='2'!AB15 -> 75.705829 | T12: ='2'!Y15 -> 3172 | U12: =IF('2'!AA15=1,'2'!AR6,'2'!AR7) -> S.A.L | V12: =ESCALA!$B$4 -> 0 | X12: 0.29166667 | Y12: 3211 | Z12: 1360 | AA12: 1 | AB12: =IF('2'!AA12=1,(('2'!Z12*'2'!$AS$6*'2'!$AT$6)/('2'!Y12*0.0036)),IF('2'!AA12=2,(('2'!Z12*'2'!$AS$7*'2'!$AT$7)/('2'!Y12*0.0036)))) -> 78.238001 | AD12: =(('2'!AC12*'2'!$Q$10*1000000))/('2'!Y12*3600) -> 0 | AF12: =('2'!AE12/24)*0.454 -> 0 | AH12: =('2'!AG12/24)*0.454 -> 0 | AI12: 3300 | AJ12: =('2'!AI12/24)*0.454 -> 62.425 | AL12: =('2'!AK12/24)*0.454 -> 0 | AN12: =('2'!AM12/24)*0.454 -> 0 | AP12: =('2'!AO12/24)*0.454 -> 0
A13: 0.5 | B13: 233 | C13: 16 | D13: 18 | E13: 9 | F13: 59 | G13: 2 | H13: 2.5 | I13: 0.69 | J13: 0.8 | K13: 7 | L13: 6.2 | M13: 6.3 | N13: 6 | O13: 2.5 | R13: ='2'!Z17 -> 1300 | S13: ='2'!AB17 -> 74.92633 | T13: ='2'!Y17 -> 3205 | U13: =IF('2'!AA17=1,'2'!AR6,'2'!AR7) -> S.A.L | X13: 0.33333333 | Y13: 3205 | Z13: 1320 | AA13: 1 | AB13: =IF('2'!AA13=1,(('2'!Z13*'2'!$AS$6*'2'!$AT$6)/('2'!Y13*0.0036)),IF('2'!AA13=2,(('2'!Z13*'2'!$AS$7*'2'!$AT$7)/('2'!Y13*0.0036)))) -> 76.079043 | AD13: =(('2'!AC13*'2'!$Q$10*1000000))/('2'!Y13*3600) -> 0 | AF13: =('2'!AE13/24)*0.454 -> 0 | AH13: =('2'!AG13/24)*0.454 -> 0 | AI13: 3300 | AJ13: =('2'!AI13/24)*0.454 -> 62.425 | AL13: =('2'!AK13/24)*0.454 -> 0 | AN13: =('2'!AM13/24)*0.454 -> 0 | AP13: =('2'!AO13/24)*0.454 -> 0
A14: 0.58333333 | B14: 233 | C14: 17 | D14: 19 | E14: 9 | F14: 60 | G14: 2.2 | H14: 2.7 | I14: 1 | J14: 1 | K14: 7 | L14: 6.2 | M14: 6.3 | N14: 6 | O14: 2.5 | R14: ='2'!Z19 -> 1300 | S14: ='2'!AB19 -> 74.832935 | T14: ='2'!Y19 -> 3209 | U14: =IF('2'!AA19=1,'2'!AR6,'2'!AR7) -> S.A.L | X14: 0.375 | Y14: 3196 | Z14: 1320 | AA14: 1 | AB14: =IF('2'!AA14=1,(('2'!Z14*'2'!$AS$6*'2'!$AT$6)/('2'!Y14*0.0036)),IF('2'!AA14=2,(('2'!Z14*'2'!$AS$7*'2'!$AT$7)/('2'!Y14*0.0036)))) -> 76.293283 | AD14: =(('2'!AC14*'2'!$Q$10*1000000))/('2'!Y14*3600) -> 0 | AF14: =('2'!AE14/24)*0.454 -> 0 | AH14: =('2'!AG14/24)*0.454 -> 0 | AI14: 4000 | AJ14: =('2'!AI14/24)*0.454 -> 75.666667 | AL14: =('2'!AK14/24)*0.454 -> 0 | AN14: =('2'!AM14/24)*0.454 -> 0 | AP14: =('2'!AO14/24)*0.454 -> 0
A15: 0.66666667 | B15: 243 | C15: 17 | D15: 18 | E15: 8 | F15: 62 | G15: 2.2 | H15: 2.7 | I15: 1 | J15: 1 | K15: 7 | L15: 6.2 | M15: 6.3 | N15: 6 | O15: 3 | R15: ='2'!Z21 -> 1340 | S15: ='2'!AB21 -> 77.473483 | T15: ='2'!Y21 -> 3195 | U15: =IF('2'!AA21=1,'2'!AR6,'2'!AR7) -> S.A.L | X15: 0.41666667 | Y15: 3172 | Z15: 1300 | AA15: 1 | AB15: =IF('2'!AA15=1,(('2'!Z15*'2'!$AS$6*'2'!$AT$6)/('2'!Y15*0.0036)),IF('2'!AA15=2,(('2'!Z15*'2'!$AS$7*'2'!$AT$7)/('2'!Y15*0.0036)))) -> 75.705829 | AD15: =(('2'!AC15*'2'!$Q$10*1000000))/('2'!Y15*3600) -> 0 | AF15: =('2'!AE15/24)*0.454 -> 0 | AH15: =('2'!AG15/24)*0.454 -> 0 | AI15: 4000 | AJ15: =('2'!AI15/24)*0.454 -> 75.666667 | AL15: =('2'!AK15/24)*0.454 -> 0 | AN15: =('2'!AM15/24)*0.454 -> 0 | AP15: =('2'!AO15/24)*0.454 -> 0
A16: 0.75 | B16: 245 | C16: 17 | D16: 18 | E16: 8 | F16: 63 | G16: 2.5 | H16: 2.6 | I16: 1 | J16: 1.2 | K16: 7 | L16: 6.2 | M16: 6.3 | N16: 6 | O16: 3.2 | R16: ='2'!Z23 -> 1360 | S16: ='2'!AB23 -> 78.335585 | T16: ='2'!Y23 -> 3207 | U16: =IF('2'!AA23=1,'2'!AR6,'2'!AR7) -> S.A.L | X16: 0.45833333 | Y16: 3199 | Z16: 1300 | AA16: 1 | AB16: =IF('2'!AA16=1,(('2'!Z16*'2'!$AS$6*'2'!$AT$6)/('2'!Y16*0.0036)),IF('2'!AA16=2,(('2'!Z16*'2'!$AS$7*'2'!$AT$7)/('2'!Y16*0.0036)))) -> 75.066861 | AD16: =(('2'!AC16*'2'!$Q$10*1000000))/('2'!Y16*3600) -> 0 | AF16: =('2'!AE16/24)*0.454 -> 0 | AH16: =('2'!AG16/24)*0.454 -> 0 | AI16: 4000 | AJ16: =('2'!AI16/24)*0.454 -> 75.666667 | AL16: =('2'!AK16/24)*0.454 -> 0 | AN16: =('2'!AM16/24)*0.454 -> 0 | AP16: =('2'!AO16/24)*0.454 -> 0
A17: 0.83333333 | B17: 256 | C17: 18 | D17: 18 | E17: 8 | F17: 67 | G17: 2.9 | H17: 2.5 | I17: 1 | J17: 1.4 | K17: 7 | L17: 6.2 | M17: 6.3 | N17: 6 | O17: 3.3 | R17: ='2'!Z25 -> 1360 | S17: ='2'!AB25 -> 78.286763 | T17: ='2'!Y25 -> 3209 | U17: =IF('2'!AA25=1,'2'!AR6,'2'!AR7) -> S.A.L | V17: =ESCALA!$C$4 -> 0 | X17: 0.5 | Y17: 3205 | Z17: 1300 | AA17: 1 | AB17: =IF('2'!AA17=1,(('2'!Z17*'2'!$AS$6*'2'!$AT$6)/('2'!Y17*0.0036)),IF('2'!AA17=2,(('2'!Z17*'2'!$AS$7*'2'!$AT$7)/('2'!Y17*0.0036)))) -> 74.92633 | AD17: =(('2'!AC17*'2'!$Q$10*1000000))/('2'!Y17*3600) -> 0 | AF17: =('2'!AE17/24)*0.454 -> 0 | AH17: =('2'!AG17/24)*0.454 -> 0 | AI17: 4000 | AJ17: =('2'!AI17/24)*0.454 -> 75.666667 | AL17: =('2'!AK17/24)*0.454 -> 0 | AN17: =('2'!AM17/24)*0.454 -> 0 | AP17: =('2'!AO17/24)*0.454 -> 0
A18: 0.91666667 | B18: 248 | C18: 18 | D18: 18 | E18: 8 | F18: 65 | G18: 2.9 | H18: 2.4 | I18: 1 | J18: 1.4 | K18: 7 | L18: 6.2 | M18: 6.3 | N18: 6 | O18: 3.3 | R18: ='2'!Z27 -> 1400 | S18: ='2'!AB27 -> 81.273134 | T18: ='2'!Y27 -> 3182 | U18: =IF('2'!AA27=1,'2'!AR6,'2'!AR7) -> S.A.L | X18: 0.54166667 | Y18: 3185 | Z18: 1300 | AA18: 1 | AB18: =IF('2'!AA18=1,(('2'!Z18*'2'!$AS$6*'2'!$AT$6)/('2'!Y18*0.0036)),IF('2'!AA18=2,(('2'!Z18*'2'!$AS$7*'2'!$AT$7)/('2'!Y18*0.0036)))) -> 75.396825 | AD18: =(('2'!AC18*'2'!$Q$10*1000000))/('2'!Y18*3600) -> 0 | AF18: =('2'!AE18/24)*0.454 -> 0 | AH18: =('2'!AG18/24)*0.454 -> 0 | AI18: 4000 | AJ18: =('2'!AI18/24)*0.454 -> 75.666667 | AL18: =('2'!AK18/24)*0.454 -> 0 | AN18: =('2'!AM18/24)*0.454 -> 0 | AP18: =('2'!AO18/24)*0.454 -> 0
A19: Média | B19: {=IF('2'!B7:B18>0.01,AVERAGE('2'!B7:B18),"")} -> 241.75 | C19: {=IF('2'!C7:C18>0.01,AVERAGE('2'!C7:C18),"")} -> 16.25 | D19: {=IF('2'!D7:D18>0.01,AVERAGE('2'!D7:D18),"")} -> 17.916667 | E19: {=IF('2'!E7:E18>0.01,AVERAGE('2'!E7:E18),"")} -> 8 | F19: {=IF('2'!F7:F18>0.01,AVERAGE('2'!F7:F18),"")} -> 62.5 | G19: {=IF('2'!G7:G18>0.01,AVERAGE('2'!G7:G18),"")} -> 2.0916667 | H19: {=IF('2'!H7:H18>0.01,AVERAGE('2'!H7:H18),"")} -> 2.3583333 | I19: {=IF('2'!I7:I18>0.01,AVERAGE('2'!I7:I18),"")} -> 0.8575 | ... S19: {=IF('2'!S7:S18>0.01,AVERAGE('2'!S7:S18),"")} -> 77.202979 | X19: 0.58333333 | Y19: 3209 | Z19: 1300 | AA19: 1 | AB19: =IF('2'!AA19=1,(('2'!Z19*'2'!$AS$6*'2'!$AT$6)/('2'!Y19*0.0036)),IF('2'!AA19=2,(('2'!Z19*'2'!$AS$7*'2'!$AT$7)/('2'!Y19*0.0036)))) -> 74.832935 | AD19: =(('2'!AC19*'2'!$Q$10*1000000))/('2'!Y19*3600) -> 0 | AF19: =('2'!AE19/24)*0.454 -> 0 | AH19: =('2'!AG19/24)*0.454 -> 0 | AI19: 4000 | AJ19: =('2'!AI19/24)*0.454 -> 75.666667 | AL19: =('2'!AK19/24)*0.454 -> 0 | AN19: =('2'!AM19/24)*0.454 -> 0 | AP19: =('2'!AO19/24)*0.454 -> 0
A20: Máximo | B20: =MAX('2'!B7:B18) -> 256 | C20: =MAX('2'!C7:C18) -> 18 | D20: =MAX('2'!D7:D18) -> 19 | E20: =MAX('2'!E7:E18) -> 9 | F20: =MAX('2'!F7:F18) -> 67 | G20: =MAX('2'!G7:G18) -> 2.9 | H20: =MAX('2'!H7:H18) -> 2.7 | I20: =MAX('2'!I7:I18) -> 1 | ... S20: =MAX('2'!S7:S18) -> 81.273134 | X20: 0.625 | Y20: 3164 | Z20: 1300 | AA20: 1 | AB20: =IF('2'!AA20=1,(('2'!Z20*'2'!$AS$6*'2'!$AT$6)/('2'!Y20*0.0036)),IF('2'!AA20=2,(('2'!Z20*'2'!$AS$7*'2'!$AT$7)/('2'!Y20*0.0036)))) -> 75.897247 | AD20: =(('2'!AC20*'2'!$Q$10*1000000))/('2'!Y20*3600) -> 0 | AF20: =('2'!AE20/24)*0.454 -> 0 | AH20: =('2'!AG20/24)*0.454 -> 0 | AI20: 4000 | AJ20: =('2'!AI20/24)*0.454 -> 75.666667 | AL20: =('2'!AK20/24)*0.454 -> 0 | AN20: =('2'!AM20/24)*0.454 -> 0 | AP20: =('2'!AO20/24)*0.454 -> 0
A21: Mínimo | B21: =MIN('2'!B7:B18) -> 232 | C21: =MIN('2'!C7:C18) -> 15 | D21: =MIN('2'!D7:D18) -> 17 | E21: =MIN('2'!E7:E18) -> 7 | F21: =MIN('2'!F7:F18) -> 59 | G21: =MIN('2'!G7:G18) -> 1.7 | H21: =MIN('2'!H7:H18) -> 2 | I21: =MIN('2'!I7:I18) -> 0.69 | ... S21: =MIN('2'!S7:S18) -> 74.832935 | X21: 0.66666667 | Y21: 3195 | Z21: 1340 | AA21: 1 | AB21: =IF('2'!AA21=1,(('2'!Z21*'2'!$AS$6*'2'!$AT$6)/('2'!Y21*0.0036)),IF('2'!AA21=2,(('2'!Z21*'2'!$AS$7*'2'!$AT$7)/('2'!Y21*0.0036)))) -> 77.473483 | AD21: =(('2'!AC21*'2'!$Q$10*1000000))/('2'!Y21*3600) -> 0 | AF21: =('2'!AE21/24)*0.454 -> 0 | AH21: =('2'!AG21/24)*0.454 -> 0 | AI21: 4000 | AJ21: =('2'!AI21/24)*0.454 -> 75.666667 | AL21: =('2'!AK21/24)*0.454 -> 0 | AN21: =('2'!AM21/24)*0.454 -> 0 | AP21: =('2'!AO21/24)*0.454 -> 0
R22: Total | X22: 0.70833333 | Y22: 3216 | Z22: 1350 | AA22: 1 | AB22: =IF('2'!AA22=1,(('2'!Z22*'2'!$AS$6*'2'!$AT$6)/('2'!Y22*0.0036)),IF('2'!AA22=2,(('2'!Z22*'2'!$AS$7*'2'!$AT$7)/('2'!Y22*0.0036)))) -> 77.541978 | AD22: =(('2'!AC22*'2'!$Q$10*1000000))/('2'!Y22*3600) -> 0 | AF22: =('2'!AE22/24)*0.454 -> 0 | AH22: =('2'!AG22/24)*0.454 -> 0 | AI22: 4000 | AJ22: =('2'!AI22/24)*0.454 -> 75.666667 | AL22: =('2'!AK22/24)*0.454 -> 0 | AN22: =('2'!AM22/24)*0.454 -> 0 | AP22: =('2'!AO22/24)*0.454 -> 0
A23: TURBIDEZ DOS FILTROS DA 1ª E 2ª ETAPAS | R23: 440 | S23: Litros | X23: 0.75 | Y23: 3207 | Z23: 1360 | AA23: 1 | AB23: =IF('2'!AA23=1,(('2'!Z23*'2'!$AS$6*'2'!$AT$6)/('2'!Y23*0.0036)),IF('2'!AA23=2,(('2'!Z23*'2'!$AS$7*'2'!$AT$7)/('2'!Y23*0.0036)))) -> 78.335585 | AD23: =(('2'!AC23*'2'!$Q$10*1000000))/('2'!Y23*3600) -> 0 | AF23: =('2'!AE23/24)*0.454 -> 0 | AH23: =('2'!AG23/24)*0.454 -> 0 | AI23: 4000 | AJ23: =('2'!AI23/24)*0.454 -> 75.666667 | AL23: =('2'!AK23/24)*0.454 -> 0 | AN23: =('2'!AM23/24)*0.454 -> 0 | AP23: =('2'!AO23/24)*0.454 -> 0
A24: HORA | B24: 1 | C24: 2 | D24: 3 | E24: 4 | F24: 5 | G24: 6 | H24: 7 | I24: 8 | J24: 9 | K24: 10 | L24: 11 | M24: 12 | N24: 13 | O24: 14 | P24: 15 | Q24: 16 | R24: 0 | S24: Kilos | X24: 0.79166667 | Y24: 3171 | Z24: 1360 | AA24: 1 | AB24: =IF('2'!AA24=1,(('2'!Z24*'2'!$AS$6*'2'!$AT$6)/('2'!Y24*0.0036)),IF('2'!AA24=2,(('2'!Z24*'2'!$AS$7*'2'!$AT$7)/('2'!Y24*0.0036)))) -> 79.22492 | AD24: =(('2'!AC24*'2'!$Q$10*1000000))/('2'!Y24*3600) -> 0 | AF24: =('2'!AE24/24)*0.454 -> 0 | AH24: =('2'!AG24/24)*0.454 -> 0 | AI24: 4000 | AJ24: =('2'!AI24/24)*0.454 -> 75.666667 | AL24: =('2'!AK24/24)*0.454 -> 0 | AN24: =('2'!AM24/24)*0.454 -> 0 | AP24: =('2'!AO24/24)*0.454 -> 0
A25: 0.41666667 | B25: 0.26 | C25: 0.22 | D25: 0.71 | E25: 1.1 | F25: 0.59 | G25: 0.67 | H25: 0.66 | I25: 0.52 | J25: 0.17 | K25: 0.57 | L25: 0.77 | M25: 0.98 | N25: 0.37 | O25: 0.22 | P25: 1.15 | R25: =#DIV/0! -> #DIV/0! | T25: DATA | U25: =ESCALA!$A$4 -> 43923 | X25: 0.83333333 | Y25: 3209 | Z25: 1360 | AA25: 1 | AB25: =IF('2'!AA25=1,(('2'!Z25*'2'!$AS$6*'2'!$AT$6)/('2'!Y25*0.0036)),IF('2'!AA25=2,(('2'!Z25*'2'!$AS$7*'2'!$AT$7)/('2'!Y25*0.0036)))) -> 78.286763 | AD25: =(('2'!AC25*'2'!$Q$10*1000000))/('2'!Y25*3600) -> 0 | AF25: =('2'!AE25/24)*0.454 -> 0 | AH25: =('2'!AG25/24)*0.454 -> 0 | AI25: 3500 | AJ25: =('2'!AI25/24)*0.454 -> 66.208333 | AL25: =('2'!AK25/24)*0.454 -> 0 | AN25: =('2'!AM25/24)*0.454 -> 0 | AP25: =('2'!AO25/24)*0.454 -> 0
A26: 0.66666667 | R26: =#DIV/0! -> #DIV/0! | X26: 0.875 | Y26: 3175 | Z26: 1400 | AA26: 1 | AB26: =IF('2'!AA26=1,(('2'!Z26*'2'!$AS$6*'2'!$AT$6)/('2'!Y26*0.0036)),IF('2'!AA26=2,(('2'!Z26*'2'!$AS$7*'2'!$AT$7)/('2'!Y26*0.0036)))) -> 81.452318 | AD26: =(('2'!AC26*'2'!$Q$10*1000000))/('2'!Y26*3600) -> 0 | AF26: =('2'!AE26/24)*0.454 -> 0 | AH26: =('2'!AG26/24)*0.454 -> 0 | AI26: 3500 | AJ26: =('2'!AI26/24)*0.454 -> 66.208333 | AL26: =('2'!AK26/24)*0.454 -> 0 | AN26: =('2'!AM26/24)*0.454 -> 0 | AP26: =('2'!AO26/24)*0.454 -> 0
A27: Média | B27: =#DIV/0! -> #DIV/0! | C27: =#DIV/0! -> #DIV/0! | D27: =#DIV/0! -> #DIV/0! | E27: =#DIV/0! -> #DIV/0! | F27: =#DIV/0! -> #DIV/0! | G27: =#DIV/0! -> #DIV/0! | H27: =#DIV/0! -> #DIV/0! | I27: =#DIV/0! -> #DIV/0! | ... Q27: =#DIV/0! -> #DIV/0! | X27: 0.91666667 | Y27: 3182 | Z27: 1400 | AA27: 1 | AB27: =IF('2'!AA27=1,(('2'!Z27*'2'!$AS$6*'2'!$AT$6)/('2'!Y27*0.0036)),IF('2'!AA27=2,(('2'!Z27*'2'!$AS$7*'2'!$AT$7)/('2'!Y27*0.0036)))) -> 81.273134 | AD27: =(('2'!AC27*'2'!$Q$10*1000000))/('2'!Y27*3600) -> 0 | AF27: =('2'!AE27/24)*0.454 -> 0 | AH27: =('2'!AG27/24)*0.454 -> 0 | AI27: 3500 | AJ27: =('2'!AI27/24)*0.454 -> 66.208333 | AL27: =('2'!AK27/24)*0.454 -> 0 | AN27: =('2'!AM27/24)*0.454 -> 0 | AP27: =('2'!AO27/24)*0.454 -> 0
A28: OBSERVAÇÕES | X28: 0.95833333 | Y28: 3177 | Z28: 1400 | AA28: 1 | AB28: =IF('2'!AA28=1,(('2'!Z28*'2'!$AS$6*'2'!$AT$6)/('2'!Y28*0.0036)),IF('2'!AA28=2,(('2'!Z28*'2'!$AS$7*'2'!$AT$7)/('2'!Y28*0.0036)))) -> 81.401042 | AD28: =(('2'!AC28*'2'!$Q$10*1000000))/('2'!Y28*3600) -> 0 | AF28: =('2'!AE28/24)*0.454 -> 0 | AH28: =('2'!AG28/24)*0.454 -> 0 | AI28: 3500 | AJ28: =('2'!AI28/24)*0.454 -> 66.208333 | AL28: =('2'!AK28/24)*0.454 -> 0 | AN28: =('2'!AM28/24)*0.454 -> 0 | AP28: =('2'!AO28/24)*0.454 -> 0
X29: 1 | Y29: 3151 | Z29: 1400 | AA29: 1 | AB29: =IF('2'!AA29=1,(('2'!Z29*'2'!$AS$6*'2'!$AT$6)/('2'!Y29*0.0036)),IF('2'!AA29=2,(('2'!Z29*'2'!$AS$7*'2'!$AT$7)/('2'!Y29*0.0036)))) -> 82.072711 | AD29: =(('2'!AC29*'2'!$Q$10*1000000))/('2'!Y29*3600) -> 0 | AF29: =('2'!AE29/24)*0.454 -> 0 | AH29: =('2'!AG29/24)*0.454 -> 0 | AI29: 3500 | AJ29: =('2'!AI29/24)*0.454 -> 66.208333 | AL29: =('2'!AK29/24)*0.454 -> 0 | AN29: =('2'!AM29/24)*0.454 -> 0 | AP29: =('2'!AO29/24)*0.454 -> 0
X30: Total | Y30: =SUM('2'!Y6:Y29)*3.6 -> 276022.8 | Z30: =SUM('2'!Z6:Z29) -> 32270 | AF30: =SUM('2'!AF6:AF29) -> 0 | AH30: =SUM('2'!AH6:AH29) -> 0 | AJ30: =SUM('2'!AJ6:AJ29) -> 1662.775 | AL30: =SUM('2'!AL6:AL29) -> 0 | AN30: =SUM('2'!AN6:AN29) -> 0 | AP30: =SUM('2'!AP6:AP29) -> 0
X32: S.A.L (l) - (kg) | Z32: =SUMIF('2'!AA6:AA29,"=1",'2'!Z6:Z29) -> 32270 | AA32: ='2'!Z32*'2'!AS6 -> 42919.1 | AB32: =SUMIF('2'!$AA$6:$AA$29,"=1",'2'!$AB$6:$AB$29)/COUNTIF('2'!$AA$6:$AA$29,"=1") -> 77.75048 | AC32: =SUMIF('2'!AA6:AA29,"=1",'2'!AC6:AC29) -> 0
X33: PAC 18 (l) - (kg) | Z33: =SUMIF('2'!AA6:AA29,"=2",'2'!Z6:Z29) -> 0 | AA33: ='2'!Z33*'2'!AS7 -> 0 | AB33: =SUMIF('2'!$AA$6:$AA$29,"=2",'2'!$AB$6:$AB$29)/COUNTIF('2'!$AA$6:$AA$29,"=2") -> #DIV/0! | AC33: =SUMIF('2'!AA6:AA29,"=2",'2'!AC6:AC29) -> 0
X34: Média | Y34: =AVERAGE('2'!Y6:Y29) -> 3194.7083 | Z34: =AVERAGE('2'!Z6:Z29) -> 1344.5833 | AC34: =SUM('2'!AC6:AC29)/COUNTIF('2'!AC6:AC29,"<>0") -> 0 | AD34: =SUM('2'!AD6:AD29)/COUNTIF('2'!AD6:AD29,"<>0") -> #DIV/0! | AF34: =AVERAGE('2'!AF6:AF29) -> 0 | AH34: =AVERAGE('2'!AH6:AH29) -> 0 | AJ34: ='2'!AJ30/24 -> 69.282292 | AL34: =AVERAGE('2'!AL6:AL29) -> 0 | AN34: =AVERAGE('2'!AN6:AN29) -> 0 | AP34: =AVERAGE('2'!AP6:AP29) -> 0
C35: Alcalinidade (mg/L) | F35: Ferro (mg/L) | I35: Manganês (mg/L) | L35: Alumínio (mg/L) | U35: TÉCNICO | X35: Decantadores | AA35: Filtros | AC35: Decantadores 2ª etapa | AJ35: CLORAÇÃO INTERMEDIÁRIA | AO35: PÓS CLORAÇÃO
B36: HORA | C36: Bruta | D36: Dec. | E36: Trat (R-3) | F36: Bruta | G36: Filt. | H36: Trat (R-3) | I36: Bruta | J36: Filt. | K36: Trat (R-3) | L36: Trat (R-3) | X36: Lavados | Y36: 0 | AA36: Lavados | AB36: 6 | AC36: Descargas | AD36: 4
B37: 0.33333333 | C37: 46.12 | D37: 20 | E37: 10 | F37: 1.4 | G37: 0.2 | H37: 0.1 | I37: 0.2 | J37: 0.13 | K37: 0.04 | L37: 0.15 | U37: ='2'!V12 -> 0 | X37: HORAS OPERANDO | Z37: =COUNTA('2'!Z6:Z29) -> 24 | AC37: Tempo de duração | AD37: 60’ | AJ37: CARRETA | AL37: CILINDROS | AO37: CARRETA | AQ37: CILINDROS
B38: 0.66666667 | AJ38: CONSUMO | AK38: =SUM('2'!AF30+'2'!AH30) -> 0 | AL38: CONSUMO | AM38: =SUM('2'!AL30+'2'!AN30) -> 0 | AO38: CONSUMO | AP38: ='2'!AJ30 -> 1662.775 | AQ38: CONSUMO | AR38: ='2'!AP30 -> 0
A39: Nº amostras de água TRATADA | C39: Nº amostras de água FILTRADA | E39: Nº amostras de água tratada/filtrada FORA DO PADRÃO | J39: Nº amostras de água tratada/filtrada no PADRÃO | O39: Nº de amostras com turbidez menor ou igual a 0,5 NTU | R39: ÁGUA FILTRADA | S39: Nº de amostras com turbidez menor ou igual a 1,0 NTU | AJ39: DOSAGEM | AK39: =('2'!AK38/'2'!Y30)*1000 -> 0 | AL39: DOSAGEM | AM39: =('2'!AM38/'2'!Y30)*1000 -> 0 | AO39: DOSAGEM | AP39: =('2'!AP38/'2'!Y30)*1000 -> 6.0240495 | AQ39: DOSAGEM | AR39: =('2'!AR38/'2'!Y30)*1000 -> 0
A40: COR | B40: TURBIDEZ | C40: TURBIDEZ | E40: COR | G40: TURBIDEZ | J40: COR | L40: TURBIDEZ | X40: ESTOQUE DE COAGULANTE | AJ40: Consumo Total | AL40: =SUM('2'!AK38,'2'!AM38) -> 0 | AO40: Consumo Total | AQ40: =SUM('2'!AP38,'2'!AR38) -> 1662.775
A41: =COUNTA('2'!E7:E18) -> 12 | B41: =COUNTA('2'!I7:I18) -> 12 | C41: =COUNTA('2'!J7:J18) -> 12 | D41: =COUNTA('2'!K7:K18) -> 12 | E41: =COUNTIF('2'!E7:E18,">15") -> 0 | G41: =COUNTIF('2'!J7:J18,">1") -> 3 | J41: ='2'!A41-'2'!E41 -> 12 | L41: ='2'!C41-'2'!G41 -> 9 | O41: =COUNTIF('2'!J7:J18,"<=0,5") -> 0 | S41: =COUNTIF('2'!J7:J18,"<=1,0") -> 9 | AJ41: Dosagem Final | AL41: =SUM(('2'!AK38+'2'!AM38)/'2'!Y30)*1000 -> 0 | AO41: Dosagem Final | AQ41: =SUM(('2'!AP38+'2'!AR38)/'2'!Y30)*1000 -> 6.0240495
O42: ÁGUA FILTRATADA | X42: SULFATO DE ALUMÍNIO
H43: Nº de amostras água tratada com turbidez <= 5,0 NTU | L43: Nº de amostras água tratada para aluminio | Q43: Nº de amostras com turbidez entre 0,5 e 1,0 NTU | X43: TINA 01 | Z43: TINA 02 | AB43: TINA 03 | AD43: TANQUE
...

Sheet 3
D2: CONTROLE DE ANÁLISE FÍSICO - QUÍMICAS \ ETA CASTELO BRANCO | AB2: CONTROLE DE PRODUTOS QUÍMICOS APLICADOS \ ETA CASTELO BRANCO
A4: HORA | B4: COR (Uc) | F4: TURBIDEZ (Ut) | K4: Ph | O4: CLORO RESIDUAL (mg/L) | R4: DOSAGEM DO COAGULANTE | T4: VAZÃO DA ETA | U4: TIPO DE COAGULANTE | V4: TÉCNICO | X4: Hora | Y4: Vazão ETA (l/s) | Z4: Vazão Coagulante (l/h) | AA4: Código | AB4: Dosagem (mg/l) | AC4: Vazão Polímero (l/h) | AD4: Dosagem (mg/l) | AE4: Pré 1 (Lib/dia) | AF4: Pré 1 (Kg/h) | AG4: Pré 2 (Lib/dia) | AH4: Pré 2 (Kg/h) | AI4: Pós (Lib/dia) | AJ4: Pós (Kg/h) | AK4: Pré 1 (Lib/dia) cilindros | AL4: Pré 1 (Kg/h) cilindros | AM4: Pré 2 (Lib/dia) cilindros | AN4: Pré 2 (Kg/h) cilindros | AO4: Pós (Lib/dia) cilindros | AP4: Pós (Kg/h) cilindros | AQ4: COAGULANTE | AU4: Tempo de Utilização (h)
AQ5: Codigo | AR5: Nome | AS5: d (g/ml) | AT5: C (%)
B6: Bruta | C6: DEC_1 | D6: DEC_2 | E6: TRAT | F6: Bruta | G6: DEC_1 | H6: DEC_2 | I6: TRAT | J6: FILT | K6: Bruta | L6: DEC_1 | M6: DEC_2 | N6: TRAT | O6: TRAT | P6: DEC_1 | Q6: DEC_2 | R6: L/h | S6: mg/l | T6: L/s | X6: 0.041666667 | Y6: 3182 | Z6: 1400 | AA6: 1 | AB6: =IF('3'!AA6=1,(('3'!Z6*'3'!$AS$6*'3'!$AT$6)/('3'!Y6*0.0036)),IF('3'!AA6=2,(('3'!Z6*'3'!$AS$7*'3'!$AT$7)/('3'!Y6*0.0036)))) -> 81.273134 | AD6: =(('3'!AC6*'3'!$O$9*1000000))/('3'!Y6*3600) -> 0 | AF6: =('3'!AE6/24)*0.454 -> 0 | AH6: =('3'!AG6/24)*0.454 -> 0 | AI6: 3500 | AJ6: =('3'!AI6/24)*0.454 -> 66.208333 | AL6: =('3'!AK6/24)*0.454 -> 0 | AN6: =('3'!AM6/24)*0.454 -> 0 | AP6: =('3'!AO6/24)*0.454 -> 0 | AQ6: 1 | AR6: S.A.L | AS6: 1.33 | AT6: 0.5 | AU6: 0
A7: 0 | B7: 245 | C7: 19 | D7: 18 | E7: 9 | F7: 63 | G7: 3 | H7: 2.3 | I7: 1.1 | J7: 1.5 | K7: 7 | L7: 6.2 | M7: 6.3 | N7: 6 | O7: 3.3 | R7: ='2'!$Z$29 -> 1400 | S7: ='2'!$AB$29 -> 82.072711 | T7: ='2'!$Y$29 -> 3151 | U7: =IF('3'!AA6=1,'3'!AR6,'3'!AR7) -> S.A.L | V7: =ESCALA!$C$4 -> 0 | X7: 0.083333333 | Y7: 3186 | Z7: 1400 | AA7: 1 | AB7: =IF('3'!AA7=1,(('3'!Z7*'3'!$AS$6*'3'!$AT$6)/('3'!Y7*0.0036)),IF('3'!AA7=2,(('3'!Z7*'3'!$AS$7*'3'!$AT$7)/('3'!Y7*0.0036)))) -> 81.171096 | AD7: =(('3'!AC7*'3'!$O$9*1000000))/('3'!Y7*3600) -> 0 | AF7: =('3'!AE7/24)*0.454 -> 0 | AH7: =('3'!AG7/24)*0.454 -> 0 | AI7: 3500 | AJ7: =('3'!AI7/24)*0.454 -> 66.208333 | AL7: =('3'!AK7/24)*0.454 -> 0 | AN7: =('3'!AM7/24)*0.454 -> 0 | AP7: =('3'!AO7/24)*0.454 -> 0 | AQ7: 2 | AR7: PAC 18 | AS7: 1.377 | AT7: 1 | AU7: 24
A8: 0.083333333 | B8: 241 | C8: 19 | D8: 18 | E8: 9 | F8: 61 | G8: 3 | H8: 2.1 | I8: 1.1 | J8: 1.5 | K8: 7 | L8: 6.2 | M8: 6.3 | N8: 6 | O8: 3.3 | R8: ='3'!Z7 -> 1400 | S8: ='3'!AB7 -> 81.171096 | T8: ='3'!Y7 -> 3186 | U8: =IF('3'!AA7=1,'3'!AR6,'3'!AR7) -> S.A.L | X8: 0.125 | Y8: 3191 | Z8: 1400 | AA8: 1 | AB8: =IF('3'!AA8=1,(('3'!Z8*'3'!$AS$6*'3'!$AT$6)/('3'!Y8*0.0036)),IF('3'!AA8=2,(('3'!Z8*'3'!$AS$7*'3'!$AT$7)/('3'!Y8*0.0036)))) -> 81.043908 | AD8: =(('3'!AC8*'3'!$O$9*1000000))/('3'!Y8*3600) -> 0 | AF8: =('3'!AE8/24)*0.454 -> 0 | AH8: =('3'!AG8/24)*0.454 -> 0 | AI8: 3500 | AJ8: =('3'!AI8/24)*0.454 -> 66.208333 | AL8: =('3'!AK8/24)*0.454 -> 0 | AN8: =('3'!AM8/24)*0.454 -> 0 | AP8: =('3'!AO8/24)*0.454 -> 0 | AQ8: Polímero Catiônico
A9: 0.16666667 | B9: 238 | C9: 19 | D9: 18 | E9: 9 | F9: 60 | G9: 3.1 | H9: 2 | I9: 1.2 | J9: 1.6 | K9: 7 | L9: 6.2 | M9: 6.3 | N9: 6 | O9: 3.3 | R9: ='3'!Z9 -> 1400 | S9: ='3'!AB9 -> 81.196581 | T9: ='3'!Y9 -> 3185 | U9: =IF('3'!AA9=1,'3'!AR6,'3'!AR7) -> S.A.L | X9: 0.16666667 | Y9: 3185 | Z9: 1400 | AA9: 1 | AB9: =IF('3'!AA9=1,(('3'!Z9*'3'!$AS$6*'3'!$AT$6)/('3'!Y9*0.0036)),IF('3'!AA9=2,(('3'!Z9*'3'!$AS$7*'3'!$AT$7)/('3'!Y9*0.0036)))) -> 81.196581 | AD9: =(('3'!AC9*'3'!$O$9*1000000))/('3'!Y9*3600) -> 0 | AF9: =('3'!AE9/24)*0.454 -> 0 | AH9: =('3'!AG9/24)*0.454 -> 0 | AI9: 3500 | AJ9: =('3'!AI9/24)*0.454 -> 66.208333 | AL9: =('3'!AK9/24)*0.454 -> 0 | AN9: =('3'!AM9/24)*0.454 -> 0 | AP9: =('3'!AO9/24)*0.454 -> 0 | AQ9: Nome | AT9: C (%)
A10: 0.25 | B10: 236 | C10: 19 | D10: 18 | E10: 10 | F10: 60 | G10: 3.1 | H10: 1.9 | I10: 1.2 | J10: 1.6 | K10: 7 | L10: 6.2 | M10: 6.3 | N10: 6 | O10: 3.3 | R10: ='3'!Z11 -> 1400 | S10: ='3'!AB11 -> 81.094735 | T10: ='3'!Y11 -> 3189 | U10: =IF('3'!AA11=1,'3'!AR6,'3'!AR7) -> S.A.L | X10: 0.20833333 | Y10: 3189 | Z10: 1400 | AA10: 1 | AB10: =IF('3'!AA10=1,(('3'!Z10*'3'!$AS$6*'3'!$AT$6)/('3'!Y10*0.0036)),IF('3'!AA10=2,(('3'!Z10*'3'!$AS$7*'3'!$AT$7)/('3'!Y10*0.0036)))) -> 81.094735 | AD10: =(('3'!AC10*'3'!$O$9*1000000))/('3'!Y10*3600) -> 0 | AF10: =('3'!AE10/24)*0.454 -> 0 | AH10: =('3'!AG10/24)*0.454 -> 0 | AI10: 3500 | AJ10: =('3'!AI10/24)*0.454 -> 66.208333 | AL10: =('3'!AK10/24)*0.454 -> 0 | AN10: =('3'!AM10/24)*0.454 -> 0 | AP10: =('3'!AO10/24)*0.454 -> 0 | AQ10: Aguapol 200 | AT10: 0.002
A11: 0.33333333 | B11: 232 | C11: 18 | D11: 18 | E11: 9 | F11: 57 | G11: 2.6 | H11: 1.8 | I11: 1.4 | J11: 1.3 | K11: 7.3 | L11: 6.3 | M11: 6.3 | N11: 6.3 | O11: 3 | R11: ='3'!Z13 -> 1390 | S11: ='3'!AB13 -> 80.038619 | T11: ='3'!Y13 -> 3208 | U11: =IF('3'!AA13=1,'3'!AR6,'3'!AR7) -> S.A.L | X11: 0.25 | Y11: 3189 | Z11: 1400 | AA11: 1 | AB11: =IF('3'!AA11=1,(('3'!Z11*'3'!$AS$6*'3'!$AT$6)/('3'!Y11*0.0036)),IF('3'!AA11=2,(('3'!Z11*'3'!$AS$7*'3'!$AT$7)/('3'!Y11*0.0036)))) -> 81.094735 | AD11: =(('3'!AC11*'3'!$O$9*1000000))/('3'!Y11*3600) -> 0 | AF11: =('3'!AE11/24)*0.454 -> 0 | AH11: =('3'!AG11/24)*0.454 -> 0 | AI11: 3500 | AJ11: =('3'!AI11/24)*0.454 -> 66.208333 | AL11: =('3'!AK11/24)*0.454 -> 0 | AN11: =('3'!AM11/24)*0.454 -> 0 | AP11: =('3'!AO11/24)*0.454 -> 0
A12: 0.41666667 | B12: 218 | C12: 17 | D12: 17 | E12: 9 | F12: 53 | G12: 3.2 | H12: 2.1 | I12: 1 | J12: 1.4 | K12: 6.9 | L12: 6.3 | M12: 6.3 | N12: 6.3 | O12: 3.5 | R12: ='3'!Z15 -> 1350 | S12: ='3'!AB15 -> 77.59023 | T12: ='3'!Y15 -> 3214 | U12: =IF('3'!AA15=1,'3'!AR6,'3'!AR7) -> S.A.L | V12: =ESCALA!$B$5 -> 0 | X12: 0.29166667 | Y12: 3222 | Z12: 1400 | AA12: 1 | AB12: =IF('3'!AA12=1,(('3'!Z12*'3'!$AS$6*'3'!$AT$6)/('3'!Y12*0.0036)),IF('3'!AA12=2,(('3'!Z12*'3'!$AS$7*'3'!$AT$7)/('3'!Y12*0.0036)))) -> 80.264156 | AD12: =(('3'!AC12*'3'!$O$9*1000000))/('3'!Y12*3600) -> 0 | AF12: =('3'!AE12/24)*0.454 -> 0 | AH12: =('3'!AG12/24)*0.454 -> 0 | AI12: 3500 | AJ12: =('3'!AI12/24)*0.454 -> 66.208333 | AL12: =('3'!AK12/24)*0.454 -> 0 | AN12: =('3'!AM12/24)*0.454 -> 0 | AP12: =('3'!AO12/24)*0.454 -> 0
A13: 0.5 | B13: 216 | C13: 17 | D13: 17 | E13: 9 | F13: 56 | G13: 3 | H13: 2.2 | I13: 1 | J13: 1.3 | K13: 6.9 | L13: 6.3 | M13: 6.3 | N13: 6.3 | O13: 3.5 | R13: ='3'!Z17 -> 1350 | S13: ='3'!AB17 -> 78.395159 | T13: ='3'!Y17 -> 3181 | U13: =IF('3'!AA17=1,'3'!AR6,'3'!AR7) -> S.A.L | X13: 0.33333333 | Y13: 3208 | Z13: 1390 | AA13: 1 | AB13: =IF('3'!AA13=1,(('3'!Z13*'3'!$AS$6*'3'!$AT$6)/('3'!Y13*0.0036)),IF('3'!AA13=2,(('3'!Z13*'3'!$AS$7*'3'!$AT$7)/('3'!Y13*0.0036)))) -> 80.038619 | AD13: =(('3'!AC13*'3'!$O$9*1000000))/('3'!Y13*3600) -> 0 | AF13: =('3'!AE13/24)*0.454 -> 0 | AH13: =('3'!AG13/24)*0.454 -> 0 | AI13: 3500 | AJ13: =('3'!AI13/24)*0.454 -> 66.208333 | AL13: =('3'!AK13/24)*0.454 -> 0 | AN13: =('3'!AM13/24)*0.454 -> 0 | AP13: =('3'!AO13/24)*0.454 -> 0
A14: 0.58333333 | B14: 225 | C14: 19 | D14: 16 | E14: 10 | F14: 56 | G14: 3 | H14: 1.7 | I14: 1.1 | J14: 1.4 | K14: 6.9 | L14: 6.3 | M14: 6.3 | N14: 6.3 | O14: 3 | R14: ='3'!Z19 -> 1320 | S14: ='3'!AB19 -> 76.508733 | T14: ='3'!Y19 -> 3187 | U14: =IF('3'!AA19=1,'3'!AR6,'3'!AR7) -> S.A.L | X14: 0.375 | Y14: 3192 | Z14: 1350 | AA14: 1 | AB14: =IF('3'!AA14=1,(('3'!Z14*'3'!$AS$6*'3'!$AT$6)/('3'!Y14*0.0036)),IF('3'!AA14=2,(('3'!Z14*'3'!$AS$7*'3'!$AT$7)/('3'!Y14*0.0036)))) -> 78.125 | AD14: =(('3'!AC14*'3'!$O$9*1000000))/('3'!Y14*3600) -> 0 | AF14: =('3'!AE14/24)*0.454 -> 0 | AH14: =('3'!AG14/24)*0.454 -> 0 | AI14: 3500 | AJ14: =('3'!AI14/24)*0.454 -> 66.208333 | AL14: =('3'!AK14/24)*0.454 -> 0 | AN14: =('3'!AM14/24)*0.454 -> 0 | AP14: =('3'!AO14/24)*0.454 -> 0
A15: 0.66666667 | B15: 218 | C15: 19 | D15: 17 | E15: 10 | F15: 57 | G15: 3 | H15: 2 | I15: 1.1 | J15: 1.4 | K15: 6.9 | L15: 6.3 | M15: 6.3 | N15: 6.3 | O15: 3 | R15: ='3'!Z21 -> 1320 | S15: ='3'!AB21 -> 76.556777 | T15: ='3'!Y21 -> 3185 | U15: =IF('3'!AA21=1,'3'!AR6,'3'!AR7) -> S.A.L | X15: 0.41666667 | Y15: 3214 | Z15: 1350 | AA15: 1 | AB15: =IF('3'!AA15=1,(('3'!Z15*'3'!$AS$6*'3'!$AT$6)/('3'!Y15*0.0036)),IF('3'!AA15=2,(('3'!Z15*'3'!$AS$7*'3'!$AT$7)/('3'!Y15*0.0036)))) -> 77.59023 | AD15: =(('3'!AC15*'3'!$O$9*1000000))/('3'!Y15*3600) -> 0 | AF15: =('3'!AE15/24)*0.454 -> 0 | AH15: =('3'!AG15/24)*0.454 -> 0 | AI15: 3500 | AJ15: =('3'!AI15/24)*0.454 -> 66.208333 | AL15: =('3'!AK15/24)*0.454 -> 0 | AN15: =('3'!AM15/24)*0.454 -> 0 | AP15: =('3'!AO15/24)*0.454 -> 0
A16: 0.75 | B16: 257 | C16: 18 | D16: 16 | E16: 10 | F16: 65 | G16: 2.6 | H16: 1.9 | I16: 1.2 | J16: 1.6 | K16: 6.7 | L16: 6.3 | M16: 6.4 | N16: 6.1 | O16: 3.5 | R16: ='3'!Z23 -> 1400 | S16: ='3'!AB23 -> 80.664726 | T16: ='3'!Y23 -> 3206 | U16: =IF('3'!AA23=1,'3'!AR6,'3'!AR7) -> S.A.L | X16: 0.45833333 | Y16: 3177 | Z16: 1350 | AA16: 1 | AB16: =IF('3'!AA16=1,(('3'!Z16*'3'!$AS$6*'3'!$AT$6)/('3'!Y16*0.0036)),IF('3'!AA16=2,(('3'!Z16*'3'!$AS$7*'3'!$AT$7)/('3'!Y16*0.0036)))) -> 78.493862 | AD16: =(('3'!AC16*'3'!$O$9*1000000))/('3'!Y16*3600) -> 0 | AF16: =('3'!AE16/24)*0.454 -> 0 | AH16: =('3'!AG16/24)*0.454 -> 0 | AI16: 3500 | AJ16: =('3'!AI16/24)*0.454 -> 66.208333 | AL16: =('3'!AK16/24)*0.454 -> 0 | AN16: =('3'!AM16/24)*0.454 -> 0 | AP16: =('3'!AO16/24)*0.454 -> 0
A17: 0.83333333 | B17: 252 | C17: 21 | D17: 19 | E17: 11 | F17: 65 | G17: 2.2 | H17: 1.5 | I17: 1.4 | J17: 1.4 | K17: 6.7 | L17: 6.3 | M17: 6.3 | N17: 6.1 | O17: 3.5 | R17: ='3'!Z25 -> 1400 | S17: ='3'!AB25 -> 80.740278 | T17: ='3'!Y25 -> 3203 | U17: =IF('3'!AA25=1,'3'!AR6,'3'!AR7) -> S.A.L | V17: =ESCALA!$C$5 -> 0 | X17: 0.5 | Y17: 3181 | Z17: 1350 | AA17: 1 | AB17: =IF('3'!AA17=1,(('3'!Z17*'3'!$AS$6*'3'!$AT$6)/('3'!Y17*0.0036)),IF('3'!AA17=2,(('3'!Z17*'3'!$AS$7*'3'!$AT$7)/('3'!Y17*0.0036)))) -> 78.395159 | AD17: =(('3'!AC17*'3'!$O$9*1000000))/('3'!Y17*3600) -> 0 | AF17: =('3'!AE17/24)*0.454 -> 0 | AH17: =('3'!AG17/24)*0.454 -> 0 | AI17: 3500 | AJ17: =('3'!AI17/24)*0.454 -> 66.208333 | AL17: =('3'!AK17/24)*0.454 -> 0 | AN17: =('3'!AM17/24)*0.454 -> 0 | AP17: =('3'!AO17/24)*0.454 -> 0
A18: 0.91666667 | B18: 250 | C18: 19 | D18: 18 | E18: 11 | F18: 62 | G18: 2 | H18: 1.5 | I18: 1.4 | J18: 1.3 | K18: 6.7 | L18: 6.3 | M18: 6.3 | N18: 6.1 | O18: 3.5 | R18: ='3'!Z27 -> 1400 | S18: ='3'!AB27 -> 81.632295 | T18: ='3'!Y27 -> 3168 | U18: =IF('3'!AA27=1,'3'!AR6,'3'!AR7) -> S.A.L | X18: 0.54166667 | Y18: 3162 | Z18: 1320 | AA18: 1 | AB18: =IF('3'!AA18=1,(('3'!Z18*'3'!$AS$6*'3'!$AT$6)/('3'!Y18*0.0036)),IF('3'!AA18=2,(('3'!Z18*'3'!$AS$7*'3'!$AT$7)/('3'!Y18*0.0036)))) -> 77.113641 | AD18: =(('3'!AC18*'3'!$O$9*1000000))/('3'!Y18*3600) -> 0 | AF18: =('3'!AE18/24)*0.454 -> 0 | AH18: =('3'!AG18/24)*0.454 -> 0 | AI18: 3500 | AJ18: =('3'!AI18/24)*0.454 -> 66.208333 | AL18: =('3'!AK18/24)*0.454 -> 0 | AN18: =('3'!AM18/24)*0.454 -> 0 | AP18: =('3'!AO18/24)*0.454 -> 0
A19: Média | B19: {=IF('3'!B7:B18>0.01,AVERAGE('3'!B7:B18),"")} -> 235.66667 | C19: {=IF('3'!C7:C18>0.01,AVERAGE('3'!C7:C18),"")} -> 18.666667 | D19: {=IF('3'!D7:D18>0.01,AVERAGE('3'!D7:D18),"")} -> 17.5 | E19: {=IF('3'!E7:E18>0.01,AVERAGE('3'!E7:E18),"")} -> 9.6666667 | F19: {=IF('3'!F7:F18>0.01,AVERAGE('3'!F7:F18),"")} -> 59.583333 | G19: {=IF('3'!G7:G18>0.01,AVERAGE('3'!G7:G18),"")} -> 2.8166667 | H19: {=IF('3'!H7:H18>0.01,AVERAGE('3'!H7:H18),"")} -> 1.9166667 | I19: {=IF('3'!I7:I18>0.01,AVERAGE('3'!I7:I18),"")} -> 1.1833333 | ... S19: {=IF('3'!S7:S18>0.01,AVERAGE('3'!S7:S18),"")} -> 79.805162 | X19: 0.58333333 | Y19: 3187 | Z19: 1320 | AA19: 1 | AB19: =IF('3'!AA19=1,(('3'!Z19*'3'!$AS$6*'3'!$AT$6)/('3'!Y19*0.0036)),IF('3'!AA19=2,(('3'!Z19*'3'!$AS$7*'3'!$AT$7)/('3'!Y19*0.0036)))) -> 76.508733 | AD19: =(('3'!AC19*'3'!$O$9*1000000))/('3'!Y19*3600) -> 0 | AF19: =('3'!AE19/24)*0.454 -> 0 | AH19: =('3'!AG19/24)*0.454 -> 0 | AI19: 3500 | AJ19: =('3'!AI19/24)*0.454 -> 66.208333 | AL19: =('3'!AK19/24)*0.454 -> 0 | AN19: =('3'!AM19/24)*0.454 -> 0 | AP19: =('3'!AO19/24)*0.454 -> 0
A20: Máximo | B20: =MAX('3'!B7:B18) -> 257 | C20: =MAX('3'!C7:C18) -> 21 | D20: =MAX('3'!D7:D18) -> 19 | E20: =MAX('3'!E7:E18) -> 11 | F20: =MAX('3'!F7:F18) -> 65 | G20: =MAX('3'!G7:G18) -> 3.2 | H20: =MAX('3'!H7:H18) -> 2.3 | I20: =MAX('3'!I7:I18) -> 1.4 | ... S20: =MAX('3'!S7:S18) -> 82.072711 | X20: 0.625 | Y20: 3173 | Z20: 1320 | AA20: 1 | AB20: =IF('3'!AA20=1,(('3'!Z20*'3'!$AS$6*'3'!$AT$6)/('3'!Y20*0.0036)),IF('3'!AA20=2,(('3'!Z20*'3'!$AS$7*'3'!$AT$7)/('3'!Y20*0.0036)))) -> 76.846307 | AD20: =(('3'!AC20*'3'!$O$9*1000000))/('3'!Y20*3600) -> 0 | AF20: =('3'!AE20/24)*0.454 -> 0 | AH20: =('3'!AG20/24)*0.454 -> 0 | AI20: 3500 | AJ20: =('3'!AI20/24)*0.454 -> 66.208333 | AL20: =('3'!AK20/24)*0.454 -> 0 | AN20: =('3'!AM20/24)*0.454 -> 0 | AP20: =('3'!AO20/24)*0.454 -> 0
A21: Mínimo | B21: =MIN('3'!B7:B18) -> 216 | C21: =MIN('3'!C7:C18) -> 17 | D21: =MIN('3'!D7:D18) -> 16 | E21: =MIN('3'!E7:E18) -> 9 | F21: =MIN('3'!F7:F18) -> 53 | G21: =MIN('3'!G7:G18) -> 2 | H21: =MIN('3'!H7:H18) -> 1.5 | I21: =MIN('3'!I7:I18) -> 1 | ... S21: =MIN('3'!S7:S18) -> 76.508733 | X21: 0.66666667 | Y21: 3185 | Z21: 1320 | AA21: 1 | AB21: =IF('3'!AA21=1,(('3'!Z21*'3'!$AS$6*'3'!$AT$6)/('3'!Y21*0.0036)),IF('3'!AA21=2,(('3'!Z21*'3'!$AS$7*'3'!$AT$7)/('3'!Y21*0.0036)))) -> 76.556777 | AD21: =(('3'!AC21*'3'!$O$9*1000000))/('3'!Y21*3600) -> 0 | AF21: =('3'!AE21/24)*0.454 -> 0 | AH21: =('3'!AG21/24)*0.454 -> 0 | AI21: 3500 | AJ21: =('3'!AI21/24)*0.454 -> 66.208333 | AL21: =('3'!AK21/24)*0.454 -> 0 | AN21: =('3'!AM21/24)*0.454 -> 0 | AP21: =('3'!AO21/24)*0.454 -> 0
R22: Total | X22: 0.70833333 | Y22: 3185 | Z22: 1350 | AA22: 1 | AB22: =IF('3'!AA22=1,(('3'!Z22*'3'!$AS$6*'3'!$AT$6)/('3'!Y22*0.0036)),IF('3'!AA22=2,(('3'!Z22*'3'!$AS$7*'3'!$AT$7)/('3'!Y22*0.0036)))) -> 78.296703 | AD22: =(('3'!AC22*'3'!$O$9*1000000))/('3'!Y22*3600) -> 0 | AF22: =('3'!AE22/24)*0.454 -> 0 | AH22: =('3'!AG22/24)*0.454 -> 0 | AI22: 3500 | AJ22: =('3'!AI22/24)*0.454 -> 66.208333 | AL22: =('3'!AK22/24)*0.454 -> 0 | AN22: =('3'!AM22/24)*0.454 -> 0 | AP22: =('3'!AO22/24)*0.454 -> 0
A23: TURBIDEZ DOS FILTROS DA 1ª E 2ª ETAPAS | R23: 440 | S23: Litros | X23: 0.75 | Y23: 3206 | Z23: 1400 | AA23: 1 | AB23: =IF('3'!AA23=1,(('3'!Z23*'3'!$AS$6*'3'!$AT$6)/('3'!Y23*0.0036)),IF('3'!AA23=2,(('3'!Z23*'3'!$AS$7*'3'!$AT$7)/('3'!Y23*0.0036)))) -> 80.664726 | AD23: =(('3'!AC23*'3'!$O$9*1000000))/('3'!Y23*3600) -> 0 | AF23: =('3'!AE23/24)*0.454 -> 0 | AH23: =('3'!AG23/24)*0.454 -> 0 | AI23: 3500 | AJ23: =('3'!AI23/24)*0.454 -> 66.208333 | AL23: =('3'!AK23/24)*0.454 -> 0 | AN23: =('3'!AM23/24)*0.454 -> 0 | AP23: =('3'!AO23/24)*0.454 -> 0
