Workbook
Name _FilterDatabase_0: #REF!
Name G: NA()
Name Hi: NA()
Name hii: NA()
Name Ho: NA()
Name maruza: [1]Jenipapo!$E$73
Name N: NA()
Name Resumo_da_Avaliação_do_Desempenho_do_Elo_Ibura: [1]Ibura!$A$11:$D$13
Name T: NA()
Name Vazão: NA()
Name Vi: NA()
Name Viii: NA()
Name W: NA()

Sheet ESCALA
A1: DATA | B1: ESCALA | C1: ESCALA
B2: 07:00h às 19:00h | C2: 19:00h às 07:00h
A3: 44317 | E3: DIGITAR PRIMEIRO DIA DO MÊS
A4: =ESCALA!A3+1 -> 44318
A5: =ESCALA!A4+1 -> 44319
A6: =ESCALA!A5+1 -> 44320
A7: =ESCALA!A6+1 -> 44321
A8: =ESCALA!A7+1 -> 44322
A9: =ESCALA!A8+1 -> 44323
A10: =ESCALA!A9+1 -> 44324
A11: =ESCALA!A10+1 -> 44325
A12: =ESCALA!A11+1 -> 44326
A13: =ESCALA!A12+1 -> 44327
A14: =ESCALA!A13+1 -> 44328
A15: =ESCALA!A14+1 -> 44329
... A33: =ESCALA!A32+1 -> 44347

Sheet 1
D2: CONTROLE DE ANÁLISE FÍSICO - QUÍMICAS \ ETA CASTELO BRANCO | AB2: CONTROLE DE PRODUTOS QUÍMICOS APLICADOS \ ETA CASTELO BRANCO
A4: HORA | B4: COR (Uc) | F4: TURBIDEZ (Ut) | K4: Ph | O4: CLORO RESIDUAL (mg/L) | R4: DOSAGEM DO COAGULANTE | T4: VAZÃO DA ETA | U4: TIPO DE COAGU LANTE | V4: TÉCNICO | X4: Hora | Y4: Vazão ETA (l/s) | Z4: Vazão Coagulante (l/h) | AA4: Código | AB4: Dosagem (mg/l) | AC4: Vazão Polímero (l/h) | AD4: Dosagem (mg/l) | AE4: Pré 1 (Lib/dia) | AF4: Pré 1 (Kg/h) | AG4: Pré 2 (Lib/dia) | AH4: Pré 2 (Kg/h) | AI4: Pós (Lib/dia) | AJ4: Pós (Kg/h) | AK4: Pré 1 (Lib/dia) cilindros | AL4: Pré 1 (Kg/h) cilindros | AM4: Pré 2 (Lib/dia) cilindros | AN4: Pré 2 (Kg/h) cilindros | AO4: Pós (Lib/dia) cilindros | AP4: Pós (Kg/h) cilindros | AQ4: COAGULANTE | AU4: Tempo de Utilização (h)
AQ5: Codigo | AR5: Nome | AS5: d (g/ml) | AT5: C (%)
B6: Bruta | C6: DEC_1 | D6: DEC_2 | E6: TRAT | F6: Bruta | G6: DEC_1 | H6: DEC_2 | I6: TRAT | J6: FILT | K6: Bruta | L6: DEC_1 | M6: DEC_2 | N6: TRAT | O6: TRAT | P6: DEC_1 | Q6: DEC_2 | R6: L/h | S6: mg/l | T6: L/s | X6: 0.041666667 | Y6: 2780 | Z6: 1897 | AA6: 1 | AB6: =IF('1'!AA6=1,(('1'!Z6*'1'!$AS$6*'1'!$AT$6)/('1'!Y6*0.0036)),IF('1'!AA6=2,(('1'!Z6*'1'!$AS$7*'1'!$AT$7)/('1'!Y6*0.0036)))) -> 126.04966 | AD6: =(('1'!AC6*'1'!$Q$10*1000000))/('1'!Z10*3600) -> 0 | AE6: 3000 | AF6: =('1'!AE6/24)*0.454 -> 56.75 | AG6: 500 | AH6: =('1'!AG6/24)*0.454 -> 9.4583333 | AI6: 3000 | AJ6: =('1'!AI6/24)*0.454 -> 56.75 | AL6: =('1'!AK6/24)*0.454 -> 0 | AN6: =('1'!AM6/24)*0.454 -> 0 | AP6: =('1'!AO6/24)*0.454 -> 0 | AQ6: 1 | AR6: S.A.L | AS6: 1.33 | AT6: 0.5 | AU6: 0
A7: 0 | B7: 1100 | C7: 60 | D7: 80 | E7: 5 | F7: 342 | G7: 52 | H7: 91 | I7: 0.92 | J7: 3.4 | K7: 6.8 | L7: 6 | M7: 5.7 | N7: 5.5 | O7: 3.2 | P7: 0.4 | Q7: 2 | U7: =IF('1'!AA6=1,'1'!AR6,'1'!AR7) -> S.A.L | X7: 0.083333333 | Y7: 2798 | Z7: 1897 | AA7: 1 | AB7: =IF('1'!AA7=1,(('1'!Z7*'1'!$AS$6*'1'!$AT$6)/('1'!Y7*0.0036)),IF('1'!AA7=2,(('1'!Z7*'1'!$AS$7*'1'!$AT$7)/('1'!Y7*0.0036)))) -> 125.23876 | AD7: =(('1'!AC7*'1'!$Q$10*1000000))/('1'!Z11*3600) -> 0 | AE7: 3000 | AF7: =('1'!AE7/24)*0.454 -> 56.75 | AG7: 500 | AH7: =('1'!AG7/24)*0.454 -> 9.4583333 | AI7: 3000 | AJ7: =('1'!AI7/24)*0.454 -> 56.75 | AL7: =('1'!AK7/24)*0.454 -> 0 | AN7: =('1'!AM7/24)*0.454 -> 0 | AP7: =('1'!AO7/24)*0.454 -> 0 | AQ7: 2 | AR7: PAC 18 | AS7: 1.262 | AT7: 1 | AU7: 24
A8: 0.083333333 | B8: 1100 | C8: 80 | D8: 60 | E8: 7.5 | F8: 340 | G8: 63 | H8: 74 | I8: 1.98 | J8: 3.2 | K8: 6.8 | L8: 5.7 | M8: 5.7 | N8: 5.5 | O8: 3.2 | P8: 0.3 | Q8: 2.2 | R8: ='1'!Z7 -> 1897 | S8: ='1'!AB7 -> 125.23876 | T8: ='1'!Y7 -> 2798 | U8: =IF('1'!AA7=1,'1'!AR6,'1'!AR7) -> S.A.L | X8: 0.125 | Y8: 2803 | Z8: 1897 | AA8: 1 | AB8: =IF('1'!AA8=1,(('1'!Z8*'1'!$AS$6*'1'!$AT$6)/('1'!Y8*0.0036)),IF('1'!AA8=2,(('1'!Z8*'1'!$AS$7*'1'!$AT$7)/('1'!Y8*0.0036)))) -> 125.01536 | AD8: =(('1'!AC8*'1'!$Q$10*1000000))/('1'!Z12*3600) -> 0 | AE8: 3000 | AF8: =('1'!AE8/24)*0.454 -> 56.75 | AG8: 500 | AH8: =('1'!AG8/24)*0.454 -> 9.4583333 | AI8: 3000 | AJ8: =('1'!AI8/24)*0.454 -> 56.75 | AL8: =('1'!AK8/24)*0.454 -> 0 | AN8: =('1'!AM8/24)*0.454 -> 0 | AP8: =('1'!AO8/24)*0.454 -> 0 | AQ8: Polímero Catiônico
A9: 0.16666667 | B9: 1100 | C9: 30 | D9: 20 | E9: 7.5 | F9: 336 | G9: 21 | H9: 11 | I9: 2.54 | J9: 2.6 | K9: 6.8 | L9: 5.7 | M9: 5.7 | N9: 5.5 | O9: 3.6 | P9: 0.7 | Q9: 2.4 | R9: ='1'!Z9 -> 1897 | S9: ='1'!AB9 -> 126.04966 | T9: ='1'!Y9 -> 2780 | U9: =IF('1'!AA9=1,'1'!AR6,'1'!AR7) -> S.A.L | X9: 0.16666667 | Y9: 2780 | Z9: 1897 | AA9: 1 | AB9: =IF('1'!AA9=1,(('1'!Z9*'1'!$AS$6*'1'!$AT$6)/('1'!Y9*0.0036)),IF('1'!AA9=2,(('1'!Z9*'1'!$AS$7*'1'!$AT$7)/('1'!Y9*0.0036)))) -> 126.04966 | AD9: =(('1'!AC9*'1'!$Q$10*1000000))/('1'!Z13*3600) -> 0 | AE9: 3000 | AF9: =('1'!AE9/24)*0.454 -> 56.75 | AG9: 500 | AH9: =('1'!AG9/24)*0.454 -> 9.4583333 | AI9: 3000 | AJ9: =('1'!AI9/24)*0.454 -> 56.75 | AL9: =('1'!AK9/24)*0.454 -> 0 | AN9: =('1'!AM9/24)*0.454 -> 0 | AP9: =('1'!AO9/24)*0.454 -> 0 | AQ9: Nome | AT9: C (%)
A10: 0.25 | B10: 1100 | C10: 15 | D10: 15 | E10: 5 | F10: 334 | G10: 3.9 | H10: 4.3 | I10: 1.8 | J10: 2.3 | K10: 6.8 | L10: 5.7 | M10: 5.7 | N10: 5.5 | O10: 3.8 | P10: 1.3 | Q10: 2.7 | R10: ='1'!Z11 -> 1897 | S10: ='1'!AB11 -> 128.83017 | T10: ='1'!Y11 -> 2720 | U10: =IF('1'!AA11=1,'1'!AR6,'1'!AR7) -> S.A.L | X10: 0.20833333 | Y10: 2771 | Z10: 1897 | AA10: 1 | AB10: =IF('1'!AA10=1,(('1'!Z10*'1'!$AS$6*'1'!$AT$6)/('1'!Y10*0.0036)),IF('1'!AA10=2,(('1'!Z10*'1'!$AS$7*'1'!$AT$7)/('1'!Y10*0.0036)))) -> 126.45906 | AD10: =(('1'!AC10*'1'!$Q$10*1000000))/('1'!Z14*3600) -> 0 | AE10: 3000 | AF10: =('1'!AE10/24)*0.454 -> 56.75 | AG10: 500 | AH10: =('1'!AG10/24)*0.454 -> 9.4583333 | AI10: 3000 | AJ10: =('1'!AI10/24)*0.454 -> 56.75 | AL10: =('1'!AK10/24)*0.454 -> 0 | AN10: =('1'!AM10/24)*0.454 -> 0 | AP10: =('1'!AO10/24)*0.454 -> 0 | AQ10: Aguapol 200 | AT10: 0.002
A11: 0.33333333 | B11: 1100 | C11: 12.5 | D11: 5 | E11: 2.5 | F11: 286 | G11: 3.7 | H11: 2 | I11: 1.2 | J11: 1 | K11: 7 | L11: 4.8 | M11: 4.8 | N11: 5.7 | O11: 3.8 | P11: 0.1 | Q11: 0 | R11: ='1'!Z13 -> 1897 | S11: ='1'!AB13 -> 127.28589 | T11: ='1'!Y13 -> 2753 | U11: =IF('1'!AA13=1,'1'!AR6,'1'!AR7) -> S.A.L | X11: 0.25 | Y11: 2720 | Z11: 1897 | AA11: 1 | AB11: =IF('1'!AA11=1,(('1'!Z11*'1'!$AS$6*'1'!$AT$6)/('1'!Y11*0.0036)),IF('1'!AA11=2,(('1'!Z11*'1'!$AS$7*'1'!$AT$7)/('1'!Y11*0.0036)))) -> 128.83017 | AD11: =(('1'!AC11*'1'!$Q$10*1000000))/('1'!Z15*3600) -> 0 | AE11: 3000 | AF11: =('1'!AE11/24)*0.454 -> 56.75 | AG11: 500 | AH11: =('1'!AG11/24)*0.454 -> 9.4583333 | AI11: 3000 | AJ11: =('1'!AI11/24)*0.454 -> 56.75 | AL11: =('1'!AK11/24)*0.454 -> 0 | AN11: =('1'!AM11/24)*0.454 -> 0 | AP11: =('1'!AO11/24)*0.454 -> 0
A12: 0.41666667 | B12: 1100 | C12: 12.5 | D12: 5 | E12: 2.5 | F12: 278 | G12: 3.5 | H12: 1.9 | I12: 1.2 | J12: 1 | K12: 7 | L12: 4.8 | M12: 4.8 | N12: 5.7 | O12: 3.8 | P12: 0.1 | Q12: 0 | R12: ='1'!Z15 -> 1897 | S12: ='1'!AB15 -> 125.37319 | T12: ='1'!Y15 -> 2795 | U12: =IF('1'!AA15=1,'1'!AR6,'1'!AR7) -> S.A.L | V12: =ESCALA!$B$3 -> 0 | X12: 0.29166667 | Y12: 2794 | Z12: 1897 | AA12: 1 | AB12: =IF('1'!AA12=1,(('1'!Z12*'1'!$AS$6*'1'!$AT$6)/('1'!Y12*0.0036)),IF('1'!AA12=2,(('1'!Z12*'1'!$AS$7*'1'!$AT$7)/('1'!Y12*0.0036)))) -> 125.41806 | AD12: =(('1'!AC12*'1'!$Q$10*1000000))/('1'!Z16*3600) -> 0 | AE12: 3000 | AF12: =('1'!AE12/24)*0.454 -> 56.75 | AG12: 500 | AH12: =('1'!AG12/24)*0.454 -> 9.4583333 | AI12: 3000 | AJ12: =('1'!AI13/24)*0.454 -> 56.75 | AL12: =('1'!AK12/24)*0.454 -> 0 | AN12: =('1'!AM12/24)*0.454 -> 0 | AP12: =('1'!AO12/24)*0.454 -> 0
A13: 0.5 | B13: 1100 | C13: 12.5 | D13: 5 | E13: 2.5 | F13: 291 | G13: 3.6 | H13: 1.9 | I13: 1.01 | J13: 1 | K13: 7 | L13: 4.8 | M13: 4.8 | N13: 5.7 | O13: 3.8 | P13: 0.2 | Q13: 0 | R13: ='1'!Z17 -> 1897 | S13: ='1'!AB17 -> 125.68797 | T13: ='1'!Y17 -> 2788 | U13: =IF('1'!AA17=1,'1'!AR6,'1'!AR7) -> S.A.L | X13: 0.33333333 | Y13: 2753 | Z13: 1897 | AA13: 1 | AB13: =IF('1'!AA13=1,(('1'!Z13*'1'!$AS$6*'1'!$AT$6)/('1'!Y13*0.0036)),IF('1'!AA13=2,(('1'!Z13*'1'!$AS$7*'1'!$AT$7)/('1'!Y13*0.0036)))) -> 127.28589 | AD13: =(('1'!AC13*'1'!$Q$10*1000000))/('1'!Z17*3600) -> 0 | AE13: 3000 | AF13: =('1'!AE13/24)*0.454 -> 56.75 | AG13: 500 | AH13: =('1'!AG13/24)*0.454 -> 9.4583333 | AI13: 3000 | AJ13: =('1'!#REF!/24)*0.454 -> #REF! | AL13: =('1'!AK13/24)*0.454 -> 0 | AN13: =('1'!AM13/24)*0.454 -> 0 | AP13: =('1'!AO13/24)*0.454 -> 0
A14: 0.58333333 | B14: 1100 | C14: 12.5 | D14: 5 | E14: 2.5 | F14: 311 | G14: 3.6 | H14: 1.9 | I14: 0.8 | J14: 1.1 | K14: 7 | L14: 4.8 | M14: 4.8 | N14: 5.7 | O14: 3.8 | P14: 0.3 | Q14: 0 | R14: ='1'!Z19 -> 1406 | S14: ='1'!AB19 -> 116.72784 | T14: ='1'!Y19 -> 2225 | U14: =IF('1'!AA19=1,'1'!AR6,'1'!AR7) -> S.A.L | X14: 0.375 | Y14: 2784 | Z14: 1897 | AA14: 1 | AB14: =IF('1'!AA14=1,(('1'!Z14*'1'!$AS$6*'1'!$AT$6)/('1'!Y14*0.0036)),IF('1'!AA14=2,(('1'!Z14*'1'!$AS$7*'1'!$AT$7)/('1'!Y14*0.0036)))) -> 125.86855 | AD14: =(('1'!AC14*'1'!$Q$10*1000000))/('1'!Z18*3600) -> 0 | AE14: 3000 | AF14: =('1'!AE14/24)*0.454 -> 56.75 | AG14: 500 | AH14: =('1'!AG14/24)*0.454 -> 9.4583333 | AI14: 3000 | AJ14: =('1'!AI14/24)*0.454 -> 56.75 | AL14: =('1'!AK14/24)*0.454 -> 0 | AN14: =('1'!AM14/24)*0.454 -> 0 | AP14: =('1'!AO14/24)*0.454 -> 0
A15: 0.66666667 | B15: 1100 | C15: 12.5 | D15: 7.5 | E15: 2.5 | F15: 265 | G15: 3.3 | H15: 2.5 | I15: 1 | J15: 1.8 | K15: 7 | L15: 4.8 | M15: 4.8 | N15: 5.7 | O15: 3.8 | P15: 1 | Q15: 1.8 | R15: ='1'!Z21 -> 1406 | S15: ='1'!AB21 -> 110.8491 | T15: ='1'!Y21 -> 2343 | U15: =IF('1'!AA21=1,'1'!AR6,'1'!AR7) -> S.A.L | X15: 0.41666667 | Y15: 2795 | Z15: 1897 | AA15: 1 | AB15: =IF('1'!AA15=1,(('1'!Z15*'1'!$AS$6*'1'!$AT$6)/('1'!Y15*0.0036)),IF('1'!AA15=2,(('1'!Z15*'1'!$AS$7*'1'!$AT$7)/('1'!Y15*0.0036)))) -> 125.37319 | AD15: =(('1'!AC15*'1'!$Q$10*1000000))/('1'!Z19*3600) -> 0 | AE15: 3000 | AF15: =('1'!AE15/24)*0.454 -> 56.75 | AG15: 500 | AH15: =('1'!AG15/24)*0.454 -> 9.4583333 | AI15: 3000 | AJ15: =('1'!AI15/24)*0.454 -> 56.75 | AL15: =('1'!AK15/24)*0.454 -> 0 | AN15: =('1'!AM15/24)*0.454 -> 0 | AP15: =('1'!AO15/24)*0.454 -> 0
A16: 0.75 | B16: 1100 | C16: 12.5 | D16: 15 | E16: 2.5 | F16: 235 | G16: 2.8 | H16: 5.6 | I16: 1.3 | J16: 2.7 | K16: 7 | L16: 4.8 | M16: 4.8 | N16: 5.7 | O16: 3.7 | P16: 1.5 | Q16: 2.5 | R16: ='1'!Z23 -> 1406 | S16: ='1'!AB23 -> 110.56596 | T16: ='1'!Y23 -> 2349 | U16: =IF('1'!AA23=1,'1'!AR6,'1'!AR7) -> S.A.L | X16: 0.45833333 | Y16: 2783 | Z16: 1897 | AA16: 1 | AB16: =IF('1'!AA16=1,(('1'!Z16*'1'!$AS$6*'1'!$AT$6)/('1'!Y16*0.0036)),IF('1'!AA16=2,(('1'!Z16*'1'!$AS$7*'1'!$AT$7)/('1'!Y16*0.0036)))) -> 125.91378 | AD16: =(('1'!AC16*'1'!$Q$10*1000000))/('1'!Z20*3600) -> 0 | AE16: 3000 | AF16: =('1'!AE16/24)*0.454 -> 56.75 | AG16: 500 | AH16: =('1'!AG16/24)*0.454 -> 9.4583333 | AI16: 3000 | AJ16: =('1'!AI16/24)*0.454 -> 56.75 | AL16: =('1'!AK16/24)*0.454 -> 0 | AN16: =('1'!AM16/24)*0.454 -> 0 | AP16: =('1'!AO16/24)*0.454 -> 0
A17: 0.83333333 | B17: 1100 | C17: 12.5 | D17: 17.5 | E17: 2.5 | F17: 216 | G17: 3.2 | H17: 6.6 | I17: 1.2 | J17: 1.6 | K17: 7 | L17: 4.8 | M17: 4.8 | N17: 5.7 | O17: 3.8 | P17: 1.7 | Q17: 2.5 | R17: ='1'!Z25 -> 1823 | S17: ='1'!AB25 -> 114.34588 | T17: ='1'!Y25 -> 2945 | U17: =IF('1'!AA25=1,'1'!AR6,'1'!AR7) -> S.A.L | V17: =ESCALA!$C$3 -> 0 | X17: 0.5 | Y17: 2788 | Z17: 1897 | AA17: 1 | AB17: =IF('1'!AA17=1,(('1'!Z17*'1'!$AS$6*'1'!$AT$6)/('1'!Y17*0.0036)),IF('1'!AA17=2,(('1'!Z17*'1'!$AS$7*'1'!$AT$7)/('1'!Y17*0.0036)))) -> 125.68797 | AD17: =(('1'!AC17*'1'!$Q$10*1000000))/('1'!Z21*3600) -> 0 | AE17: 3000 | AF17: =('1'!AE17/24)*0.454 -> 56.75 | AG17: 500 | AH17: =('1'!AG17/24)*0.454 -> 9.4583333 | AI17: 3000 | AJ17: =('1'!AI17/24)*0.454 -> 56.75 | AL17: =('1'!AK17/24)*0.454 -> 0 | AN17: =('1'!AM17/24)*0.454 -> 0 | AP17: =('1'!AO17/24)*0.454 -> 0
A18: 0.91666667 | B18: 1100 | C18: 12.5 | D18: 17.5 | E18: 2.5 | F18: 212 | G18: 3.4 | H18: 6.4 | I18: 1.1 | J18: 1.4 | K18: 7 | L18: 4.8 | M18: 4.8 | N18: 5.7 | O18: 3.8 | P18: 1.8 | Q18: 2.5 | R18: ='1'!Z27 -> 1823 | S18: ='1'!AB27 -> 118.15741 | T18: ='1'!Y27 -> 2850 | U18: =IF('1'!AA27=1,'1'!AR6,'1'!AR7) -> S.A.L | X18: 0.54166667 | Y18: 2821 | Z18: 1897 | AA18: 1 | AB18: =IF('1'!AA18=1,(('1'!Z18*'1'!$AS$6*'1'!$AT$6)/('1'!Y18*0.0036)),IF('1'!AA18=2,(('1'!Z18*'1'!$AS$7*'1'!$AT$7)/('1'!Y18*0.0036)))) -> 124.21767 | AD18: =(('1'!AC18*'1'!$Q$10*1000000))/('1'!Z22*3600) -> 0 | AE18: 3000 | AF18: =('1'!AE18/24)*0.454 -> 56.75 | AG18: 500 | AH18: =('1'!AG18/24)*0.454 -> 9.4583333 | AI18: 3000 | AJ18: =('1'!AI18/24)*0.454 -> 56.75 | AL18: =('1'!AK18/24)*0.454 -> 0 | AN18: =('1'!AM18/24)*0.454 -> 0 | AP18: =('1'!AO18/24)*0.454 -> 0
A19: Média | B19: {=IF('1'!B7:B18>0.01,AVERAGE('1'!B7:B18),"")} -> 1100 | C19: {=IF('1'!C7:C18>0.01,AVERAGE('1'!C7:C18),"")} -> 23.75 | D19: {=IF('1'!D7:D18>0.01,AVERAGE('1'!D7:D18),"")} -> 21.041667 | E19: {=IF('1'!E7:E18>0.01,AVERAGE('1'!E7:E18),"")} -> 3.75 | F19: {=IF('1'!F7:F18>0.01,AVERAGE('1'!F7:F18),"")} -> 287.16667 | G19: {=IF('1'!G7:G18>0.01,AVERAGE('1'!G7:G18),"")} -> 13.916667 | H19: {=IF('1'!H7:H18>0.01,AVERAGE('1'!H7:H18),"")} -> 17.425 | I19: {=IF('1'!I7:I18>0.01,AVERAGE('1'!I7:I18),"")} -> 1.3375 | ... S19: {=IF('1'!S7:S18>0.01,AVERAGE('1'!S7:S18),"")} | X19: 0.58333333 | Y19: 2225 | Z19: 1406 | AA19: 1 | AB19: =IF('1'!AA19=1,(('1'!Z19*'1'!$AS$6*'1'!$AT$6)/('1'!Y19*0.0036)),IF('1'!AA19=2,(('1'!Z19*'1'!$AS$7*'1'!$AT$7)/('1'!Y19*0.0036)))) -> 116.72784 | AD19: =(('1'!AC19*'1'!$Q$10*1000000))/('1'!Z23*3600) -> 0 | AE19: 3000 | AF19: =('1'!AE19/24)*0.454 -> 56.75 | AG19: 500 | AH19: =('1'!AG19/24)*0.454 -> 9.4583333 | AI19: 3000 | AJ19: =('1'!AI19/24)*0.454 -> 56.75 | AL19: =('1'!AK19/24)*0.454 -> 0 | AN19: =('1'!AM19/24)*0.454 -> 0 | AP19: =('1'!AO19/24)*0.454 -> 0
A20: Máximo | B20: =MAX('1'!B7:B18) -> 1100 | C20: =MAX('1'!C7:C18) -> 80 | D20: =MAX('1'!D7:D18) -> 80 | E20: =MAX('1'!E7:E18) -> 7.5 | F20: =MAX('1'!F7:F18) -> 342 | G20: =MAX('1'!G7:G18) -> 63 | H20: =MAX('1'!H7:H18) -> 91 | I20: =MAX('1'!I7:I18) -> 2.54 | ... S20: =MAX('1'!S7:S18) -> 128.83017 | X20: 0.625 | Y20: 2374 | Z20: 1406 | AA20: 1 | AB20: =IF('1'!AA20=1,(('1'!Z20*'1'!$AS$6*'1'!$AT$6)/('1'!Y20*0.0036)),IF('1'!AA20=2,(('1'!Z20*'1'!$AS$7*'1'!$AT$7)/('1'!Y20*0.0036)))) -> 109.40162 | AD20: =(('1'!AC20*'1'!$Q$10*1000000))/('1'!Z24*3600) -> 0 | AE20: 3000 | AF20: =('1'!AE20/24)*0.454 -> 56.75 | AG20: 500 | AH20: =('1'!AG20/24)*0.454 -> 9.4583333 | AI20: 3000 | AJ20: =('1'!AI20/24)*0.454 -> 56.75 | AL20: =('1'!AK20/24)*0.454 -> 0 | AN20: =('1'!AM20/24)*0.454 -> 0 | AP20: =('1'!AO20/24)*0.454 -> 0
A21: Mínimo | B21: =MIN('1'!B7:B18) -> 1100 | C21: =MIN('1'!C7:C18) -> 12.5 | D21: =MIN('1'!D7:D18) -> 5 | E21: =MIN('1'!E7:E18) -> 2.5 | F21: =MIN('1'!F7:F18) -> 212 | G21: =MIN('1'!G7:G18) -> 2.8 | H21: =MIN('1'!H7:H18) -> 1.9 | I21: =MIN('1'!I7:I18) -> 0.8 | ... S21: =MIN('1'!S7:S18) -> 110.56596 | X21: 0.66666667 | Y21: 2343 | Z21: 1406 | AA21: 1 | AB21: =IF('1'!AA21=1,(('1'!Z21*'1'!$AS$6*'1'!$AT$6)/('1'!Y21*0.0036)),IF('1'!AA21=2,(('1'!Z21*'1'!$AS$7*'1'!$AT$7)/('1'!Y21*0.0036)))) -> 110.8491 | AD21: =(('1'!AC21*'1'!$Q$10*1000000))/('1'!Y21*3600) -> 0 | AE21: 3000 | AF21: =('1'!AE21/24)*0.454 -> 56.75 | AG21: 500 | AH21: =('1'!AG21/24)*0.454 -> 9.4583333 | AI21: 3000 | AJ21: =('1'!AI21/24)*0.454 -> 56.75 | AL21: =('1'!AK21/24)*0.454 -> 0 | AN21: =('1'!AM21/24)*0.454 -> 0 | AP21: =('1'!AO21/24)*0.454 -> 0
R22: Total | X22: 0.70833333 | Y22: 2370 | Z22: 1406 | AA22: 1 | AB22: =IF('1'!AA22=1,(('1'!Z22*'1'!$AS$6*'1'!$AT$6)/('1'!Y22*0.0036)),IF('1'!AA22=2,(('1'!Z22*'1'!$AS$7*'1'!$AT$7)/('1'!Y22*0.0036)))) -> 109.58626 | AD22: =(('1'!AC22*'1'!$Q$10*1000000))/('1'!Y22*3600) -> 0 | AE22: 3000 | AF22: =('1'!AE22/24)*0.454 -> 56.75 | AG22: 500 | AH22: =('1'!AG22/24)*0.454 -> 9.4583333 | AI22: 3000 | AJ22: =('1'!AI22/24)*0.454 -> 56.75 | AL22: =('1'!AK22/24)*0.454 -> 0 | AN22: =('1'!AM22/24)*0.454 -> 0 | AP22: =('1'!AO22/24)*0.454 -> 0
A23: TURBIDEZ DOS FILTROS DA 1ª E 2ª ETAPAS | R23: 440 | S23: Litros | X23: 0.75 | Y23: 2349 | Z23: 1406 | AA23: 1 | AB23: =IF('1'!AA23=1,(('1'!Z23*'1'!$AS$6*'1'!$AT$6)/('1'!Y23*0.0036)),IF('1'!AA23=2,(('1'!Z23*'1'!$AS$7*'1'!$AT$7)/('1'!Y23*0.0036)))) -> 110.56596 | AD23: =(('1'!AC23*'1'!$Q$10*1000000))/('1'!Y23*3600) -> 0 | AE23: 3000 | AF23: =('1'!AE23/24)*0.454 -> 56.75 | AG23: 500 | AH23: =('1'!AG23/24)*0.454 -> 9.4583333 | AI23: 3000 | AJ23: =('1'!AI23/24)*0.454 -> 56.75 | AL23: =('1'!AK23/24)*0.454 -> 0 | AN23: =('1'!AM23/24)*0.454 -> 0 | AP23: =('1'!AO23/24)*0.454 -> 0
A24: HORA | B24: 1 | C24: 2 | D24: 3 | E24: 4 | F24: 5 | G24: 6 | H24: 7 | I24: 8 | J24: 9 | K24: 10 | L24: 11 | M24: 12 | N24: 13 | O24: 14 | P24: 15 | Q24: 16 | R24: 0 | S24: Kilos | X24: 0.79166667 | Y24: 2932 | Z24: 1823 | AA24: 1 | AB24: =IF('1'!AA24=1,(('1'!Z24*'1'!$AS$6*'1'!$AT$6)/('1'!Y24*0.0036)),IF('1'!AA24=2,(('1'!Z24*'1'!$AS$7*'1'!$AT$7)/('1'!Y24*0.0036)))) -> 114.85287 | AD24: =(('1'!AC24*'1'!$Q$10*1000000))/('1'!Y24*3600) -> 0 | AE24: 3000 | AF24: =('1'!AE24/24)*0.454 -> 56.75 | AG24: 500 | AH24: =('1'!AG24/24)*0.454 -> 9.4583333 | AI24: 3000 | AJ24: =('1'!AI24/24)*0.454 -> 56.75 | AL24: =('1'!AK24/24)*0.454 -> 0 | AN24: =('1'!AM24/24)*0.454 -> 0 | AP24: =('1'!AO24/24)*0.454 -> 0
A25: 0.41666667 | C25: 0.38 | D25: 1.24 | E25: 0.89 | F25: 0.46 | H25: 1.32 | I25: 1.35 | K25: 1.27 | L25: 0.42 | M25: 0.84 | N25: 0.88 | O25: 0.51 | R25: =#DIV/0! -> #DIV/0! | T25: DATA | U25: =ESCALA!$A$3 -> 44317 | X25: 0.83333333 | Y25: 2945 | Z25: 1823 | AA25: 1 | AB25: =IF('1'!AA25=1,(('1'!Z25*'1'!$AS$6*'1'!$AT$6)/('1'!Y25*0.0036)),IF('1'!AA25=2,(('1'!Z25*'1'!$AS$7*'1'!$AT$7)/('1'!Y25*0.0036)))) -> 114.34588 | AD25: =(('1'!AC25*'1'!$Q$10*1000000))/('1'!Y25*3600) -> 0 | AE25: 3000 | AF25: =('1'!AE25/24)*0.454 -> 56.75 | AG25: 500 | AH25: =('1'!AG25/24)*0.454 -> 9.4583333 | AI25: 3000 | AJ25: =('1'!AI25/24)*0.454 -> 56.75 | AL25: =('1'!AK25/24)*0.454 -> 0 | AN25: =('1'!AM25/24)*0.454 -> 0 | AP25: =('1'!AO25/24)*0.454 -> 0
A26: 0.66666667 | X26: 0.875 | Y26: 2827 | Z26: 1823 | AA26: 1 | AB26: =IF('1'!AA26=1,(('1'!Z26*'1'!$AS$6*'1'!$AT$6)/('1'!Y26*0.0036)),IF('1'!AA26=2,(('1'!Z26*'1'!$AS$7*'1'!$AT$7)/('1'!Y26*0.0036)))) -> 119.11872 | AD26: =(('1'!AC26*'1'!$Q$10*1000000))/('1'!Y26*3600) -> 0 | AE26: 3000 | AF26: =('1'!AE26/24)*0.454 -> 56.75 | AG26: 500 | AH26: =('1'!AG26/24)*0.454 -> 9.4583333 | AI26: 3000 | AJ26: =('1'!AI26/24)*0.454 -> 56.75 | AL26: =('1'!AK26/24)*0.454 -> 0 | AN26: =('1'!AM26/24)*0.454 -> 0 | AP26: =('1'!AO26/24)*0.454 -> 0
A27: Média | B27: =#DIV/0! -> #DIV/0! | C27: =#DIV/0! -> #DIV/0! | D27: =#DIV/0! -> #DIV/0! | E27: =#DIV/0! -> #DIV/0! | F27: =#DIV/0! -> #DIV/0! | G27: =#DIV/0! -> #DIV/0! | H27: =#DIV/0! -> #DIV/0! | I27: =#DIV/0! -> #DIV/0! | ... Q27: =#DIV/0! -> #DIV/0! | X27: 0.91666667 | Y27: 2850 | Z27: 1823 | AA27: 1 | AB27: =IF('1'!AA27=1,(('1'!Z27*'1'!$AS$6*'1'!$AT$6)/('1'!Y27*0.0036)),IF('1'!AA27=2,(('1'!Z27*'1'!$AS$7*'1'!$AT$7)/('1'!Y27*0.0036)))) -> 118.15741 | AD27: =(('1'!AC27*'1'!$Q$10*1000000))/('1'!Y27*3600) -> 0 | AE27: 3000 | AF27: =('1'!AE27/24)*0.454 -> 56.75 | AG27: 500 | AH27: =('1'!AG27/24)*0.454 -> 9.4583333 | AI27: 3000 | AJ27: =('1'!AI27/24)*0.454 -> 56.75 | AL27: =('1'!AK27/24)*0.454 -> 0 | AN27: =('1'!AM27/24)*0.454 -> 0 | AP27: =('1'!AO27/24)*0.454 -> 0
A28: OBSERVAÇÕES | X28: 0.95833333 | Y28: 2831 | Z28: 1823 | AA28: 1 | AB28: =IF('1'!AA28=1,(('1'!Z28*'1'!$AS$6*'1'!$AT$6)/('1'!Y28*0.0036)),IF('1'!AA28=2,(('1'!Z28*'1'!$AS$7*'1'!$AT$7)/('1'!Y28*0.0036)))) -> 118.95041 | AD28: =(('1'!AC28*'1'!$Q$10*1000000))/('1'!Y28*3600) -> 0 | AE28: 3000 | AF28: =('1'!AE28/24)*0.454 -> 56.75 | AG28: 500 | AH28: =('1'!AG28/24)*0.454 -> 9.4583333 | AI28: 3000 | AJ28: =('1'!AI28/24)*0.454 -> 56.75 | AL28: =('1'!AK28/24)*0.454 -> 0 | AN28: =('1'!AM28/24)*0.454 -> 0 | AP28: =('1'!AO28/24)*0.454 -> 0
X29: 1 | Y29: 2871 | Z29: 1823 | AA29: 1 | AB29: =IF('1'!AA29=1,(('1'!Z29*'1'!$AS$6*'1'!$AT$6)/('1'!Y29*0.0036)),IF('1'!AA29=2,(('1'!Z29*'1'!$AS$7*'1'!$AT$7)/('1'!Y29*0.0036)))) -> 117.29314 | AD29: =(('1'!AC29*'1'!$Q$10*1000000))/('1'!Y29*3600) -> 0 | AE29: 3000 | AF29: =('1'!AE29/24)*0.454 -> 56.75 | AG29: 500 | AH29: =('1'!AG29/24)*0.454 -> 9.4583333 | AI29: 3000 | AJ29: =('1'!AI29/24)*0.454 -> 56.75 | AL29: =('1'!AK29/24)*0.454 -> 0 | AN29: =('1'!AM29/24)*0.454 -> 0 | AP29: =('1'!AO29/24)*0.454 -> 0
X30: Total | Y30: =SUM('1'!Y6:Y29)*3.6 -> 234313.2 | Z30: =SUM('1'!Z6:Z29) -> 42629 | AF30: =SUM('1'!AF6:AF29) -> 1362 | AH30: =SUM('1'!AH6:AH29) -> 227 | AJ30: =SUM('1'!AJ6:AJ29) -> #REF! | AL30: =SUM('1'!AL6:AL29) -> 0 | AN30: =SUM('1'!AN6:AN29) -> 0 | AP30: =SUM('1'!AP6:AP29) -> 0
X32: S.A.L (l) - (kg) | Z32: =SUMIF('1'!AA6:AA29,"=1",'1'!Z6:Z29) -> 42629 | AA32: ='1'!Z32*'1'!AS6 -> 56696.57 | AB32: =SUMIF('1'!$AA$6:$AA$29,"=1",'1'!$AB$6:$AB$29)/COUNTIF('1'!$AA$6:$AA$29,"=1") -> 120.71904 | AC32: =SUMIF('1'!AA6:AA29,"=1",'1'!AC6:AC29) -> 0
X33: PAC 18 (l) - (kg) | Z33: =SUMIF('1'!AA6:AA29,"=2",'1'!Z6:Z29) -> 0 | AA33: ='1'!Z33*'1'!AS7 -> 0 | AB33: =SUMIF('1'!$AA$6:$AA$29,"=2",'1'!$AB$6:$AB$29)/COUNTIF('1'!$AA$6:$AA$29,"=2") -> #DIV/0! | AC33: =SUMIF('1'!AA6:AA29,"=2",'1'!AC6:AC29) -> 0
X34: Média | Y34: =AVERAGE('1'!Y6:Y29) -> 2711.9583 | Z34: =AVERAGE('1'!Z6:Z29) -> 1776.2083 | AC34: =SUM('1'!AC6:AC29)/COUNTIF('1'!AC6:AC29,"<>0") -> 0 | AD34: =SUM('1'!AD6:AD29)/COUNTIF('1'!AD6:AD29,"<>0") -> #DIV/0! | AF34: =AVERAGE('1'!AF6:AF29) -> 56.75 | AH34: =AVERAGE('1'!AH6:AH29) -> 9.4583333 | AJ34: ='1'!AJ30/24 -> #REF! | AL34: =AVERAGE('1'!AL6:AL29) -> 0 | AN34: =AVERAGE('1'!AN6:AN29) -> 0 | AP34: =AVERAGE('1'!AP6:AP29) -> 0
C35: Alcalinidade (mg/L) | F35: Ferro (mg/L) | I35: Manganês (mg/L) | L35: Alumínio (mg/L) | U35: TÉCNICO | X35: Decantadores | AA35: Filtros | AJ35: CLORAÇÃO INTERMEDIÁRIA | AO35: PÓS CLORAÇÃO
B36: HORA | C36: Bruta | D36: Dec. | E36: Trat (R-3) | F36: Bruta | G36: Filt. | H36: Trat (R-3) | I36: Bruta | J36: Filt. | K36: Trat (R-3) | L36: Trat (R-3) | X36: Lavados | Y36: 0 | AA36: Lavados | AB36: 4
B37: 0.33333333 | C37: 33.9 | D37: 4 | E37: 4 | F37: 4 | G37: 0.2 | H37: 0.2 | I37: 0.3 | J37: 0.1 | K37: 0.1 | U37: ='1'!V12 -> 0 | X37: HORAS OPERANDO | Z37: =COUNTA('1'!Z6:Z29) -> 24 | AJ37: CARRETA | AL37: CILINDROS | AO37: CARRETA | AQ37: CILINDROS
B38: 0.66666667 | AJ38: CONSUMO | AK38: =SUM('1'!AF30+'1'!AH30) -> 1589 | AL38: CONSUMO | AM38: =SUM('1'!AL30+'1'!AN30) -> 0 | AO38: CONSUMO | AP38: ='1'!AJ30 -> #REF! | AQ38: CONSUMO | AR38: ='1'!AP30 -> 0
A39: Nº amostras de água TRATADA | C39: Nº amostras de água FILTRADA | E39: Nº amostras de água tratada/filtrada FORA DO PADRÃO | J39: Nº amostras de água tratada/filtrada no PADRÃO | O39: Nº de amostras com turbidez menor ou igual a 0,5 NTU | R39: ÁGUA FILTRADA | S39: Nº de amostras com turbidez menor ou igual a 1,0 NTU | AJ39: DOSAGEM | AK39: =('1'!AK38/'1'!Y30)*1000 -> 6.7815215 | AL39: DOSAGEM | AM39: =('1'!AM38/'1'!Y30)*1000 -> 0 | AO39: DOSAGEM | AP39: =('1'!AP38/'1'!Y30)*1000 -> #REF! | AQ39: DOSAGEM | AR39: =('1'!AR38/'1'!Y30)*1000 -> 0
A40: COR | B40: TURBIDEZ | C40: TURBIDEZ | E40: COR | G40: TURBIDEZ | J40: COR | L40: TURBIDEZ | X40: ESTOQUE DE COAGULANTE | AJ40: Consumo Total | AL40: =SUM('1'!AK38,'1'!AM38) -> 1589 | AO40: Consumo Total | AQ40: =SUM('1'!AP38,'1'!AR38) -> #REF!
A41: =COUNTA('1'!E7:E18) -> 12 | B41: =COUNTA('1'!I7:I18) -> 12 | C41: =COUNTA('1'!J7:J18) -> 12 | D41: =COUNTA('1'!K7:K18) -> 12 | E41: =COUNTIF('1'!E7:E18,">15") -> 0 | G41: =COUNTIF('1'!J7:J18,">1") -> 9 | J41: ='1'!A41-'1'!E41 -> 12 | L41: ='1'!C41-'1'!G41 -> 3 | O41: =COUNTIF('1'!J7:J18,"<=0,5") -> 0 | S41: =COUNTIF('1'!J7:J18,"<=1,0") -> 3 | AJ41: Dosagem Final | AL41: =SUM(('1'!AK38+'1'!AM38)/'1'!Y30)*1000 -> 6.7815215 | AO41: Dosagem Final | AQ41: =SUM(('1'!AP38+'1'!AR38)/'1'!Y30)*1000 -> #REF!
O42: ÁGUA FILTRATADA | X42: SULFATO DE ALUMÍNIO
H43: Nº de amostras água tratada com turbidez <= 5,0 NTU | L43: Nº de amostras água tratada para aluminio | Q43: Nº de amostras com turbidez entre 0,5 e 1,0 NTU | X43: TINA 01 | Z43: TINA 02 | AB43: TINA 03 | AD43: TANQUE
...

Sheet 2
D2: CONTROLE DE ANÁLISE FÍSICO - QUÍMICAS \ ETA CASTELO BRANCO | AB2: CONTROLE DE PRODUTOS QUÍMICOS APLICADOS \ ETA CASTELO BRANCO
A4: HORA | B4: COR (Uc) | F4: TURBIDEZ (Ut) | K4: Ph | O4: CLORO RESIDUAL (mg/L) | R4: DOSAGEM DO COAGULANTE | T4: VAZÃO DA ETA | U4: TIPO DE COAGULANTE | V4: TÉCNICO | X4: Hora | Y4: Vazão ETA (l/s) | Z4: Vazão Coagulante (l/h) | AA4: Código | AB4: Dosagem (mg/l) | AC4: Vazão Polímero (l/h) | AD4: Dosagem (mg/l) | AE4: Pré 1 (Lib/dia) | AF4: Pré 1 (Kg/h) | AG4: Pré 2 (Lib/dia) | AH4: Pré 2 (Kg/h) | AI4: Pós (Lib/dia) | AJ4: Pós (Kg/h) | AK4: Pré 1 (Lib/dia) cilindros | AL4: Pré 1 (Kg/h) cilindros | AM4: Pré 2 (Lib/dia) cilindros | AN4: Pré 2 (Kg/h) cilindros | AO4: Pós (Lib/dia) cilindros | AP4: Pós (Kg/h) cilindros | AQ4: COAGULANTE | AU4: Tempo de Utilização (h)
AQ5: Codigo | AR5: Nome | AS5: d (g/ml) | AT5: C (%)
B6: Bruta | C6: DEC_1 | D6: DEC_2 | E6: TRAT | F6: Bruta | G6: DEC_1 | H6: DEC_2 | I6: TRAT | J6: FILT | K6: Bruta | L6: DEC_1 | M6: DEC_2 | N6: TRAT | O6: TRAT | P6: DEC_1 | Q6: DEC_2 | R6: L/h | S6: mg/l | T6: L/s | X6: 0.041666667 | Y6: 2877 | Z6: 1823 | AA6: 1 | AB6: =IF('2'!AA6=1,(('2'!Z6*'2'!$AS$6*'2'!$AT$6)/('2'!Y6*0.0036)),IF('2'!AA6=2,(('2'!Z6*'2'!$AS$7*'2'!$AT$7)/('2'!Y6*0.0036)))) -> 117.04853 | AD6: =(('2'!AC6*'2'!$Q$10*1000000))/('2'!Y6*3600) -> 0 | AE6: 3000 | AF6: =('2'!AE6/24)*0.454 -> 56.75 | AG6: 500 | AH6: =('2'!AG12/24)*0.454 -> 9.4583333 | AI6: 3000 | AJ6: =('2'!AI6/24)*0.454 -> 56.75 | AL6: =('2'!AK6/24)*0.454 -> 0 | AN6: =('2'!AM6/24)*0.454 -> 0 | AP6: =('2'!AO6/24)*0.454 -> 0 | AQ6: 1 | AR6: S.A.L | AS6: 1.33 | AT6: 0.5 | AU6: 0
A7: 0 | B7: 800 | C7: 7.5 | D7: 7.5 | E7: 2.5 | F7: 211 | G7: 2.7 | H7: 6 | I7: 1.1 | J7: 1.3 | K7: 6.8 | L7: 4.8 | M7: 4.8 | N7: 5.7 | O7: 3.8 | P7: 1.7 | Q7: 3 | R7: ='1'!$Z$29 -> 1823 | S7: ='1'!$AB$29 -> 117.29314 | T7: ='1'!$Y$29 -> 2871 | U7: =IF('2'!AA6=1,'2'!AR6,'2'!AR7) -> S.A.L | V7: =ESCALA!$B$3 -> 0 | X7: 2653.0833 | Y7: 2846 | Z7: 1823 | AA7: 1 | AB7: =IF('2'!AA7=1,(('2'!Z7*'2'!$AS$6*'2'!$AT$6)/('2'!Y7*0.0036)),IF('2'!AA7=2,(('2'!Z7*'2'!$AS$7*'2'!$AT$7)/('2'!Y7*0.0036)))) -> 118.32348 | AD7: =(('2'!AC7*'2'!$Q$10*1000000))/('2'!Y7*3600) -> 0 | AE7: 3000 | AF7: =('2'!AE7/24)*0.454 -> 56.75 | AG7: 500 | AH7: =('2'!AG7/24)*0.454 -> 9.4583333 | AI7: 3000 | AJ7: =('2'!AI7/24)*0.454 -> 56.75 | AL7: =('2'!AK7/24)*0.454 -> 0 | AN7: =('2'!AM7/24)*0.454 -> 0 | AP7: =('2'!AO7/24)*0.454 -> 0 | AQ7: 2 | AR7: PAC 18 | AS7: 1.262 | AT7: 1 | AU7: 24
A8: 0.083333333 | B8: 800 | C8: 5 | D8: 7.5 | E8: 2.5 | F8: 210 | G8: 1.8 | H8: 5.1 | I8: 1.1 | J8: 1.3 | K8: 6.8 | L8: 4.8 | M8: 4.8 | N8: 5.7 | O8: 3.8 | P8: 1.5 | Q8: 3.3 | R8: ='2'!Z7 -> 1823 | S8: ='2'!AB7 -> 118.32348 | T8: ='2'!Y7 -> 2846 | U8: =IF('2'!AA7=1,'2'!AR6,'2'!AR7) -> S.A.L | X8: 2645.125 | Y8: 2805 | Z8: 1823 | AA8: 1 | AB8: =IF('2'!AA8=1,(('2'!Z8*'2'!$AS$6*'2'!$AT$6)/('2'!Y8*0.0036)),IF('2'!AA8=2,(('2'!Z8*'2'!$AS$7*'2'!$AT$7)/('2'!Y8*0.0036)))) -> 120.05298 | AD8: =(('2'!AC8*'2'!$Q$10*1000000))/('2'!Y8*3600) -> 0 | AE8: 3000 | AF8: =('2'!AE8/24)*0.454 -> 56.75 | AG8: 500 | AH8: =('2'!AG8/24)*0.454 -> 9.4583333 | AI8: 3000 | AJ8: =('2'!AI8/24)*0.454 -> 56.75 | AL8: =('2'!AK8/24)*0.454 -> 0 | AN8: =('2'!AM8/24)*0.454 -> 0 | AP8: =('2'!AO8/24)*0.454 -> 0 | AQ8: Polímero Catiônico
A9: 0.16666667 | B9: 800 | C9: 5 | D9: 7.5 | E9: 2.5 | F9: 208 | G9: 1.5 | H9: 4.3 | I9: 1.1 | J9: 1.2 | K9: 6.8 | L9: 4.8 | M9: 4.8 | N9: 5.7 | O9: 3.8 | P9: 1.5 | Q9: 3.5 | R9: ='2'!Z9 -> 1823 | S9: ='2'!AB9 -> 119.2875 | T9: ='2'!Y9 -> 2823 | U9: =IF('2'!AA9=1,'2'!AR6,'2'!AR7) -> S.A.L | X9: 0.16666667 | Y9: 2823 | Z9: 1823 | AA9: 1 | AB9: =IF('2'!AA9=1,(('2'!Z9*'2'!$AS$6*'2'!$AT$6)/('2'!Y9*0.0036)),IF('2'!AA9=2,(('2'!Z9*'2'!$AS$7*'2'!$AT$7)/('2'!Y9*0.0036)))) -> 119.2875 | AD9: =(('2'!AC9*'2'!$Q$10*1000000))/('2'!Y9*3600) -> 0 | AE9: 3000 | AF9: =('2'!AE9/24)*0.454 -> 56.75 | AG9: 500 | AH9: =('2'!AG9/24)*0.454 -> 9.4583333 | AI9: 3000 | AJ9: =('2'!AI9/24)*0.454 -> 56.75 | AL9: =('2'!AK9/24)*0.454 -> 0 | AN9: =('2'!AM9/24)*0.454 -> 0 | AP9: =('2'!AO9/24)*0.454 -> 0 | AQ9: Nome | AT9: C (%)
A10: 0.25 | B10: 800 | C10: 5 | D10: 7.5 | E10: 2.5 | F10: 207 | G10: 1.4 | H10: 3.9 | I10: 1.1 | J10: 1.2 | K10: 6.8 | L10: 4.8 | M10: 4.8 | N10: 5.7 | O10: 3.8 | P10: 1.4 | Q10: 3.8 | R10: ='2'!Z11 -> 1823 | S10: ='2'!AB11 -> 117.57982 | T10: ='2'!Y11 -> 2864 | U10: =IF('2'!AA11=1,'2'!AR6,'2'!AR7) -> S.A.L | X10: 0.20833333 | Y10: 2851 | Z10: 1823 | AA10: 1 | AB10: =IF('2'!AA10=1,(('2'!Z10*'2'!$AS$6*'2'!$AT$6)/('2'!Y10*0.0036)),IF('2'!AA10=2,(('2'!Z10*'2'!$AS$7*'2'!$AT$7)/('2'!Y10*0.0036)))) -> 118.11596 | AD10: =(('2'!AC10*'2'!$Q$10*1000000))/('2'!Y10*3600) -> 0 | AE10: 3000 | AF10: =('2'!AE10/24)*0.454 -> 56.75 | AG10: 500 | AH10: =('2'!AG10/24)*0.454 -> 9.4583333 | AI10: 3000 | AJ10: =('2'!AI10/24)*0.454 -> 56.75 | AL10: =('2'!AK10/24)*0.454 -> 0 | AN10: =('2'!AM10/24)*0.454 -> 0 | AP10: =('2'!AO10/24)*0.454 -> 0 | AQ10: Aguapol 200 | AT10: 0.002
A11: 0.33333333 | B11: 800 | C11: 12.5 | D11: 7.5 | E11: 2.5 | F11: 196 | G11: 3.8 | H11: 3 | I11: 1.1 | J11: 1.5 | K11: 6.8 | L11: 4.8 | M11: 4.58 | N11: 5.3 | O11: 3.8 | P11: 3.8 | Q11: 3.2 | R11: ='2'!Z13 -> 1377 | S11: ='2'!AB13 -> 90.199468 | T11: ='2'!Y13 -> 2820 | U11: =IF('2'!AA13=1,'2'!AR6,'2'!AR7) -> S.A.L | X11: 0.25 | Y11: 2864 | Z11: 1823 | AA11: 1 | AB11: =IF('2'!AA11=1,(('2'!Z11*'2'!$AS$6*'2'!$AT$6)/('2'!Y11*0.0036)),IF('2'!AA11=2,(('2'!Z11*'2'!$AS$7*'2'!$AT$7)/('2'!Y11*0.0036)))) -> 117.57982 | AD11: =(('2'!AC11*'2'!$Q$10*1000000))/('2'!Y11*3600) -> 0 | AE11: 3000 | AF11: =('2'!AE11/24)*0.454 -> 56.75 | AG11: 500 | AH11: =('2'!AG11/24)*0.454 -> 9.4583333 | AI11: 3000 | AJ11: =('2'!AI11/24)*0.454 -> 56.75 | AL11: =('2'!AK11/24)*0.454 -> 0 | AN11: =('2'!AM11/24)*0.454 -> 0 | AP11: =('2'!AO11/24)*0.454 -> 0
A12: 0.41666667 | B12: 800 | C12: 12.5 | D12: 7.5 | E12: 2.5 | F12: 195 | G12: 3.9 | H12: 2.8 | I12: 1 | J12: 1.5 | K12: 6.8 | L12: 4.8 | M12: 4.58 | N12: 5.3 | O12: 3.2 | P12: 3.2 | Q12: 0 | R12: ='2'!Z15 -> 1377 | S12: ='2'!AB15 -> 88.782723 | T12: ='2'!Y15 -> 2865 | U12: =IF('2'!AA15=1,'2'!AR6,'2'!AR7) -> S.A.L | V12: =ESCALA!$B$4 -> 0 | X12: 0.29166667 | Y12: 2797 | Z12: 1823 | AA12: 1 | AB12: =IF('2'!AA12=1,(('2'!Z12*'2'!$AS$6*'2'!$AT$6)/('2'!Y12*0.0036)),IF('2'!AA12=2,(('2'!Z12*'2'!$AS$7*'2'!$AT$7)/('2'!Y12*0.0036)))) -> 120.39636 | AD12: =(('2'!AC12*'2'!$Q$10*1000000))/('2'!Y12*3600) -> 0 | AE12: 3000 | AF12: =('2'!AE12/24)*0.454 -> 56.75 | AG12: 500 | AH12: =('2'!#REF!/24)*0.454 -> #REF! | AI12: 3000 | AJ12: =('2'!AI12/24)*0.454 -> 56.75 | AL12: =('2'!AK12/24)*0.454 -> 0 | AN12: =('2'!AM12/24)*0.454 -> 0 | AP12: =('2'!AO12/24)*0.454 -> 0
A13: 0.5 | B13: 800 | C13: 10 | D13: 7.5 | E13: 2.5 | F13: 196 | G13: 3.9 | H13: 2.7 | I13: 0.98 | J13: 1.4 | K13: 6.8 | L13: 4.8 | M13: 4.58 | N13: 5.3 | O13: 3 | P13: 3 | Q13: 0 | R13: ='2'!Z17 -> 1377 | S13: ='2'!AB17 -> 93.481257 | T13: ='2'!Y17 -> 2721 | U13: =IF('2'!AA17=1,'2'!AR6,'2'!AR7) -> S.A.L | X13: 0.33333333 | Y13: 2820 | Z13: 1377 | AA13: 1 | AB13: =IF('2'!AA13=1,(('2'!Z13*'2'!$AS$6*'2'!$AT$6)/('2'!Y13*0.0036)),IF('2'!AA13=2,(('2'!Z13*'2'!$AS$7*'2'!$AT$7)/('2'!Y13*0.0036)))) -> 90.199468 | AD13: =(('2'!AC13*'2'!$Q$10*1000000))/('2'!Y13*3600) -> 0 | AE13: 3000 | AF13: =('2'!AE13/24)*0.454 -> 56.75 | AG13: 500 | AH13: =('2'!AG13/24)*0.454 -> 9.4583333 | AI13: 3000 | AJ13: =('2'!AI13/24)*0.454 -> 56.75 | AL13: =('2'!AK13/24)*0.454 -> 0 | AN13: =('2'!AM13/24)*0.454 -> 0 | AP13: =('2'!AO13/24)*0.454 -> 0
A14: 0.58333333 | B14: 800 | C14: 10 | D14: 7.5 | E14: 2.5 | F14: 193 | G14: 3.8 | H14: 2.1 | I14: 0.97 | J14: 1.3 | K14: 6.8 | L14: 4.8 | M14: 4.58 | N14: 5.3 | O14: 2.7 | P14: 2.7 | Q14: 0 | R14: ='2'!Z19 -> 1377 | S14: ='2'!AB19 -> 92.093592 | T14: ='2'!Y19 -> 2762 | U14: =IF('2'!AA19=1,'2'!AR6,'2'!AR7) -> S.A.L | X14: 0.375 | Y14: 2847 | Z14: 1377 | AA14: 1 | AB14: =IF('2'!AA14=1,(('2'!Z14*'2'!$AS$6*'2'!$AT$6)/('2'!Y14*0.0036)),IF('2'!AA14=2,(('2'!Z14*'2'!$AS$7*'2'!$AT$7)/('2'!Y14*0.0036)))) -> 89.344046 | AD14: =(('2'!AC14*'2'!$Q$10*1000000))/('2'!Y14*3600) -> 0 | AE14: 3000 | AF14: =('2'!AE14/24)*0.454 -> 56.75 | AG14: 0 | AH14: =('2'!AG14/24)*0.454 -> 0 | AI14: 3000 | AJ14: =('2'!AI14/24)*0.454 -> 56.75 | AL14: =('2'!AK14/24)*0.454 -> 0 | AN14: =('2'!AM14/24)*0.454 -> 0 | AP14: =('2'!AO14/24)*0.454 -> 0
A15: 0.66666667 | B15: 750 | C15: 10 | D15: 7.5 | E15: 2.5 | F15: 184 | G15: 3.6 | H15: 2.3 | I15: 0.97 | J15: 1.3 | K15: 6.8 | L15: 4.8 | M15: 4.58 | N15: 5.3 | O15: 2.7 | P15: 2.7 | Q15: 0 | R15: ='2'!Z21 -> 1377 | S15: ='2'!AB21 -> 87.53011 | T15: ='2'!Y21 -> 2906 | U15: =IF('2'!AA21=1,'2'!AR6,'2'!AR7) -> S.A.L | X15: 0.41666667 | Y15: 2865 | Z15: 1377 | AA15: 1 | AB15: =IF('2'!AA15=1,(('2'!Z15*'2'!$AS$6*'2'!$AT$6)/('2'!Y15*0.0036)),IF('2'!AA15=2,(('2'!Z15*'2'!$AS$7*'2'!$AT$7)/('2'!Y15*0.0036)))) -> 88.782723 | AD15: =(('2'!AC15*'2'!$Q$10*1000000))/('2'!Y15*3600) -> 0 | AE15: 3000 | AF15: =('2'!AE15/24)*0.454 -> 56.75 | AG15: 0 | AH15: =('2'!AG15/24)*0.454 -> 0 | AI15: 3000 | AJ15: =('2'!AI15/24)*0.454 -> 56.75 | AL15: =('2'!AK15/24)*0.454 -> 0 | AN15: =('2'!AM15/24)*0.454 -> 0 | AP15: =('2'!AO15/24)*0.454 -> 0
A16: 0.75 | B16: 750 | C16: 10 | D16: 7.5 | E16: 2.5 | F16: 177 | G16: 3.4 | H16: 2.5 | I16: 0.97 | J16: 1.2 | K16: 6.8 | L16: 4.8 | M16: 4.58 | N16: 5.3 | O16: 2.7 | P16: 2.7 | Q16: 0.5 | R16: ='2'!Z23 -> 1832 | S16: ='2'!AB23 -> 114.21232 | T16: ='2'!Y23 -> 2963 | U16: =IF('2'!AA23=1,'2'!AR6,'2'!AR7) -> S.A.L | X16: 0.45833333 | Y16: 2849 | Z16: 1377 | AA16: 1 | AB16: =IF('2'!AA16=1,(('2'!Z16*'2'!$AS$6*'2'!$AT$6)/('2'!Y16*0.0036)),IF('2'!AA16=2,(('2'!Z16*'2'!$AS$7*'2'!$AT$7)/('2'!Y16*0.0036)))) -> 89.281327 | AD16: =(('2'!AC16*'2'!$Q$10*1000000))/('2'!Y16*3600) -> 0 | AE16: 3000 | AF16: =('2'!AE16/24)*0.454 -> 56.75 | AG16: 0 | AH16: =('2'!AG16/24)*0.454 -> 0 | AI16: 3000 | AJ16: =('2'!AI16/24)*0.454 -> 56.75 | AL16: =('2'!AK16/24)*0.454 -> 0 | AN16: =('2'!AM16/24)*0.454 -> 0 | AP16: =('2'!AO16/24)*0.454 -> 0
A17: 0.83333333 | B17: 700 | C17: 10 | D17: 7.5 | E17: 2.5 | F17: 171 | G17: 3.2 | H17: 2.6 | I17: 0.97 | J17: 1.2 | K17: 6.8 | L17: 4.8 | M17: 4.58 | N17: 5.3 | O17: 2.8 | P17: 2.8 | Q17: 0.8 | R17: ='2'!Z25 -> 1832 | S17: ='2'!AB25 -> 117.62639 | T17: ='2'!Y25 -> 2877 | U17: =IF('2'!AA25=1,'2'!AR6,'2'!AR7) -> S.A.L | V17: =ESCALA!$C$4 -> 0 | X17: 0.5 | Y17: 2721 | Z17: 1377 | AA17: 1 | AB17: =IF('2'!AA17=1,(('2'!Z17*'2'!$AS$6*'2'!$AT$6)/('2'!Y17*0.0036)),IF('2'!AA17=2,(('2'!Z17*'2'!$AS$7*'2'!$AT$7)/('2'!Y17*0.0036)))) -> 93.481257 | AD17: =(('2'!AC17*'2'!$Q$10*1000000))/('2'!Y17*3600) -> 0 | AE17: 3000 | AF17: =('2'!AE17/24)*0.454 -> 56.75 | AG17: 0 | AH17: =('2'!AG17/24)*0.454 -> 0 | AI17: 3000 | AJ17: =('2'!AI17/24)*0.454 -> 56.75 | AL17: =('2'!AK17/24)*0.454 -> 0 | AN17: =('2'!AM17/24)*0.454 -> 0 | AP17: =('2'!AO17/24)*0.454 -> 0
A18: 0.91666667 | B18: 650 | C18: 10 | D18: 7.5 | E18: 2.5 | F18: 166 | G18: 3 | H18: 2.7 | I18: 0.97 | J18: 1.2 | K18: 6.8 | L18: 4.8 | M18: 4.58 | N18: 5.3 | O18: 3.5 | P18: 3.5 | Q18: 1 | R18: ='2'!Z27 -> 1832 | S18: ='2'!AB27 -> 117.01629 | T18: ='2'!Y27 -> 2892 | U18: =IF('2'!AA27=1,'2'!AR6,'2'!AR7) -> S.A.L | X18: 0.54166667 | Y18: 2841 | Z18: 1377 | AA18: 1 | AB18: =IF('2'!AA18=1,(('2'!Z18*'2'!$AS$6*'2'!$AT$6)/('2'!Y18*0.0036)),IF('2'!AA18=2,(('2'!Z18*'2'!$AS$7*'2'!$AT$7)/('2'!Y18*0.0036)))) -> 89.532735 | AD18: =(('2'!AC18*'2'!$Q$10*1000000))/('2'!Y18*3600) -> 0 | AE18: 3000 | AF18: =('2'!AE18/24)*0.454 -> 56.75 | AG18: 0 | AH18: =('2'!AG18/24)*0.454 -> 0 | AI18: 3000 | AJ18: =('2'!AI18/24)*0.454 -> 56.75 | AL18: =('2'!AK18/24)*0.454 -> 0 | AN18: =('2'!AM18/24)*0.454 -> 0 | AP18: =('2'!AO18/24)*0.454 -> 0
A19: Média | B19: {=IF('2'!B7:B18>0.01,AVERAGE('2'!B7:B18),"")} -> 770.83333 | C19: {=IF('2'!C7:C18>0.01,AVERAGE('2'!C7:C18),"")} -> 8.9583333 | D19: {=IF('2'!D7:D18>0.01,AVERAGE('2'!D7:D18),"")} -> 7.5 | E19: {=IF('2'!E7:E18>0.01,AVERAGE('2'!E7:E18),"")} -> 2.5 | F19: {=IF('2'!F7:F18>0.01,AVERAGE('2'!F7:F18),"")} -> 192.83333 | G19: {=IF('2'!G7:G18>0.01,AVERAGE('2'!G7:G18),"")} -> 3 | H19: {=IF('2'!H7:H18>0.01,AVERAGE('2'!H7:H18),"")} -> 3.3333333 | I19: {=IF('2'!I7:I18>0.01,AVERAGE('2'!I7:I18),"")} -> 1.0275 | ... S19: {=IF('2'!S7:S18>0.01,AVERAGE('2'!S7:S18),"")} -> 106.11884 | X19: 0.58333333 | Y19: 2762 | Z19: 1377 | AA19: 1 | AB19: =IF('2'!AA19=1,(('2'!Z19*'2'!$AS$6*'2'!$AT$6)/('2'!Y19*0.0036)),IF('2'!AA19=2,(('2'!Z19*'2'!$AS$7*'2'!$AT$7)/('2'!Y19*0.0036)))) -> 92.093592 | AD19: =(('2'!AC19*'2'!$Q$10*1000000))/('2'!Y19*3600) -> 0 | AE19: 3000 | AF19: =('2'!AE19/24)*0.454 -> 56.75 | AG19: 0 | AH19: =('2'!AG19/24)*0.454 -> 0 | AI19: 3000 | AJ19: =('2'!AI19/24)*0.454 -> 56.75 | AL19: =('2'!AK19/24)*0.454 -> 0 | AN19: =('2'!AM19/24)*0.454 -> 0 | AP19: =('2'!AO19/24)*0.454 -> 0
A20: Máximo | B20: =MAX('2'!B7:B18) -> 800 | C20: =MAX('2'!C7:C18) -> 12.5 | D20: =MAX('2'!D7:D18) -> 7.5 | E20: =MAX('2'!E7:E18) -> 2.5 | F20: =MAX('2'!F7:F18) -> 211 | G20: =MAX('2'!G7:G18) -> 3.9 | H20: =MAX('2'!H7:H18) -> 6 | I20: =MAX('2'!I7:I18) -> 1.1 | ... S20: =MAX('2'!S7:S18) -> 119.2875 | X20: 0.625 | Y20: 2464 | Z20: 1377 | AA20: 1 | AB20: =IF('2'!AA20=1,(('2'!Z20*'2'!$AS$6*'2'!$AT$6)/('2'!Y20*0.0036)),IF('2'!AA20=2,(('2'!Z20*'2'!$AS$7*'2'!$AT$7)/('2'!Y20*0.0036)))) -> 103.23153 | AD20: =(('2'!AC20*'2'!$Q$10*1000000))/('2'!Y20*3600) -> 0 | AE20: 3000 | AF20: =('2'!AE20/24)*0.454 -> 56.75 | AG20: 0 | AH20: =('2'!AG20/24)*0.454 -> 0 | AI20: 3000 | AJ20: =('2'!AI20/24)*0.454 -> 56.75 | AL20: =('2'!AK20/24)*0.454 -> 0 | AN20: =('2'!AM20/24)*0.454 -> 0 | AP20: =('2'!AO20/24)*0.454 -> 0
A21: Mínimo | B21: =MIN('2'!B7:B18) -> 650 | C21: =MIN('2'!C7:C18) -> 5 | D21: =MIN('2'!D7:D18) -> 7.5 | E21: =MIN('2'!E7:E18) -> 2.5 | F21: =MIN('2'!F7:F18) -> 166 | G21: =MIN('2'!G7:G18) -> 1.4 | H21: =MIN('2'!H7:H18) -> 2.1 | I21: =MIN('2'!I7:I18) -> 0.97 | ... S21: =MIN('2'!S7:S18) -> 87.53011 | X21: 0.66666667 | Y21: 2906 | Z21: 1377 | AA21: 1 | AB21: =IF('2'!AA21=1,(('2'!Z21*'2'!$AS$6*'2'!$AT$6)/('2'!Y21*0.0036)),IF('2'!AA21=2,(('2'!Z21*'2'!$AS$7*'2'!$AT$7)/('2'!Y21*0.0036)))) -> 87.53011 | AD21: =(('2'!AC21*'2'!$Q$10*1000000))/('2'!Y21*3600) -> 0 | AE21: 3000 | AF21: =('2'!AE21/24)*0.454 -> 56.75 | AG21: 0 | AH21: =('2'!AG21/24)*0.454 -> 0 | AI21: 3000 | AJ21: =('2'!AI21/24)*0.454 -> 56.75 | AL21: =('2'!AK21/24)*0.454 -> 0 | AN21: =('2'!AM21/24)*0.454 -> 0 | AP21: =('2'!AO21/24)*0.454 -> 0
R22: Total | X22: 0.70833333 | Y22: 2940 | Z22: 1377 | AA22: 1 | AB22: =IF('2'!AA22=1,(('2'!Z22*'2'!$AS$6*'2'!$AT$6)/('2'!Y22*0.0036)),IF('2'!AA22=2,(('2'!Z22*'2'!$AS$7*'2'!$AT$7)/('2'!Y22*0.0036)))) -> 86.517857 | AD22: =(('2'!AC22*'2'!$Q$10*1000000))/('2'!Y22*3600) -> 0 | AE22: 3000 | AF22: =('2'!AE22/24)*0.454 -> 56.75 | AG22: 500 | AH22: =('2'!AG22/24)*0.454 -> 9.4583333 | AI22: 3000 | AJ22: =('2'!AI22/24)*0.454 -> 56.75 | AL22: =('2'!AK22/24)*0.454 -> 0 | AN22: =('2'!AM22/24)*0.454 -> 0 | AP22: =('2'!AO22/24)*0.454 -> 0
A23: TURBIDEZ DOS FILTROS DA 1ª E 2ª ETAPAS | R23: 440 | S23: Litros | X23: 0.75 | Y23: 2963 | Z23: 1832 | AA23: 1 | AB23: =IF('2'!AA23=1,(('2'!Z23*'2'!$AS$6*'2'!$AT$6)/('2'!Y23*0.0036)),IF('2'!AA23=2,(('2'!Z23*'2'!$AS$7*'2'!$AT$7)/('2'!Y23*0.0036)))) -> 114.21232 | AD23: =(('2'!AC23*'2'!$Q$10*1000000))/('2'!Y23*3600) -> 0 | AE23: 3000 | AF23: =('2'!AE23/24)*0.454 -> 56.75 | AG23: 500 | AH23: =('2'!AG23/24)*0.454 -> 9.4583333 | AI23: 3000 | AJ23: =('2'!AI23/24)*0.454 -> 56.75 | AL23: =('2'!AK23/24)*0.454 -> 0 | AN23: =('2'!AM23/24)*0.454 -> 0 | AP23: =('2'!AO23/24)*0.454 -> 0
A24: HORA | B24: 1 | C24: 2 | D24: 3 | E24: 4 | F24: 5 | G24: 6 | H24: 7 | I24: 8 | J24: 9 | K24: 10 | L24: 11 | M24: 12 | N24: 13 | O24: 14 | P24: 15 | Q24: 16 | R24: 0 | S24: Kilos | X24: 0.79166667 | Y24: 2907 | Z24: 1832 | AA24: 1 | AB24: =IF('2'!AA24=1,(('2'!Z24*'2'!$AS$6*'2'!$AT$6)/('2'!Y24*0.0036)),IF('2'!AA24=2,(('2'!Z24*'2'!$AS$7*'2'!$AT$7)/('2'!Y24*0.0036)))) -> 116.41249 | AD24: =(('2'!AC24*'2'!$Q$10*1000000))/('2'!Y24*3600) -> 0 | AE24: 3000 | AF24: =('2'!AE24/24)*0.454 -> 56.75 | AG24: 500 | AH24: =('2'!AG24/24)*0.454 -> 9.4583333 | AI24: 3000 | AJ24: =('2'!AI24/24)*0.454 -> 56.75 | AL24: =('2'!AK24/24)*0.454 -> 0 | AN24: =('2'!AM24/24)*0.454 -> 0 | AP24: =('2'!AO24/24)*0.454 -> 0
A25: 0.41666667 | R25: =#DIV/0! -> #DIV/0! | T25: DATA | U25: =ESCALA!$A$4 -> 44318 | X25: 0.83333333 | Y25: 2877 | Z25: 1832 | AA25: 1 | AB25: =IF('2'!AA25=1,(('2'!Z25*'2'!$AS$6*'2'!$AT$6)/('2'!Y25*0.0036)),IF('2'!AA25=2,(('2'!Z25*'2'!$AS$7*'2'!$AT$7)/('2'!Y25*0.0036)))) -> 117.62639 | AD25: =(('2'!AC25*'2'!$Q$10*1000000))/('2'!Y25*3600) -> 0 | AE25: 3000 | AF25: =('2'!AE25/24)*0.454 -> 56.75 | AG25: 500 | AH25: =('2'!AG25/24)*0.454 -> 9.4583333 | AI25: 3000 | AJ25: =('2'!AI25/24)*0.454 -> 56.75 | AL25: =('2'!AK25/24)*0.454 -> 0 | AN25: =('2'!AM25/24)*0.454 -> 0 | AP25: =('2'!AO25/24)*0.454 -> 0
A26: 0.66666667 | R26: =#DIV/0! -> #DIV/0! | X26: 0.875 | Y26: 2915 | Z26: 1832 | AA26: 1 | AB26: =IF('2'!AA26=1,(('2'!Z26*'2'!$AS$6*'2'!$AT$6)/('2'!Y26*0.0036)),IF('2'!AA26=2,(('2'!Z26*'2'!$AS$7*'2'!$AT$7)/('2'!Y26*0.0036)))) -> 116.09301 | AD26: =(('2'!AC26*'2'!$Q$10*1000000))/('2'!Y26*3600) -> 0 | AE26: 3000 | AF26: =('2'!AE26/24)*0.454 -> 56.75 | AG26: 500 | AH26: =('2'!AG26/24)*0.454 -> 9.4583333 | AI26: 3000 | AJ26: =('2'!AI26/24)*0.454 -> 56.75 | AL26: =('2'!AK26/24)*0.454 -> 0 | AN26: =('2'!AM26/24)*0.454 -> 0 | AP26: =('2'!AO26/24)*0.454 -> 0
A27: Média | B27: =#DIV/0! -> #DIV/0! | C27: =#DIV/0! -> #DIV/0! | D27: =#DIV/0! -> #DIV/0! | E27: =#DIV/0! -> #DIV/0! | F27: =#DIV/0! -> #DIV/0! | G27: =#DIV/0! -> #DIV/0! | H27: =#DIV/0! -> #DIV/0! | I27: =#DIV/0! -> #DIV/0! | ... Q27: =#DIV/0! -> #DIV/0! | X27: 0.91666667 | Y27: 2892 | Z27: 1832 | AA27: 1 | AB27: =IF('2'!AA27=1,(('2'!Z27*'2'!$AS$6*'2'!$AT$6)/('2'!Y27*0.0036)),IF('2'!AA27=2,(('2'!Z27*'2'!$AS$7*'2'!$AT$7)/('2'!Y27*0.0036)))) -> 117.01629 | AD27: =(('2'!AC27*'2'!$Q$10*1000000))/('2'!Y27*3600) -> 0 | AE27: 3000 | AF27: =('2'!AE27/24)*0.454 -> 56.75 | AG27: 500 | AH27: =('2'!AG27/24)*0.454 -> 9.4583333 | AI27: 3000 | AJ27: =('2'!AI27/24)*0.454 -> 56.75 | AL27: =('2'!AK27/24)*0.454 -> 0 | AN27: =('2'!AM27/24)*0.454 -> 0 | AP27: =('2'!AO27/24)*0.454 -> 0
A28: OBSERVAÇÕES | X28: 0.95833333 | Y28: 2866 | Z28: 1932 | AA28: 1 | AB28: =IF('2'!AA28=1,(('2'!Z28*'2'!$AS$6*'2'!$AT$6)/('2'!Y28*0.0036)),IF('2'!AA28=2,(('2'!Z28*'2'!$AS$7*'2'!$AT$7)/('2'!Y28*0.0036)))) -> 124.52314 | AD28: =(('2'!AC28*'2'!$Q$10*1000000))/('2'!Y28*3600) -> 0 | AE28: 3000 | AF28: =('2'!AE28/24)*0.454 -> 56.75 | AG28: 500 | AH28: =('2'!AG28/24)*0.454 -> 9.4583333 | AI28: 3000 | AJ28: =('2'!AI28/24)*0.454 -> 56.75 | AL28: =('2'!AK28/24)*0.454 -> 0 | AN28: =('2'!AM28/24)*0.454 -> 0 | AP28: =('2'!AO28/24)*0.454 -> 0
X29: 1 | Y29: 2851 | Z29: 1932 | AA29: 1 | AB29: =IF('2'!AA29=1,(('2'!Z29*'2'!$AS$6*'2'!$AT$6)/('2'!Y29*0.0036)),IF('2'!AA29=2,(('2'!Z29*'2'!$AS$7*'2'!$AT$7)/('2'!Y29*0.0036)))) -> 125.1783 | AD29: =(('2'!AC29*'2'!$Q$10*1000000))/('2'!Y29*3600) -> 0 | AE29: 3000 | AF29: =('2'!AE29/24)*0.454 -> 56.75 | AG29: 500 | AH29: =('2'!AG29/24)*0.454 -> 9.4583333 | AI29: 3000 | AJ29: =('2'!AI29/24)*0.454 -> 56.75 | AL29: =('2'!AK29/24)*0.454 -> 0 | AN29: =('2'!AM29/24)*0.454 -> 0 | AP29: =('2'!AO29/24)*0.454 -> 0
X30: Total | Y30: =SUM('2'!Y6:Y29)*3.6 -> 245336.4 | Z30: =SUM('2'!Z6:Z29) -> 39555 | AF30: =SUM('2'!AF6:AF29) -> 1362 | AH30: =SUM('2'!AH6:AH29) -> #REF! | AJ30: =SUM('2'!AJ6:AJ29) -> 1362 | AL30: =SUM('2'!AL6:AL29) -> 0 | AN30: =SUM('2'!AN6:AN29) -> 0 | AP30: =SUM('2'!AP6:AP29) -> 0
X32: S.A.L (l) - (kg) | Z32: =SUMIF('2'!AA6:AA29,"=1",'2'!Z6:Z29) -> 39555 | AA32: ='2'!Z32*'2'!AS6 -> 52608.15 | AB32: =SUMIF('2'!$AA$6:$AA$29,"=1",'2'!$AB$6:$AB$29)/COUNTIF('2'!$AA$6:$AA$29,"=1") -> 107.16088 | AC32: =SUMIF('2'!AA6:AA29,"=1",'2'!AC6:AC29) -> 0
X33: PAC 18 (l) - (kg) | Z33: =SUMIF('2'!AA6:AA29,"=2",'2'!Z6:Z29) -> 0 | AA33: ='2'!Z33*'2'!AS7 -> 0 | AB33: =SUMIF('2'!$AA$6:$AA$29,"=2",'2'!$AB$6:$AB$29)/COUNTIF('2'!$AA$6:$AA$29,"=2") -> #DIV/0! | AC33: =SUMIF('2'!AA6:AA29,"=2",'2'!AC6:AC29) -> 0
X34: Média | Y34: =AVERAGE('2'!Y6:Y29) -> 2839.5417 | Z34: =AVERAGE('2'!Z6:Z29) -> 1648.125 | AC34: =SUM('2'!AC6:AC29)/COUNTIF('2'!AC6:AC29,"<>0") -> 0 | AD34: =SUM('2'!AD6:AD29)/COUNTIF('2'!AD6:AD29,"<>0") -> #DIV/0! | AF34: =AVERAGE('2'!AF6:AF29) -> 56.75 | AH34: =AVERAGE('2'!AH6:AH29) -> #REF! | AJ34: ='2'!AJ30/24 -> 56.75 | AL34: =AVERAGE('2'!AL6:AL29) -> 0 | AN34: =AVERAGE('2'!AN6:AN29) -> 0 | AP34: =AVERAGE('2'!AP6:AP29) -> 0
C35: Alcalinidade (mg/L) | F35: Ferro (mg/L) | I35: Manganês (mg/L) | L35: Alumínio (mg/L) | U35: TÉCNICO | X35: Decantadores | AA35: Filtros | AJ35: CLORAÇÃO INTERMEDIÁRIA | AO35: PÓS CLORAÇÃO
B36: HORA | C36: Bruta | D36: Dec. | E36: Trat (R-3) | F36: Bruta | G36: Filt. | H36: Trat (R-3) | I36: Bruta | J36: Filt. | K36: Trat (R-3) | L36: Trat (R-3) | X36: Lavados | AA36: Lavados
B37: 0.33333333 | C37: 37.8 | D37: 6 | E37: 5 | F37: 3 | G37: 0.2 | H37: 0.2 | I37: 0.3 | J37: 0.1 | K37: 0.06 | U37: ='2'!V12 -> 0 | X37: HORAS OPERANDO | Z37: =COUNTA('2'!Z6:Z29) -> 24 | AJ37: CARRETA | AL37: CILINDROS | AO37: CARRETA | AQ37: CILINDROS
B38: 0.66666667 | AJ38: CONSUMO | AK38: =SUM('2'!AF30+'2'!AH30) -> #REF! | AL38: CONSUMO | AM38: =SUM('2'!AL30+'2'!AN30) -> 0 | AO38: CONSUMO | AP38: ='2'!AJ30 -> 1362 | AQ38: CONSUMO | AR38: ='2'!AP30 -> 0
A39: Nº amostras de água TRATADA | C39: Nº amostras de água FILTRADA | E39: Nº amostras de água tratada/filtrada FORA DO PADRÃO | J39: Nº amostras de água tratada/filtrada no PADRÃO | O39: Nº de amostras com turbidez menor ou igual a 0,5 NTU | R39: ÁGUA FILTRADA | S39: Nº de amostras com turbidez menor ou igual a 1,0 NTU | AJ39: DOSAGEM | AK39: =('2'!AK38/'2'!Y30)*1000 -> #REF! | AL39: DOSAGEM | AM39: =('2'!AM38/'2'!Y30)*1000 -> 0 | AO39: DOSAGEM | AP39: =('2'!AP38/'2'!Y30)*1000 -> 5.551561 | AQ39: DOSAGEM | AR39: =('2'!AR38/'2'!Y30)*1000 -> 0
A40: COR | B40: TURBIDEZ | C40: TURBIDEZ | E40: COR | G40: TURBIDEZ | J40: COR | L40: TURBIDEZ | X40: ESTOQUE DE COAGULANTE | AJ40: Consumo Total | AL40: =SUM('2'!AK38,'2'!AM38) -> #REF! | AO40: Consumo Total | AQ40: =SUM('2'!AP38,'2'!AR38) -> 1362
A41: =COUNTA('2'!E7:E18) -> 12 | B41: =COUNTA('2'!I7:I18) -> 12 | C41: =COUNTA('2'!J7:J18) -> 12 | D41: =COUNTA('2'!K7:K18) -> 12 | E41: =COUNTIF('2'!E7:E18,">15") -> 0 | G41: =COUNTIF('2'!J7:J18,">1") -> 12 | J41: ='2'!A41-'2'!E41 -> 12 | L41: ='2'!C41-'2'!G41 -> 0 | O41: =COUNTIF('2'!J7:J18,"<=0,5") -> 0 | S41: =COUNTIF('2'!J7:J18,"<=1,0") -> 0 | AJ41: Dosagem Final | AL41: =SUM(('2'!AK38+'2'!AM38)/'2'!Y30)*1000 -> #REF! | AO41: Dosagem Final | AQ41: =SUM(('2'!AP38+'2'!AR38)/'2'!Y30)*1000 -> 5.551561
O42: ÁGUA FILTRATADA | X42: SULFATO DE ALUMÍNIO
H43: Nº de amostras água tratada com turbidez <= 5,0 NTU | L43: Nº de amostras água tratada para aluminio | Q43: Nº de amostras com turbidez entre 0,5 e 1,0 NTU | X43: TINA 01 | Z43: TINA 02 | AB43: TINA 03 | AD43: TANQUE
...

Sheet 3
D2: CONTROLE DE ANÁLISE FÍSICO - QUÍMICAS \ ETA CASTELO BRANCO | AB2: CONTROLE DE PRODUTOS QUÍMICOS APLICADOS \ ETA CASTELO BRANCO
A4: HORA | B4: COR (Uc) | F4: TURBIDEZ (Ut) | K4: Ph | O4: CLORO RESIDUAL (mg/L) | R4: DOSAGEM DO COAGULANTE | T4: VAZÃO DA ETA | U4: TIPO DE COAGULANTE | V4: TÉCNICO | X4: Hora | Y4: Vazão ETA (l/s) | Z4: Vazão Coagulante (l/h) | AA4: Código | AB4: Dosagem (mg/l) | AC4: Vazão Polímero (l/h) | AD4: Dosagem (mg/l) | AE4: Pré 1 (Lib/dia) | AF4: Pré 1 (Kg/h) | AG4: Pré 2 (Lib/dia) | AH4: Pré 2 (Kg/h) | AI4: Pós (Lib/dia) | AJ4: Pós (Kg/h) | AK4: Pré 1 (Lib/dia) cilindros | AL4: Pré 1 (Kg/h) cilindros | AM4: Pré 2 (Lib/dia) cilindros | AN4: Pré 2 (Kg/h) cilindros | AO4: Pós (Lib/dia) cilindros | AP4: Pós (Kg/h) cilindros | AQ4: COAGULANTE | AU4: Tempo de Utilização (h)
AQ5: Codigo | AR5: Nome | AS5: d (g/ml) | AT5: C (%)
B6: Bruta | C6: DEC_1 | D6: DEC_2 | E6: TRAT | F6: Bruta | G6: DEC_1 | H6: DEC_2 | I6: TRAT | J6: FILT | K6: Bruta | L6: DEC_1 | M6: DEC_2 | N6: TRAT | O6: TRAT | P6: DEC_1 | Q6: DEC_2 | R6: L/h | S6: mg/l | T6: L/s | X6: 0.041666667 | Y6: 2894 | Z6: 1932 | AA6: 1 | AB6: =IF('3'!AA6=1,(('3'!Z6*'3'!$AS$6*'3'!$AT$6)/('3'!Y6*0.0036)),IF('3'!AA6=2,(('3'!Z6*'3'!$AS$7*'3'!$AT$7)/('3'!Y6*0.0036)))) -> 123.31836 | AD6: =(('3'!AC6*'3'!$O$9*1000000))/('3'!Y6*3600) -> 0 | AE6: 3000 | AF6: =('3'!AE6/24)*0.454 -> 56.75 | AG6: 500 | AH6: =('3'!AG6/24)*0.454 -> 9.4583333 | AI6: 3000 | AJ6: =('3'!AI6/24)*0.454 -> 56.75 | AL6: =('3'!AK6/24)*0.454 -> 0 | AN6: =('3'!AM6/24)*0.454 -> 0 | AP6: =('3'!AO6/24)*0.454 -> 0 | AQ6: 1 | AR6: S.A.L | AS6: 1.33 | AT6: 0.5 | AU6: 0
A7: 0 | B7: 700 | C7: 10 | D7: 7.5 | E7: 2.5 | F7: 166 | G7: 3.2 | H7: 2.7 | I7: 0.95 | J7: 1.1 | K7: 6.8 | L7: 4.8 | M7: 4.8 | N7: 5.3 | O7: 3.5 | P7: 0.4 | Q7: 1.2 | R7: ='2'!$Z$29 -> 1932 | S7: ='2'!$AB$29 -> 125.1783 | T7: ='2'!$Y$29 -> 2851 | U7: =IF('3'!AA6=1,'3'!AR6,'3'!AR7) -> S.A.L | V7: =ESCALA!$C$4 -> 0 | X7: 0.083333333 | Y7: 2792 | Z7: 1932 | AA7: 1 | AB7: =IF('3'!AA7=1,(('3'!Z7*'3'!$AS$6*'3'!$AT$6)/('3'!Y7*0.0036)),IF('3'!AA7=2,(('3'!Z7*'3'!$AS$7*'3'!$AT$7)/('3'!Y7*0.0036)))) -> 127.82354 | AD7: =(('3'!AC7*'3'!$O$9*1000000))/('3'!Y7*3600) -> 0 | AE7: 3000 | AF7: =('3'!AE7/24)*0.454 -> 56.75 | AG7: 500 | AH7: =('3'!AG7/24)*0.454 -> 9.4583333 | AI7: 3000 | AJ7: =('3'!AI7/24)*0.454 -> 56.75 | AL7: =('3'!AK7/24)*0.454 -> 0 | AN7: =('3'!AM7/24)*0.454 -> 0 | AP7: =('3'!AO7/24)*0.454 -> 0 | AQ7: 2 | AR7: PAC 18 | AS7: 1.262 | AT7: 1 | AU7: 24
A8: 0.083333333 | B8: 700 | C8: 10 | D8: 7.5 | E8: 2.5 | F8: 160 | G8: 3.2 | H8: 2.7 | I8: 0.86 | J8: 0.97 | K8: 6.8 | L8: 4.8 | M8: 4.8 | N8: 5.3 | O8: 3.5 | P8: 0.4 | Q8: 1.7 | R8: ='3'!Z7 -> 1932 | S8: ='3'!AB7 -> 127.82354 | T8: ='3'!Y7 -> 2792 | U8: =IF('3'!AA7=1,'3'!AR6,'3'!AR7) -> S.A.L | X8: 0.125 | Y8: 2824 | Z8: 1932 | AA8: 1 | AB8: =IF('3'!AA8=1,(('3'!Z8*'3'!$AS$6*'3'!$AT$6)/('3'!Y8*0.0036)),IF('3'!AA8=2,(('3'!Z8*'3'!$AS$7*'3'!$AT$7)/('3'!Y8*0.0036)))) -> 126.37512 | AD8: =(('3'!AC8*'3'!$O$9*1000000))/('3'!Y8*3600) -> 0 | AE8: 3000 | AF8: =('3'!AE8/24)*0.454 -> 56.75 | AG8: 500 | AH8: =('3'!AG8/24)*0.454 -> 9.4583333 | AI8: 3000 | AJ8: =('3'!AI8/24)*0.454 -> 56.75 | AL8: =('3'!AK8/24)*0.454 -> 0 | AN8: =('3'!AM8/24)*0.454 -> 0 | AP8: =('3'!AO8/24)*0.454 -> 0 | AQ8: Polímero Catiônico
A9: 0.16666667 | B9: 700 | C9: 10 | D9: 5 | E9: 2.5 | F9: 157 | G9: 3.2 | H9: 2.6 | I9: 0.76 | J9: 0.85 | K9: 6.8 | L9: 4.8 | M9: 4.8 | N9: 5.3 | O9: 3.5 | P9: 0.5 | Q9: 2 | R9: ='3'!Z9 -> 1932 | S9: ='3'!AB9 -> 124.09017 | T9: ='3'!Y9 -> 2876 | U9: =IF('3'!AA9=1,'3'!AR6,'3'!AR7) -> S.A.L | X9: 0.16666667 | Y9: 2876 | Z9: 1932 | AA9: 1 | AB9: =IF('3'!AA9=1,(('3'!Z9*'3'!$AS$6*'3'!$AT$6)/('3'!Y9*0.0036)),IF('3'!AA9=2,(('3'!Z9*'3'!$AS$7*'3'!$AT$7)/('3'!Y9*0.0036)))) -> 124.09017 | AD9: =(('3'!AC9*'3'!$O$9*1000000))/('3'!Y9*3600) -> 0 | AE9: 3000 | AF9: =('3'!AE9/24)*0.454 -> 56.75 | AG9: 500 | AH9: =('3'!AG9/24)*0.454 -> 9.4583333 | AI9: 3000 | AJ9: =('3'!AI9/24)*0.454 -> 56.75 | AL9: =('3'!AK9/24)*0.454 -> 0 | AN9: =('3'!AM9/24)*0.454 -> 0 | AP9: =('3'!AO9/24)*0.454 -> 0 | AQ9: Nome | AT9: C (%)
A10: 0.25 | B10: 700 | C10: 10 | D10: 5 | E10: 2.5 | F10: 154 | G10: 3.2 | H10: 2.6 | I10: 0.74 | J10: 0.83 | K10: 6.8 | L10: 4.8 | M10: 4.8 | N10: 5.3 | O10: 3.5 | P10: 0.5 | Q10: 2 | R10: ='3'!Z11 -> 1932 | S10: ='3'!AB11 -> 125.4864 | T10: ='3'!Y11 -> 2844 | U10: =IF('3'!AA11=1,'3'!AR6,'3'!AR7) -> S.A.L | X10: 0.20833333 | Y10: 2792 | Z10: 1932 | AA10: 1 | AB10: =IF('3'!AA10=1,(('3'!Z10*'3'!$AS$6*'3'!$AT$6)/('3'!Y10*0.0036)),IF('3'!AA10=2,(('3'!Z10*'3'!$AS$7*'3'!$AT$7)/('3'!Y10*0.0036)))) -> 127.82354 | AD10: =(('3'!AC10*'3'!$O$9*1000000))/('3'!Y10*3600) -> 0 | AE10: 3000 | AF10: =('3'!AE10/24)*0.454 -> 56.75 | AG10: 500 | AH10: =('3'!AG10/24)*0.454 -> 9.4583333 | AI10: 3000 | AJ10: =('3'!AI10/24)*0.454 -> 56.75 | AL10: =('3'!AK10/24)*0.454 -> 0 | AN10: =('3'!AM10/24)*0.454 -> 0 | AP10: =('3'!AO10/24)*0.454 -> 0 | AQ10: Aguapol 200 | AT10: 0.002
A11: 0.33333333 | B11: 700 | C11: 12.5 | D11: 7.5 | E11: 2.5 | F11: 152 | G11: 3.7 | H11: 2.8 | I11: 0.93 | J11: 1.22 | K11: 6.8 | L11: 4.8 | M11: 4.8 | N11: 5.3 | O11: 3.5 | P11: 0.4 | Q11: 1.5 | R11: ='3'!Z13 -> 1932 | S11: ='3'!AB13 -> 125.09055 | T11: ='3'!Y13 -> 2853 | U11: =IF('3'!AA13=1,'3'!AR6,'3'!AR7) -> S.A.L | X11: 0.25 | Y11: 2844 | Z11: 1932 | AA11: 1 | AB11: =IF('3'!AA11=1,(('3'!Z11*'3'!$AS$6*'3'!$AT$6)/('3'!Y11*0.0036)),IF('3'!AA11=2,(('3'!Z11*'3'!$AS$7*'3'!$AT$7)/('3'!Y11*0.0036)))) -> 125.4864 | AD11: =(('3'!AC11*'3'!$O$9*1000000))/('3'!Y11*3600) -> 0 | AE11: 3000 | AF11: =('3'!AE11/24)*0.454 -> 56.75 | AG11: 500 | AH11: =('3'!AG11/24)*0.454 -> 9.4583333 | AI11: 3000 | AJ11: =('3'!AI11/24)*0.454 -> 56.75 | AL11: =('3'!AK11/24)*0.454 -> 0 | AN11: =('3'!AM11/24)*0.454 -> 0 | AP11: =('3'!AO11/24)*0.454 -> 0
A12: 0.41666667 | B12: 700 | C12: 12.5 | D12: 10 | E12: 2.5 | F12: 150 | G12: 4 | H12: 3.1 | I12: 1.05 | J12: 1.61 | K12: 6.8 | L12: 4.8 | M12: 4.8 | N12: 5.3 | O12: 3.5 | P12: 0.3 | Q12: 1.2 | R12: ='3'!Z15 -> 1932 | S12: ='3'!AB15 -> 126.19637 | T12: ='3'!Y15 -> 2828 | U12: =IF('3'!AA15=1,'3'!AR6,'3'!AR7) -> S.A.L | V12: =ESCALA!$B$5 -> 0 | X12: 0.29166667 | Y12: 2818 | Z12: 1932 | AA12: 1 | AB12: =IF('3'!AA12=1,(('3'!Z12*'3'!$AS$6*'3'!$AT$6)/('3'!Y12*0.0036)),IF('3'!AA12=2,(('3'!Z12*'3'!$AS$7*'3'!$AT$7)/('3'!Y12*0.0036)))) -> 126.64419 | AD12: =(('3'!AC12*'3'!$O$9*1000000))/('3'!Y12*3600) -> 0 | AE12: 3000 | AF12: =('3'!AE12/24)*0.454 -> 56.75 | AG12: 500 | AH12: =('3'!AG12/24)*0.454 -> 9.4583333 | AI12: 3000 | AJ12: =('3'!AI12/24)*0.454 -> 56.75 | AL12: =('3'!AK12/24)*0.454 -> 0 | AN12: =('3'!AM12/24)*0.454 -> 0 | AP12: =('3'!AO12/24)*0.454 -> 0
A13: 0.5 | B13: 700 | C13: 12.5 | D13: 12.5 | E13: 5 | F13: 156 | G13: 4.5 | H13: 4 | I13: 1.12 | J13: 1.93 | K13: 6.8 | L13: 4.8 | M13: 4.8 | N13: 5 | O13: 3.5 | P13: 0.3 | Q13: 1.2 | R13: ='3'!Z17 -> 2580 | S13: ='3'!AB17 -> 167.51611 | T13: ='3'!Y17 -> 2845 | U13: =IF('3'!AA17=1,'3'!AR6,'3'!AR7) -> S.A.L | X13: 0.33333333 | Y13: 2853 | Z13: 1932 | AA13: 1 | AB13: =IF('3'!AA13=1,(('3'!Z13*'3'!$AS$6*'3'!$AT$6)/('3'!Y13*0.0036)),IF('3'!AA13=2,(('3'!Z13*'3'!$AS$7*'3'!$AT$7)/('3'!Y13*0.0036)))) -> 125.09055 | AD13: =(('3'!AC13*'3'!$O$9*1000000))/('3'!Y13*3600) -> 0 | AE13: 3000 | AF13: =('3'!AE13/24)*0.454 -> 56.75 | AG13: 500 | AH13: =('3'!AG13/24)*0.454 -> 9.4583333 | AI13: 3000 | AJ13: =('3'!AI13/24)*0.454 -> 56.75 | AL13: =('3'!AK13/24)*0.454 -> 0 | AN13: =('3'!AM13/24)*0.454 -> 0 | AP13: =('3'!AO13/24)*0.454 -> 0
A14: 0.58333333 | B14: 700 | C14: 10 | D14: 10 | E14: 5 | F14: 156 | G14: 4.2 | H14: 3.8 | I14: 1.15 | J14: 2.05 | K14: 6.8 | L14: 4.8 | M14: 4.8 | N14: 4.5 | O14: 3.3 | P14: 0.5 | Q14: 1.4 | R14: ='3'!Z19 -> 2005 | S14: ='3'!AB19 -> 126.88183 | T14: ='3'!Y19 -> 2919 | U14: =IF('3'!AA19=1,'3'!AR6,'3'!AR7) -> S.A.L | X14: 0.375 | Y14: 2868 | Z14: 1932 | AA14: 1 | AB14: =IF('3'!AA14=1,(('3'!Z14*'3'!$AS$6*'3'!$AT$6)/('3'!Y14*0.0036)),IF('3'!AA14=2,(('3'!Z14*'3'!$AS$7*'3'!$AT$7)/('3'!Y14*0.0036)))) -> 124.43631 | AD14: =(('3'!AC14*'3'!$O$9*1000000))/('3'!Y14*3600) -> 0 | AE14: 3000 | AF14: =('3'!AE14/24)*0.454 -> 56.75 | AG14: 500 | AH14: =('3'!AG14/24)*0.454 -> 9.4583333 | AI14: 3000 | AJ14: =('3'!AI14/24)*0.454 -> 56.75 | AL14: =('3'!AK14/24)*0.454 -> 0 | AN14: =('3'!AM14/24)*0.454 -> 0 | AP14: =('3'!AO14/24)*0.454 -> 0
A15: 0.66666667 | B15: 700 | C15: 12.5 | D15: 10 | E15: 5 | F15: 152 | G15: 4 | H15: 3.3 | I15: 1.21 | J15: 2.02 | K15: 6.8 | L15: 4.8 | M15: 4.8 | N15: 4.5 | O15: 3.3 | P15: 0.5 | Q15: 1.5 | R15: ='3'!Z21 -> 1505 | S15: ='3'!AB21 -> 97.273249 | T15: ='3'!Y21 -> 2858 | U15: =IF('3'!AA21=1,'3'!AR6,'3'!AR7) -> S.A.L | X15: 0.41666667 | Y15: 2828 | Z15: 1932 | AA15: 1 | AB15: =IF('3'!AA15=1,(('3'!Z15*'3'!$AS$6*'3'!$AT$6)/('3'!Y15*0.0036)),IF('3'!AA15=2,(('3'!Z15*'3'!$AS$7*'3'!$AT$7)/('3'!Y15*0.0036)))) -> 126.19637 | AD15: =(('3'!AC15*'3'!$O$9*1000000))/('3'!Y15*3600) -> 0 | AE15: 3000 | AF15: =('3'!AE15/24)*0.454 -> 56.75 | AG15: 500 | AH15: =('3'!AG15/24)*0.454 -> 9.4583333 | AI15: 3000 | AJ15: =('3'!AI15/24)*0.454 -> 56.75 | AL15: =('3'!AK15/24)*0.454 -> 0 | AN15: =('3'!AM15/24)*0.454 -> 0 | AP15: =('3'!AO15/24)*0.454 -> 0
A16: 0.75 | B16: 700 | C16: 10 | D16: 10 | E16: 5 | F16: 150 | G16: 3.8 | H16: 3.2 | I16: 1.21 | J16: 1.91 | K16: 6.8 | L16: 4.8 | M16: 4.8 | N16: 4.5 | O16: 3.2 | P16: 0.4 | Q16: 1.5 | R16: ='3'!Z23 -> 1375 | S16: ='3'!AB23 -> 89.497201 | T16: ='3'!Y23 -> 2838 | U16: =IF('3'!AA23=1,'3'!AR6,'3'!AR7) -> S.A.L | X16: 0.45833333 | Y16: 2847 | Z16: 3540 | AA16: 1 | AB16: =IF('3'!AA16=1,(('3'!Z16*'3'!$AS$6*'3'!$AT$6)/('3'!Y16*0.0036)),IF('3'!AA16=2,(('3'!Z16*'3'!$AS$7*'3'!$AT$7)/('3'!Y16*0.0036)))) -> 229.68622 | AD16: =(('3'!AC16*'3'!$O$9*1000000))/('3'!Y16*3600) -> 0 | AE16: 3000 | AF16: =('3'!AE16/24)*0.454 -> 56.75 | AG16: 500 | AH16: =('3'!AG16/24)*0.454 -> 9.4583333 | AI16: 3000 | AJ16: =('3'!AI16/24)*0.454 -> 56.75 | AL16: =('3'!AK16/24)*0.454 -> 0 | AN16: =('3'!AM16/24)*0.454 -> 0 | AP16: =('3'!AO16/24)*0.454 -> 0
A17: 0.83333333 | B17: 700 | C17: 10 | D17: 10 | E17: 5 | F17: 148 | G17: 3.6 | H17: 3 | I17: 0.94 | J17: 1.88 | K17: 6.8 | L17: 4.8 | M17: 4.8 | N17: 4.5 | O17: 3.2 | P17: 0.4 | Q17: 1.5 | R17: ='3'!Z25 -> 2016 | S17: ='3'!AB25 -> 131.49718 | T17: ='3'!Y25 -> 2832 | U17: =IF('3'!AA25=1,'3'!AR6,'3'!AR7) -> S.A.L | V17: =ESCALA!$C$5 -> 0 | X17: 0.5 | Y17: 2845 | Z17: 2580 | AA17: 1 | AB17: =IF('3'!AA17=1,(('3'!Z17*'3'!$AS$6*'3'!$AT$6)/('3'!Y17*0.0036)),IF('3'!AA17=2,(('3'!Z17*'3'!$AS$7*'3'!$AT$7)/('3'!Y17*0.0036)))) -> 167.51611 | AD17: =(('3'!AC17*'3'!$O$9*1000000))/('3'!Y17*3600) -> 0 | AE17: 3000 | AF17: =('3'!AE17/24)*0.454 -> 56.75 | AG17: 500 | AH17: =('3'!AG17/24)*0.454 -> 9.4583333 | AI17: 3000 | AJ17: =('3'!AI17/24)*0.454 -> 56.75 | AL17: =('3'!AK17/24)*0.454 -> 0 | AN17: =('3'!AM17/24)*0.454 -> 0 | AP17: =('3'!AO17/24)*0.454 -> 0
A18: 0.91666667 | B18: 700 | C18: 10 | D18: 10 | E18: 5 | F18: 146 | G18: 3.2 | H18: 3 | I18: 0.91 | J18: 1.82 | K18: 6.8 | L18: 4.8 | M18: 4.8 | N18: 4.5 | O18: 3.2 | P18: 0.3 | Q18: 1.5 | R18: ='3'!Z27 -> 2016 | S18: ='3'!AB27 -> 133.4767 | T18: ='3'!Y27 -> 2790 | U18: =IF('3'!AA27=1,'3'!AR6,'3'!AR7) -> S.A.L | X18: 0.54166667 | Y18: 2876 | Z18: 2320 | AA18: 1 | AB18: =IF('3'!AA18=1,(('3'!Z18*'3'!$AS$6*'3'!$AT$6)/('3'!Y18*0.0036)),IF('3'!AA18=2,(('3'!Z18*'3'!$AS$7*'3'!$AT$7)/('3'!Y18*0.0036)))) -> 149.01097 | AD18: =(('3'!AC18*'3'!$O$9*1000000))/('3'!Y18*3600) -> 0 | AE18: 3000 | AF18: =('3'!AE18/24)*0.454 -> 56.75 | AG18: 500 | AH18: =('3'!AG18/24)*0.454 -> 9.4583333 | AI18: 3000 | AJ18: =('3'!AI18/24)*0.454 -> 56.75 | AL18: =('3'!AK18/24)*0.454 -> 0 | AN18: =('3'!AM18/24)*0.454 -> 0 | AP18: =('3'!AO18/24)*0.454 -> 0
A19: Média | B19: {=IF('3'!B7:B18>0.01,AVERAGE('3'!B7:B18),"")} -> 700 | C19: {=IF('3'!C7:C18>0.01,AVERAGE('3'!C7:C18),"")} -> 10.833333 | D19: {=IF('3'!D7:D18>0.01,AVERAGE('3'!D7:D18),"")} -> 8.75 | E19: {=IF('3'!E7:E18>0.01,AVERAGE('3'!E7:E18),"")} -> 3.75 | F19: {=IF('3'!F7:F18>0.01,AVERAGE('3'!F7:F18),"")} -> 153.91667 | G19: {=IF('3'!G7:G18>0.01,AVERAGE('3'!G7:G18),"")} -> 3.65 | H19: {=IF('3'!H7:H18>0.01,AVERAGE('3'!H7:H18),"")} -> 3.0666667 | I19: {=IF('3'!I7:I18>0.01,AVERAGE('3'!I7:I18),"")} -> 0.98583333 | ... S19: {=IF('3'!S7:S18>0.01,AVERAGE('3'!S7:S18),"")} -> 125.00063 | X19: 0.58333333 | Y19: 2919 | Z19: 2005 | AA19: 1 | AB19: =IF('3'!AA19=1,(('3'!Z19*'3'!$AS$6*'3'!$AT$6)/('3'!Y19*0.0036)),IF('3'!AA19=2,(('3'!Z19*'3'!$AS$7*'3'!$AT$7)/('3'!Y19*0.0036)))) -> 126.88183 | AD19: =(('3'!AC19*'3'!$O$9*1000000))/('3'!Y19*3600) -> 0 | AE19: 3000 | AF19: =('3'!AE19/24)*0.454 -> 56.75 | AG19: 500 | AH19: =('3'!AG19/24)*0.454 -> 9.4583333 | AI19: 3000 | AJ19: =('3'!AI19/24)*0.454 -> 56.75 | AL19: =('3'!AK19/24)*0.454 -> 0 | AN19: =('3'!AM19/24)*0.454 -> 0 | AP19: =('3'!AO19/24)*0.454 -> 0
