Workbook
Name _FilterDatabase_0: #REF!
Name G: NA()
Name Hi: NA()
Name hii: NA()
Name Ho: NA()
Name maruza: [1]Jenipapo!$E$73
Name N: NA()
Name Resumo_da_Avaliação_do_Desempenho_do_Elo_Ibura: [1]Ibura!$A$11:$D$13
Name T: NA()
Name Vazão: NA()
Name Vi: NA()
Name Viii: NA()
Name W: NA()

Sheet ESCALA
A1: DATA | B1: ESCALA | C1: ESCALA
B2: 07:00h às 19:00h | C2: 19:00h às 07:00h
A3: 43891 | E3: DIGITAR PRIMEIRO DIA DO MÊS
A4: =ESCALA!A3+1 -> 43892
A5: =ESCALA!A4+1 -> 43893
A6: =ESCALA!A5+1 -> 43894
A7: =ESCALA!A6+1 -> 43895
A8: =ESCALA!A7+1 -> 43896
A9: =ESCALA!A8+1 -> 43897
A10: =ESCALA!A9+1 -> 43898
A11: =ESCALA!A10+1 -> 43899
A12: =ESCALA!A11+1 -> 43900
A13: =ESCALA!A12+1 -> 43901
A14: =ESCALA!A13+1 -> 43902
A15: =ESCALA!A14+1 -> 43903
... A33: =ESCALA!A32+1 -> 43921

Sheet 1
D2: CONTROLE DE ANÁLISE FÍSICO - QUÍMICAS \ ETA CASTELO BRANCO | AB2: CONTROLE DE PRODUTOS QUÍMICOS APLICADOS \ ETA CASTELO BRANCO
A4: HORA | B4: COR (Uc) | F4: TURBIDEZ (Ut) | K4: Ph | O4: CLORO RESIDUAL (mg/L) | R4: DOSAGEM DO COAGULANTE | T4: VAZÃO DA ETA | U4: TIPO DE COAGU LANTE | V4: TÉCNICO | X4: Hora | Y4: Vazão ETA (l/s) | Z4: Vazão Coagulante (l/h) | AA4: Código | AB4: Dosagem (mg/l) | AC4: Vazão Polímero (l/h) | AD4: Dosagem (mg/l) | AE4: Pré 1 (Lib/dia) | AF4: Pré 1 (Kg/h) | AG4: Pré 2 (Lib/dia) | AH4: Pré 2 (Kg/h) | AI4: Pós (Lib/dia) | AJ4: Pós (Kg/h) | AK4: Pré 1 (Lib/dia) cilindros | AL4: Pré 1 (Kg/h) cilindros | AM4: Pré 2 (Lib/dia) cilindros | AN4: Pré 2 (Kg/h) cilindros | AO4: Pós (Lib/dia) cilindros | AP4: Pós (Kg/h) cilindros | AQ4: COAGULANTE | AU4: Tempo de Utilização (h)
AQ5: Codigo | AR5: Nome | AS5: d (g/ml) | AT5: C (%)
B6: Bruta | C6: DEC_1 | D6: DEC_2 | E6: TRAT | F6: Bruta | G6: DEC_1 | H6: DEC_2 | I6: TRAT | J6: FILT | K6: Bruta | L6: DEC_1 | M6: DEC_2 | N6: TRAT | O6: TRAT | P6: DEC_1 | Q6: DEC_2 | R6: L/h | S6: mg/l | T6: L/s | X6: 0.041666667 | Y6: 2806 | Z6: 987 | AA6: 1 | AB6: =IF('1'!AA6=1,(('1'!Z6*'1'!$AS$6*'1'!$AT$6)/('1'!Y6*0.0036)),IF('1'!AA6=2,(('1'!Z6*'1'!$AS$7*'1'!$AT$7)/('1'!Y6*0.0036)))) -> 64.97535 | AD6: =(('1'!AC6*'1'!$Q$10*1000000))/('1'!Z10*3600) -> 0 | AF6: =('1'!AE6/24)*0.454 -> 0 | AH6: =('1'!AG6/24)*0.454 -> 0 | AI6: 5200 | AJ6: =('1'!AI6/24)*0.454 -> 98.366667 | AL6: =('1'!AK6/24)*0.454 -> 0 | AN6: =('1'!AM6/24)*0.454 -> 0 | AP6: =('1'!AO6/24)*0.454 -> 0 | AQ6: 1 | AR6: S.A.L | AS6: 1.33 | AT6: 0.5 | AU6: 0
A7: 0 | B7: 80 | C7: 12.5 | D7: 12.5 | E7: 2.5 | F7: 9.4 | G7: 1.4 | H7: 1.6 | I7: 0.4 | J7: 0.4 | K7: 7.3 | L7: 6.7 | M7: 6.7 | N7: 6.4 | O7: 3.2 | R7: 987 | S7: 65.1 | T7: 2802 | U7: =IF('1'!AA6=1,'1'!AR6,'1'!AR7) -> S.A.L | X7: 0.083333333 | Y7: 2800 | Z7: 987 | AA7: 1 | AB7: =IF('1'!AA7=1,(('1'!Z7*'1'!$AS$6*'1'!$AT$6)/('1'!Y7*0.0036)),IF('1'!AA7=2,(('1'!Z7*'1'!$AS$7*'1'!$AT$7)/('1'!Y7*0.0036)))) -> 65.114583 | AD7: =(('1'!AC7*'1'!$Q$10*1000000))/('1'!Z11*3600) -> 0 | AF7: =('1'!AE7/24)*0.454 -> 0 | AH7: =('1'!AG7/24)*0.454 -> 0 | AI7: 5200 | AJ7: =('1'!AI7/24)*0.454 -> 98.366667 | AL7: =('1'!AK7/24)*0.454 -> 0 | AN7: =('1'!AM7/24)*0.454 -> 0 | AP7: =('1'!AO7/24)*0.454 -> 0 | AQ7: 2 | AR7: PAC 18 | AS7: 1.377 | AT7: 1 | AU7: 24
A8: 0.083333333 | B8: 80 | C8: 12.5 | D8: 12.5 | E8: 2.5 | F8: 9 | G8: 1.2 | H8: 1.5 | I8: 0.4 | J8: 0.4 | K8: 7.3 | L8: 6.7 | M8: 6.7 | N8: 6.4 | O8: 3.2 | R8: ='1'!Z7 -> 987 | S8: ='1'!AB7 -> 65.114583 | T8: ='1'!Y7 -> 2800 | U8: =IF('1'!AA7=1,'1'!AR6,'1'!AR7) -> S.A.L | X8: 0.125 | Y8: 2792 | Z8: 987 | AA8: 1 | AB8: =IF('1'!AA8=1,(('1'!Z8*'1'!$AS$6*'1'!$AT$6)/('1'!Y8*0.0036)),IF('1'!AA8=2,(('1'!Z8*'1'!$AS$7*'1'!$AT$7)/('1'!Y8*0.0036)))) -> 65.301158 | AD8: =(('1'!AC8*'1'!$Q$10*1000000))/('1'!Z12*3600) -> 0 | AF8: =('1'!AE8/24)*0.454 -> 0 | AH8: =('1'!AG8/24)*0.454 -> 0 | AI8: 5200 | AJ8: =('1'!AI8/24)*0.454 -> 98.366667 | AL8: =('1'!AK8/24)*0.454 -> 0 | AN8: =('1'!AM8/24)*0.454 -> 0 | AP8: =('1'!AO8/24)*0.454 -> 0 | AQ8: Polímero Catiônico
A9: 0.16666667 | B9: 70 | C9: 12.5 | D9: 12.5 | E9: 2.5 | F9: 8.9 | G9: 1.2 | H9: 1.5 | I9: 0.4 | J9: 0.4 | K9: 7.3 | L9: 6.7 | M9: 6.7 | N9: 6.4 | O9: 3.2 | R9: ='1'!Z9 -> 987 | S9: ='1'!AB9 -> 64.79063 | T9: ='1'!Y9 -> 2814 | U9: =IF('1'!AA9=1,'1'!AR6,'1'!AR7) -> S.A.L | X9: 0.16666667 | Y9: 2814 | Z9: 987 | AA9: 1 | AB9: =IF('1'!AA9=1,(('1'!Z9*'1'!$AS$6*'1'!$AT$6)/('1'!Y9*0.0036)),IF('1'!AA9=2,(('1'!Z9*'1'!$AS$7*'1'!$AT$7)/('1'!Y9*0.0036)))) -> 64.79063 | AD9: =(('1'!AC9*'1'!$Q$10*1000000))/('1'!Z13*3600) -> 0 | AF9: =('1'!AE9/24)*0.454 -> 0 | AH9: =('1'!AG9/24)*0.454 -> 0 | AI9: 5200 | AJ9: =('1'!AI9/24)*0.454 -> 98.366667 | AL9: =('1'!AK9/24)*0.454 -> 0 | AN9: =('1'!AM9/24)*0.454 -> 0 | AP9: =('1'!AO9/24)*0.454 -> 0 | AQ9: Nome | AT9: C (%)
A10: 0.25 | B10: 70 | C10: 12.5 | D10: 12.5 | E10: 2.5 | F10: 8.7 | G10: 1.2 | H10: 1.5 | I10: 0.4 | J10: 0.4 | K10: 7.3 | L10: 6.7 | M10: 6.7 | N10: 6.4 | O10: 3.2 | R10: ='1'!Z11 -> 987 | S10: ='1'!AB11 -> 66.370889 | T10: ='1'!Y11 -> 2747 | U10: =IF('1'!AA11=1,'1'!AR6,'1'!AR7) -> S.A.L | X10: 0.20833333 | Y10: 2758 | Z10: 987 | AA10: 1 | AB10: =IF('1'!AA10=1,(('1'!Z10*'1'!$AS$6*'1'!$AT$6)/('1'!Y10*0.0036)),IF('1'!AA10=2,(('1'!Z10*'1'!$AS$7*'1'!$AT$7)/('1'!Y10*0.0036)))) -> 66.106176 | AD10: =(('1'!AC10*'1'!$Q$10*1000000))/('1'!Z14*3600) -> 0 | AF10: =('1'!AE10/24)*0.454 -> 0 | AH10: =('1'!AG10/24)*0.454 -> 0 | AI10: 5200 | AJ10: =('1'!AI10/24)*0.454 -> 98.366667 | AL10: =('1'!AK10/24)*0.454 -> 0 | AN10: =('1'!AM10/24)*0.454 -> 0 | AP10: =('1'!AO10/24)*0.454 -> 0 | AQ10: Aguapol 200 | AT10: 0.002
A11: 0.33333333 | B11: 80 | C11: 12.5 | D11: 12.5 | E11: 2.5 | F11: 9.2 | G11: 1.3 | H11: 1.4 | I11: 0.4 | J11: 0.4 | K11: 7.3 | L11: 6.7 | M11: 6.7 | N11: 6.4 | O11: 3.2 | R11: ='1'!Z13 -> 987 | S11: ='1'!AB13 -> 65.3714 | T11: ='1'!Y13 -> 2789 | U11: =IF('1'!AA13=1,'1'!AR6,'1'!AR7) -> S.A.L | X11: 0.25 | Y11: 2747 | Z11: 987 | AA11: 1 | AB11: =IF('1'!AA11=1,(('1'!Z11*'1'!$AS$6*'1'!$AT$6)/('1'!Y11*0.0036)),IF('1'!AA11=2,(('1'!Z11*'1'!$AS$7*'1'!$AT$7)/('1'!Y11*0.0036)))) -> 66.370889 | AD11: =(('1'!AC11*'1'!$Q$10*1000000))/('1'!Z15*3600) -> 0 | AF11: =('1'!AE11/24)*0.454 -> 0 | AH11: =('1'!AG11/24)*0.454 -> 0 | AI11: 5200 | AJ11: =('1'!AI11/24)*0.454 -> 98.366667 | AL11: =('1'!AK11/24)*0.454 -> 0 | AN11: =('1'!AM11/24)*0.454 -> 0 | AP11: =('1'!AO11/24)*0.454 -> 0
A12: 0.41666667 | B12: 80 | C12: 12.5 | D12: 12.5 | E12: 2.5 | F12: 9.4 | G12: 1.4 | H12: 1.4 | I12: 0.4 | J12: 0.4 | K12: 7.3 | L12: 6.7 | M12: 6.7 | N12: 6.4 | O12: 3.2 | R12: ='1'!Z15 -> 987 | S12: ='1'!AB15 -> 65.207737 | T12: ='1'!Y15 -> 2796 | U12: =IF('1'!AA15=1,'1'!AR6,'1'!AR7) -> S.A.L | V12: =ESCALA!$B$3 -> 0 | X12: 0.29166667 | Y12: 2769 | Z12: 987 | AA12: 1 | AB12: =IF('1'!AA12=1,(('1'!Z12*'1'!$AS$6*'1'!$AT$6)/('1'!Y12*0.0036)),IF('1'!AA12=2,(('1'!Z12*'1'!$AS$7*'1'!$AT$7)/('1'!Y12*0.0036)))) -> 65.843566 | AD12: =(('1'!AC12*'1'!$Q$10*1000000))/('1'!Z16*3600) -> 0 | AF12: =('1'!AE12/24)*0.454 -> 0 | AH12: =('1'!AG12/24)*0.454 -> 0 | AI12: 5200 | AJ12: =('1'!AI12/24)*0.454 -> 98.366667 | AL12: =('1'!AK12/24)*0.454 -> 0 | AN12: =('1'!AM12/24)*0.454 -> 0 | AP12: =('1'!AO12/24)*0.454 -> 0
A13: 0.5 | B13: 80 | C13: 12.5 | D13: 12.5 | E13: 2.5 | F13: 9.2 | G13: 1.4 | H13: 1.4 | I13: 0.4 | J13: 0.4 | K13: 7.3 | L13: 6.7 | M13: 6.7 | N13: 6.4 | O13: 3.2 | R13: ='1'!Z17 -> 987 | S13: ='1'!AB17 -> 63.972222 | T13: ='1'!Y17 -> 2850 | U13: =IF('1'!AA17=1,'1'!AR6,'1'!AR7) -> S.A.L | X13: 0.33333333 | Y13: 2789 | Z13: 987 | AA13: 1 | AB13: =IF('1'!AA13=1,(('1'!Z13*'1'!$AS$6*'1'!$AT$6)/('1'!Y13*0.0036)),IF('1'!AA13=2,(('1'!Z13*'1'!$AS$7*'1'!$AT$7)/('1'!Y13*0.0036)))) -> 65.3714 | AD13: =(('1'!AC13*'1'!$Q$10*1000000))/('1'!Z17*3600) -> 0 | AF13: =('1'!AE13/24)*0.454 -> 0 | AH13: =('1'!AG13/24)*0.454 -> 0 | AI13: 5200 | AJ13: =('1'!AI13/24)*0.454 -> 98.366667 | AL13: =('1'!AK13/24)*0.454 -> 0 | AN13: =('1'!AM13/24)*0.454 -> 0 | AP13: =('1'!AO13/24)*0.454 -> 0
A14: 0.58333333 | B14: 80 | C14: 12.5 | D14: 12.5 | E14: 2.5 | F14: 9.1 | G14: 1.4 | H14: 1.5 | I14: 0.4 | J14: 0.4 | K14: 7.3 | L14: 6.7 | M14: 6.7 | N14: 6.4 | O14: 3.2 | R14: ='1'!Z19 -> 987 | S14: ='1'!AB19 -> 62.869253 | T14: ='1'!Y19 -> 2900 | U14: =IF('1'!AA19=1,'1'!AR6,'1'!AR7) -> S.A.L | X14: 0.375 | Y14: 2798 | Z14: 987 | AA14: 1 | AB14: =IF('1'!AA14=1,(('1'!Z14*'1'!$AS$6*'1'!$AT$6)/('1'!Y14*0.0036)),IF('1'!AA14=2,(('1'!Z14*'1'!$AS$7*'1'!$AT$7)/('1'!Y14*0.0036)))) -> 65.161127 | AD14: =(('1'!AC14*'1'!$Q$10*1000000))/('1'!Z18*3600) -> 0 | AF14: =('1'!AE14/24)*0.454 -> 0 | AH14: =('1'!AG14/24)*0.454 -> 0 | AI14: 5200 | AJ14: =('1'!AI14/24)*0.454 -> 98.366667 | AL14: =('1'!AK14/24)*0.454 -> 0 | AN14: =('1'!AM14/24)*0.454 -> 0 | AP14: =('1'!AO14/24)*0.454 -> 0
A15: 0.66666667 | B15: 80 | C15: 12.5 | D15: 12.5 | E15: 2.5 | F15: 9 | G15: 1.4 | H15: 1.5 | I15: 0.4 | J15: 0.4 | K15: 7.3 | L15: 6.7 | M15: 6.7 | N15: 6.4 | O15: 3.2 | R15: ='1'!Z21 -> 987 | S15: ='1'!AB21 -> 63.949784 | T15: ='1'!Y21 -> 2851 | U15: =IF('1'!AA21=1,'1'!AR6,'1'!AR7) -> S.A.L | X15: 0.41666667 | Y15: 2796 | Z15: 987 | AA15: 1 | AB15: =IF('1'!AA15=1,(('1'!Z15*'1'!$AS$6*'1'!$AT$6)/('1'!Y15*0.0036)),IF('1'!AA15=2,(('1'!Z15*'1'!$AS$7*'1'!$AT$7)/('1'!Y15*0.0036)))) -> 65.207737 | AD15: =(('1'!AC15*'1'!$Q$10*1000000))/('1'!Z19*3600) -> 0 | AF15: =('1'!AE15/24)*0.454 -> 0 | AH15: =('1'!AG15/24)*0.454 -> 0 | AI15: 5200 | AJ15: =('1'!AI15/24)*0.454 -> 98.366667 | AL15: =('1'!AK15/24)*0.454 -> 0 | AN15: =('1'!AM15/24)*0.454 -> 0 | AP15: =('1'!AO15/24)*0.454 -> 0
A16: 0.75 | B16: 80 | C16: 12.5 | D16: 12.5 | E16: 2.5 | F16: 9.1 | G16: 1.3 | H16: 1.5 | I16: 0.4 | J16: 0.4 | K16: 7.3 | L16: 6.7 | M16: 6.7 | N16: 6.4 | O16: 3.2 | R16: ='1'!Z23 -> 987 | S16: ='1'!AB23 -> 64.107185 | T16: ='1'!Y23 -> 2844 | U16: =IF('1'!AA23=1,'1'!AR6,'1'!AR7) -> S.A.L | X16: 0.45833333 | Y16: 2754 | Z16: 987 | AA16: 1 | AB16: =IF('1'!AA16=1,(('1'!Z16*'1'!$AS$6*'1'!$AT$6)/('1'!Y16*0.0036)),IF('1'!AA16=2,(('1'!Z16*'1'!$AS$7*'1'!$AT$7)/('1'!Y16*0.0036)))) -> 66.202191 | AD16: =(('1'!AC16*'1'!$Q$10*1000000))/('1'!Z20*3600) -> 0 | AF16: =('1'!AE16/24)*0.454 -> 0 | AH16: =('1'!AG16/24)*0.454 -> 0 | AI16: 5200 | AJ16: =('1'!AI16/24)*0.454 -> 98.366667 | AL16: =('1'!AK16/24)*0.454 -> 0 | AN16: =('1'!AM16/24)*0.454 -> 0 | AP16: =('1'!AO16/24)*0.454 -> 0
A17: 0.83333333 | B17: 80 | C17: 12.5 | D17: 12.5 | E17: 2.5 | F17: 9.4 | G17: 1.3 | H17: 1.4 | I17: 0.4 | J17: 0.4 | K17: 7.3 | L17: 6.7 | M17: 6.7 | N17: 6.4 | O17: 3.2 | R17: ='1'!Z25 -> 987 | S17: ='1'!AB25 -> 65.606633 | T17: ='1'!Y25 -> 2779 | U17: =IF('1'!AA25=1,'1'!AR6,'1'!AR7) -> S.A.L | V17: =ESCALA!$C$3 -> 0 | X17: 0.5 | Y17: 2850 | Z17: 987 | AA17: 1 | AB17: =IF('1'!AA17=1,(('1'!Z17*'1'!$AS$6*'1'!$AT$6)/('1'!Y17*0.0036)),IF('1'!AA17=2,(('1'!Z17*'1'!$AS$7*'1'!$AT$7)/('1'!Y17*0.0036)))) -> 63.972222 | AD17: =(('1'!AC17*'1'!$Q$10*1000000))/('1'!Z21*3600) -> 0 | AF17: =('1'!AE17/24)*0.454 -> 0 | AH17: =('1'!AG17/24)*0.454 -> 0 | AI17: 5200 | AJ17: =('1'!AI17/24)*0.454 -> 98.366667 | AL17: =('1'!AK17/24)*0.454 -> 0 | AN17: =('1'!AM17/24)*0.454 -> 0 | AP17: =('1'!AO17/24)*0.454 -> 0
A18: 0.91666667 | B18: 80 | C18: 12.5 | D18: 12.5 | E18: 2.5 | F18: 9.6 | G18: 1.2 | H18: 1.4 | I18: 0.4 | J18: 0.4 | K18: 7.3 | L18: 6.7 | M18: 6.7 | N18: 6.4 | O18: 3.2 | R18: ='1'!Z27 -> 987 | S18: ='1'!AB27 -> 65.418311 | T18: ='1'!Y27 -> 2787 | U18: =IF('1'!AA27=1,'1'!AR6,'1'!AR7) -> S.A.L | X18: 0.54166667 | Y18: 2852 | Z18: 987 | AA18: 1 | AB18: =IF('1'!AA18=1,(('1'!Z18*'1'!$AS$6*'1'!$AT$6)/('1'!Y18*0.0036)),IF('1'!AA18=2,(('1'!Z18*'1'!$AS$7*'1'!$AT$7)/('1'!Y18*0.0036)))) -> 63.927361 | AD18: =(('1'!AC18*'1'!$Q$10*1000000))/('1'!Z22*3600) -> 0 | AF18: =('1'!AE18/24)*0.454 -> 0 | AH18: =('1'!AG18/24)*0.454 -> 0 | AI18: 5200 | AJ18: =('1'!AI18/24)*0.454 -> 98.366667 | AL18: =('1'!AK18/24)*0.454 -> 0 | AN18: =('1'!AM18/24)*0.454 -> 0 | AP18: =('1'!AO18/24)*0.454 -> 0
A19: Média | B19: {=IF('1'!B7:B18>0.01,AVERAGE('1'!B7:B18),"")} -> 78.333333 | C19: {=IF('1'!C7:C18>0.01,AVERAGE('1'!C7:C18),"")} -> 12.5 | D19: {=IF('1'!D7:D18>0.01,AVERAGE('1'!D7:D18),"")} -> 12.5 | E19: {=IF('1'!E7:E18>0.01,AVERAGE('1'!E7:E18),"")} -> 2.5 | F19: {=IF('1'!F7:F18>0.01,AVERAGE('1'!F7:F18),"")} -> 9.1666667 | G19: {=IF('1'!G7:G18>0.01,AVERAGE('1'!G7:G18),"")} -> 1.3083333 | H19: {=IF('1'!H7:H18>0.01,AVERAGE('1'!H7:H18),"")} -> 1.4666667 | I19: {=IF('1'!I7:I18>0.01,AVERAGE('1'!I7:I18),"")} -> 0.4 | ... S19: {=IF('1'!S7:S18>0.01,AVERAGE('1'!S7:S18),"")} -> 64.823219 | X19: 0.58333333 | Y19: 2900 | Z19: 987 | AA19: 1 | AB19: =IF('1'!AA19=1,(('1'!Z19*'1'!$AS$6*'1'!$AT$6)/('1'!Y19*0.0036)),IF('1'!AA19=2,(('1'!Z19*'1'!$AS$7*'1'!$AT$7)/('1'!Y19*0.0036)))) -> 62.869253 | AD19: =(('1'!AC19*'1'!$Q$10*1000000))/('1'!Z23*3600) -> 0 | AF19: =('1'!AE19/24)*0.454 -> 0 | AH19: =('1'!AG19/24)*0.454 -> 0 | AI19: 5200 | AJ19: =('1'!AI19/24)*0.454 -> 98.366667 | AL19: =('1'!AK19/24)*0.454 -> 0 | AN19: =('1'!AM19/24)*0.454 -> 0 | AP19: =('1'!AO19/24)*0.454 -> 0
A20: Máximo | B20: =MAX('1'!B7:B18) -> 80 | C20: =MAX('1'!C7:C18) -> 12.5 | D20: =MAX('1'!D7:D18) -> 12.5 | E20: =MAX('1'!E7:E18) -> 2.5 | F20: =MAX('1'!F7:F18) -> 9.6 | G20: =MAX('1'!G7:G18) -> 1.4 | H20: =MAX('1'!H7:H18) -> 1.6 | I20: =MAX('1'!I7:I18) -> 0.4 | ... S20: =MAX('1'!S7:S18) -> 66.370889 | X20: 0.625 | Y20: 2912 | Z20: 987 | AA20: 1 | AB20: =IF('1'!AA20=1,(('1'!Z20*'1'!$AS$6*'1'!$AT$6)/('1'!Y20*0.0036)),IF('1'!AA20=2,(('1'!Z20*'1'!$AS$7*'1'!$AT$7)/('1'!Y20*0.0036)))) -> 62.610176 | AD20: =(('1'!AC20*'1'!$Q$10*1000000))/('1'!Z24*3600) -> 0 | AF20: =('1'!AE20/24)*0.454 -> 0 | AH20: =('1'!AG20/24)*0.454 -> 0 | AI20: 5200 | AJ20: =('1'!AI20/24)*0.454 -> 98.366667 | AL20: =('1'!AK20/24)*0.454 -> 0 | AN20: =('1'!AM20/24)*0.454 -> 0 | AP20: =('1'!AO20/24)*0.454 -> 0
A21: Mínimo | B21: =MIN('1'!B7:B18) -> 70 | C21: =MIN('1'!C7:C18) -> 12.5 | D21: =MIN('1'!D7:D18) -> 12.5 | E21: =MIN('1'!E7:E18) -> 2.5 | F21: =MIN('1'!F7:F18) -> 8.7 | G21: =MIN('1'!G7:G18) -> 1.2 | H21: =MIN('1'!H7:H18) -> 1.4 | I21: =MIN('1'!I7:I18) -> 0.4 | ... S21: =MIN('1'!S7:S18) -> 62.869253 | X21: 0.66666667 | Y21: 2851 | Z21: 987 | AA21: 1 | AB21: =IF('1'!AA21=1,(('1'!Z21*'1'!$AS$6*'1'!$AT$6)/('1'!Y21*0.0036)),IF('1'!AA21=2,(('1'!Z21*'1'!$AS$7*'1'!$AT$7)/('1'!Y21*0.0036)))) -> 63.949784 | AD21: =(('1'!AC21*'1'!$Q$10*1000000))/('1'!Y21*3600) -> 0 | AF21: =('1'!AE21/24)*0.454 -> 0 | AH21: =('1'!AG21/24)*0.454 -> 0 | AI21: 5200 | AJ21: =('1'!AI21/24)*0.454 -> 98.366667 | AL21: =('1'!AK21/24)*0.454 -> 0 | AN21: =('1'!AM21/24)*0.454 -> 0 | AP21: =('1'!AO21/24)*0.454 -> 0
R22: Total | X22: 0.70833333 | Y22: 2823 | Z22: 987 | AA22: 1 | AB22: =IF('1'!AA22=1,(('1'!Z22*'1'!$AS$6*'1'!$AT$6)/('1'!Y22*0.0036)),IF('1'!AA22=2,(('1'!Z22*'1'!$AS$7*'1'!$AT$7)/('1'!Y22*0.0036)))) -> 64.584071 | AD22: =(('1'!AC22*'1'!$Q$10*1000000))/('1'!Y22*3600) -> 0 | AF22: =('1'!AE22/24)*0.454 -> 0 | AH22: =('1'!AG22/24)*0.454 -> 0 | AI22: 5200 | AJ22: =('1'!AI22/24)*0.454 -> 98.366667 | AL22: =('1'!AK22/24)*0.454 -> 0 | AN22: =('1'!AM22/24)*0.454 -> 0 | AP22: =('1'!AO22/24)*0.454 -> 0
A23: TURBIDEZ DOS FILTROS DA 1ª E 2ª ETAPAS | R23: 440 | S23: Litros | X23: 0.75 | Y23: 2844 | Z23: 987 | AA23: 1 | AB23: =IF('1'!AA23=1,(('1'!Z23*'1'!$AS$6*'1'!$AT$6)/('1'!Y23*0.0036)),IF('1'!AA23=2,(('1'!Z23*'1'!$AS$7*'1'!$AT$7)/('1'!Y23*0.0036)))) -> 64.107185 | AD23: =(('1'!AC23*'1'!$Q$10*1000000))/('1'!Y23*3600) -> 0 | AF23: =('1'!AE23/24)*0.454 -> 0 | AH23: =('1'!AG23/24)*0.454 -> 0 | AI23: 5200 | AJ23: =('1'!AI23/24)*0.454 -> 98.366667 | AL23: =('1'!AK23/24)*0.454 -> 0 | AN23: =('1'!AM23/24)*0.454 -> 0 | AP23: =('1'!AO23/24)*0.454 -> 0
A24: HORA | B24: 1 | C24: 2 | D24: 3 | E24: 4 | F24: 5 | G24: 6 | H24: 7 | I24: 8 | J24: 9 | K24: 10 | L24: 11 | M24: 12 | N24: 13 | O24: 14 | P24: 15 | Q24: 16 | R24: 0 | S24: Kilos | X24: 0.79166667 | Y24: 2812 | Z24: 987 | AA24: 1 | AB24: =IF('1'!AA24=1,(('1'!Z24*'1'!$AS$6*'1'!$AT$6)/('1'!Y24*0.0036)),IF('1'!AA24=2,(('1'!Z24*'1'!$AS$7*'1'!$AT$7)/('1'!Y24*0.0036)))) -> 64.836712 | AD24: =(('1'!AC24*'1'!$Q$10*1000000))/('1'!Y24*3600) -> 0 | AF24: =('1'!AE24/24)*0.454 -> 0 | AH24: =('1'!AG24/24)*0.454 -> 0 | AI24: 5200 | AJ24: =('1'!AI24/24)*0.454 -> 98.366667 | AL24: =('1'!AK24/24)*0.454 -> 0 | AN24: =('1'!AM24/24)*0.454 -> 0 | AP24: =('1'!AO24/24)*0.454 -> 0
A25: 0.41666667 | R25: =#DIV/0! -> #DIV/0! | T25: DATA | U25: =ESCALA!$A$3 -> 43891 | X25: 0.83333333 | Y25: 2779 | Z25: 987 | AA25: 1 | AB25: =IF('1'!AA25=1,(('1'!Z25*'1'!$AS$6*'1'!$AT$6)/('1'!Y25*0.0036)),IF('1'!AA25=2,(('1'!Z25*'1'!$AS$7*'1'!$AT$7)/('1'!Y25*0.0036)))) -> 65.606633 | AD25: =(('1'!AC25*'1'!$Q$10*1000000))/('1'!Y25*3600) -> 0 | AF25: =('1'!AE25/24)*0.454 -> 0 | AH25: =('1'!AG25/24)*0.454 -> 0 | AI25: 5200 | AJ25: =('1'!AI25/24)*0.454 -> 98.366667 | AL25: =('1'!AK25/24)*0.454 -> 0 | AN25: =('1'!AM25/24)*0.454 -> 0 | AP25: =('1'!AO25/24)*0.454 -> 0
A26: 0.66666667 | C26: 0.49 | D26: 0.55 | E26: 0.56 | F26: 0.46 | G26: 0.44 | H26: 0.55 | I26: 0.51 | K26: 0.44 | L26: 0.49 | M26: 0.46 | N26: 0.54 | O26: 0.43 | P26: 0.48 | X26: 0.875 | Y26: 2784 | Z26: 987 | AA26: 1 | AB26: =IF('1'!AA26=1,(('1'!Z26*'1'!$AS$6*'1'!$AT$6)/('1'!Y26*0.0036)),IF('1'!AA26=2,(('1'!Z26*'1'!$AS$7*'1'!$AT$7)/('1'!Y26*0.0036)))) -> 65.488805 | AD26: =(('1'!AC26*'1'!$Q$10*1000000))/('1'!Y26*3600) -> 0 | AF26: =('1'!AE26/24)*0.454 -> 0 | AH26: =('1'!AG26/24)*0.454 -> 0 | AI26: 5200 | AJ26: =('1'!AI26/24)*0.454 -> 98.366667 | AL26: =('1'!AK26/24)*0.454 -> 0 | AN26: =('1'!AM26/24)*0.454 -> 0 | AP26: =('1'!AO26/24)*0.454 -> 0
A27: Média | B27: =#DIV/0! -> #DIV/0! | C27: =#DIV/0! -> #DIV/0! | D27: =#DIV/0! -> #DIV/0! | E27: =#DIV/0! -> #DIV/0! | F27: =#DIV/0! -> #DIV/0! | G27: =#DIV/0! -> #DIV/0! | H27: =#DIV/0! -> #DIV/0! | I27: =#DIV/0! -> #DIV/0! | ... Q27: =#DIV/0! -> #DIV/0! | X27: 0.91666667 | Y27: 2787 | Z27: 987 | AA27: 1 | AB27: =IF('1'!AA27=1,(('1'!Z27*'1'!$AS$6*'1'!$AT$6)/('1'!Y27*0.0036)),IF('1'!AA27=2,(('1'!Z27*'1'!$AS$7*'1'!$AT$7)/('1'!Y27*0.0036)))) -> 65.418311 | AD27: =(('1'!AC27*'1'!$Q$10*1000000))/('1'!Y27*3600) -> 0 | AF27: =('1'!AE27/24)*0.454 -> 0 | AH27: =('1'!AG27/24)*0.454 -> 0 | AI27: 5200 | AJ27: =('1'!AI27/24)*0.454 -> 98.366667 | AL27: =('1'!AK27/24)*0.454 -> 0 | AN27: =('1'!AM27/24)*0.454 -> 0 | AP27: =('1'!AO27/24)*0.454 -> 0
A28: OBSERVAÇÕES | X28: 0.95833333 | Y28: 2795 | Z28: 987 | AA28: 1 | AB28: =IF('1'!AA28=1,(('1'!Z28*'1'!$AS$6*'1'!$AT$6)/('1'!Y28*0.0036)),IF('1'!AA28=2,(('1'!Z28*'1'!$AS$7*'1'!$AT$7)/('1'!Y28*0.0036)))) -> 65.231067 | AD28: =(('1'!AC28*'1'!$Q$10*1000000))/('1'!Y28*3600) -> 0 | AF28: =('1'!AE28/24)*0.454 -> 0 | AH28: =('1'!AG28/24)*0.454 -> 0 | AI28: 5200 | AJ28: =('1'!AI28/24)*0.454 -> 98.366667 | AL28: =('1'!AK28/24)*0.454 -> 0 | AN28: =('1'!AM28/24)*0.454 -> 0 | AP28: =('1'!AO28/24)*0.454 -> 0
X29: 1 | Y29: 2791 | Z29: 987 | AA29: 1 | AB29: =IF('1'!AA29=1,(('1'!Z29*'1'!$AS$6*'1'!$AT$6)/('1'!Y29*0.0036)),IF('1'!AA29=2,(('1'!Z29*'1'!$AS$7*'1'!$AT$7)/('1'!Y29*0.0036)))) -> 65.324555 | AD29: =(('1'!AC29*'1'!$Q$10*1000000))/('1'!Y29*3600) -> 0 | AF29: =('1'!AE29/24)*0.454 -> 0 | AH29: =('1'!AG29/24)*0.454 -> 0 | AI29: 5200 | AJ29: =('1'!AI29/24)*0.454 -> 98.366667 | AL29: =('1'!AK29/24)*0.454 -> 0 | AN29: =('1'!AM29/24)*0.454 -> 0 | AP29: =('1'!AO29/24)*0.454 -> 0
X30: Total | Y30: =SUM('1'!Y6:Y29)*3.6 -> 242650.8 | Z30: =SUM('1'!Z6:Z29) -> 23688 | AF30: =SUM('1'!AF6:AF29) -> 0 | AH30: =SUM('1'!AH6:AH29) -> 0 | AJ30: =SUM('1'!AJ6:AJ29) -> 2360.8 | AL30: =SUM('1'!AL6:AL29) -> 0 | AN30: =SUM('1'!AN6:AN29) -> 0 | AP30: =SUM('1'!AP6:AP29) -> 0
X32: S.A.L (l) - (kg) | Z32: =SUMIF('1'!AA6:AA29,"=1",'1'!Z6:Z29) -> 23688 | AA32: ='1'!Z32*'1'!AS6 -> 31505.04 | AB32: =SUMIF('1'!$AA$6:$AA$29,"=1",'1'!$AB$6:$AB$29)/COUNTIF('1'!$AA$6:$AA$29,"=1") -> 64.932123 | AC32: =SUMIF('1'!AA6:AA29,"=1",'1'!AC6:AC29) -> 0
X33: PAC 18 (l) - (kg) | Z33: =SUMIF('1'!AA6:AA29,"=2",'1'!Z6:Z29) -> 0 | AA33: ='1'!Z33*'1'!AS7 -> 0 | AB33: =SUMIF('1'!$AA$6:$AA$29,"=2",'1'!$AB$6:$AB$29)/COUNTIF('1'!$AA$6:$AA$29,"=2") -> #DIV/0! | AC33: =SUMIF('1'!AA6:AA29,"=2",'1'!AC6:AC29) -> 0
X34: Média | Y34: =AVERAGE('1'!Y6:Y29) -> 2808.4583 | Z34: =AVERAGE('1'!Z6:Z29) -> 987 | AC34: =SUM('1'!AC6:AC29)/COUNTIF('1'!AC6:AC29,"<>0") -> 0 | AD34: =SUM('1'!AD6:AD29)/COUNTIF('1'!AD6:AD29,"<>0") -> #DIV/0! | AF34: =AVERAGE('1'!AF6:AF29) -> 0 | AH34: =AVERAGE('1'!AH6:AH29) -> 0 | AJ34: ='1'!AJ30/24 -> 98.366667 | AL34: =AVERAGE('1'!AL6:AL29) -> 0 | AN34: =AVERAGE('1'!AN6:AN29) -> 0 | AP34: =AVERAGE('1'!AP6:AP29) -> 0
C35: Alcalinidade (mg/L) | F35: Ferro (mg/L) | I35: Manganês (mg/L) | L35: Alumínio (mg/L) | U35: TÉCNICO | X35: Decantadores | AA35: Filtros | AJ35: CLORAÇÃO INTERMEDIÁRIA | AO35: PÓS CLORAÇÃO
B36: HORA | C36: Bruta | D36: Dec. | E36: Trat (R-3) | F36: Bruta | G36: Filt. | H36: Trat (R-3) | I36: Bruta | J36: Filt. | K36: Trat (R-3) | L36: Trat (R-3) | X36: Lavados | AA36: Lavados
B37: 0.33333333 | C37: 81.6 | D37: 53.4 | E37: 48.4 | F37: 0.8 | G37: 0.1 | H37: 0.1 | I37: 0.06 | J37: 0.06 | K37: 0.03 | L37: 0.05 | U37: ='1'!V12 -> 0 | X37: HORAS OPERANDO | Z37: =COUNTA('1'!Z6:Z29) -> 24 | AJ37: CARRETA | AL37: CILINDROS | AO37: CARRETA | AQ37: CILINDROS
B38: 0.66666667 | AJ38: CONSUMO | AK38: =SUM('1'!AF30+'1'!AH30) -> 0 | AL38: CONSUMO | AM38: =SUM('1'!AL30+'1'!AN30) -> 0 | AO38: CONSUMO | AP38: ='1'!AJ30 -> 2360.8 | AQ38: CONSUMO | AR38: ='1'!AP30 -> 0
A39: Nº amostras de água TRATADA | C39: Nº amostras de água FILTRADA | E39: Nº amostras de água tratada/filtrada FORA DO PADRÃO | J39: Nº amostras de água tratada/filtrada no PADRÃO | O39: Nº de amostras com turbidez menor ou igual a 0,5 NTU | R39: ÁGUA FILTRADA | S39: Nº de amostras com turbidez menor ou igual a 1,0 NTU | AJ39: DOSAGEM | AK39: =('1'!AK38/'1'!Y30)*1000 -> 0 | AL39: DOSAGEM | AM39: =('1'!AM38/'1'!Y30)*1000 -> 0 | AO39: DOSAGEM | AP39: =('1'!AP38/'1'!Y30)*1000 -> 9.7292076 | AQ39: DOSAGEM | AR39: =('1'!AR38/'1'!Y30)*1000 -> 0
A40: COR | B40: TURBIDEZ | C40: TURBIDEZ | E40: COR | G40: TURBIDEZ | J40: COR | L40: TURBIDEZ | X40: ESTOQUE DE COAGULANTE | AJ40: Consumo Total | AL40: =SUM('1'!AK38,'1'!AM38) -> 0 | AO40: Consumo Total | AQ40: =SUM('1'!AP38,'1'!AR38) -> 2360.8
A41: =COUNTA('1'!E7:E18) -> 12 | B41: =COUNTA('1'!I7:I18) -> 12 | C41: =COUNTA('1'!J7:J18) -> 12 | D41: =COUNTA('1'!K7:K18) -> 12 | E41: =COUNTIF('1'!E7:E18,">15") -> 0 | G41: =COUNTIF('1'!J7:J18,">1") -> 0 | J41: ='1'!A41-'1'!E41 -> 12 | L41: ='1'!C41-'1'!G41 -> 12 | O41: =COUNTIF('1'!J7:J18,"<=0,5") -> 12 | S41: =COUNTIF('1'!J7:J18,"<=1,0") -> 12 | AJ41: Dosagem Final | AL41: =SUM(('1'!AK38+'1'!AM38)/'1'!Y30)*1000 -> 0 | AO41: Dosagem Final | AQ41: =SUM(('1'!AP38+'1'!AR38)/'1'!Y30)*1000 -> 9.7292076
O42: ÁGUA FILTRATADA | X42: SULFATO DE ALUMÍNIO
H43: Nº de amostras água tratada com turbidez <= 5,0 NTU | L43: Nº de amostras água tratada para aluminio | Q43: Nº de amostras com turbidez entre 0,5 e 1,0 NTU | X43: TINA 01 | Z43: TINA 02 | AB43: TINA 03 | AD43: TANQUE
...

Sheet 2
D2: CONTROLE DE ANÁLISE FÍSICO - QUÍMICAS \ ETA CASTELO BRANCO | AB2: CONTROLE DE PRODUTOS QUÍMICOS APLICADOS \ ETA CASTELO BRANCO
A4: HORA | B4: COR (Uc) | F4: TURBIDEZ (Ut) | K4: Ph | O4: CLORO RESIDUAL (mg/L) | R4: DOSAGEM DO COAGULANTE | T4: VAZÃO DA ETA | U4: TIPO DE COAGULANTE | V4: TÉCNICO | X4: Hora | Y4: Vazão ETA (l/s) | Z4: Vazão Coagulante (l/h) | AA4: Código | AB4: Dosagem (mg/l) | AC4: Vazão Polímero (l/h) | AD4: Dosagem (mg/l) | AE4: Pré 1 (Lib/dia) | AF4: Pré 1 (Kg/h) | AG4: Pré 2 (Lib/dia) | AH4: Pré 2 (Kg/h) | AI4: Pós (Lib/dia) | AJ4: Pós (Kg/h) | AK4: Pré 1 (Lib/dia) cilindros | AL4: Pré 1 (Kg/h) cilindros | AM4: Pré 2 (Lib/dia) cilindros | AN4: Pré 2 (Kg/h) cilindros | AO4: Pós (Lib/dia) cilindros | AP4: Pós (Kg/h) cilindros | AQ4: COAGULANTE | AU4: Tempo de Utilização (h)
AQ5: Codigo | AR5: Nome | AS5: d (g/ml) | AT5: C (%)
B6: Bruta | C6: DEC_1 | D6: DEC_2 | E6: TRAT | F6: Bruta | G6: DEC_1 | H6: DEC_2 | I6: TRAT | J6: FILT | K6: Bruta | L6: DEC_1 | M6: DEC_2 | N6: TRAT | O6: TRAT | P6: DEC_1 | Q6: DEC_2 | R6: L/h | S6: mg/l | T6: L/s | X6: 0.041666667 | Y6: 2784 | Z6: 987 | AA6: 1 | AB6: =IF('2'!AA6=1,(('2'!Z6*'2'!$AS$6*'2'!$AT$6)/('2'!Y6*0.0036)),IF('2'!AA6=2,(('2'!Z6*'2'!$AS$7*'2'!$AT$7)/('2'!Y6*0.0036)))) -> 65.488805 | AD6: =(('2'!AC6*'2'!$Q$10*1000000))/('2'!Y6*3600) -> 0 | AF6: =('2'!AE6/24)*0.454 -> 0 | AH6: =('2'!AG6/24)*0.454 -> 0 | AI6: 5200 | AJ6: =('2'!AI6/24)*0.454 -> 98.366667 | AL6: =('2'!AK6/24)*0.454 -> 0 | AN6: =('2'!AM6/24)*0.454 -> 0 | AP6: =('2'!AO6/24)*0.454 -> 0 | AQ6: 1 | AR6: S.A.L | AS6: 1.33 | AT6: 0.5 | AU6: 0
A7: 0 | B7: 80 | C7: 12.5 | D7: 12.5 | E7: 2.5 | F7: 9.2 | G7: 1.2 | H7: 1.4 | I7: 0.4 | J7: 0.3 | K7: 7.3 | L7: 6.7 | M7: 6.7 | N7: 6.4 | O7: 3.2 | R7: ='1'!$Z$29 -> 987 | S7: ='1'!$AB$29 -> 65.324555 | T7: ='1'!$Y$29 -> 2791 | U7: =IF('2'!AA6=1,'2'!AR6,'2'!AR7) -> S.A.L | V7: =ESCALA!$B$3 -> 0 | X7: 2653.0833 | Y7: 2784 | Z7: 987 | AA7: 1 | AB7: =IF('2'!AA7=1,(('2'!Z7*'2'!$AS$6*'2'!$AT$6)/('2'!Y7*0.0036)),IF('2'!AA7=2,(('2'!Z7*'2'!$AS$7*'2'!$AT$7)/('2'!Y7*0.0036)))) -> 65.488805 | AD7: =(('2'!AC7*'2'!$Q$10*1000000))/('2'!Y7*3600) -> 0 | AF7: =('2'!AE7/24)*0.454 -> 0 | AH7: =('2'!AG7/24)*0.454 -> 0 | AI7: 5200 | AJ7: =('2'!AI7/24)*0.454 -> 98.366667 | AL7: =('2'!AK7/24)*0.454 -> 0 | AN7: =('2'!AM7/24)*0.454 -> 0 | AP7: =('2'!AO7/24)*0.454 -> 0 | AQ7: 2 | AR7: PAC 18 | AS7: 1.377 | AT7: 1 | AU7: 24
A8: 0.083333333 | B8: 80 | C8: 12.5 | D8: 12.5 | E8: 2.5 | F8: 9.2 | G8: 1.2 | H8: 1.4 | I8: 0.4 | J8: 0.3 | K8: 7.3 | L8: 6.7 | M8: 6.7 | N8: 6.4 | O8: 3.3 | R8: ='2'!Z7 -> 987 | S8: ='2'!AB7 -> 65.488805 | T8: ='2'!Y7 -> 2784 | U8: =IF('2'!AA7=1,'2'!AR6,'2'!AR7) -> S.A.L | X8: 2645.125 | Y8: 2754 | Z8: 987 | AA8: 1 | AB8: =IF('2'!AA8=1,(('2'!Z8*'2'!$AS$6*'2'!$AT$6)/('2'!Y8*0.0036)),IF('2'!AA8=2,(('2'!Z8*'2'!$AS$7*'2'!$AT$7)/('2'!Y8*0.0036)))) -> 66.202191 | AD8: =(('2'!AC8*'2'!$Q$10*1000000))/('2'!Y8*3600) -> 0 | AF8: =('2'!AE8/24)*0.454 -> 0 | AH8: =('2'!AG8/24)*0.454 -> 0 | AI8: 5200 | AJ8: =('2'!AI8/24)*0.454 -> 98.366667 | AL8: =('2'!AK8/24)*0.454 -> 0 | AN8: =('2'!AM8/24)*0.454 -> 0 | AP8: =('2'!AO8/24)*0.454 -> 0 | AQ8: Polímero Catiônico
A9: 0.16666667 | B9: 80 | C9: 12.5 | D9: 12.5 | E9: 2.5 | F9: 9.2 | G9: 1.2 | H9: 1.4 | I9: 0.3 | J9: 0.3 | K9: 7.3 | L9: 6.7 | M9: 6.7 | N9: 6.4 | O9: 3.5 | R9: ='2'!Z9 -> 987 | S9: ='2'!AB9 -> 62.934357 | T9: ='2'!Y9 -> 2897 | U9: =IF('2'!AA9=1,'2'!AR6,'2'!AR7) -> S.A.L | X9: 0.16666667 | Y9: 2897 | Z9: 987 | AA9: 1 | AB9: =IF('2'!AA9=1,(('2'!Z9*'2'!$AS$6*'2'!$AT$6)/('2'!Y9*0.0036)),IF('2'!AA9=2,(('2'!Z9*'2'!$AS$7*'2'!$AT$7)/('2'!Y9*0.0036)))) -> 62.934357 | AD9: =(('2'!AC9*'2'!$Q$10*1000000))/('2'!Y9*3600) -> 0 | AF9: =('2'!AE9/24)*0.454 -> 0 | AH9: =('2'!AG9/24)*0.454 -> 0 | AI9: 5200 | AJ9: =('2'!AI9/24)*0.454 -> 98.366667 | AL9: =('2'!AK9/24)*0.454 -> 0 | AN9: =('2'!AM9/24)*0.454 -> 0 | AP9: =('2'!AO9/24)*0.454 -> 0 | AQ9: Nome | AT9: C (%)
A10: 0.25 | B10: 80 | C10: 12.5 | D10: 12.5 | E10: 2.5 | F10: 9.2 | G10: 1.2 | H10: 1.4 | I10: 0.3 | J10: 0.3 | K10: 7.3 | L10: 6.7 | M10: 6.7 | N10: 6.4 | O10: 3.5 | R10: ='2'!Z11 -> 987 | S10: ='2'!AB11 -> 65.724886 | T10: ='2'!Y11 -> 2774 | U10: =IF('2'!AA11=1,'2'!AR6,'2'!AR7) -> S.A.L | X10: 0.20833333 | Y10: 2790 | Z10: 987 | AA10: 1 | AB10: =IF('2'!AA10=1,(('2'!Z10*'2'!$AS$6*'2'!$AT$6)/('2'!Y10*0.0036)),IF('2'!AA10=2,(('2'!Z10*'2'!$AS$7*'2'!$AT$7)/('2'!Y10*0.0036)))) -> 65.347969 | AD10: =(('2'!AC10*'2'!$Q$10*1000000))/('2'!Y10*3600) -> 0 | AF10: =('2'!AE10/24)*0.454 -> 0 | AH10: =('2'!AG10/24)*0.454 -> 0 | AI10: 5200 | AJ10: =('2'!AI10/24)*0.454 -> 98.366667 | AL10: =('2'!AK10/24)*0.454 -> 0 | AN10: =('2'!AM10/24)*0.454 -> 0 | AP10: =('2'!AO10/24)*0.454 -> 0 | AQ10: Aguapol 200 | AT10: 0.002
A11: 0.33333333 | B11: 50 | C11: 7.5 | D11: 7.5 | E11: 2.5 | F11: 7.9 | G11: 1.2 | H11: 1.2 | I11: 0.3 | J11: 0.3 | K11: 7.3 | L11: 6.6 | M11: 6.6 | N11: 6.4 | O11: 3.5 | R11: ='2'!Z13 -> 987 | S11: ='2'!AB13 -> 65.986548 | T11: ='2'!Y13 -> 2763 | U11: =IF('2'!AA13=1,'2'!AR6,'2'!AR7) -> S.A.L | X11: 0.25 | Y11: 2774 | Z11: 987 | AA11: 1 | AB11: =IF('2'!AA11=1,(('2'!Z11*'2'!$AS$6*'2'!$AT$6)/('2'!Y11*0.0036)),IF('2'!AA11=2,(('2'!Z11*'2'!$AS$7*'2'!$AT$7)/('2'!Y11*0.0036)))) -> 65.724886 | AD11: =(('2'!AC11*'2'!$Q$10*1000000))/('2'!Y11*3600) -> 0 | AF11: =('2'!AE11/24)*0.454 -> 0 | AH11: =('2'!AG11/24)*0.454 -> 0 | AI11: 5000 | AJ11: =('2'!AI11/24)*0.454 -> 94.583333 | AL11: =('2'!AK11/24)*0.454 -> 0 | AN11: =('2'!AM11/24)*0.454 -> 0 | AP11: =('2'!AO11/24)*0.454 -> 0
A12: 0.41666667 | B12: 50 | C12: 7.5 | D12: 7.5 | E12: 2.5 | F12: 7.8 | G12: 1.2 | H12: 1.2 | I12: 0.3 | J12: 0.3 | K12: 7.3 | L12: 6.6 | M12: 6.6 | N12: 6.4 | O12: 3.3 | R12: ='2'!Z15 -> 940 | S12: ='2'!AB15 -> 62.102607 | T12: ='2'!Y15 -> 2796 | U12: =IF('2'!AA15=1,'2'!AR6,'2'!AR7) -> S.A.L | V12: =ESCALA!$B$4 -> 0 | X12: 0.29166667 | Y12: 2768 | Z12: 987 | AA12: 1 | AB12: =IF('2'!AA12=1,(('2'!Z12*'2'!$AS$6*'2'!$AT$6)/('2'!Y12*0.0036)),IF('2'!AA12=2,(('2'!Z12*'2'!$AS$7*'2'!$AT$7)/('2'!Y12*0.0036)))) -> 65.867353 | AD12: =(('2'!AC12*'2'!$Q$10*1000000))/('2'!Y12*3600) -> 0 | AF12: =('2'!AE12/24)*0.454 -> 0 | AH12: =('2'!AG12/24)*0.454 -> 0 | AI12: 5000 | AJ12: =('2'!AI12/24)*0.454 -> 94.583333 | AL12: =('2'!AK12/24)*0.454 -> 0 | AN12: =('2'!AM12/24)*0.454 -> 0 | AP12: =('2'!AO12/24)*0.454 -> 0
A13: 0.5 | B13: 50 | C13: 10 | D13: 10 | E13: 2.5 | F13: 8.5 | G13: 1.5 | H13: 1.6 | I13: 0.3 | J13: 0.3 | K13: 7.3 | L13: 6.6 | M13: 6.6 | N13: 6.4 | O13: 3 | R13: ='2'!Z17 -> 940 | S13: ='2'!AB17 -> 61.727298 | T13: ='2'!Y17 -> 2813 | U13: =IF('2'!AA17=1,'2'!AR6,'2'!AR7) -> S.A.L | X13: 0.33333333 | Y13: 2763 | Z13: 987 | AA13: 1 | AB13: =IF('2'!AA13=1,(('2'!Z13*'2'!$AS$6*'2'!$AT$6)/('2'!Y13*0.0036)),IF('2'!AA13=2,(('2'!Z13*'2'!$AS$7*'2'!$AT$7)/('2'!Y13*0.0036)))) -> 65.986548 | AD13: =(('2'!AC13*'2'!$Q$10*1000000))/('2'!Y13*3600) -> 0 | AF13: =('2'!AE13/24)*0.454 -> 0 | AH13: =('2'!AG13/24)*0.454 -> 0 | AI13: 2000 | AJ13: =('2'!AI13/24)*0.454 -> 37.833333 | AK13: 1500 | AL13: =('2'!AK13/24)*0.454 -> 28.375 | AM13: 1500 | AN13: =('2'!AM13/24)*0.454 -> 28.375 | AP13: =('2'!AO13/24)*0.454 -> 0
A14: 0.58333333 | B14: 50 | C14: 10 | D14: 10 | E14: 2.5 | F14: 8.1 | G14: 1.3 | H14: 1.5 | I14: 0.3 | J14: 0.3 | K14: 7.3 | L14: 6.6 | M14: 6.6 | N14: 6.4 | O14: 3.8 | R14: ='2'!Z19 -> 940 | S14: ='2'!AB19 -> 61.991749 | T14: ='2'!Y19 -> 2801 | U14: =IF('2'!AA19=1,'2'!AR6,'2'!AR7) -> S.A.L | X14: 0.375 | Y14: 2819 | Z14: 940 | AA14: 1 | AB14: =IF('2'!AA14=1,(('2'!Z14*'2'!$AS$6*'2'!$AT$6)/('2'!Y14*0.0036)),IF('2'!AA14=2,(('2'!Z14*'2'!$AS$7*'2'!$AT$7)/('2'!Y14*0.0036)))) -> 61.595917 | AD14: =(('2'!AC14*'2'!$Q$10*1000000))/('2'!Y14*3600) -> 0 | AF14: =('2'!AE14/24)*0.454 -> 0 | AH14: =('2'!AG14/24)*0.454 -> 0 | AI14: 2000 | AJ14: =('2'!AI14/24)*0.454 -> 37.833333 | AK14: 1500 | AL14: =('2'!AK14/24)*0.454 -> 28.375 | AM14: 1500 | AN14: =('2'!AM14/24)*0.454 -> 28.375 | AP14: =('2'!AO14/24)*0.454 -> 0
A15: 0.66666667 | B15: 50 | C15: 10 | D15: 10 | E15: 2.5 | F15: 8 | G15: 1.3 | H15: 1.7 | I15: 0.3 | J15: 0.3 | K15: 7.3 | L15: 6.6 | M15: 6.6 | N15: 6.4 | O15: 2.5 | R15: ='2'!Z21 -> 940 | S15: ='2'!AB21 -> 58.681612 | T15: ='2'!Y21 -> 2959 | U15: =IF('2'!AA21=1,'2'!AR6,'2'!AR7) -> S.A.L | X15: 0.41666667 | Y15: 2796 | Z15: 940 | AA15: 1 | AB15: =IF('2'!AA15=1,(('2'!Z15*'2'!$AS$6*'2'!$AT$6)/('2'!Y15*0.0036)),IF('2'!AA15=2,(('2'!Z15*'2'!$AS$7*'2'!$AT$7)/('2'!Y15*0.0036)))) -> 62.102607 | AD15: =(('2'!AC15*'2'!$Q$10*1000000))/('2'!Y15*3600) -> 0 | AF15: =('2'!AE15/24)*0.454 -> 0 | AH15: =('2'!AG15/24)*0.454 -> 0 | AI15: 2000 | AJ15: =('2'!AI15/24)*0.454 -> 37.833333 | AK15: 1500 | AL15: =('2'!AK15/24)*0.454 -> 28.375 | AM15: 1500 | AN15: =('2'!AM15/24)*0.454 -> 28.375 | AP15: =('2'!AO15/24)*0.454 -> 0
A16: 0.75 | B16: 50 | C16: 10 | D16: 10 | E16: 2.5 | F16: 8.1 | G16: 1.4 | H16: 1.7 | I16: 0.3 | J16: 0.4 | K16: 7.3 | L16: 6.6 | M16: 6.6 | N16: 6.4 | O16: 2.5 | R16: ='2'!Z23 -> 940 | S16: ='2'!AB23 -> 61.705362 | T16: ='2'!Y23 -> 2814 | U16: =IF('2'!AA23=1,'2'!AR6,'2'!AR7) -> S.A.L | X16: 0.45833333 | Y16: 2754 | Z16: 940 | AA16: 1 | AB16: =IF('2'!AA16=1,(('2'!Z16*'2'!$AS$6*'2'!$AT$6)/('2'!Y16*0.0036)),IF('2'!AA16=2,(('2'!Z16*'2'!$AS$7*'2'!$AT$7)/('2'!Y16*0.0036)))) -> 63.049705 | AD16: =(('2'!AC16*'2'!$Q$10*1000000))/('2'!Y16*3600) -> 0 | AF16: =('2'!AE16/24)*0.454 -> 0 | AH16: =('2'!AG16/24)*0.454 -> 0 | AI16: 2000 | AJ16: =('2'!AI16/24)*0.454 -> 37.833333 | AK16: 1500 | AL16: =('2'!AK16/24)*0.454 -> 28.375 | AM16: 1500 | AN16: =('2'!AM16/24)*0.454 -> 28.375 | AP16: =('2'!AO16/24)*0.454 -> 0
A17: 0.83333333 | B17: 70 | C17: 12.5 | D17: 12.5 | E17: 2.5 | F17: 8.4 | G17: 1.3 | H17: 1.6 | I17: 0.3 | J17: 0.4 | K17: 7.3 | L17: 6.7 | M17: 6.7 | N17: 6.4 | O17: 2.6 | R17: ='2'!Z25 -> 940 | S17: ='2'!AB25 -> 62.415129 | T17: ='2'!Y25 -> 2782 | U17: =IF('2'!AA25=1,'2'!AR6,'2'!AR7) -> S.A.L | V17: =ESCALA!$C$4 -> 0 | X17: 0.5 | Y17: 2813 | Z17: 940 | AA17: 1 | AB17: =IF('2'!AA17=1,(('2'!Z17*'2'!$AS$6*'2'!$AT$6)/('2'!Y17*0.0036)),IF('2'!AA17=2,(('2'!Z17*'2'!$AS$7*'2'!$AT$7)/('2'!Y17*0.0036)))) -> 61.727298 | AD17: =(('2'!AC17*'2'!$Q$10*1000000))/('2'!Y17*3600) -> 0 | AF17: =('2'!AE17/24)*0.454 -> 0 | AH17: =('2'!AG17/24)*0.454 -> 0 | AI17: 2000 | AJ17: =('2'!AI17/24)*0.454 -> 37.833333 | AK17: 1500 | AL17: =('2'!AK17/24)*0.454 -> 28.375 | AM17: 1500 | AN17: =('2'!AM17/24)*0.454 -> 28.375 | AP17: =('2'!AO17/24)*0.454 -> 0
A18: 0.91666667 | B18: 70 | C18: 12.5 | D18: 12.5 | E18: 2.5 | F18: 8.5 | G18: 1.3 | H18: 1.6 | I18: 0.3 | J18: 0.4 | K18: 7.3 | L18: 6.7 | M18: 6.7 | N18: 6.4 | O18: 2.7 | R18: ='2'!Z27 -> 940 | S18: ='2'!AB27 -> 62.437572 | T18: ='2'!Y27 -> 2781 | U18: =IF('2'!AA27=1,'2'!AR6,'2'!AR7) -> S.A.L | X18: 0.54166667 | Y18: 2802 | Z18: 940 | AA18: 1 | AB18: =IF('2'!AA18=1,(('2'!Z18*'2'!$AS$6*'2'!$AT$6)/('2'!Y18*0.0036)),IF('2'!AA18=2,(('2'!Z18*'2'!$AS$7*'2'!$AT$7)/('2'!Y18*0.0036)))) -> 61.969625 | AD18: =(('2'!AC18*'2'!$Q$10*1000000))/('2'!Y18*3600) -> 0 | AF18: =('2'!AE18/24)*0.454 -> 0 | AH18: =('2'!AG18/24)*0.454 -> 0 | AI18: 2000 | AJ18: =('2'!AI18/24)*0.454 -> 37.833333 | AK18: 1500 | AL18: =('2'!AK18/24)*0.454 -> 28.375 | AM18: 1500 | AN18: =('2'!AM18/24)*0.454 -> 28.375 | AP18: =('2'!AO18/24)*0.454 -> 0
A19: Média | B19: {=IF('2'!B7:B18>0.01,AVERAGE('2'!B7:B18),"")} -> 63.333333 | C19: {=IF('2'!C7:C18>0.01,AVERAGE('2'!C7:C18),"")} -> 10.833333 | D19: {=IF('2'!D7:D18>0.01,AVERAGE('2'!D7:D18),"")} -> 10.833333 | E19: {=IF('2'!E7:E18>0.01,AVERAGE('2'!E7:E18),"")} -> 2.5 | F19: {=IF('2'!F7:F18>0.01,AVERAGE('2'!F7:F18),"")} -> 8.5083333 | G19: {=IF('2'!G7:G18>0.01,AVERAGE('2'!G7:G18),"")} -> 1.275 | H19: {=IF('2'!H7:H18>0.01,AVERAGE('2'!H7:H18),"")} -> 1.475 | I19: {=IF('2'!I7:I18>0.01,AVERAGE('2'!I7:I18),"")} -> 0.31666667 | ... S19: {=IF('2'!S7:S18>0.01,AVERAGE('2'!S7:S18),"")} -> 63.043373 | X19: 0.58333333 | Y19: 2801 | Z19: 940 | AA19: 1 | AB19: =IF('2'!AA19=1,(('2'!Z19*'2'!$AS$6*'2'!$AT$6)/('2'!Y19*0.0036)),IF('2'!AA19=2,(('2'!Z19*'2'!$AS$7*'2'!$AT$7)/('2'!Y19*0.0036)))) -> 61.991749 | AD19: =(('2'!AC19*'2'!$Q$10*1000000))/('2'!Y19*3600) -> 0 | AF19: =('2'!AE19/24)*0.454 -> 0 | AH19: =('2'!AG19/24)*0.454 -> 0 | AI19: 2000 | AJ19: =('2'!AI19/24)*0.454 -> 37.833333 | AK19: 1500 | AL19: =('2'!AK19/24)*0.454 -> 28.375 | AM19: 1500 | AN19: =('2'!AM19/24)*0.454 -> 28.375 | AP19: =('2'!AO19/24)*0.454 -> 0
A20: Máximo | B20: =MAX('2'!B7:B18) -> 80 | C20: =MAX('2'!C7:C18) -> 12.5 | D20: =MAX('2'!D7:D18) -> 12.5 | E20: =MAX('2'!E7:E18) -> 2.5 | F20: =MAX('2'!F7:F18) -> 9.2 | G20: =MAX('2'!G7:G18) -> 1.5 | H20: =MAX('2'!H7:H18) -> 1.7 | I20: =MAX('2'!I7:I18) -> 0.4 | ... S20: =MAX('2'!S7:S18) -> 65.986548 | X20: 0.625 | Y20: 2846 | Z20: 940 | AA20: 1 | AB20: =IF('2'!AA20=1,(('2'!Z20*'2'!$AS$6*'2'!$AT$6)/('2'!Y20*0.0036)),IF('2'!AA20=2,(('2'!Z20*'2'!$AS$7*'2'!$AT$7)/('2'!Y20*0.0036)))) -> 61.011556 | AD20: =(('2'!AC20*'2'!$Q$10*1000000))/('2'!Y20*3600) -> 0 | AF20: =('2'!AE20/24)*0.454 -> 0 | AH20: =('2'!AG20/24)*0.454 -> 0 | AI20: 2000 | AJ20: =('2'!AI20/24)*0.454 -> 37.833333 | AK20: 1500 | AL20: =('2'!AK20/24)*0.454 -> 28.375 | AM20: 1500 | AN20: =('2'!AM20/24)*0.454 -> 28.375 | AP20: =('2'!AO20/24)*0.454 -> 0
A21: Mínimo | B21: =MIN('2'!B7:B18) -> 50 | C21: =MIN('2'!C7:C18) -> 7.5 | D21: =MIN('2'!D7:D18) -> 7.5 | E21: =MIN('2'!E7:E18) -> 2.5 | F21: =MIN('2'!F7:F18) -> 7.8 | G21: =MIN('2'!G7:G18) -> 1.2 | H21: =MIN('2'!H7:H18) -> 1.2 | I21: =MIN('2'!I7:I18) -> 0.3 | ... S21: =MIN('2'!S7:S18) -> 58.681612 | X21: 0.66666667 | Y21: 2959 | Z21: 940 | AA21: 1 | AB21: =IF('2'!AA21=1,(('2'!Z21*'2'!$AS$6*'2'!$AT$6)/('2'!Y21*0.0036)),IF('2'!AA21=2,(('2'!Z21*'2'!$AS$7*'2'!$AT$7)/('2'!Y21*0.0036)))) -> 58.681612 | AD21: =(('2'!AC21*'2'!$Q$10*1000000))/('2'!Y21*3600) -> 0 | AF21: =('2'!AE21/24)*0.454 -> 0 | AH21: =('2'!AG21/24)*0.454 -> 0 | AI21: 2000 | AJ21: =('2'!AI21/24)*0.454 -> 37.833333 | AK21: 1500 | AL21: =('2'!AK21/24)*0.454 -> 28.375 | AM21: 1500 | AN21: =('2'!AM21/24)*0.454 -> 28.375 | AP21: =('2'!AO21/24)*0.454 -> 0
R22: Total | X22: 0.70833333 | Y22: 2854 | Z22: 940 | AA22: 1 | AB22: =IF('2'!AA22=1,(('2'!Z22*'2'!$AS$6*'2'!$AT$6)/('2'!Y22*0.0036)),IF('2'!AA22=2,(('2'!Z22*'2'!$AS$7*'2'!$AT$7)/('2'!Y22*0.0036)))) -> 60.840536 | AD22: =(('2'!AC22*'2'!$Q$10*1000000))/('2'!Y22*3600) -> 0 | AF22: =('2'!AE22/24)*0.454 -> 0 | AH22: =('2'!AG22/24)*0.454 -> 0 | AI22: 5000 | AJ22: =('2'!AI22/24)*0.454 -> 94.583333 | AL22: =('2'!AK22/24)*0.454 -> 0 | AN22: =('2'!AM22/24)*0.454 -> 0 | AP22: =('2'!AO22/24)*0.454 -> 0
A23: TURBIDEZ DOS FILTROS DA 1ª E 2ª ETAPAS | R23: 440 | S23: Litros | X23: 0.75 | Y23: 2814 | Z23: 940 | AA23: 1 | AB23: =IF('2'!AA23=1,(('2'!Z23*'2'!$AS$6*'2'!$AT$6)/('2'!Y23*0.0036)),IF('2'!AA23=2,(('2'!Z23*'2'!$AS$7*'2'!$AT$7)/('2'!Y23*0.0036)))) -> 61.705362 | AD23: =(('2'!AC23*'2'!$Q$10*1000000))/('2'!Y23*3600) -> 0 | AF23: =('2'!AE23/24)*0.454 -> 0 | AH23: =('2'!AG23/24)*0.454 -> 0 | AI23: 5000 | AJ23: =('2'!AI23/24)*0.454 -> 94.583333 | AL23: =('2'!AK23/24)*0.454 -> 0 | AN23: =('2'!AM23/24)*0.454 -> 0 | AP23: =('2'!AO23/24)*0.454 -> 0
A24: HORA | B24: 1 | C24: 2 | D24: 3 | E24: 4 | F24: 5 | G24: 6 | H24: 7 | I24: 8 | J24: 9 | K24: 10 | L24: 11 | M24: 12 | N24: 13 | O24: 14 | P24: 15 | Q24: 16 | R24: 0 | S24: Kilos | X24: 0.79166667 | Y24: 2794 | Z24: 940 | AA24: 1 | AB24: =IF('2'!AA24=1,(('2'!Z24*'2'!$AS$6*'2'!$AT$6)/('2'!Y24*0.0036)),IF('2'!AA24=2,(('2'!Z24*'2'!$AS$7*'2'!$AT$7)/('2'!Y24*0.0036)))) -> 62.147061 | AD24: =(('2'!AC24*'2'!$Q$10*1000000))/('2'!Y24*3600) -> 0 | AF24: =('2'!AE24/24)*0.454 -> 0 | AH24: =('2'!AG24/24)*0.454 -> 0 | AI24: 5000 | AJ24: =('2'!AI24/24)*0.454 -> 94.583333 | AL24: =('2'!AK24/24)*0.454 -> 0 | AN24: =('2'!AM24/24)*0.454 -> 0 | AP24: =('2'!AO24/24)*0.454 -> 0
A25: 0.41666667 | C25: 0.37 | D25: 0.45 | E25: 0.37 | F25: 0.31 | G25: 0.28 | H25: 0.28 | I25: 0.36 | K25: 0.31 | L25: 0.26 | M25: 0.26 | N25: 0.26 | O25: 0.31 | P25: 0.31 | R25: =#DIV/0! -> #DIV/0! | T25: DATA | U25: =ESCALA!$A$4 -> 43892 | X25: 0.83333333 | Y25: 2782 | Z25: 940 | AA25: 1 | AB25: =IF('2'!AA25=1,(('2'!Z25*'2'!$AS$6*'2'!$AT$6)/('2'!Y25*0.0036)),IF('2'!AA25=2,(('2'!Z25*'2'!$AS$7*'2'!$AT$7)/('2'!Y25*0.0036)))) -> 62.415129 | AD25: =(('2'!AC25*'2'!$Q$10*1000000))/('2'!Y25*3600) -> 0 | AF25: =('2'!AE25/24)*0.454 -> 0 | AH25: =('2'!AG25/24)*0.454 -> 0 | AI25: 5000 | AJ25: =('2'!AI25/24)*0.454 -> 94.583333 | AL25: =('2'!AK25/24)*0.454 -> 0 | AN25: =('2'!AM25/24)*0.454 -> 0 | AP25: =('2'!AO25/24)*0.454 -> 0
A26: 0.66666667 | R26: =#DIV/0! -> #DIV/0! | X26: 0.875 | Y26: 2788 | Z26: 940 | AA26: 1 | AB26: =IF('2'!AA26=1,(('2'!Z26*'2'!$AS$6*'2'!$AT$6)/('2'!Y26*0.0036)),IF('2'!AA26=2,(('2'!Z26*'2'!$AS$7*'2'!$AT$7)/('2'!Y26*0.0036)))) -> 62.280807 | AD26: =(('2'!AC26*'2'!$Q$10*1000000))/('2'!Y26*3600) -> 0 | AF26: =('2'!AE26/24)*0.454 -> 0 | AH26: =('2'!AG26/24)*0.454 -> 0 | AI26: 5000 | AJ26: =('2'!AI26/24)*0.454 -> 94.583333 | AL26: =('2'!AK26/24)*0.454 -> 0 | AN26: =('2'!AM26/24)*0.454 -> 0 | AP26: =('2'!AO26/24)*0.454 -> 0
A27: Média | B27: =#DIV/0! -> #DIV/0! | C27: =#DIV/0! -> #DIV/0! | D27: =#DIV/0! -> #DIV/0! | E27: =#DIV/0! -> #DIV/0! | F27: =#DIV/0! -> #DIV/0! | G27: =#DIV/0! -> #DIV/0! | H27: =#DIV/0! -> #DIV/0! | I27: =#DIV/0! -> #DIV/0! | ... Q27: =#DIV/0! -> #DIV/0! | X27: 0.91666667 | Y27: 2781 | Z27: 940 | AA27: 1 | AB27: =IF('2'!AA27=1,(('2'!Z27*'2'!$AS$6*'2'!$AT$6)/('2'!Y27*0.0036)),IF('2'!AA27=2,(('2'!Z27*'2'!$AS$7*'2'!$AT$7)/('2'!Y27*0.0036)))) -> 62.437572 | AD27: =(('2'!AC27*'2'!$Q$10*1000000))/('2'!Y27*3600) -> 0 | AF27: =('2'!AE27/24)*0.454 -> 0 | AH27: =('2'!AG27/24)*0.454 -> 0 | AI27: 5000 | AJ27: =('2'!AI27/24)*0.454 -> 94.583333 | AL27: =('2'!AK27/24)*0.454 -> 0 | AN27: =('2'!AM27/24)*0.454 -> 0 | AP27: =('2'!AO27/24)*0.454 -> 0
A28: OBSERVAÇÕES | X28: 0.95833333 | Y28: 2760 | Z28: 940 | AA28: 1 | AB28: =IF('2'!AA28=1,(('2'!Z28*'2'!$AS$6*'2'!$AT$6)/('2'!Y28*0.0036)),IF('2'!AA28=2,(('2'!Z28*'2'!$AS$7*'2'!$AT$7)/('2'!Y28*0.0036)))) -> 62.912641 | AD28: =(('2'!AC28*'2'!$Q$10*1000000))/('2'!Y28*3600) -> 0 | AF28: =('2'!AE28/24)*0.454 -> 0 | AH28: =('2'!AG28/24)*0.454 -> 0 | AI28: 5000 | AJ28: =('2'!AI28/24)*0.454 -> 94.583333 | AL28: =('2'!AK28/24)*0.454 -> 0 | AN28: =('2'!AM28/24)*0.454 -> 0 | AP28: =('2'!AO28/24)*0.454 -> 0
X29: 1 | Y29: 2730 | Z29: 940 | AA29: 1 | AB29: =IF('2'!AA29=1,(('2'!Z29*'2'!$AS$6*'2'!$AT$6)/('2'!Y29*0.0036)),IF('2'!AA29=2,(('2'!Z29*'2'!$AS$7*'2'!$AT$7)/('2'!Y29*0.0036)))) -> 63.603989 | AD29: =(('2'!AC29*'2'!$Q$10*1000000))/('2'!Y29*3600) -> 0 | AF29: =('2'!AE29/24)*0.454 -> 0 | AH29: =('2'!AG29/24)*0.454 -> 0 | AI29: 5000 | AJ29: =('2'!AI29/24)*0.454 -> 94.583333 | AL29: =('2'!AK29/24)*0.454 -> 0 | AN29: =('2'!AM29/24)*0.454 -> 0 | AP29: =('2'!AO29/24)*0.454 -> 0
X30: Total | Y30: =SUM('2'!Y6:Y29)*3.6 -> 241945.2 | Z30: =SUM('2'!Z6:Z29) -> 22936 | AF30: =SUM('2'!AF6:AF29) -> 0 | AH30: =SUM('2'!AH6:AH29) -> 0 | AJ30: =SUM('2'!AJ6:AJ29) -> 1778.1667 | AL30: =SUM('2'!AL6:AL29) -> 255.375 | AN30: =SUM('2'!AN6:AN29) -> 255.375 | AP30: =SUM('2'!AP6:AP29) -> 0
X32: S.A.L (l) - (kg) | Z32: =SUMIF('2'!AA6:AA29,"=1",'2'!Z6:Z29) -> 22936 | AA32: ='2'!Z32*'2'!AS6 -> 30504.88 | AB32: =SUMIF('2'!$AA$6:$AA$29,"=1",'2'!$AB$6:$AB$29)/COUNTIF('2'!$AA$6:$AA$29,"=1") -> 63.063087 | AC32: =SUMIF('2'!AA6:AA29,"=1",'2'!AC6:AC29) -> 0
X33: PAC 18 (l) - (kg) | Z33: =SUMIF('2'!AA6:AA29,"=2",'2'!Z6:Z29) -> 0 | AA33: ='2'!Z33*'2'!AS7 -> 0 | AB33: =SUMIF('2'!$AA$6:$AA$29,"=2",'2'!$AB$6:$AB$29)/COUNTIF('2'!$AA$6:$AA$29,"=2") -> #DIV/0! | AC33: =SUMIF('2'!AA6:AA29,"=2",'2'!AC6:AC29) -> 0
X34: Média | Y34: =AVERAGE('2'!Y6:Y29) -> 2800.2917 | Z34: =AVERAGE('2'!Z6:Z29) -> 955.66667 | AC34: =SUM('2'!AC6:AC29)/COUNTIF('2'!AC6:AC29,"<>0") -> 0 | AD34: =SUM('2'!AD6:AD29)/COUNTIF('2'!AD6:AD29,"<>0") -> #DIV/0! | AF34: =AVERAGE('2'!AF6:AF29) -> 0 | AH34: =AVERAGE('2'!AH6:AH29) -> 0 | AJ34: ='2'!AJ30/24 -> 74.090278 | AL34: =AVERAGE('2'!AL6:AL29) -> 10.640625 | AN34: =AVERAGE('2'!AN6:AN29) -> 10.640625 | AP34: =AVERAGE('2'!AP6:AP29) -> 0
C35: Alcalinidade (mg/L) | F35: Ferro (mg/L) | I35: Manganês (mg/L) | L35: Alumínio (mg/L) | U35: TÉCNICO | X35: Decantadores | AA35: Filtros | AJ35: CLORAÇÃO INTERMEDIÁRIA | AO35: PÓS CLORAÇÃO
B36: HORA | C36: Bruta | D36: Dec. | E36: Trat (R-3) | F36: Bruta | G36: Filt. | H36: Trat (R-3) | I36: Bruta | J36: Filt. | K36: Trat (R-3) | L36: Trat (R-3) | X36: Lavados | AA36: Lavados
B37: 0.33333333 | C37: 80.7 | D37: 58.5 | E37: 50.4 | F37: 1 | G37: 0.1 | H37: 0.1 | I37: 0.1 | J37: 0.06 | K37: 0.03 | L37: 0.05 | U37: ='2'!V12 -> 0 | X37: HORAS OPERANDO | Z37: =COUNTA('2'!Z6:Z29) -> 24 | AJ37: CARRETA | AL37: CILINDROS | AO37: CARRETA | AQ37: CILINDROS
B38: 0.66666667 | AJ38: CONSUMO | AK38: =SUM('2'!AF30+'2'!AH30) -> 0 | AL38: CONSUMO | AM38: =SUM('2'!AL30+'2'!AN30) -> 510.75 | AO38: CONSUMO | AP38: ='2'!AJ30 -> 1778.1667 | AQ38: CONSUMO | AR38: ='2'!AP30 -> 0
A39: Nº amostras de água TRATADA | C39: Nº amostras de água FILTRADA | E39: Nº amostras de água tratada/filtrada FORA DO PADRÃO | J39: Nº amostras de água tratada/filtrada no PADRÃO | O39: Nº de amostras com turbidez menor ou igual a 0,5 NTU | R39: ÁGUA FILTRADA | S39: Nº de amostras com turbidez menor ou igual a 1,0 NTU | AJ39: DOSAGEM | AK39: =('2'!AK38/'2'!Y30)*1000 -> 0 | AL39: DOSAGEM | AM39: =('2'!AM38/'2'!Y30)*1000 -> 2.1110152 | AO39: DOSAGEM | AP39: =('2'!AP38/'2'!Y30)*1000 -> 7.3494604 | AQ39: DOSAGEM | AR39: =('2'!AR38/'2'!Y30)*1000 -> 0
A40: COR | B40: TURBIDEZ | C40: TURBIDEZ | E40: COR | G40: TURBIDEZ | J40: COR | L40: TURBIDEZ | X40: ESTOQUE DE COAGULANTE | AJ40: Consumo Total | AL40: =SUM('2'!AK38,'2'!AM38) -> 510.75 | AO40: Consumo Total | AQ40: =SUM('2'!AP38,'2'!AR38) -> 1778.1667
A41: =COUNTA('2'!E7:E18) -> 12 | B41: =COUNTA('2'!I7:I18) -> 12 | C41: =COUNTA('2'!J7:J18) -> 12 | D41: =COUNTA('2'!K7:K18) -> 12 | E41: =COUNTIF('2'!E7:E18,">15") -> 0 | G41: =COUNTIF('2'!J7:J18,">1") -> 0 | J41: ='2'!A41-'2'!E41 -> 12 | L41: ='2'!C41-'2'!G41 -> 12 | O41: =COUNTIF('2'!J7:J18,"<=0,5") -> 12 | S41: =COUNTIF('2'!J7:J18,"<=1,0") -> 12 | AJ41: Dosagem Final | AL41: =SUM(('2'!AK38+'2'!AM38)/'2'!Y30)*1000 -> 2.1110152 | AO41: Dosagem Final | AQ41: =SUM(('2'!AP38+'2'!AR38)/'2'!Y30)*1000 -> 7.3494604
O42: ÁGUA FILTRATADA | X42: SULFATO DE ALUMÍNIO
H43: Nº de amostras água tratada com turbidez <= 5,0 NTU | L43: Nº de amostras água tratada para aluminio | Q43: Nº de amostras com turbidez entre 0,5 e 1,0 NTU | X43: TINA 01 | Z43: TINA 02 | AB43: TINA 03 | AD43: TANQUE
...

Sheet 3
D2: CONTROLE DE ANÁLISE FÍSICO - QUÍMICAS \ ETA CASTELO BRANCO | AB2: CONTROLE DE PRODUTOS QUÍMICOS APLICADOS \ ETA CASTELO BRANCO
A4: HORA | B4: COR (Uc) | F4: TURBIDEZ (Ut) | K4: Ph | O4: CLORO RESIDUAL (mg/L) | R4: DOSAGEM DO COAGULANTE | T4: VAZÃO DA ETA | U4: TIPO DE COAGULANTE | V4: TÉCNICO | X4: Hora | Y4: Vazão ETA (l/s) | Z4: Vazão Coagulante (l/h) | AA4: Código | AB4: Dosagem (mg/l) | AC4: Vazão Polímero (l/h) | AD4: Dosagem (mg/l) | AE4: Pré 1 (Lib/dia) | AF4: Pré 1 (Kg/h) | AG4: Pré 2 (Lib/dia) | AH4: Pré 2 (Kg/h) | AI4: Pós (Lib/dia) | AJ4: Pós (Kg/h) | AK4: Pré 1 (Lib/dia) cilindros | AL4: Pré 1 (Kg/h) cilindros | AM4: Pré 2 (Lib/dia) cilindros | AN4: Pré 2 (Kg/h) cilindros | AO4: Pós (Lib/dia) cilindros | AP4: Pós (Kg/h) cilindros | AQ4: COAGULANTE | AU4: Tempo de Utilização (h)
AQ5: Codigo | AR5: Nome | AS5: d (g/ml) | AT5: C (%)
B6: Bruta | C6: DEC_1 | D6: DEC_2 | E6: TRAT | F6: Bruta | G6: DEC_1 | H6: DEC_2 | I6: TRAT | J6: FILT | K6: Bruta | L6: DEC_1 | M6: DEC_2 | N6: TRAT | O6: TRAT | P6: DEC_1 | Q6: DEC_2 | R6: L/h | S6: mg/l | T6: L/s | X6: 0.041666667 | Y6: 2773 | Z6: 940 | AA6: 1 | AB6: =IF('3'!AA6=1,(('3'!Z6*'3'!$AS$6*'3'!$AT$6)/('3'!Y6*0.0036)),IF('3'!AA6=2,(('3'!Z6*'3'!$AS$7*'3'!$AT$7)/('3'!Y6*0.0036)))) -> 62.617702 | AD6: =(('3'!AC6*'3'!$O$9*1000000))/('3'!Y6*3600) -> 0 | AF6: =('3'!AE6/24)*0.454 -> 0 | AH6: =('3'!AG6/24)*0.454 -> 0 | AI6: 5000 | AJ6: =('3'!AI6/24)*0.454 -> 94.583333 | AL6: =('3'!AK6/24)*0.454 -> 0 | AN6: =('3'!AM6/24)*0.454 -> 0 | AP6: =('3'!AO6/24)*0.454 -> 0 | AQ6: 1 | AR6: S.A.L | AS6: 1.33 | AT6: 0.5 | AU6: 0
A7: 0 | B7: 70 | C7: 12.5 | D7: 12.5 | E7: 2.5 | F7: 8.4 | G7: 1.3 | H7: 1.5 | I7: 0.3 | J7: 0.4 | K7: 7.3 | L7: 6.7 | M7: 6.7 | N7: 6.4 | O7: 2.7 | R7: ='2'!$Z$29 -> 940 | S7: ='2'!$AB$29 -> 63.603989 | T7: ='2'!$Y$29 -> 2730 | U7: =IF('3'!AA6=1,'3'!AR6,'3'!AR7) -> S.A.L | V7: =ESCALA!$C$4 -> 0 | X7: 0.083333333 | Y7: 2727 | Z7: 940 | AA7: 1 | AB7: =IF('3'!AA7=1,(('3'!Z7*'3'!$AS$6*'3'!$AT$6)/('3'!Y7*0.0036)),IF('3'!AA7=2,(('3'!Z7*'3'!$AS$7*'3'!$AT$7)/('3'!Y7*0.0036)))) -> 63.67396 | AD7: =(('3'!AC7*'3'!$O$9*1000000))/('3'!Y7*3600) -> 0 | AF7: =('3'!AE7/24)*0.454 -> 0 | AH7: =('3'!AG7/24)*0.454 -> 0 | AI7: 5000 | AJ7: =('3'!AI7/24)*0.454 -> 94.583333 | AL7: =('3'!AK7/24)*0.454 -> 0 | AN7: =('3'!AM7/24)*0.454 -> 0 | AP7: =('3'!AO7/24)*0.454 -> 0 | AQ7: 2 | AR7: PAC 18 | AS7: 1.377 | AT7: 1 | AU7: 24
A8: 0.083333333 | B8: 70 | C8: 12.5 | D8: 12.5 | E8: 2.5 | F8: 8.2 | G8: 1.3 | H8: 1.5 | I8: 0.3 | J8: 0.4 | K8: 7.3 | L8: 6.7 | M8: 6.7 | N8: 6.4 | O8: 2.7 | R8: ='3'!Z7 -> 940 | S8: ='3'!AB7 -> 63.67396 | T8: ='3'!Y7 -> 2727 | U8: =IF('3'!AA7=1,'3'!AR6,'3'!AR7) -> S.A.L | X8: 0.125 | Y8: 2727 | Z8: 940 | AA8: 1 | AB8: =IF('3'!AA8=1,(('3'!Z8*'3'!$AS$6*'3'!$AT$6)/('3'!Y8*0.0036)),IF('3'!AA8=2,(('3'!Z8*'3'!$AS$7*'3'!$AT$7)/('3'!Y8*0.0036)))) -> 63.67396 | AD8: =(('3'!AC8*'3'!$O$9*1000000))/('3'!Y8*3600) -> 0 | AF8: =('3'!AE8/24)*0.454 -> 0 | AH8: =('3'!AG8/24)*0.454 -> 0 | AI8: 5000 | AJ8: =('3'!AI8/24)*0.454 -> 94.583333 | AL8: =('3'!AK8/24)*0.454 -> 0 | AN8: =('3'!AM8/24)*0.454 -> 0 | AP8: =('3'!AO8/24)*0.454 -> 0 | AQ8: Polímero Catiônico
A9: 0.16666667 | B9: 70 | C9: 12.5 | D9: 12.5 | E9: 2.5 | F9: 8.1 | G9: 1.2 | H9: 1.6 | I9: 0.4 | J9: 0.3 | K9: 7.3 | L9: 6.7 | M9: 6.7 | N9: 6.4 | O9: 2.8 | R9: ='3'!Z9 -> 940 | S9: ='3'!AB9 -> 63.534171 | T9: ='3'!Y9 -> 2733 | U9: =IF('3'!AA9=1,'3'!AR6,'3'!AR7) -> S.A.L | X9: 0.16666667 | Y9: 2733 | Z9: 940 | AA9: 1 | AB9: =IF('3'!AA9=1,(('3'!Z9*'3'!$AS$6*'3'!$AT$6)/('3'!Y9*0.0036)),IF('3'!AA9=2,(('3'!Z9*'3'!$AS$7*'3'!$AT$7)/('3'!Y9*0.0036)))) -> 63.534171 | AD9: =(('3'!AC9*'3'!$O$9*1000000))/('3'!Y9*3600) -> 0 | AF9: =('3'!AE9/24)*0.454 -> 0 | AH9: =('3'!AG9/24)*0.454 -> 0 | AI9: 5000 | AJ9: =('3'!AI9/24)*0.454 -> 94.583333 | AL9: =('3'!AK9/24)*0.454 -> 0 | AN9: =('3'!AM9/24)*0.454 -> 0 | AP9: =('3'!AO9/24)*0.454 -> 0 | AQ9: Nome | AT9: C (%)
A10: 0.25 | B10: 70 | C10: 12.5 | D10: 12.5 | E10: 2.5 | F10: 8 | G10: 1.2 | H10: 1.6 | I10: 0.4 | J10: 0.3 | K10: 7.3 | L10: 6.7 | M10: 6.7 | N10: 6.4 | O10: 2.8 | R10: ='3'!Z11 -> 940 | S10: ='3'!AB11 -> 64.406116 | T10: ='3'!Y11 -> 2696 | U10: =IF('3'!AA11=1,'3'!AR6,'3'!AR7) -> S.A.L | X10: 0.20833333 | Y10: 2767 | Z10: 940 | AA10: 1 | AB10: =IF('3'!AA10=1,(('3'!Z10*'3'!$AS$6*'3'!$AT$6)/('3'!Y10*0.0036)),IF('3'!AA10=2,(('3'!Z10*'3'!$AS$7*'3'!$AT$7)/('3'!Y10*0.0036)))) -> 62.753484 | AD10: =(('3'!AC10*'3'!$O$9*1000000))/('3'!Y10*3600) -> 0 | AF10: =('3'!AE10/24)*0.454 -> 0 | AH10: =('3'!AG10/24)*0.454 -> 0 | AI10: 5000 | AJ10: =('3'!AI10/24)*0.454 -> 94.583333 | AL10: =('3'!AK10/24)*0.454 -> 0 | AN10: =('3'!AM10/24)*0.454 -> 0 | AP10: =('3'!AO10/24)*0.454 -> 0 | AQ10: Aguapol 200 | AT10: 0.002
A11: 0.33333333 | B11: 60 | C11: 12.5 | D11: 12.5 | E11: 2.5 | F11: 7.7 | G11: 1.6 | H11: 1.6 | I11: 0.4 | J11: 0.5 | K11: 7.3 | L11: 6.7 | M11: 6.7 | N11: 6.4 | O11: 2.8 | R11: ='3'!Z13 -> 940 | S11: ='3'!AB13 -> 62.347895 | T11: ='3'!Y13 -> 2785 | U11: =IF('3'!AA13=1,'3'!AR6,'3'!AR7) -> S.A.L | X11: 0.25 | Y11: 2696 | Z11: 940 | AA11: 1 | AB11: =IF('3'!AA11=1,(('3'!Z11*'3'!$AS$6*'3'!$AT$6)/('3'!Y11*0.0036)),IF('3'!AA11=2,(('3'!Z11*'3'!$AS$7*'3'!$AT$7)/('3'!Y11*0.0036)))) -> 64.406116 | AD11: =(('3'!AC11*'3'!$O$9*1000000))/('3'!Y11*3600) -> 0 | AF11: =('3'!AE11/24)*0.454 -> 0 | AH11: =('3'!AG11/24)*0.454 -> 0 | AI11: 5000 | AJ11: =('3'!AI11/24)*0.454 -> 94.583333 | AL11: =('3'!AK11/24)*0.454 -> 0 | AN11: =('3'!AM11/24)*0.454 -> 0 | AP11: =('3'!AO11/24)*0.454 -> 0
A12: 0.41666667 | B12: 60 | C12: 12.5 | D12: 12.5 | E12: 2.5 | F12: 7.8 | G12: 1.6 | H12: 1.9 | I12: 0.4 | J12: 0.5 | K12: 7.3 | L12: 6.7 | M12: 6.7 | N12: 6.4 | O12: 2.8 | R12: ='3'!Z15 -> 940 | S12: ='3'!AB15 -> 62.258476 | T12: ='3'!Y15 -> 2789 | U12: =IF('3'!AA15=1,'3'!AR6,'3'!AR7) -> S.A.L | V12: =ESCALA!$B$5 -> 0 | X12: 0.29166667 | Y12: 2754 | Z12: 940 | AA12: 1 | AB12: =IF('3'!AA12=1,(('3'!Z12*'3'!$AS$6*'3'!$AT$6)/('3'!Y12*0.0036)),IF('3'!AA12=2,(('3'!Z12*'3'!$AS$7*'3'!$AT$7)/('3'!Y12*0.0036)))) -> 63.049705 | AD12: =(('3'!AC12*'3'!$O$9*1000000))/('3'!Y12*3600) -> 0 | AF12: =('3'!AE12/24)*0.454 -> 0 | AH12: =('3'!AG12/24)*0.454 -> 0 | AI12: 5000 | AJ12: =('3'!AI12/24)*0.454 -> 94.583333 | AL12: =('3'!AK12/24)*0.454 -> 0 | AN12: =('3'!AM12/24)*0.454 -> 0 | AP12: =('3'!AO12/24)*0.454 -> 0
A13: 0.5 | B13: 60 | C13: 12.5 | D13: 12.5 | E13: 2.5 | F13: 8.1 | G13: 1.6 | H13: 1.9 | I13: 0.5 | J13: 0.5 | K13: 7.3 | L13: 6.7 | M13: 6.7 | N13: 6.4 | O13: 2.8 | R13: ='3'!Z17 -> 940 | S13: ='3'!AB17 -> 61.859241 | T13: ='3'!Y17 -> 2807 | U13: =IF('3'!AA17=1,'3'!AR6,'3'!AR7) -> S.A.L | X13: 0.33333333 | Y13: 2785 | Z13: 940 | AA13: 1 | AB13: =IF('3'!AA13=1,(('3'!Z13*'3'!$AS$6*'3'!$AT$6)/('3'!Y13*0.0036)),IF('3'!AA13=2,(('3'!Z13*'3'!$AS$7*'3'!$AT$7)/('3'!Y13*0.0036)))) -> 62.347895 | AD13: =(('3'!AC13*'3'!$O$9*1000000))/('3'!Y13*3600) -> 0 | AF13: =('3'!AE13/24)*0.454 -> 0 | AH13: =('3'!AG13/24)*0.454 -> 0 | AI13: 5000 | AJ13: =('3'!AI13/24)*0.454 -> 94.583333 | AL13: =('3'!AK13/24)*0.454 -> 0 | AN13: =('3'!AM13/24)*0.454 -> 0 | AP13: =('3'!AO13/24)*0.454 -> 0
A14: 0.58333333 | B14: 60 | C14: 12.5 | D14: 12.5 | E14: 2.5 | F14: 8 | G14: 8 | H14: 1.7 | I14: 0.5 | J14: 0.6 | K14: 7.3 | L14: 6.7 | M14: 6.7 | N14: 6.4 | O14: 3 | R14: ='3'!Z19 -> 940 | S14: ='3'!AB19 -> 63.279478 | T14: ='3'!Y19 -> 2744 | U14: =IF('3'!AA19=1,'3'!AR6,'3'!AR7) -> S.A.L | X14: 0.375 | Y14: 2814 | Z14: 940 | AA14: 1 | AB14: =IF('3'!AA14=1,(('3'!Z14*'3'!$AS$6*'3'!$AT$6)/('3'!Y14*0.0036)),IF('3'!AA14=2,(('3'!Z14*'3'!$AS$7*'3'!$AT$7)/('3'!Y14*0.0036)))) -> 61.705362 | AD14: =(('3'!AC14*'3'!$O$9*1000000))/('3'!Y14*3600) -> 0 | AF14: =('3'!AE14/24)*0.454 -> 0 | AH14: =('3'!AG14/24)*0.454 -> 0 | AI14: 5000 | AJ14: =('3'!AI14/24)*0.454 -> 94.583333 | AL14: =('3'!AK14/24)*0.454 -> 0 | AN14: =('3'!AM14/24)*0.454 -> 0 | AP14: =('3'!AO14/24)*0.454 -> 0
A15: 0.66666667 | B15: 60 | C15: 12.5 | D15: 12.5 | E15: 2.5 | F15: 8.2 | G15: 1.7 | H15: 1.9 | I15: 0.5 | J15: 0.6 | K15: 7.3 | L15: 6.7 | M15: 6.7 | N15: 6.4 | O15: 3 | R15: ='3'!Z21 -> 940 | S15: ='3'!AB21 -> 60.375135 | T15: ='3'!Y21 -> 2876 | U15: =IF('3'!AA21=1,'3'!AR6,'3'!AR7) -> S.A.L | X15: 0.41666667 | Y15: 2789 | Z15: 940 | AA15: 1 | AB15: =IF('3'!AA15=1,(('3'!Z15*'3'!$AS$6*'3'!$AT$6)/('3'!Y15*0.0036)),IF('3'!AA15=2,(('3'!Z15*'3'!$AS$7*'3'!$AT$7)/('3'!Y15*0.0036)))) -> 62.258476 | AD15: =(('3'!AC15*'3'!$O$9*1000000))/('3'!Y15*3600) -> 0 | AF15: =('3'!AE15/24)*0.454 -> 0 | AH15: =('3'!AG15/24)*0.454 -> 0 | AI15: 5000 | AJ15: =('3'!AI15/24)*0.454 -> 94.583333 | AL15: =('3'!AK15/24)*0.454 -> 0 | AN15: =('3'!AM15/24)*0.454 -> 0 | AP15: =('3'!AO15/24)*0.454 -> 0
A16: 0.75 | B16: 60 | C16: 12.5 | D16: 12.5 | E16: 2.5 | F16: 8.4 | G16: 1.7 | H16: 1.8 | I16: 0.5 | J16: 0.6 | K16: 7.3 | L16: 6.7 | M16: 6.7 | N16: 6.4 | O16: 3.3 | R16: ='3'!Z23 -> 940 | S16: ='3'!AB23 -> 61.39989 | T16: ='3'!Y23 -> 2828 | U16: =IF('3'!AA23=1,'3'!AR6,'3'!AR7) -> S.A.L | X16: 0.45833333 | Y16: 2791 | Z16: 940 | AA16: 1 | AB16: =IF('3'!AA16=1,(('3'!Z16*'3'!$AS$6*'3'!$AT$6)/('3'!Y16*0.0036)),IF('3'!AA16=2,(('3'!Z16*'3'!$AS$7*'3'!$AT$7)/('3'!Y16*0.0036)))) -> 62.213862 | AD16: =(('3'!AC16*'3'!$O$9*1000000))/('3'!Y16*3600) -> 0 | AF16: =('3'!AE16/24)*0.454 -> 0 | AH16: =('3'!AG16/24)*0.454 -> 0 | AI16: 5000 | AJ16: =('3'!AI16/24)*0.454 -> 94.583333 | AL16: =('3'!AK16/24)*0.454 -> 0 | AN16: =('3'!AM16/24)*0.454 -> 0 | AP16: =('3'!AO16/24)*0.454 -> 0
A17: 0.83333333 | B17: 50 | C17: 10 | D17: 12.5 | E17: 2.5 | F17: 8.4 | G17: 1.4 | H17: 2 | I17: 0.5 | J17: 0.4 | K17: 7.3 | L17: 6.7 | M17: 6.7 | N17: 6.4 | O17: 3.7 | R17: ='3'!Z25 -> 940 | S17: ='3'!AB25 -> 61.269897 | T17: ='3'!Y25 -> 2834 | U17: =IF('3'!AA25=1,'3'!AR6,'3'!AR7) -> S.A.L | V17: =ESCALA!$C$5 -> 0 | X17: 0.5 | Y17: 2807 | Z17: 940 | AA17: 1 | AB17: =IF('3'!AA17=1,(('3'!Z17*'3'!$AS$6*'3'!$AT$6)/('3'!Y17*0.0036)),IF('3'!AA17=2,(('3'!Z17*'3'!$AS$7*'3'!$AT$7)/('3'!Y17*0.0036)))) -> 61.859241 | AD17: =(('3'!AC17*'3'!$O$9*1000000))/('3'!Y17*3600) -> 0 | AF17: =('3'!AE17/24)*0.454 -> 0 | AH17: =('3'!AG17/24)*0.454 -> 0 | AI17: 5000 | AJ17: =('3'!AI17/24)*0.454 -> 94.583333 | AL17: =('3'!AK17/24)*0.454 -> 0 | AN17: =('3'!AM17/24)*0.454 -> 0 | AP17: =('3'!AO17/24)*0.454 -> 0
A18: 0.91666667 | B18: 50 | C18: 10 | D18: 12.5 | E18: 2.5 | F18: 8.4 | G18: 1.4 | H18: 2 | I18: 0.5 | J18: 0.4 | K18: 7.3 | L18: 6.7 | M18: 6.7 | N18: 6.4 | O18: 3.7 | R18: ='3'!Z27 -> 940 | S18: ='3'!AB27 -> 61.749249 | T18: ='3'!Y27 -> 2812 | U18: =IF('3'!AA27=1,'3'!AR6,'3'!AR7) -> S.A.L | X18: 0.54166667 | Y18: 2878 | Z18: 940 | AA18: 1 | AB18: =IF('3'!AA18=1,(('3'!Z18*'3'!$AS$6*'3'!$AT$6)/('3'!Y18*0.0036)),IF('3'!AA18=2,(('3'!Z18*'3'!$AS$7*'3'!$AT$7)/('3'!Y18*0.0036)))) -> 60.333179 | AD18: =(('3'!AC18*'3'!$O$9*1000000))/('3'!Y18*3600) -> 0 | AF18: =('3'!AE18/24)*0.454 -> 0 | AH18: =('3'!AG18/24)*0.454 -> 0 | AI18: 5000 | AJ18: =('3'!AI18/24)*0.454 -> 94.583333 | AL18: =('3'!AK18/24)*0.454 -> 0 | AN18: =('3'!AM18/24)*0.454 -> 0 | AP18: =('3'!AO18/24)*0.454 -> 0
A19: Média | B19: {=IF('3'!B7:B18>0.01,AVERAGE('3'!B7:B18),"")} -> 61.666667 | C19: {=IF('3'!C7:C18>0.01,AVERAGE('3'!C7:C18),"")} -> 12.083333 | D19: {=IF('3'!D7:D18>0.01,AVERAGE('3'!D7:D18),"")} -> 12.5 | E19: {=IF('3'!E7:E18>0.01,AVERAGE('3'!E7:E18),"")} -> 2.5 | F19: {=IF('3'!F7:F18>0.01,AVERAGE('3'!F7:F18),"")} -> 8.1416667 | G19: {=IF('3'!G7:G18>0.01,AVERAGE('3'!G7:G18),"")} -> 2 | H19: {=IF('3'!H7:H18>0.01,AVERAGE('3'!H7:H18),"")} -> 1.75 | I19: {=IF('3'!I7:I18>0.01,AVERAGE('3'!I7:I18),"")} -> 0.43333333 | ... S19: {=IF('3'!S7:S18>0.01,AVERAGE('3'!S7:S18),"")} -> 62.479791 | X19: 0.58333333 | Y19: 2744 | Z19: 940 | AA19: 1 | AB19: =IF('3'!AA19=1,(('3'!Z19*'3'!$AS$6*'3'!$AT$6)/('3'!Y19*0.0036)),IF('3'!AA19=2,(('3'!Z19*'3'!$AS$7*'3'!$AT$7)/('3'!Y19*0.0036)))) -> 63.279478 | AD19: =(('3'!AC19*'3'!$O$9*1000000))/('3'!Y19*3600) -> 0 | AF19: =('3'!AE19/24)*0.454 -> 0 | AH19: =('3'!AG19/24)*0.454 -> 0 | AI19: 5000 | AJ19: =('3'!AI19/24)*0.454 -> 94.583333 | AL19: =('3'!AK19/24)*0.454 -> 0 | AN19: =('3'!AM19/24)*0.454 -> 0 | AP19: =('3'!AO19/24)*0.454 -> 0
A20: Máximo | B20: =MAX('3'!B7:B18) -> 70 | C20: =MAX('3'!C7:C18) -> 12.5 | D20: =MAX('3'!D7:D18) -> 12.5 | E20: =MAX('3'!E7:E18) -> 2.5 | F20: =MAX('3'!F7:F18) -> 8.4 | G20: =MAX('3'!G7:G18) -> 8 | H20: =MAX('3'!H7:H18) -> 2 | I20: =MAX('3'!I7:I18) -> 0.5 | ... S20: =MAX('3'!S7:S18) -> 64.406116 | X20: 0.625 | Y20: 2843 | Z20: 940 | AA20: 1 | AB20: =IF('3'!AA20=1,(('3'!Z20*'3'!$AS$6*'3'!$AT$6)/('3'!Y20*0.0036)),IF('3'!AA20=2,(('3'!Z20*'3'!$AS$7*'3'!$AT$7)/('3'!Y20*0.0036)))) -> 61.075937 | AD20: =(('3'!AC20*'3'!$O$9*1000000))/('3'!Y20*3600) -> 0 | AF20: =('3'!AE20/24)*0.454 -> 0 | AH20: =('3'!AG20/24)*0.454 -> 0 | AI20: 5000 | AJ20: =('3'!AI20/24)*0.454 -> 94.583333 | AL20: =('3'!AK20/24)*0.454 -> 0 | AN20: =('3'!AM20/24)*0.454 -> 0 | AP20: =('3'!AO20/24)*0.454 -> 0
A21: Mínimo | B21: =MIN('3'!B7:B18) -> 50 | C21: =MIN('3'!C7:C18) -> 10 | D21: =MIN('3'!D7:D18) -> 12.5 | E21: =MIN('3'!E7:E18) -> 2.5 | F21: =MIN('3'!F7:F18) -> 7.7 | G21: =MIN('3'!G7:G18) -> 1.2 | H21: =MIN('3'!H7:H18) -> 1.5 | I21: =MIN('3'!I7:I18) -> 0.3 | ... S21: =MIN('3'!S7:S18) -> 60.375135 | X21: 0.66666667 | Y21: 2876 | Z21: 940 | AA21: 1 | AB21: =IF('3'!AA21=1,(('3'!Z21*'3'!$AS$6*'3'!$AT$6)/('3'!Y21*0.0036)),IF('3'!AA21=2,(('3'!Z21*'3'!$AS$7*'3'!$AT$7)/('3'!Y21*0.0036)))) -> 60.375135 | AD21: =(('3'!AC21*'3'!$O$9*1000000))/('3'!Y21*3600) -> 0 | AF21: =('3'!AE21/24)*0.454 -> 0 | AH21: =('3'!AG21/24)*0.454 -> 0 | AI21: 5000 | AJ21: =('3'!AI21/24)*0.454 -> 94.583333 | AL21: =('3'!AK21/24)*0.454 -> 0 | AN21: =('3'!AM21/24)*0.454 -> 0 | AP21: =('3'!AO21/24)*0.454 -> 0
R22: Total | X22: 0.70833333 | Y22: 2777 | Z22: 940 | AA22: 1 | AB22: =IF('3'!AA22=1,(('3'!Z22*'3'!$AS$6*'3'!$AT$6)/('3'!Y22*0.0036)),IF('3'!AA22=2,(('3'!Z22*'3'!$AS$7*'3'!$AT$7)/('3'!Y22*0.0036)))) -> 62.527508 | AD22: =(('3'!AC22*'3'!$O$9*1000000))/('3'!Y22*3600) -> 0 | AF22: =('3'!AE22/24)*0.454 -> 0 | AH22: =('3'!AG22/24)*0.454 -> 0 | AI22: 5000 | AJ22: =('3'!AI22/24)*0.454 -> 94.583333 | AL22: =('3'!AK22/24)*0.454 -> 0 | AN22: =('3'!AM22/24)*0.454 -> 0 | AP22: =('3'!AO22/24)*0.454 -> 0
A23: TURBIDEZ DOS FILTROS DA 1ª E 2ª ETAPAS | R23: 440 | S23: Litros | X23: 0.75 | Y23: 2828 | Z23: 940 | AA23: 1 | AB23: =IF('3'!AA23=1,(('3'!Z23*'3'!$AS$6*'3'!$AT$6)/('3'!Y23*0.0036)),IF('3'!AA23=2,(('3'!Z23*'3'!$AS$7*'3'!$AT$7)/('3'!Y23*0.0036)))) -> 61.39989 | AD23: =(('3'!AC23*'3'!$O$9*1000000))/('3'!Y23*3600) -> 0 | AF23: =('3'!AE23/24)*0.454 -> 0 | AH23: =('3'!AG23/24)*0.454 -> 0 | AI23: 5000 | AJ23: =('3'!AI23/24)*0.454 -> 94.583333 | AL23: =('3'!AK23/24)*0.454 -> 0 | AN23: =('3'!AM23/24)*0.454 -> 0 | AP23: =('3'!AO23/24)*0.454 -> 0
